Workbook

Sheet Hypothèses
A1: Boulangerie artisanale — Hypothèses
A2: Métier : boulangerie-pâtisserie artisanale | CA cible ≈ 310 k€ en Année 1, sur 3 ans | Cellules bleues = modifiables
A4: Chiffre d'affaires annuel HT — Année 1 (€) | C4: 310000
A5: Taux de TVA moyen sur les ventes (%) | C5: 0.055
A6: Taux de TVA moyen sur les achats (%) | C6: 0.11
A7: Trésorerie disponible au 1er janvier Année 1 (€) | C7: 12000
A8: Cotisations sociales du dirigeant (TNS) — par trimestre, Année 1 (€) | C8: 3200
A9: Remboursement emprunt matériel — mensualité fixe (€) | C9: 480
A10: Part du CA encaissée le mois même (vente comptoir cash/CB) (%) | C10: 1
A11: Part du CA encaissée à M-1 (%) | C11: 0
A12: Part du CA encaissée à M-2 (%) | C12: 0 | D12: Contrôle (doit = 100%) | E12: =C10+C11+C12
A13: Taux de croissance du CA — par an (%) | C13: 0.025
A14: Taux d'inflation des prix d'achat — par an (%) | C14: 0.03
A16: Mois (motif répété chaque année) | C16: Jan | D16: Fév | E16: Mar | F16: Avr | G16: Mai | H16: Jui | I16: Jui | J16: Aoû | K16: Sep | L16: Oct | M16: Nov | N16: Déc
A17: Indice de saisonnalité (1 = mois moyen) | C17: 1.08 | D17: 0.97 | E17: 0.98 | F17: 1.03 | G17: 1 | H17: 0.97 | I17: 0.93 | J17: 0.75 | K17: 1.02 | L17: 1.02 | M17: 1.02 | N17: 1.18
A18: Poids du mois dans l'année (%, normalisé) | C18: =C17/SUM($C$17:$N$17) | D18: =D17/SUM($C$17:$N$17) | E18: =E17/SUM($C$17:$N$17) | F18: =F17/SUM($C$17:$N$17) | G18: =G17/SUM($C$17:$N$17) | H18: =H17/SUM($C$17:$N$17) | I18: =I17/SUM($C$17:$N$17) | J18: =J17/SUM($C$17:$N$17) | ... N18: =N17/SUM($C$17:$N$17)
A20: Note saisonnalité : -25% en août (congés), pic +18% en décembre (fêtes), +8% en janvier (galette des rois). Ce même profil se répète à l'identique chaque année.
A21: Note TVA : les ventes de boulangerie sont taxées à 5,5% alors que les achats (énergie, services, équipement) sont en grande partie à 20% → la boulangerie est structurellement en CRÉDIT de TVA. C'est pourquoi le décaissement TVA du Plan de trésorerie reste à 0 dans ce scénario (résultat cohérent, pas une erreur).
A22: Note évolution 3 ans : le CA croît de 2,5%/an mais les prix d'achat augmentent de 3%/an (hausse non totalement répercutée sur les prix de vente) → la marge se resserre progressivement (≈7,6% → 2,3% → 1,9%), comme observé sur le secteur en 2023-2025. Les lignes « commodités » (farine, sucre, chocolat, électricité, gaz) utilisent en plus une simulation de fluctuation mensuelle réaliste (pas une simple inflation lissée).
A24: Légende
A25: ■ | B25: Saisie modifiable (hypothèse)
A26: ■ | B26: Formule calculée automatiquement
A27: ■ | B27: Lien vers un autre onglet
A28: ■ | B28: Prix indicatif en attente de connexion à une API de prix de marché (voir onglet Benchmarks & sources)

Sheet Revenus
A1: Boulangerie — Revenus mensuels (3 ans)
A2: Répartition du CA par famille de produits × saisonnalité × croissance annuelle (lien automatique vers Hypothèses)
C3: ANNÉE 1 | O3: ANNÉE 2 | AA3: ANNÉE 3
A4: Source de revenus | B4: % du CA annuel | C4: Jan A1 | D4: Fév A1 | E4: Mar A1 | F4: Avr A1 | G4: Mai A1 | H4: Jui A1 | I4: Jui A1 | J4: Aoû A1 | K4: Sep A1 | L4: Oct A1 | M4: Nov A1 | N4: Déc A1 | O4: Jan A2 | P4: Fév A2 | Q4: Mar A2 | R4: Avr A2 | S4: Mai A2 | T4: Jui A2 | U4: Jui A2 | V4: Aoû A2 | W4: Sep A2 | X4: Oct A2 | Y4: Nov A2 | Z4: Déc A2 | AA4: Jan A3 | AB4: Fév A3 | AC4: Mar A3 | AD4: Avr A3 | AE4: Mai A3 | AF4: Jui A3 | AG4: Jui A3 | AH4: Aoû A3 | AI4: Sep A3 | AJ4: Oct A3 | AK4: Nov A3 | AL4: Déc A3 | AM4: Total A1 | AN4: Total A2 | AO4: Total A3 | AP4: Total 3 ans
A5: Pain (baguettes, pains spéciaux, pains de tradition) | B5: 0.45 | C5: =Hypothèses!$C$4*$B5*Hypothèses!C$18*(1+Hypothèses!$C$13)^0 | D5: =Hypothèses!$C$4*$B5*Hypothèses!D$18*(1+Hypothèses!$C$13)^0 | E5: =Hypothèses!$C$4*$B5*Hypothèses!E$18*(1+Hypothèses!$C$13)^0 | F5: =Hypothèses!$C$4*$B5*Hypothèses!F$18*(1+Hypothèses!$C$13)^0 | G5: =Hypothèses!$C$4*$B5*Hypothèses!G$18*(1+Hypothèses!$C$13)^0 | H5: =Hypothèses!$C$4*$B5*Hypothèses!H$18*(1+Hypothèses!$C$13)^0 | I5: =Hypothèses!$C$4*$B5*Hypothèses!I$18*(1+Hypothèses!$C$13)^0 | J5: =Hypothèses!$C$4*$B5*Hypothèses!J$18*(1+Hypothèses!$C$13)^0 | ... N5: =Hypothèses!$C$4*$B5*Hypothèses!N$18*(1+Hypothèses!$C$13)^0 | O5: =Hypothèses!$C$4*$B5*Hypothèses!C$18*(1+Hypothèses!$C$13)^1 | P5: =Hypothèses!$C$4*$B5*Hypothèses!D$18*(1+Hypothèses!$C$13)^1 | Q5: =Hypothèses!$C$4*$B5*Hypothèses!E$18*(1+Hypothèses!$C$13)^1 | R5: =Hypothèses!$C$4*$B5*Hypothèses!F$18*(1+Hypothèses!$C$13)^1 | S5: =Hypothèses!$C$4*$B5*Hypothèses!G$18*(1+Hypothèses!$C$13)^1 | T5: =Hypothèses!$C$4*$B5*Hypothèses!H$18*(1+Hypothèses!$C$13)^1 | U5: =Hypothèses!$C$4*$B5*Hypothèses!I$18*(1+Hypothèses!$C$13)^1 | V5: =Hypothèses!$C$4*$B5*Hypothèses!J$18*(1+Hypothèses!$C$13)^1 | ... Z5: =Hypothèses!$C$4*$B5*Hypothèses!N$18*(1+Hypothèses!$C$13)^1 | AA5: =Hypothèses!$C$4*$B5*Hypothèses!C$18*(1+Hypothèses!$C$13)^2 | AB5: =Hypothèses!$C$4*$B5*Hypothèses!D$18*(1+Hypothèses!$C$13)^2 | AC5: =Hypothèses!$C$4*$B5*Hypothèses!E$18*(1+Hypothèses!$C$13)^2 | AD5: =Hypothèses!$C$4*$B5*Hypothèses!F$18*(1+Hypothèses!$C$13)^2 | AE5: =Hypothèses!$C$4*$B5*Hypothèses!G$18*(1+Hypothèses!$C$13)^2 | AF5: =Hypothèses!$C$4*$B5*Hypothèses!H$18*(1+Hypothèses!$C$13)^2 | AG5: =Hypothèses!$C$4*$B5*Hypothèses!I$18*(1+Hypothèses!$C$13)^2 | AH5: =Hypothèses!$C$4*$B5*Hypothèses!J$18*(1+Hypothèses!$C$13)^2 | ... AL5: =Hypothèses!$C$4*$B5*Hypothèses!N$18*(1+Hypothèses!$C$13)^2 | AM5: =SUM(C5:N5) | AN5: =SUM(O5:Z5) | AO5: =SUM(AA5:AL5) | AP5: =SUM(AM5:AO5)
A6: Viennoiserie (croissants, pains au chocolat...) | B6: 0.2 | C6: =Hypothèses!$C$4*$B6*Hypothèses!C$18*(1+Hypothèses!$C$13)^0 | D6: =Hypothèses!$C$4*$B6*Hypothèses!D$18*(1+Hypothèses!$C$13)^0 | E6: =Hypothèses!$C$4*$B6*Hypothèses!E$18*(1+Hypothèses!$C$13)^0 | F6: =Hypothèses!$C$4*$B6*Hypothèses!F$18*(1+Hypothèses!$C$13)^0 | G6: =Hypothèses!$C$4*$B6*Hypothèses!G$18*(1+Hypothèses!$C$13)^0 | H6: =Hypothèses!$C$4*$B6*Hypothèses!H$18*(1+Hypothèses!$C$13)^0 | I6: =Hypothèses!$C$4*$B6*Hypothèses!I$18*(1+Hypothèses!$C$13)^0 | J6: =Hypothèses!$C$4*$B6*Hypothèses!J$18*(1+Hypothèses!$C$13)^0 | ... N6: =Hypothèses!$C$4*$B6*Hypothèses!N$18*(1+Hypothèses!$C$13)^0 | O6: =Hypothèses!$C$4*$B6*Hypothèses!C$18*(1+Hypothèses!$C$13)^1 | P6: =Hypothèses!$C$4*$B6*Hypothèses!D$18*(1+Hypothèses!$C$13)^1 | Q6: =Hypothèses!$C$4*$B6*Hypothèses!E$18*(1+Hypothèses!$C$13)^1 | R6: =Hypothèses!$C$4*$B6*Hypothèses!F$18*(1+Hypothèses!$C$13)^1 | S6: =Hypothèses!$C$4*$B6*Hypothèses!G$18*(1+Hypothèses!$C$13)^1 | T6: =Hypothèses!$C$4*$B6*Hypothèses!H$18*(1+Hypothèses!$C$13)^1 | U6: =Hypothèses!$C$4*$B6*Hypothèses!I$18*(1+Hypothèses!$C$13)^1 | V6: =Hypothèses!$C$4*$B6*Hypothèses!J$18*(1+Hypothèses!$C$13)^1 | ... Z6: =Hypothèses!$C$4*$B6*Hypothèses!N$18*(1+Hypothèses!$C$13)^1 | AA6: =Hypothèses!$C$4*$B6*Hypothèses!C$18*(1+Hypothèses!$C$13)^2 | AB6: =Hypothèses!$C$4*$B6*Hypothèses!D$18*(1+Hypothèses!$C$13)^2 | AC6: =Hypothèses!$C$4*$B6*Hypothèses!E$18*(1+Hypothèses!$C$13)^2 | AD6: =Hypothèses!$C$4*$B6*Hypothèses!F$18*(1+Hypothèses!$C$13)^2 | AE6: =Hypothèses!$C$4*$B6*Hypothèses!G$18*(1+Hypothèses!$C$13)^2 | AF6: =Hypothèses!$C$4*$B6*Hypothèses!H$18*(1+Hypothèses!$C$13)^2 | AG6: =Hypothèses!$C$4*$B6*Hypothèses!I$18*(1+Hypothèses!$C$13)^2 | AH6: =Hypothèses!$C$4*$B6*Hypothèses!J$18*(1+Hypothèses!$C$13)^2 | ... AL6: =Hypothèses!$C$4*$B6*Hypothèses!N$18*(1+Hypothèses!$C$13)^2 | AM6: =SUM(C6:N6) | AN6: =SUM(O6:Z6) | AO6: =SUM(AA6:AL6) | AP6: =SUM(AM6:AO6)
A7: Pâtisserie | B7: 0.15 | C7: =Hypothèses!$C$4*$B7*Hypothèses!C$18*(1+Hypothèses!$C$13)^0 | D7: =Hypothèses!$C$4*$B7*Hypothèses!D$18*(1+Hypothèses!$C$13)^0 | E7: =Hypothèses!$C$4*$B7*Hypothèses!E$18*(1+Hypothèses!$C$13)^0 | F7: =Hypothèses!$C$4*$B7*Hypothèses!F$18*(1+Hypothèses!$C$13)^0 | G7: =Hypothèses!$C$4*$B7*Hypothèses!G$18*(1+Hypothèses!$C$13)^0 | H7: =Hypothèses!$C$4*$B7*Hypothèses!H$18*(1+Hypothèses!$C$13)^0 | I7: =Hypothèses!$C$4*$B7*Hypothèses!I$18*(1+Hypothèses!$C$13)^0 | J7: =Hypothèses!$C$4*$B7*Hypothèses!J$18*(1+Hypothèses!$C$13)^0 | ... N7: =Hypothèses!$C$4*$B7*Hypothèses!N$18*(1+Hypothèses!$C$13)^0 | O7: =Hypothèses!$C$4*$B7*Hypothèses!C$18*(1+Hypothèses!$C$13)^1 | P7: =Hypothèses!$C$4*$B7*Hypothèses!D$18*(1+Hypothèses!$C$13)^1 | Q7: =Hypothèses!$C$4*$B7*Hypothèses!E$18*(1+Hypothèses!$C$13)^1 | R7: =Hypothèses!$C$4*$B7*Hypothèses!F$18*(1+Hypothèses!$C$13)^1 | S7: =Hypothèses!$C$4*$B7*Hypothèses!G$18*(1+Hypothèses!$C$13)^1 | T7: =Hypothèses!$C$4*$B7*Hypothèses!H$18*(1+Hypothèses!$C$13)^1 | U7: =Hypothèses!$C$4*$B7*Hypothèses!I$18*(1+Hypothèses!$C$13)^1 | V7: =Hypothèses!$C$4*$B7*Hypothèses!J$18*(1+Hypothèses!$C$13)^1 | ... Z7: =Hypothèses!$C$4*$B7*Hypothèses!N$18*(1+Hypothèses!$C$13)^1 | AA7: =Hypothèses!$C$4*$B7*Hypothèses!C$18*(1+Hypothèses!$C$13)^2 | AB7: =Hypothèses!$C$4*$B7*Hypothèses!D$18*(1+Hypothèses!$C$13)^2 | AC7: =Hypothèses!$C$4*$B7*Hypothèses!E$18*(1+Hypothèses!$C$13)^2 | AD7: =Hypothèses!$C$4*$B7*Hypothèses!F$18*(1+Hypothèses!$C$13)^2 | AE7: =Hypothèses!$C$4*$B7*Hypothèses!G$18*(1+Hypothèses!$C$13)^2 | AF7: =Hypothèses!$C$4*$B7*Hypothèses!H$18*(1+Hypothèses!$C$13)^2 | AG7: =Hypothèses!$C$4*$B7*Hypothèses!I$18*(1+Hypothèses!$C$13)^2 | AH7: =Hypothèses!$C$4*$B7*Hypothèses!J$18*(1+Hypothèses!$C$13)^2 | ... AL7: =Hypothèses!$C$4*$B7*Hypothèses!N$18*(1+Hypothèses!$C$13)^2 | AM7: =SUM(C7:N7) | AN7: =SUM(O7:Z7) | AO7: =SUM(AA7:AL7) | AP7: =SUM(AM7:AO7)
A8: Snacking & traiteur (sandwichs, quiches...) | B8: 0.15 | C8: =Hypothèses!$C$4*$B8*Hypothèses!C$18*(1+Hypothèses!$C$13)^0 | D8: =Hypothèses!$C$4*$B8*Hypothèses!D$18*(1+Hypothèses!$C$13)^0 | E8: =Hypothèses!$C$4*$B8*Hypothèses!E$18*(1+Hypothèses!$C$13)^0 | F8: =Hypothèses!$C$4*$B8*Hypothèses!F$18*(1+Hypothèses!$C$13)^0 | G8: =Hypothèses!$C$4*$B8*Hypothèses!G$18*(1+Hypothèses!$C$13)^0 | H8: =Hypothèses!$C$4*$B8*Hypothèses!H$18*(1+Hypothèses!$C$13)^0 | I8: =Hypothèses!$C$4*$B8*Hypothèses!I$18*(1+Hypothèses!$C$13)^0 | J8: =Hypothèses!$C$4*$B8*Hypothèses!J$18*(1+Hypothèses!$C$13)^0 | ... N8: =Hypothèses!$C$4*$B8*Hypothèses!N$18*(1+Hypothèses!$C$13)^0 | O8: =Hypothèses!$C$4*$B8*Hypothèses!C$18*(1+Hypothèses!$C$13)^1 | P8: =Hypothèses!$C$4*$B8*Hypothèses!D$18*(1+Hypothèses!$C$13)^1 | Q8: =Hypothèses!$C$4*$B8*Hypothèses!E$18*(1+Hypothèses!$C$13)^1 | R8: =Hypothèses!$C$4*$B8*Hypothèses!F$18*(1+Hypothèses!$C$13)^1 | S8: =Hypothèses!$C$4*$B8*Hypothèses!G$18*(1+Hypothèses!$C$13)^1 | T8: =Hypothèses!$C$4*$B8*Hypothèses!H$18*(1+Hypothèses!$C$13)^1 | U8: =Hypothèses!$C$4*$B8*Hypothèses!I$18*(1+Hypothèses!$C$13)^1 | V8: =Hypothèses!$C$4*$B8*Hypothèses!J$18*(1+Hypothèses!$C$13)^1 | ... Z8: =Hypothèses!$C$4*$B8*Hypothèses!N$18*(1+Hypothèses!$C$13)^1 | AA8: =Hypothèses!$C$4*$B8*Hypothèses!C$18*(1+Hypothèses!$C$13)^2 | AB8: =Hypothèses!$C$4*$B8*Hypothèses!D$18*(1+Hypothèses!$C$13)^2 | AC8: =Hypothèses!$C$4*$B8*Hypothèses!E$18*(1+Hypothèses!$C$13)^2 | AD8: =Hypothèses!$C$4*$B8*Hypothèses!F$18*(1+Hypothèses!$C$13)^2 | AE8: =Hypothèses!$C$4*$B8*Hypothèses!G$18*(1+Hypothèses!$C$13)^2 | AF8: =Hypothèses!$C$4*$B8*Hypothèses!H$18*(1+Hypothèses!$C$13)^2 | AG8: =Hypothèses!$C$4*$B8*Hypothèses!I$18*(1+Hypothèses!$C$13)^2 | AH8: =Hypothèses!$C$4*$B8*Hypothèses!J$18*(1+Hypothèses!$C$13)^2 | ... AL8: =Hypothèses!$C$4*$B8*Hypothèses!N$18*(1+Hypothèses!$C$13)^2 | AM8: =SUM(C8:N8) | AN8: =SUM(O8:Z8) | AO8: =SUM(AA8:AL8) | AP8: =SUM(AM8:AO8)
A9: Boissons & divers | B9: 0.05 | C9: =Hypothèses!$C$4*$B9*Hypothèses!C$18*(1+Hypothèses!$C$13)^0 | D9: =Hypothèses!$C$4*$B9*Hypothèses!D$18*(1+Hypothèses!$C$13)^0 | E9: =Hypothèses!$C$4*$B9*Hypothèses!E$18*(1+Hypothèses!$C$13)^0 | F9: =Hypothèses!$C$4*$B9*Hypothèses!F$18*(1+Hypothèses!$C$13)^0 | G9: =Hypothèses!$C$4*$B9*Hypothèses!G$18*(1+Hypothèses!$C$13)^0 | H9: =Hypothèses!$C$4*$B9*Hypothèses!H$18*(1+Hypothèses!$C$13)^0 | I9: =Hypothèses!$C$4*$B9*Hypothèses!I$18*(1+Hypothèses!$C$13)^0 | J9: =Hypothèses!$C$4*$B9*Hypothèses!J$18*(1+Hypothèses!$C$13)^0 | ... N9: =Hypothèses!$C$4*$B9*Hypothèses!N$18*(1+Hypothèses!$C$13)^0 | O9: =Hypothèses!$C$4*$B9*Hypothèses!C$18*(1+Hypothèses!$C$13)^1 | P9: =Hypothèses!$C$4*$B9*Hypothèses!D$18*(1+Hypothèses!$C$13)^1 | Q9: =Hypothèses!$C$4*$B9*Hypothèses!E$18*(1+Hypothèses!$C$13)^1 | R9: =Hypothèses!$C$4*$B9*Hypothèses!F$18*(1+Hypothèses!$C$13)^1 | S9: =Hypothèses!$C$4*$B9*Hypothèses!G$18*(1+Hypothèses!$C$13)^1 | T9: =Hypothèses!$C$4*$B9*Hypothèses!H$18*(1+Hypothèses!$C$13)^1 | U9: =Hypothèses!$C$4*$B9*Hypothèses!I$18*(1+Hypothèses!$C$13)^1 | V9: =Hypothèses!$C$4*$B9*Hypothèses!J$18*(1+Hypothèses!$C$13)^1 | ... Z9: =Hypothèses!$C$4*$B9*Hypothèses!N$18*(1+Hypothèses!$C$13)^1 | AA9: =Hypothèses!$C$4*$B9*Hypothèses!C$18*(1+Hypothèses!$C$13)^2 | AB9: =Hypothèses!$C$4*$B9*Hypothèses!D$18*(1+Hypothèses!$C$13)^2 | AC9: =Hypothèses!$C$4*$B9*Hypothèses!E$18*(1+Hypothèses!$C$13)^2 | AD9: =Hypothèses!$C$4*$B9*Hypothèses!F$18*(1+Hypothèses!$C$13)^2 | AE9: =Hypothèses!$C$4*$B9*Hypothèses!G$18*(1+Hypothèses!$C$13)^2 | AF9: =Hypothèses!$C$4*$B9*Hypothèses!H$18*(1+Hypothèses!$C$13)^2 | AG9: =Hypothèses!$C$4*$B9*Hypothèses!I$18*(1+Hypothèses!$C$13)^2 | AH9: =Hypothèses!$C$4*$B9*Hypothèses!J$18*(1+Hypothèses!$C$13)^2 | ... AL9: =Hypothèses!$C$4*$B9*Hypothèses!N$18*(1+Hypothèses!$C$13)^2 | AM9: =SUM(C9:N9) | AN9: =SUM(O9:Z9) | AO9: =SUM(AA9:AL9) | AP9: =SUM(AM9:AO9)
A10: TOTAL CA HT | C10: =SUM(C5:C9) | D10: =SUM(D5:D9) | E10: =SUM(E5:E9) | F10: =SUM(F5:F9) | G10: =SUM(G5:G9) | H10: =SUM(H5:H9) | I10: =SUM(I5:I9) | J10: =SUM(J5:J9) | ... AL10: =SUM(AL5:AL9) | AM10: =SUM(C10:N10) | AN10: =SUM(O10:Z10) | AO10: =SUM(AA10:AL10) | AP10: =SUM(AM10:AO10)
A11: Contrôle Σ % répartition (doit = 100%) | B11: =SUM(B5:B9)
A12: TVA collectée sur les ventes | C12: =C10*Hypothèses!$C$5 | D12: =D10*Hypothèses!$C$5 | E12: =E10*Hypothèses!$C$5 | F12: =F10*Hypothèses!$C$5 | G12: =G10*Hypothèses!$C$5 | H12: =H10*Hypothèses!$C$5 | I12: =I10*Hypothèses!$C$5 | J12: =J10*Hypothèses!$C$5 | ... AL12: =AL10*Hypothèses!$C$5 | AM12: =SUM(C12:N12) | AN12: =SUM(O12:Z12) | AO12: =SUM(AA12:AL12) | AP12: =SUM(AM12:AO12)
A13: CA TTC (encaissable) | C13: =C10+C12 | D13: =D10+D12 | E13: =E10+E12 | F13: =F10+F12 | G13: =G10+G12 | H13: =H10+H12 | I13: =I10+I12 | J13: =J10+J12 | ... AL13: =AL10+AL12 | AM13: =SUM(C13:N13) | AN13: =SUM(O13:Z13) | AO13: =SUM(AA13:AL13) | AP13: =SUM(AM13:AO13)

Sheet Dépenses détaillées
A1: Boulangerie — Dépenses détaillées (3 ans, mois par mois)
A2: Quantité de base × indice de saisonnalité × Prix de base × (1+inflation)^année = Coût du mois. Chaque ligne suit sa propre évolution mensuelle.
G3: ANNÉE 1 | S3: ANNÉE 2 | AE3: ANNÉE 3
A4: Catégorie | B4: Poste | C4: Qté base/mois (A1) | D4: Unité | E4: Prix unitaire base (A1, €) | F4: Source prix | G4: Jan A1 | H4: Fév A1 | I4: Mar A1 | J4: Avr A1 | K4: Mai A1 | L4: Jui A1 | M4: Jui A1 | N4: Aoû A1 | O4: Sep A1 | P4: Oct A1 | Q4: Nov A1 | R4: Déc A1 | S4: Jan A2 | T4: Fév A2 | U4: Mar A2 | V4: Avr A2 | W4: Mai A2 | X4: Jui A2 | Y4: Jui A2 | Z4: Aoû A2 | AA4: Sep A2 | AB4: Oct A2 | AC4: Nov A2 | AD4: Déc A2 | AE4: Jan A3 | AF4: Fév A3 | AG4: Mar A3 | AH4: Avr A3 | AI4: Mai A3 | AJ4: Jui A3 | AK4: Jui A3 | AL4: Aoû A3 | AM4: Sep A3 | AN4: Oct A3 | AO4: Nov A3 | AP4: Déc A3 | AQ4: Total A1 | AR4: Total A2 | AS4: Total A3 | AT4: Total 3 ans
A5: Matières premières | B5: Farine de blé T55/T65 (meunier) — prix de marché simulé (€/unité) | D5: kg | E5: =AVERAGE(G5:AP5) | F5: API marché (WHEAT, Alpha Vantage) — simulation calibrée, à remplacer par un fetch live | G5: 0.5356 | H5: 0.5283 | I5: 0.5882 | J5: 0.5752 | K5: 0.5351 | L5: 0.5445 | M5: 0.5501 | N5: 0.5705 | O5: 0.5614 | P5: 0.6047 | Q5: 0.625 | R5: 0.7075 | S5: 0.7302 | T5: 0.7423 | U5: 0.7981 | V5: 0.8363 | W5: 0.8069 | X5: 0.8428 | Y5: 0.8173 | Z5: 0.871 | AA5: 0.8487 | AB5: 0.8673 | AC5: 0.836 | AD5: 0.8532 | AE5: 0.9163 | AF5: 0.9733 | AG5: 0.9452 | AH5: 0.8843 | AI5: 0.9193 | AJ5: 0.8906 | AK5: 0.8589 | AL5: 0.892 | AM5: 0.8395 | AN5: 0.8768 | AO5: 0.9279 | AP5: 0.9324
A6: Matières premières | B6: ↳ Coût (Farine de blé T55/T65 (meunier)) | C6: 5000 | D6: kg | F6: Coût = Qté de base × saisonnalité × prix simulé ci-dessus | G6: =$C6*Hypothèses!C$17*G5 | H6: =$C6*Hypothèses!D$17*H5 | I6: =$C6*Hypothèses!E$17*I5 | J6: =$C6*Hypothèses!F$17*J5 | K6: =$C6*Hypothèses!G$17*K5 | L6: =$C6*Hypothèses!H$17*L5 | M6: =$C6*Hypothèses!I$17*M5 | N6: =$C6*Hypothèses!J$17*N5 | ... R6: =$C6*Hypothèses!N$17*R5 | S6: =$C6*Hypothèses!C$17*S5 | T6: =$C6*Hypothèses!D$17*T5 | U6: =$C6*Hypothèses!E$17*U5 | V6: =$C6*Hypothèses!F$17*V5 | W6: =$C6*Hypothèses!G$17*W5 | X6: =$C6*Hypothèses!H$17*X5 | Y6: =$C6*Hypothèses!I$17*Y5 | Z6: =$C6*Hypothèses!J$17*Z5 | ... AD6: =$C6*Hypothèses!N$17*AD5 | AE6: =$C6*Hypothèses!C$17*AE5 | AF6: =$C6*Hypothèses!D$17*AF5 | AG6: =$C6*Hypothèses!E$17*AG5 | AH6: =$C6*Hypothèses!F$17*AH5 | AI6: =$C6*Hypothèses!G$17*AI5 | AJ6: =$C6*Hypothèses!H$17*AJ5 | AK6: =$C6*Hypothèses!I$17*AK5 | AL6: =$C6*Hypothèses!J$17*AL5 | ... AP6: =$C6*Hypothèses!N$17*AP5 | AQ6: =SUM(G6:R6) | AR6: =SUM(S6:AD6) | AS6: =SUM(AE6:AP6) | AT6: =SUM(AQ6:AS6)
A7: Matières premières | B7: Beurre de tourage (feuilletage) | C7: 280 | D7: kg | E7: 6.2 | F7: Estimé — grossiste matières premières BVP | G7: =$C7*Hypothèses!C$17*$E7*(1+Hypothèses!$C$14)^0 | H7: =$C7*Hypothèses!D$17*$E7*(1+Hypothèses!$C$14)^0 | I7: =$C7*Hypothèses!E$17*$E7*(1+Hypothèses!$C$14)^0 | J7: =$C7*Hypothèses!F$17*$E7*(1+Hypothèses!$C$14)^0 | K7: =$C7*Hypothèses!G$17*$E7*(1+Hypothèses!$C$14)^0 | L7: =$C7*Hypothèses!H$17*$E7*(1+Hypothèses!$C$14)^0 | M7: =$C7*Hypothèses!I$17*$E7*(1+Hypothèses!$C$14)^0 | N7: =$C7*Hypothèses!J$17*$E7*(1+Hypothèses!$C$14)^0 | ... R7: =$C7*Hypothèses!N$17*$E7*(1+Hypothèses!$C$14)^0 | S7: =$C7*Hypothèses!C$17*$E7*(1+Hypothèses!$C$14)^1 | T7: =$C7*Hypothèses!D$17*$E7*(1+Hypothèses!$C$14)^1 | U7: =$C7*Hypothèses!E$17*$E7*(1+Hypothèses!$C$14)^1 | V7: =$C7*Hypothèses!F$17*$E7*(1+Hypothèses!$C$14)^1 | W7: =$C7*Hypothèses!G$17*$E7*(1+Hypothèses!$C$14)^1 | X7: =$C7*Hypothèses!H$17*$E7*(1+Hypothèses!$C$14)^1 | Y7: =$C7*Hypothèses!I$17*$E7*(1+Hypothèses!$C$14)^1 | Z7: =$C7*Hypothèses!J$17*$E7*(1+Hypothèses!$C$14)^1 | ... AD7: =$C7*Hypothèses!N$17*$E7*(1+Hypothèses!$C$14)^1 | AE7: =$C7*Hypothèses!C$17*$E7*(1+Hypothèses!$C$14)^2 | AF7: =$C7*Hypothèses!D$17*$E7*(1+Hypothèses!$C$14)^2 | AG7: =$C7*Hypothèses!E$17*$E7*(1+Hypothèses!$C$14)^2 | AH7: =$C7*Hypothèses!F$17*$E7*(1+Hypothèses!$C$14)^2 | AI7: =$C7*Hypothèses!G$17*$E7*(1+Hypothèses!$C$14)^2 | AJ7: =$C7*Hypothèses!H$17*$E7*(1+Hypothèses!$C$14)^2 | AK7: =$C7*Hypothèses!I$17*$E7*(1+Hypothèses!$C$14)^2 | AL7: =$C7*Hypothèses!J$17*$E7*(1+Hypothèses!$C$14)^2 | ... AP7: =$C7*Hypothèses!N$17*$E7*(1+Hypothèses!$C$14)^2 | AQ7: =SUM(G7:R7) | AR7: =SUM(S7:AD7) | AS7: =SUM(AE7:AP7) | AT7: =SUM(AQ7:AS7)
A8: Matières premières | B8: Beurre d'incorporation | C8: 110 | D8: kg | E8: 5.1 | F8: Estimé — grossiste matières premières BVP | G8: =$C8*Hypothèses!C$17*$E8*(1+Hypothèses!$C$14)^0 | H8: =$C8*Hypothèses!D$17*$E8*(1+Hypothèses!$C$14)^0 | I8: =$C8*Hypothèses!E$17*$E8*(1+Hypothèses!$C$14)^0 | J8: =$C8*Hypothèses!F$17*$E8*(1+Hypothèses!$C$14)^0 | K8: =$C8*Hypothèses!G$17*$E8*(1+Hypothèses!$C$14)^0 | L8: =$C8*Hypothèses!H$17*$E8*(1+Hypothèses!$C$14)^0 | M8: =$C8*Hypothèses!I$17*$E8*(1+Hypothèses!$C$14)^0 | N8: =$C8*Hypothèses!J$17*$E8*(1+Hypothèses!$C$14)^0 | ... R8: =$C8*Hypothèses!N$17*$E8*(1+Hypothèses!$C$14)^0 | S8: =$C8*Hypothèses!C$17*$E8*(1+Hypothèses!$C$14)^1 | T8: =$C8*Hypothèses!D$17*$E8*(1+Hypothèses!$C$14)^1 | U8: =$C8*Hypothèses!E$17*$E8*(1+Hypothèses!$C$14)^1 | V8: =$C8*Hypothèses!F$17*$E8*(1+Hypothèses!$C$14)^1 | W8: =$C8*Hypothèses!G$17*$E8*(1+Hypothèses!$C$14)^1 | X8: =$C8*Hypothèses!H$17*$E8*(1+Hypothèses!$C$14)^1 | Y8: =$C8*Hypothèses!I$17*$E8*(1+Hypothèses!$C$14)^1 | Z8: =$C8*Hypothèses!J$17*$E8*(1+Hypothèses!$C$14)^1 | ... AD8: =$C8*Hypothèses!N$17*$E8*(1+Hypothèses!$C$14)^1 | AE8: =$C8*Hypothèses!C$17*$E8*(1+Hypothèses!$C$14)^2 | AF8: =$C8*Hypothèses!D$17*$E8*(1+Hypothèses!$C$14)^2 | AG8: =$C8*Hypothèses!E$17*$E8*(1+Hypothèses!$C$14)^2 | AH8: =$C8*Hypothèses!F$17*$E8*(1+Hypothèses!$C$14)^2 | AI8: =$C8*Hypothèses!G$17*$E8*(1+Hypothèses!$C$14)^2 | AJ8: =$C8*Hypothèses!H$17*$E8*(1+Hypothèses!$C$14)^2 | AK8: =$C8*Hypothèses!I$17*$E8*(1+Hypothèses!$C$14)^2 | AL8: =$C8*Hypothèses!J$17*$E8*(1+Hypothèses!$C$14)^2 | ... AP8: =$C8*Hypothèses!N$17*$E8*(1+Hypothèses!$C$14)^2 | AQ8: =SUM(G8:R8) | AR8: =SUM(S8:AD8) | AS8: =SUM(AE8:AP8) | AT8: =SUM(AQ8:AS8)
A9: Matières premières | B9: Levure boulangère | C9: 65 | D9: kg | E9: 3.6 | F9: Estimé — fournisseur boulangerie | G9: =$C9*Hypothèses!C$17*$E9*(1+Hypothèses!$C$14)^0 | H9: =$C9*Hypothèses!D$17*$E9*(1+Hypothèses!$C$14)^0 | I9: =$C9*Hypothèses!E$17*$E9*(1+Hypothèses!$C$14)^0 | J9: =$C9*Hypothèses!F$17*$E9*(1+Hypothèses!$C$14)^0 | K9: =$C9*Hypothèses!G$17*$E9*(1+Hypothèses!$C$14)^0 | L9: =$C9*Hypothèses!H$17*$E9*(1+Hypothèses!$C$14)^0 | M9: =$C9*Hypothèses!I$17*$E9*(1+Hypothèses!$C$14)^0 | N9: =$C9*Hypothèses!J$17*$E9*(1+Hypothèses!$C$14)^0 | ... R9: =$C9*Hypothèses!N$17*$E9*(1+Hypothèses!$C$14)^0 | S9: =$C9*Hypothèses!C$17*$E9*(1+Hypothèses!$C$14)^1 | T9: =$C9*Hypothèses!D$17*$E9*(1+Hypothèses!$C$14)^1 | U9: =$C9*Hypothèses!E$17*$E9*(1+Hypothèses!$C$14)^1 | V9: =$C9*Hypothèses!F$17*$E9*(1+Hypothèses!$C$14)^1 | W9: =$C9*Hypothèses!G$17*$E9*(1+Hypothèses!$C$14)^1 | X9: =$C9*Hypothèses!H$17*$E9*(1+Hypothèses!$C$14)^1 | Y9: =$C9*Hypothèses!I$17*$E9*(1+Hypothèses!$C$14)^1 | Z9: =$C9*Hypothèses!J$17*$E9*(1+Hypothèses!$C$14)^1 | ... AD9: =$C9*Hypothèses!N$17*$E9*(1+Hypothèses!$C$14)^1 | AE9: =$C9*Hypothèses!C$17*$E9*(1+Hypothèses!$C$14)^2 | AF9: =$C9*Hypothèses!D$17*$E9*(1+Hypothèses!$C$14)^2 | AG9: =$C9*Hypothèses!E$17*$E9*(1+Hypothèses!$C$14)^2 | AH9: =$C9*Hypothèses!F$17*$E9*(1+Hypothèses!$C$14)^2 | AI9: =$C9*Hypothèses!G$17*$E9*(1+Hypothèses!$C$14)^2 | AJ9: =$C9*Hypothèses!H$17*$E9*(1+Hypothèses!$C$14)^2 | AK9: =$C9*Hypothèses!I$17*$E9*(1+Hypothèses!$C$14)^2 | AL9: =$C9*Hypothèses!J$17*$E9*(1+Hypothèses!$C$14)^2 | ... AP9: =$C9*Hypothèses!N$17*$E9*(1+Hypothèses!$C$14)^2 | AQ9: =SUM(G9:R9) | AR9: =SUM(S9:AD9) | AS9: =SUM(AE9:AP9) | AT9: =SUM(AQ9:AS9)
A10: Matières premières | B10: Sel | C10: 55 | D10: kg | E10: 0.65 | F10: Estimé — fournisseur boulangerie | G10: =$C10*Hypothèses!C$17*$E10*(1+Hypothèses!$C$14)^0 | H10: =$C10*Hypothèses!D$17*$E10*(1+Hypothèses!$C$14)^0 | I10: =$C10*Hypothèses!E$17*$E10*(1+Hypothèses!$C$14)^0 | J10: =$C10*Hypothèses!F$17*$E10*(1+Hypothèses!$C$14)^0 | K10: =$C10*Hypothèses!G$17*$E10*(1+Hypothèses!$C$14)^0 | L10: =$C10*Hypothèses!H$17*$E10*(1+Hypothèses!$C$14)^0 | M10: =$C10*Hypothèses!I$17*$E10*(1+Hypothèses!$C$14)^0 | N10: =$C10*Hypothèses!J$17*$E10*(1+Hypothèses!$C$14)^0 | ... R10: =$C10*Hypothèses!N$17*$E10*(1+Hypothèses!$C$14)^0 | S10: =$C10*Hypothèses!C$17*$E10*(1+Hypothèses!$C$14)^1 | T10: =$C10*Hypothèses!D$17*$E10*(1+Hypothèses!$C$14)^1 | U10: =$C10*Hypothèses!E$17*$E10*(1+Hypothèses!$C$14)^1 | V10: =$C10*Hypothèses!F$17*$E10*(1+Hypothèses!$C$14)^1 | W10: =$C10*Hypothèses!G$17*$E10*(1+Hypothèses!$C$14)^1 | X10: =$C10*Hypothèses!H$17*$E10*(1+Hypothèses!$C$14)^1 | Y10: =$C10*Hypothèses!I$17*$E10*(1+Hypothèses!$C$14)^1 | Z10: =$C10*Hypothèses!J$17*$E10*(1+Hypothèses!$C$14)^1 | ... AD10: =$C10*Hypothèses!N$17*$E10*(1+Hypothèses!$C$14)^1 | AE10: =$C10*Hypothèses!C$17*$E10*(1+Hypothèses!$C$14)^2 | AF10: =$C10*Hypothèses!D$17*$E10*(1+Hypothèses!$C$14)^2 | AG10: =$C10*Hypothèses!E$17*$E10*(1+Hypothèses!$C$14)^2 | AH10: =$C10*Hypothèses!F$17*$E10*(1+Hypothèses!$C$14)^2 | AI10: =$C10*Hypothèses!G$17*$E10*(1+Hypothèses!$C$14)^2 | AJ10: =$C10*Hypothèses!H$17*$E10*(1+Hypothèses!$C$14)^2 | AK10: =$C10*Hypothèses!I$17*$E10*(1+Hypothèses!$C$14)^2 | AL10: =$C10*Hypothèses!J$17*$E10*(1+Hypothèses!$C$14)^2 | ... AP10: =$C10*Hypothèses!N$17*$E10*(1+Hypothèses!$C$14)^2 | AQ10: =SUM(G10:R10) | AR10: =SUM(S10:AD10) | AS10: =SUM(AE10:AP10) | AT10: =SUM(AQ10:AS10)
A11: Matières premières | B11: Œufs | C11: 2200 | D11: unité | E11: 0.25 | F11: Estimé — grossiste alimentaire | G11: =$C11*Hypothèses!C$17*$E11*(1+Hypothèses!$C$14)^0 | H11: =$C11*Hypothèses!D$17*$E11*(1+Hypothèses!$C$14)^0 | I11: =$C11*Hypothèses!E$17*$E11*(1+Hypothèses!$C$14)^0 | J11: =$C11*Hypothèses!F$17*$E11*(1+Hypothèses!$C$14)^0 | K11: =$C11*Hypothèses!G$17*$E11*(1+Hypothèses!$C$14)^0 | L11: =$C11*Hypothèses!H$17*$E11*(1+Hypothèses!$C$14)^0 | M11: =$C11*Hypothèses!I$17*$E11*(1+Hypothèses!$C$14)^0 | N11: =$C11*Hypothèses!J$17*$E11*(1+Hypothèses!$C$14)^0 | ... R11: =$C11*Hypothèses!N$17*$E11*(1+Hypothèses!$C$14)^0 | S11: =$C11*Hypothèses!C$17*$E11*(1+Hypothèses!$C$14)^1 | T11: =$C11*Hypothèses!D$17*$E11*(1+Hypothèses!$C$14)^1 | U11: =$C11*Hypothèses!E$17*$E11*(1+Hypothèses!$C$14)^1 | V11: =$C11*Hypothèses!F$17*$E11*(1+Hypothèses!$C$14)^1 | W11: =$C11*Hypothèses!G$17*$E11*(1+Hypothèses!$C$14)^1 | X11: =$C11*Hypothèses!H$17*$E11*(1+Hypothèses!$C$14)^1 | Y11: =$C11*Hypothèses!I$17*$E11*(1+Hypothèses!$C$14)^1 | Z11: =$C11*Hypothèses!J$17*$E11*(1+Hypothèses!$C$14)^1 | ... AD11: =$C11*Hypothèses!N$17*$E11*(1+Hypothèses!$C$14)^1 | AE11: =$C11*Hypothèses!C$17*$E11*(1+Hypothèses!$C$14)^2 | AF11: =$C11*Hypothèses!D$17*$E11*(1+Hypothèses!$C$14)^2 | AG11: =$C11*Hypothèses!E$17*$E11*(1+Hypothèses!$C$14)^2 | AH11: =$C11*Hypothèses!F$17*$E11*(1+Hypothèses!$C$14)^2 | AI11: =$C11*Hypothèses!G$17*$E11*(1+Hypothèses!$C$14)^2 | AJ11: =$C11*Hypothèses!H$17*$E11*(1+Hypothèses!$C$14)^2 | AK11: =$C11*Hypothèses!I$17*$E11*(1+Hypothèses!$C$14)^2 | AL11: =$C11*Hypothèses!J$17*$E11*(1+Hypothèses!$C$14)^2 | ... AP11: =$C11*Hypothèses!N$17*$E11*(1+Hypothèses!$C$14)^2 | AQ11: =SUM(G11:R11) | AR11: =SUM(S11:AD11) | AS11: =SUM(AE11:AP11) | AT11: =SUM(AQ11:AS11)
A12: Matières premières | B12: Sucre — prix de marché simulé (€/unité) | D12: kg | E12: =AVERAGE(G12:AP12) | F12: API marché (SUGAR, Alpha Vantage) — simulation calibrée, à remplacer par un fetch live | G12: 0.999 | H12: 1.0675 | I12: 1.1185 | J12: 1.2135 | K12: 1.1601 | L12: 1.1194 | M12: 1.0575 | N12: 1.0044 | O12: 1.0777 | P12: 1.1012 | Q12: 1.045 | R12: 0.9952 | S12: 1.0679 | T12: 0.9983 | U12: 0.9695 | V12: 1.0006 | W12: 1.0785 | X12: 1.1656 | Y12: 1.1325 | Z12: 1.0482 | AA12: 0.9811 | AB12: 1.0079 | AC12: 1.0229 | AD12: 1.0992 | AE12: 1.1576 | AF12: 1.2365 | AG12: 1.1634 | AH12: 1.0899 | AI12: 1.0927 | AJ12: 1.1237 | AK12: 1.0747 | AL12: 1.1621 | AM12: 1.049 | AN12: 1.0446 | AO12: 0.9893 | AP12: 1.0164
A13: Matières premières | B13: ↳ Coût (Sucre) | C13: 320 | D13: kg | F13: Coût = Qté de base × saisonnalité × prix simulé ci-dessus | G13: =$C13*Hypothèses!C$17*G12 | H13: =$C13*Hypothèses!D$17*H12 | I13: =$C13*Hypothèses!E$17*I12 | J13: =$C13*Hypothèses!F$17*J12 | K13: =$C13*Hypothèses!G$17*K12 | L13: =$C13*Hypothèses!H$17*L12 | M13: =$C13*Hypothèses!I$17*M12 | N13: =$C13*Hypothèses!J$17*N12 | ... R13: =$C13*Hypothèses!N$17*R12 | S13: =$C13*Hypothèses!C$17*S12 | T13: =$C13*Hypothèses!D$17*T12 | U13: =$C13*Hypothèses!E$17*U12 | V13: =$C13*Hypothèses!F$17*V12 | W13: =$C13*Hypothèses!G$17*W12 | X13: =$C13*Hypothèses!H$17*X12 | Y13: =$C13*Hypothèses!I$17*Y12 | Z13: =$C13*Hypothèses!J$17*Z12 | ... AD13: =$C13*Hypothèses!N$17*AD12 | AE13: =$C13*Hypothèses!C$17*AE12 | AF13: =$C13*Hypothèses!D$17*AF12 | AG13: =$C13*Hypothèses!E$17*AG12 | AH13: =$C13*Hypothèses!F$17*AH12 | AI13: =$C13*Hypothèses!G$17*AI12 | AJ13: =$C13*Hypothèses!H$17*AJ12 | AK13: =$C13*Hypothèses!I$17*AK12 | AL13: =$C13*Hypothèses!J$17*AL12 | ... AP13: =$C13*Hypothèses!N$17*AP12 | AQ13: =SUM(G13:R13) | AR13: =SUM(S13:AD13) | AS13: =SUM(AE13:AP13) | AT13: =SUM(AQ13:AS13)
A14: Matières premières | B14: Chocolat de couverture — prix de marché simulé (€/unité) | D14: kg | E14: =AVERAGE(G14:AP14) | F14: API marché (proxy cacao, Banque Mondiale Pink Sheet) — simulation calibrée sur la hausse réelle du cacao | G14: 7.4498 | H14: 7.423 | I14: 7.2942 | J14: 6.4198 | K14: 6.5165 | L14: 6.7737 | M14: 6.6071 | N14: 6.4978 | O14: 5.7438 | P14: 6.4403 | Q14: 6.6716 | R14: 6.5319 | S14: 6.9065 | T14: 7.1554 | U14: 7.273 | V14: 7.2164 | W14: 7.3168 | X14: 7.6507 | Y14: 8.2301 | Z14: 8.872 | AA14: 9.2389 | AB14: 10.006 | AC14: 9.9508 | AD14: 8.7619 | AE14: 7.7722 | AF14: 8.3901 | AG14: 7.3282 | AH14: 6.9037 | AI14: 6.9626 | AJ14: 7.5529 | AK14: 6.336 | AL14: 5.7946 | AM14: 5.4538 | AN14: 5.1623 | AO14: 5.2016 | AP14: 5.5814
A15: Matières premières | B15: ↳ Coût (Chocolat de couverture) | C15: 160 | D15: kg | F15: Coût = Qté de base × saisonnalité × prix simulé ci-dessus | G15: =$C15*Hypothèses!C$17*G14 | H15: =$C15*Hypothèses!D$17*H14 | I15: =$C15*Hypothèses!E$17*I14 | J15: =$C15*Hypothèses!F$17*J14 | K15: =$C15*Hypothèses!G$17*K14 | L15: =$C15*Hypothèses!H$17*L14 | M15: =$C15*Hypothèses!I$17*M14 | N15: =$C15*Hypothèses!J$17*N14 | ... R15: =$C15*Hypothèses!N$17*R14 | S15: =$C15*Hypothèses!C$17*S14 | T15: =$C15*Hypothèses!D$17*T14 | U15: =$C15*Hypothèses!E$17*U14 | V15: =$C15*Hypothèses!F$17*V14 | W15: =$C15*Hypothèses!G$17*W14 | X15: =$C15*Hypothèses!H$17*X14 | Y15: =$C15*Hypothèses!I$17*Y14 | Z15: =$C15*Hypothèses!J$17*Z14 | ... AD15: =$C15*Hypothèses!N$17*AD14 | AE15: =$C15*Hypothèses!C$17*AE14 | AF15: =$C15*Hypothèses!D$17*AF14 | AG15: =$C15*Hypothèses!E$17*AG14 | AH15: =$C15*Hypothèses!F$17*AH14 | AI15: =$C15*Hypothèses!G$17*AI14 | AJ15: =$C15*Hypothèses!H$17*AJ14 | AK15: =$C15*Hypothèses!I$17*AK14 | AL15: =$C15*Hypothèses!J$17*AL14 | ... AP15: =$C15*Hypothèses!N$17*AP14 | AQ15: =SUM(G15:R15) | AR15: =SUM(S15:AD15) | AS15: =SUM(AE15:AP15) | AT15: =SUM(AQ15:AS15)
A16: Matières premières | B16: Lait | C16: 420 | D16: L | E16: 1.05 | F16: Estimé — grossiste alimentaire | G16: =$C16*Hypothèses!C$17*$E16*(1+Hypothèses!$C$14)^0 | H16: =$C16*Hypothèses!D$17*$E16*(1+Hypothèses!$C$14)^0 | I16: =$C16*Hypothèses!E$17*$E16*(1+Hypothèses!$C$14)^0 | J16: =$C16*Hypothèses!F$17*$E16*(1+Hypothèses!$C$14)^0 | K16: =$C16*Hypothèses!G$17*$E16*(1+Hypothèses!$C$14)^0 | L16: =$C16*Hypothèses!H$17*$E16*(1+Hypothèses!$C$14)^0 | M16: =$C16*Hypothèses!I$17*$E16*(1+Hypothèses!$C$14)^0 | N16: =$C16*Hypothèses!J$17*$E16*(1+Hypothèses!$C$14)^0 | ... R16: =$C16*Hypothèses!N$17*$E16*(1+Hypothèses!$C$14)^0 | S16: =$C16*Hypothèses!C$17*$E16*(1+Hypothèses!$C$14)^1 | T16: =$C16*Hypothèses!D$17*$E16*(1+Hypothèses!$C$14)^1 | U16: =$C16*Hypothèses!E$17*$E16*(1+Hypothèses!$C$14)^1 | V16: =$C16*Hypothèses!F$17*$E16*(1+Hypothèses!$C$14)^1 | W16: =$C16*Hypothèses!G$17*$E16*(1+Hypothèses!$C$14)^1 | X16: =$C16*Hypothèses!H$17*$E16*(1+Hypothèses!$C$14)^1 | Y16: =$C16*Hypothèses!I$17*$E16*(1+Hypothèses!$C$14)^1 | Z16: =$C16*Hypothèses!J$17*$E16*(1+Hypothèses!$C$14)^1 | ... AD16: =$C16*Hypothèses!N$17*$E16*(1+Hypothèses!$C$14)^1 | AE16: =$C16*Hypothèses!C$17*$E16*(1+Hypothèses!$C$14)^2 | AF16: =$C16*Hypothèses!D$17*$E16*(1+Hypothèses!$C$14)^2 | AG16: =$C16*Hypothèses!E$17*$E16*(1+Hypothèses!$C$14)^2 | AH16: =$C16*Hypothèses!F$17*$E16*(1+Hypothèses!$C$14)^2 | AI16: =$C16*Hypothèses!G$17*$E16*(1+Hypothèses!$C$14)^2 | AJ16: =$C16*Hypothèses!H$17*$E16*(1+Hypothèses!$C$14)^2 | AK16: =$C16*Hypothèses!I$17*$E16*(1+Hypothèses!$C$14)^2 | AL16: =$C16*Hypothèses!J$17*$E16*(1+Hypothèses!$C$14)^2 | ... AP16: =$C16*Hypothèses!N$17*$E16*(1+Hypothèses!$C$14)^2 | AQ16: =SUM(G16:R16) | AR16: =SUM(S16:AD16) | AS16: =SUM(AE16:AP16) | AT16: =SUM(AQ16:AS16)
A17: Matières premières | B17: Crème fraîche/liquide | C17: 160 | D17: L | E17: 3.6 | F17: Estimé — grossiste alimentaire | G17: =$C17*Hypothèses!C$17*$E17*(1+Hypothèses!$C$14)^0 | H17: =$C17*Hypothèses!D$17*$E17*(1+Hypothèses!$C$14)^0 | I17: =$C17*Hypothèses!E$17*$E17*(1+Hypothèses!$C$14)^0 | J17: =$C17*Hypothèses!F$17*$E17*(1+Hypothèses!$C$14)^0 | K17: =$C17*Hypothèses!G$17*$E17*(1+Hypothèses!$C$14)^0 | L17: =$C17*Hypothèses!H$17*$E17*(1+Hypothèses!$C$14)^0 | M17: =$C17*Hypothèses!I$17*$E17*(1+Hypothèses!$C$14)^0 | N17: =$C17*Hypothèses!J$17*$E17*(1+Hypothèses!$C$14)^0 | ... R17: =$C17*Hypothèses!N$17*$E17*(1+Hypothèses!$C$14)^0 | S17: =$C17*Hypothèses!C$17*$E17*(1+Hypothèses!$C$14)^1 | T17: =$C17*Hypothèses!D$17*$E17*(1+Hypothèses!$C$14)^1 | U17: =$C17*Hypothèses!E$17*$E17*(1+Hypothèses!$C$14)^1 | V17: =$C17*Hypothèses!F$17*$E17*(1+Hypothèses!$C$14)^1 | W17: =$C17*Hypothèses!G$17*$E17*(1+Hypothèses!$C$14)^1 | X17: =$C17*Hypothèses!H$17*$E17*(1+Hypothèses!$C$14)^1 | Y17: =$C17*Hypothèses!I$17*$E17*(1+Hypothèses!$C$14)^1 | Z17: =$C17*Hypothèses!J$17*$E17*(1+Hypothèses!$C$14)^1 | ... AD17: =$C17*Hypothèses!N$17*$E17*(1+Hypothèses!$C$14)^1 | AE17: =$C17*Hypothèses!C$17*$E17*(1+Hypothèses!$C$14)^2 | AF17: =$C17*Hypothèses!D$17*$E17*(1+Hypothèses!$C$14)^2 | AG17: =$C17*Hypothèses!E$17*$E17*(1+Hypothèses!$C$14)^2 | AH17: =$C17*Hypothèses!F$17*$E17*(1+Hypothèses!$C$14)^2 | AI17: =$C17*Hypothèses!G$17*$E17*(1+Hypothèses!$C$14)^2 | AJ17: =$C17*Hypothèses!H$17*$E17*(1+Hypothèses!$C$14)^2 | AK17: =$C17*Hypothèses!I$17*$E17*(1+Hypothèses!$C$14)^2 | AL17: =$C17*Hypothèses!J$17*$E17*(1+Hypothèses!$C$14)^2 | ... AP17: =$C17*Hypothèses!N$17*$E17*(1+Hypothèses!$C$14)^2 | AQ17: =SUM(G17:R17) | AR17: =SUM(S17:AD17) | AS17: =SUM(AE17:AP17) | AT17: =SUM(AQ17:AS17)
A18: Matières premières | B18: Fruits (garnitures, frais/surgelés) | C18: 220 | D18: kg | E18: 2.6 | F18: Estimé — grossiste/marché | G18: =$C18*Hypothèses!C$17*$E18*(1+Hypothèses!$C$14)^0 | H18: =$C18*Hypothèses!D$17*$E18*(1+Hypothèses!$C$14)^0 | I18: =$C18*Hypothèses!E$17*$E18*(1+Hypothèses!$C$14)^0 | J18: =$C18*Hypothèses!F$17*$E18*(1+Hypothèses!$C$14)^0 | K18: =$C18*Hypothèses!G$17*$E18*(1+Hypothèses!$C$14)^0 | L18: =$C18*Hypothèses!H$17*$E18*(1+Hypothèses!$C$14)^0 | M18: =$C18*Hypothèses!I$17*$E18*(1+Hypothèses!$C$14)^0 | N18: =$C18*Hypothèses!J$17*$E18*(1+Hypothèses!$C$14)^0 | ... R18: =$C18*Hypothèses!N$17*$E18*(1+Hypothèses!$C$14)^0 | S18: =$C18*Hypothèses!C$17*$E18*(1+Hypothèses!$C$14)^1 | T18: =$C18*Hypothèses!D$17*$E18*(1+Hypothèses!$C$14)^1 | U18: =$C18*Hypothèses!E$17*$E18*(1+Hypothèses!$C$14)^1 | V18: =$C18*Hypothèses!F$17*$E18*(1+Hypothèses!$C$14)^1 | W18: =$C18*Hypothèses!G$17*$E18*(1+Hypothèses!$C$14)^1 | X18: =$C18*Hypothèses!H$17*$E18*(1+Hypothèses!$C$14)^1 | Y18: =$C18*Hypothèses!I$17*$E18*(1+Hypothèses!$C$14)^1 | Z18: =$C18*Hypothèses!J$17*$E18*(1+Hypothèses!$C$14)^1 | ... AD18: =$C18*Hypothèses!N$17*$E18*(1+Hypothèses!$C$14)^1 | AE18: =$C18*Hypothèses!C$17*$E18*(1+Hypothèses!$C$14)^2 | AF18: =$C18*Hypothèses!D$17*$E18*(1+Hypothèses!$C$14)^2 | AG18: =$C18*Hypothèses!E$17*$E18*(1+Hypothèses!$C$14)^2 | AH18: =$C18*Hypothèses!F$17*$E18*(1+Hypothèses!$C$14)^2 | AI18: =$C18*Hypothèses!G$17*$E18*(1+Hypothèses!$C$14)^2 | AJ18: =$C18*Hypothèses!H$17*$E18*(1+Hypothèses!$C$14)^2 | AK18: =$C18*Hypothèses!I$17*$E18*(1+Hypothèses!$C$14)^2 | AL18: =$C18*Hypothèses!J$17*$E18*(1+Hypothèses!$C$14)^2 | ... AP18: =$C18*Hypothèses!N$17*$E18*(1+Hypothèses!$C$14)^2 | AQ18: =SUM(G18:R18) | AR18: =SUM(S18:AD18) | AS18: =SUM(AE18:AP18) | AT18: =SUM(AQ18:AS18)
A19: Matières premières | B19: Emballages (sacs, boîtes, étiquettes) | C19: 13000 | D19: unité | E19: 0.06 | F19: Estimé — fournisseur emballage | G19: =$C19*Hypothèses!C$17*$E19*(1+Hypothèses!$C$14)^0 | H19: =$C19*Hypothèses!D$17*$E19*(1+Hypothèses!$C$14)^0 | I19: =$C19*Hypothèses!E$17*$E19*(1+Hypothèses!$C$14)^0 | J19: =$C19*Hypothèses!F$17*$E19*(1+Hypothèses!$C$14)^0 | K19: =$C19*Hypothèses!G$17*$E19*(1+Hypothèses!$C$14)^0 | L19: =$C19*Hypothèses!H$17*$E19*(1+Hypothèses!$C$14)^0 | M19: =$C19*Hypothèses!I$17*$E19*(1+Hypothèses!$C$14)^0 | N19: =$C19*Hypothèses!J$17*$E19*(1+Hypothèses!$C$14)^0 | ... R19: =$C19*Hypothèses!N$17*$E19*(1+Hypothèses!$C$14)^0 | S19: =$C19*Hypothèses!C$17*$E19*(1+Hypothèses!$C$14)^1 | T19: =$C19*Hypothèses!D$17*$E19*(1+Hypothèses!$C$14)^1 | U19: =$C19*Hypothèses!E$17*$E19*(1+Hypothèses!$C$14)^1 | V19: =$C19*Hypothèses!F$17*$E19*(1+Hypothèses!$C$14)^1 | W19: =$C19*Hypothèses!G$17*$E19*(1+Hypothèses!$C$14)^1 | X19: =$C19*Hypothèses!H$17*$E19*(1+Hypothèses!$C$14)^1 | Y19: =$C19*Hypothèses!I$17*$E19*(1+Hypothèses!$C$14)^1 | Z19: =$C19*Hypothèses!J$17*$E19*(1+Hypothèses!$C$14)^1 | ... AD19: =$C19*Hypothèses!N$17*$E19*(1+Hypothèses!$C$14)^1 | AE19: =$C19*Hypothèses!C$17*$E19*(1+Hypothèses!$C$14)^2 | AF19: =$C19*Hypothèses!D$17*$E19*(1+Hypothèses!$C$14)^2 | AG19: =$C19*Hypothèses!E$17*$E19*(1+Hypothèses!$C$14)^2 | AH19: =$C19*Hypothèses!F$17*$E19*(1+Hypothèses!$C$14)^2 | AI19: =$C19*Hypothèses!G$17*$E19*(1+Hypothèses!$C$14)^2 | AJ19: =$C19*Hypothèses!H$17*$E19*(1+Hypothèses!$C$14)^2 | AK19: =$C19*Hypothèses!I$17*$E19*(1+Hypothèses!$C$14)^2 | AL19: =$C19*Hypothèses!J$17*$E19*(1+Hypothèses!$C$14)^2 | ... AP19: =$C19*Hypothèses!N$17*$E19*(1+Hypothèses!$C$14)^2 | AQ19: =SUM(G19:R19) | AR19: =SUM(S19:AD19) | AS19: =SUM(AE19:AP19) | AT19: =SUM(AQ19:AS19)
A20: SOUS-TOTAL Matières premières | G20: =G6+G7+G8+G9+G10+G11+G13+G15+G16+G17+G18+G19 | H20: =H6+H7+H8+H9+H10+H11+H13+H15+H16+H17+H18+H19 | I20: =I6+I7+I8+I9+I10+I11+I13+I15+I16+I17+I18+I19 | J20: =J6+J7+J8+J9+J10+J11+J13+J15+J16+J17+J18+J19 | K20: =K6+K7+K8+K9+K10+K11+K13+K15+K16+K17+K18+K19 | L20: =L6+L7+L8+L9+L10+L11+L13+L15+L16+L17+L18+L19 | M20: =M6+M7+M8+M9+M10+M11+M13+M15+M16+M17+M18+M19 | N20: =N6+N7+N8+N9+N10+N11+N13+N15+N16+N17+N18+N19 | ... AP20: =AP6+AP7+AP8+AP9+AP10+AP11+AP13+AP15+AP16+AP17+AP18+AP19 | AQ20: =SUM(G20:R20) | AR20: =SUM(S20:AD20) | AS20: =SUM(AE20:AP20) | AT20: =SUM(AQ20:AS20)
A21: Énergie | B21: Électricité (four, vitrines, labo) — prix de marché simulé (€/unité) | D21: kWh | E21: =AVERAGE(G21:AP21) | F21: API/marché (Tarif Bleu Pro EDF — simulation calibrée, à actualiser via SDES) | G21: 0.1631 | H21: 0.162 | I21: 0.162 | J21: 0.1604 | K21: 0.1588 | L21: 0.1573 | M21: 0.1584 | N21: 0.158 | O21: 0.1587 | P21: 0.1597 | Q21: 0.1599 | R21: 0.153 | S21: 0.1551 | T21: 0.1529 | U21: 0.1515 | V21: 0.1529 | W21: 0.1508 | X21: 0.1532 | Y21: 0.1557 | Z21: 0.1565 | AA21: 0.1569 | AB21: 0.1631 | AC21: 0.1637 | AD21: 0.1584 | AE21: 0.1551 | AF21: 0.1528 | AG21: 0.1538 | AH21: 0.1524 | AI21: 0.1481 | AJ21: 0.1553 | AK21: 0.1534 | AL21: 0.1516 | AM21: 0.1521 | AN21: 0.1513 | AO21: 0.151 | AP21: 0.1532
A22: Énergie | B22: ↳ Coût (Électricité (four, vitrines, labo)) | C22: 5800 | D22: kWh | F22: Coût = Qté de base × saisonnalité × prix simulé ci-dessus | G22: =$C22*Hypothèses!C$17*G21 | H22: =$C22*Hypothèses!D$17*H21 | I22: =$C22*Hypothèses!E$17*I21 | J22: =$C22*Hypothèses!F$17*J21 | K22: =$C22*Hypothèses!G$17*K21 | L22: =$C22*Hypothèses!H$17*L21 | M22: =$C22*Hypothèses!I$17*M21 | N22: =$C22*Hypothèses!J$17*N21 | ... R22: =$C22*Hypothèses!N$17*R21 | S22: =$C22*Hypothèses!C$17*S21 | T22: =$C22*Hypothèses!D$17*T21 | U22: =$C22*Hypothèses!E$17*U21 | V22: =$C22*Hypothèses!F$17*V21 | W22: =$C22*Hypothèses!G$17*W21 | X22: =$C22*Hypothèses!H$17*X21 | Y22: =$C22*Hypothèses!I$17*Y21 | Z22: =$C22*Hypothèses!J$17*Z21 | ... AD22: =$C22*Hypothèses!N$17*AD21 | AE22: =$C22*Hypothèses!C$17*AE21 | AF22: =$C22*Hypothèses!D$17*AF21 | AG22: =$C22*Hypothèses!E$17*AG21 | AH22: =$C22*Hypothèses!F$17*AH21 | AI22: =$C22*Hypothèses!G$17*AI21 | AJ22: =$C22*Hypothèses!H$17*AJ21 | AK22: =$C22*Hypothèses!I$17*AK21 | AL22: =$C22*Hypothèses!J$17*AL21 | ... AP22: =$C22*Hypothèses!N$17*AP21 | AQ22: =SUM(G22:R22) | AR22: =SUM(S22:AD22) | AS22: =SUM(AE22:AP22) | AT22: =SUM(AQ22:AS22)
A23: Énergie | B23: Gaz (chauffage local) — prix de marché simulé (€/unité) | D23: kWh | E23: =AVERAGE(G23:AP23) | F23: API marché (NATURAL_GAS proxy / SDES) — simulation calibrée | G23: 0.0984 | H23: 0.0954 | I23: 0.0986 | J23: 0.087 | K23: 0.0844 | L23: 0.0912 | M23: 0.09 | N23: 0.0925 | O23: 0.0882 | P23: 0.0944 | Q23: 0.0987 | R23: 0.1047 | S23: 0.103 | T23: 0.1058 | U23: 0.1013 | V23: 0.1036 | W23: 0.0934 | X23: 0.096 | Y23: 0.0992 | Z23: 0.0977 | AA23: 0.1046 | AB23: 0.1043 | AC23: 0.1138 | AD23: 0.1114 | AE23: 0.1074 | AF23: 0.107 | AG23: 0.1253 | AH23: 0.1155 | AI23: 0.1137 | AJ23: 0.1119 | AK23: 0.1164 | AL23: 0.1077 | AM23: 0.1187 | AN23: 0.1078 | AO23: 0.1167 | AP23: 0.1155
A24: Énergie | B24: ↳ Coût (Gaz (chauffage local)) | C24: 2600 | D24: kWh | F24: Coût = Qté de base × saisonnalité × prix simulé ci-dessus | G24: =$C24*Hypothèses!C$17*G23 | H24: =$C24*Hypothèses!D$17*H23 | I24: =$C24*Hypothèses!E$17*I23 | J24: =$C24*Hypothèses!F$17*J23 | K24: =$C24*Hypothèses!G$17*K23 | L24: =$C24*Hypothèses!H$17*L23 | M24: =$C24*Hypothèses!I$17*M23 | N24: =$C24*Hypothèses!J$17*N23 | ... R24: =$C24*Hypothèses!N$17*R23 | S24: =$C24*Hypothèses!C$17*S23 | T24: =$C24*Hypothèses!D$17*T23 | U24: =$C24*Hypothèses!E$17*U23 | V24: =$C24*Hypothèses!F$17*V23 | W24: =$C24*Hypothèses!G$17*W23 | X24: =$C24*Hypothèses!H$17*X23 | Y24: =$C24*Hypothèses!I$17*Y23 | Z24: =$C24*Hypothèses!J$17*Z23 | ... AD24: =$C24*Hypothèses!N$17*AD23 | AE24: =$C24*Hypothèses!C$17*AE23 | AF24: =$C24*Hypothèses!D$17*AF23 | AG24: =$C24*Hypothèses!E$17*AG23 | AH24: =$C24*Hypothèses!F$17*AH23 | AI24: =$C24*Hypothèses!G$17*AI23 | AJ24: =$C24*Hypothèses!H$17*AJ23 | AK24: =$C24*Hypothèses!I$17*AK23 | AL24: =$C24*Hypothèses!J$17*AL23 | ... AP24: =$C24*Hypothèses!N$17*AP23 | AQ24: =SUM(G24:R24) | AR24: =SUM(S24:AD24) | AS24: =SUM(AE24:AP24) | AT24: =SUM(AQ24:AS24)
A25: SOUS-TOTAL Énergie | G25: =G22+G24 | H25: =H22+H24 | I25: =I22+I24 | J25: =J22+J24 | K25: =K22+K24 | L25: =L22+L24 | M25: =M22+M24 | N25: =N22+N24 | ... AP25: =AP22+AP24 | AQ25: =SUM(G25:R25) | AR25: =SUM(S25:AD25) | AS25: =SUM(AE25:AP25) | AT25: =SUM(AQ25:AS25)
A26: Personnel | B26: Rémunération nette du dirigeant (boulanger, TNS) | C26: 1 | D26: forfait/mois | E26: 3400 | F26: Estimé — niveau de vie artisan installé | G26: =$C26*$E26*(1+Hypothèses!$C$14)^0 | H26: =$C26*$E26*(1+Hypothèses!$C$14)^0 | I26: =$C26*$E26*(1+Hypothèses!$C$14)^0 | J26: =$C26*$E26*(1+Hypothèses!$C$14)^0 | K26: =$C26*$E26*(1+Hypothèses!$C$14)^0 | L26: =$C26*$E26*(1+Hypothèses!$C$14)^0 | M26: =$C26*$E26*(1+Hypothèses!$C$14)^0 | N26: =$C26*$E26*(1+Hypothèses!$C$14)^0 | ... R26: =$C26*$E26*(1+Hypothèses!$C$14)^0 | S26: =$C26*$E26*(1+Hypothèses!$C$14)^1 | T26: =$C26*$E26*(1+Hypothèses!$C$14)^1 | U26: =$C26*$E26*(1+Hypothèses!$C$14)^1 | V26: =$C26*$E26*(1+Hypothèses!$C$14)^1 | W26: =$C26*$E26*(1+Hypothèses!$C$14)^1 | X26: =$C26*$E26*(1+Hypothèses!$C$14)^1 | Y26: =$C26*$E26*(1+Hypothèses!$C$14)^1 | Z26: =$C26*$E26*(1+Hypothèses!$C$14)^1 | ... AD26: =$C26*$E26*(1+Hypothèses!$C$14)^1 | AE26: =$C26*$E26*(1+Hypothèses!$C$14)^2 | AF26: =$C26*$E26*(1+Hypothèses!$C$14)^2 | AG26: =$C26*$E26*(1+Hypothèses!$C$14)^2 | AH26: =$C26*$E26*(1+Hypothèses!$C$14)^2 | AI26: =$C26*$E26*(1+Hypothèses!$C$14)^2 | AJ26: =$C26*$E26*(1+Hypothèses!$C$14)^2 | AK26: =$C26*$E26*(1+Hypothèses!$C$14)^2 | AL26: =$C26*$E26*(1+Hypothèses!$C$14)^2 | ... AP26: =$C26*$E26*(1+Hypothèses!$C$14)^2 | AQ26: =SUM(G26:R26) | AR26: =SUM(S26:AD26) | AS26: =SUM(AE26:AP26) | AT26: =SUM(AQ26:AS26)
A27: Personnel | B27: Salaires & charges — 1 salarié(e) vente/production | C27: 1 | D27: forfait/mois | E27: 3000 | F27: Estimé — convention collective boulangerie | G27: =$C27*$E27*(1+Hypothèses!$C$14)^0 | H27: =$C27*$E27*(1+Hypothèses!$C$14)^0 | I27: =$C27*$E27*(1+Hypothèses!$C$14)^0 | J27: =$C27*$E27*(1+Hypothèses!$C$14)^0 | K27: =$C27*$E27*(1+Hypothèses!$C$14)^0 | L27: =$C27*$E27*(1+Hypothèses!$C$14)^0 | M27: =$C27*$E27*(1+Hypothèses!$C$14)^0 | N27: =$C27*$E27*(1+Hypothèses!$C$14)^0 | ... R27: =$C27*$E27*(1+Hypothèses!$C$14)^0 | S27: =$C27*$E27*(1+Hypothèses!$C$14)^1 | T27: =$C27*$E27*(1+Hypothèses!$C$14)^1 | U27: =$C27*$E27*(1+Hypothèses!$C$14)^1 | V27: =$C27*$E27*(1+Hypothèses!$C$14)^1 | W27: =$C27*$E27*(1+Hypothèses!$C$14)^1 | X27: =$C27*$E27*(1+Hypothèses!$C$14)^1 | Y27: =$C27*$E27*(1+Hypothèses!$C$14)^1 | Z27: =$C27*$E27*(1+Hypothèses!$C$14)^1 | ... AD27: =$C27*$E27*(1+Hypothèses!$C$14)^1 | AE27: =$C27*$E27*(1+Hypothèses!$C$14)^2 | AF27: =$C27*$E27*(1+Hypothèses!$C$14)^2 | AG27: =$C27*$E27*(1+Hypothèses!$C$14)^2 | AH27: =$C27*$E27*(1+Hypothèses!$C$14)^2 | AI27: =$C27*$E27*(1+Hypothèses!$C$14)^2 | AJ27: =$C27*$E27*(1+Hypothèses!$C$14)^2 | AK27: =$C27*$E27*(1+Hypothèses!$C$14)^2 | AL27: =$C27*$E27*(1+Hypothèses!$C$14)^2 | ... AP27: =$C27*$E27*(1+Hypothèses!$C$14)^2 | AQ27: =SUM(G27:R27) | AR27: =SUM(S27:AD27) | AS27: =SUM(AE27:AP27) | AT27: =SUM(AQ27:AS27)
A28: SOUS-TOTAL Personnel | G28: =G26+G27 | H28: =H26+H27 | I28: =I26+I27 | J28: =J26+J27 | K28: =K26+K27 | L28: =L26+L27 | M28: =M26+M27 | N28: =N26+N27 | ... AP28: =AP26+AP27 | AQ28: =SUM(G28:R28) | AR28: =SUM(S28:AD28) | AS28: =SUM(AE28:AP28) | AT28: =SUM(AQ28:AS28)
A29: Charges sociales dirigeant | B29: Cotisations URSSAF (TNS) du dirigeant — lissé mensuel (versées par trimestre, cf. Hypothèses C8) | C29: 1 | D29: forfait/mois (moy.) | E29: 1066.67 | F29: Calculé — Hypothèses!C8 (cotisation trimestrielle) ÷ 3 | G29: =$C29*$E29*(1+Hypothèses!$C$14)^0 | H29: =$C29*$E29*(1+Hypothèses!$C$14)^0 | I29: =$C29*$E29*(1+Hypothèses!$C$14)^0 | J29: =$C29*$E29*(1+Hypothèses!$C$14)^0 | K29: =$C29*$E29*(1+Hypothèses!$C$14)^0 | L29: =$C29*$E29*(1+Hypothèses!$C$14)^0 | M29: =$C29*$E29*(1+Hypothèses!$C$14)^0 | N29: =$C29*$E29*(1+Hypothèses!$C$14)^0 | ... R29: =$C29*$E29*(1+Hypothèses!$C$14)^0 | S29: =$C29*$E29*(1+Hypothèses!$C$14)^1 | T29: =$C29*$E29*(1+Hypothèses!$C$14)^1 | U29: =$C29*$E29*(1+Hypothèses!$C$14)^1 | V29: =$C29*$E29*(1+Hypothèses!$C$14)^1 | W29: =$C29*$E29*(1+Hypothèses!$C$14)^1 | X29: =$C29*$E29*(1+Hypothèses!$C$14)^1 | Y29: =$C29*$E29*(1+Hypothèses!$C$14)^1 | Z29: =$C29*$E29*(1+Hypothèses!$C$14)^1 | ... AD29: =$C29*$E29*(1+Hypothèses!$C$14)^1 | AE29: =$C29*$E29*(1+Hypothèses!$C$14)^2 | AF29: =$C29*$E29*(1+Hypothèses!$C$14)^2 | AG29: =$C29*$E29*(1+Hypothèses!$C$14)^2 | AH29: =$C29*$E29*(1+Hypothèses!$C$14)^2 | AI29: =$C29*$E29*(1+Hypothèses!$C$14)^2 | AJ29: =$C29*$E29*(1+Hypothèses!$C$14)^2 | AK29: =$C29*$E29*(1+Hypothèses!$C$14)^2 | AL29: =$C29*$E29*(1+Hypothèses!$C$14)^2 | ... AP29: =$C29*$E29*(1+Hypothèses!$C$14)^2 | AQ29: =SUM(G29:R29) | AR29: =SUM(S29:AD29) | AS29: =SUM(AE29:AP29) | AT29: =SUM(AQ29:AS29)
A30: SOUS-TOTAL Charges sociales dirigeant | G30: =G29 | H30: =H29 | I30: =I29 | J30: =J29 | K30: =K29 | L30: =L29 | M30: =M29 | N30: =N29 | ... AP30: =AP29 | AQ30: =SUM(G30:R30) | AR30: =SUM(S30:AD30) | AS30: =SUM(AE30:AP30) | AT30: =SUM(AQ30:AS30)
A31: Charges fixes | B31: Loyer commercial | C31: 1 | D31: forfait/mois | E31: 3200 | F31: Estimé — bail commercial type quartier | G31: =$C31*$E31*(1+Hypothèses!$C$14)^0 | H31: =$C31*$E31*(1+Hypothèses!$C$14)^0 | I31: =$C31*$E31*(1+Hypothèses!$C$14)^0 | J31: =$C31*$E31*(1+Hypothèses!$C$14)^0 | K31: =$C31*$E31*(1+Hypothèses!$C$14)^0 | L31: =$C31*$E31*(1+Hypothèses!$C$14)^0 | M31: =$C31*$E31*(1+Hypothèses!$C$14)^0 | N31: =$C31*$E31*(1+Hypothèses!$C$14)^0 | ... R31: =$C31*$E31*(1+Hypothèses!$C$14)^0 | S31: =$C31*$E31*(1+Hypothèses!$C$14)^1 | T31: =$C31*$E31*(1+Hypothèses!$C$14)^1 | U31: =$C31*$E31*(1+Hypothèses!$C$14)^1 | V31: =$C31*$E31*(1+Hypothèses!$C$14)^1 | W31: =$C31*$E31*(1+Hypothèses!$C$14)^1 | X31: =$C31*$E31*(1+Hypothèses!$C$14)^1 | Y31: =$C31*$E31*(1+Hypothèses!$C$14)^1 | Z31: =$C31*$E31*(1+Hypothèses!$C$14)^1 | ... AD31: =$C31*$E31*(1+Hypothèses!$C$14)^1 | AE31: =$C31*$E31*(1+Hypothèses!$C$14)^2 | AF31: =$C31*$E31*(1+Hypothèses!$C$14)^2 | AG31: =$C31*$E31*(1+Hypothèses!$C$14)^2 | AH31: =$C31*$E31*(1+Hypothèses!$C$14)^2 | AI31: =$C31*$E31*(1+Hypothèses!$C$14)^2 | AJ31: =$C31*$E31*(1+Hypothèses!$C$14)^2 | AK31: =$C31*$E31*(1+Hypothèses!$C$14)^2 | AL31: =$C31*$E31*(1+Hypothèses!$C$14)^2 | ... AP31: =$C31*$E31*(1+Hypothèses!$C$14)^2 | AQ31: =SUM(G31:R31) | AR31: =SUM(S31:AD31) | AS31: =SUM(AE31:AP31) | AT31: =SUM(AQ31:AS31)
A32: Charges fixes | B32: Assurance multirisque & RC professionnelle | C32: 1 | D32: forfait/mois | E32: 250 | F32: Estimé — devis assureur pro | G32: =$C32*$E32*(1+Hypothèses!$C$14)^0 | H32: =$C32*$E32*(1+Hypothèses!$C$14)^0 | I32: =$C32*$E32*(1+Hypothèses!$C$14)^0 | J32: =$C32*$E32*(1+Hypothèses!$C$14)^0 | K32: =$C32*$E32*(1+Hypothèses!$C$14)^0 | L32: =$C32*$E32*(1+Hypothèses!$C$14)^0 | M32: =$C32*$E32*(1+Hypothèses!$C$14)^0 | N32: =$C32*$E32*(1+Hypothèses!$C$14)^0 | ... R32: =$C32*$E32*(1+Hypothèses!$C$14)^0 | S32: =$C32*$E32*(1+Hypothèses!$C$14)^1 | T32: =$C32*$E32*(1+Hypothèses!$C$14)^1 | U32: =$C32*$E32*(1+Hypothèses!$C$14)^1 | V32: =$C32*$E32*(1+Hypothèses!$C$14)^1 | W32: =$C32*$E32*(1+Hypothèses!$C$14)^1 | X32: =$C32*$E32*(1+Hypothèses!$C$14)^1 | Y32: =$C32*$E32*(1+Hypothèses!$C$14)^1 | Z32: =$C32*$E32*(1+Hypothèses!$C$14)^1 | ... AD32: =$C32*$E32*(1+Hypothèses!$C$14)^1 | AE32: =$C32*$E32*(1+Hypothèses!$C$14)^2 | AF32: =$C32*$E32*(1+Hypothèses!$C$14)^2 | AG32: =$C32*$E32*(1+Hypothèses!$C$14)^2 | AH32: =$C32*$E32*(1+Hypothèses!$C$14)^2 | AI32: =$C32*$E32*(1+Hypothèses!$C$14)^2 | AJ32: =$C32*$E32*(1+Hypothèses!$C$14)^2 | AK32: =$C32*$E32*(1+Hypothèses!$C$14)^2 | AL32: =$C32*$E32*(1+Hypothèses!$C$14)^2 | ... AP32: =$C32*$E32*(1+Hypothèses!$C$14)^2 | AQ32: =SUM(G32:R32) | AR32: =SUM(S32:AD32) | AS32: =SUM(AE32:AP32) | AT32: =SUM(AQ32:AS32)
A33: Charges fixes | B33: Entretien matériel (four, pétrin, vitrines) | C33: 1 | D33: forfait/mois | E33: 350 | F33: Estimé — contrat maintenance | G33: =$C33*$E33*(1+Hypothèses!$C$14)^0 | H33: =$C33*$E33*(1+Hypothèses!$C$14)^0 | I33: =$C33*$E33*(1+Hypothèses!$C$14)^0 | J33: =$C33*$E33*(1+Hypothèses!$C$14)^0 | K33: =$C33*$E33*(1+Hypothèses!$C$14)^0 | L33: =$C33*$E33*(1+Hypothèses!$C$14)^0 | M33: =$C33*$E33*(1+Hypothèses!$C$14)^0 | N33: =$C33*$E33*(1+Hypothèses!$C$14)^0 | ... R33: =$C33*$E33*(1+Hypothèses!$C$14)^0 | S33: =$C33*$E33*(1+Hypothèses!$C$14)^1 | T33: =$C33*$E33*(1+Hypothèses!$C$14)^1 | U33: =$C33*$E33*(1+Hypothèses!$C$14)^1 | V33: =$C33*$E33*(1+Hypothèses!$C$14)^1 | W33: =$C33*$E33*(1+Hypothèses!$C$14)^1 | X33: =$C33*$E33*(1+Hypothèses!$C$14)^1 | Y33: =$C33*$E33*(1+Hypothèses!$C$14)^1 | Z33: =$C33*$E33*(1+Hypothèses!$C$14)^1 | ... AD33: =$C33*$E33*(1+Hypothèses!$C$14)^1 | AE33: =$C33*$E33*(1+Hypothèses!$C$14)^2 | AF33: =$C33*$E33*(1+Hypothèses!$C$14)^2 | AG33: =$C33*$E33*(1+Hypothèses!$C$14)^2 | AH33: =$C33*$E33*(1+Hypothèses!$C$14)^2 | AI33: =$C33*$E33*(1+Hypothèses!$C$14)^2 | AJ33: =$C33*$E33*(1+Hypothèses!$C$14)^2 | AK33: =$C33*$E33*(1+Hypothèses!$C$14)^2 | AL33: =$C33*$E33*(1+Hypothèses!$C$14)^2 | ... AP33: =$C33*$E33*(1+Hypothèses!$C$14)^2 | AQ33: =SUM(G33:R33) | AR33: =SUM(S33:AD33) | AS33: =SUM(AE33:AP33) | AT33: =SUM(AQ33:AS33)
A34: Charges fixes | B34: Honoraires comptable | C34: 1 | D34: forfait/mois | E34: 500 | F34: Estimé — cabinet expertise comptable TPE | G34: =$C34*$E34*(1+Hypothèses!$C$14)^0 | H34: =$C34*$E34*(1+Hypothèses!$C$14)^0 | I34: =$C34*$E34*(1+Hypothèses!$C$14)^0 | J34: =$C34*$E34*(1+Hypothèses!$C$14)^0 | K34: =$C34*$E34*(1+Hypothèses!$C$14)^0 | L34: =$C34*$E34*(1+Hypothèses!$C$14)^0 | M34: =$C34*$E34*(1+Hypothèses!$C$14)^0 | N34: =$C34*$E34*(1+Hypothèses!$C$14)^0 | ... R34: =$C34*$E34*(1+Hypothèses!$C$14)^0 | S34: =$C34*$E34*(1+Hypothèses!$C$14)^1 | T34: =$C34*$E34*(1+Hypothèses!$C$14)^1 | U34: =$C34*$E34*(1+Hypothèses!$C$14)^1 | V34: =$C34*$E34*(1+Hypothèses!$C$14)^1 | W34: =$C34*$E34*(1+Hypothèses!$C$14)^1 | X34: =$C34*$E34*(1+Hypothèses!$C$14)^1 | Y34: =$C34*$E34*(1+Hypothèses!$C$14)^1 | Z34: =$C34*$E34*(1+Hypothèses!$C$14)^1 | ... AD34: =$C34*$E34*(1+Hypothèses!$C$14)^1 | AE34: =$C34*$E34*(1+Hypothèses!$C$14)^2 | AF34: =$C34*$E34*(1+Hypothèses!$C$14)^2 | AG34: =$C34*$E34*(1+Hypothèses!$C$14)^2 | AH34: =$C34*$E34*(1+Hypothèses!$C$14)^2 | AI34: =$C34*$E34*(1+Hypothèses!$C$14)^2 | AJ34: =$C34*$E34*(1+Hypothèses!$C$14)^2 | AK34: =$C34*$E34*(1+Hypothèses!$C$14)^2 | AL34: =$C34*$E34*(1+Hypothèses!$C$14)^2 | ... AP34: =$C34*$E34*(1+Hypothèses!$C$14)^2 | AQ34: =SUM(G34:R34) | AR34: =SUM(S34:AD34) | AS34: =SUM(AE34:AP34) | AT34: =SUM(AQ34:AS34)
A35: Charges fixes | B35: Eau | C35: 1 | D35: forfait/mois | E35: 150 | F35: Estimé — facture eau professionnelle | G35: =$C35*$E35*(1+Hypothèses!$C$14)^0 | H35: =$C35*$E35*(1+Hypothèses!$C$14)^0 | I35: =$C35*$E35*(1+Hypothèses!$C$14)^0 | J35: =$C35*$E35*(1+Hypothèses!$C$14)^0 | K35: =$C35*$E35*(1+Hypothèses!$C$14)^0 | L35: =$C35*$E35*(1+Hypothèses!$C$14)^0 | M35: =$C35*$E35*(1+Hypothèses!$C$14)^0 | N35: =$C35*$E35*(1+Hypothèses!$C$14)^0 | ... R35: =$C35*$E35*(1+Hypothèses!$C$14)^0 | S35: =$C35*$E35*(1+Hypothèses!$C$14)^1 | T35: =$C35*$E35*(1+Hypothèses!$C$14)^1 | U35: =$C35*$E35*(1+Hypothèses!$C$14)^1 | V35: =$C35*$E35*(1+Hypothèses!$C$14)^1 | W35: =$C35*$E35*(1+Hypothèses!$C$14)^1 | X35: =$C35*$E35*(1+Hypothèses!$C$14)^1 | Y35: =$C35*$E35*(1+Hypothèses!$C$14)^1 | Z35: =$C35*$E35*(1+Hypothèses!$C$14)^1 | ... AD35: =$C35*$E35*(1+Hypothèses!$C$14)^1 | AE35: =$C35*$E35*(1+Hypothèses!$C$14)^2 | AF35: =$C35*$E35*(1+Hypothèses!$C$14)^2 | AG35: =$C35*$E35*(1+Hypothèses!$C$14)^2 | AH35: =$C35*$E35*(1+Hypothèses!$C$14)^2 | AI35: =$C35*$E35*(1+Hypothèses!$C$14)^2 | AJ35: =$C35*$E35*(1+Hypothèses!$C$14)^2 | AK35: =$C35*$E35*(1+Hypothèses!$C$14)^2 | AL35: =$C35*$E35*(1+Hypothèses!$C$14)^2 | ... AP35: =$C35*$E35*(1+Hypothèses!$C$14)^2 | AQ35: =SUM(G35:R35) | AR35: =SUM(S35:AD35) | AS35: =SUM(AE35:AP35) | AT35: =SUM(AQ35:AS35)
A36: Charges fixes | B36: Fournitures diverses & communication | C36: 1 | D36: forfait/mois | E36: 220 | F36: Estimé | G36: =$C36*$E36*(1+Hypothèses!$C$14)^0 | H36: =$C36*$E36*(1+Hypothèses!$C$14)^0 | I36: =$C36*$E36*(1+Hypothèses!$C$14)^0 | J36: =$C36*$E36*(1+Hypothèses!$C$14)^0 | K36: =$C36*$E36*(1+Hypothèses!$C$14)^0 | L36: =$C36*$E36*(1+Hypothèses!$C$14)^0 | M36: =$C36*$E36*(1+Hypothèses!$C$14)^0 | N36: =$C36*$E36*(1+Hypothèses!$C$14)^0 | ... R36: =$C36*$E36*(1+Hypothèses!$C$14)^0 | S36: =$C36*$E36*(1+Hypothèses!$C$14)^1 | T36: =$C36*$E36*(1+Hypothèses!$C$14)^1 | U36: =$C36*$E36*(1+Hypothèses!$C$14)^1 | V36: =$C36*$E36*(1+Hypothèses!$C$14)^1 | W36: =$C36*$E36*(1+Hypothèses!$C$14)^1 | X36: =$C36*$E36*(1+Hypothèses!$C$14)^1 | Y36: =$C36*$E36*(1+Hypothèses!$C$14)^1 | Z36: =$C36*$E36*(1+Hypothèses!$C$14)^1 | ... AD36: =$C36*$E36*(1+Hypothèses!$C$14)^1 | AE36: =$C36*$E36*(1+Hypothèses!$C$14)^2 | AF36: =$C36*$E36*(1+Hypothèses!$C$14)^2 | AG36: =$C36*$E36*(1+Hypothèses!$C$14)^2 | AH36: =$C36*$E36*(1+Hypothèses!$C$14)^2 | AI36: =$C36*$E36*(1+Hypothèses!$C$14)^2 | AJ36: =$C36*$E36*(1+Hypothèses!$C$14)^2 | AK36: =$C36*$E36*(1+Hypothèses!$C$14)^2 | AL36: =$C36*$E36*(1+Hypothèses!$C$14)^2 | ... AP36: =$C36*$E36*(1+Hypothèses!$C$14)^2 | AQ36: =SUM(G36:R36) | AR36: =SUM(S36:AD36) | AS36: =SUM(AE36:AP36) | AT36: =SUM(AQ36:AS36)
A37: Charges fixes | B37: Frais bancaires (terminal CB, tenue de compte) | C37: 1 | D37: forfait/mois | E37: 150 | F37: Estimé — grille tarifaire bancaire pro | G37: =$C37*$E37*(1+Hypothèses!$C$14)^0 | H37: =$C37*$E37*(1+Hypothèses!$C$14)^0 | I37: =$C37*$E37*(1+Hypothèses!$C$14)^0 | J37: =$C37*$E37*(1+Hypothèses!$C$14)^0 | K37: =$C37*$E37*(1+Hypothèses!$C$14)^0 | L37: =$C37*$E37*(1+Hypothèses!$C$14)^0 | M37: =$C37*$E37*(1+Hypothèses!$C$14)^0 | N37: =$C37*$E37*(1+Hypothèses!$C$14)^0 | ... R37: =$C37*$E37*(1+Hypothèses!$C$14)^0 | S37: =$C37*$E37*(1+Hypothèses!$C$14)^1 | T37: =$C37*$E37*(1+Hypothèses!$C$14)^1 | U37: =$C37*$E37*(1+Hypothèses!$C$14)^1 | V37: =$C37*$E37*(1+Hypothèses!$C$14)^1 | W37: =$C37*$E37*(1+Hypothèses!$C$14)^1 | X37: =$C37*$E37*(1+Hypothèses!$C$14)^1 | Y37: =$C37*$E37*(1+Hypothèses!$C$14)^1 | Z37: =$C37*$E37*(1+Hypothèses!$C$14)^1 | ... AD37: =$C37*$E37*(1+Hypothèses!$C$14)^1 | AE37: =$C37*$E37*(1+Hypothèses!$C$14)^2 | AF37: =$C37*$E37*(1+Hypothèses!$C$14)^2 | AG37: =$C37*$E37*(1+Hypothèses!$C$14)^2 | AH37: =$C37*$E37*(1+Hypothèses!$C$14)^2 | AI37: =$C37*$E37*(1+Hypothèses!$C$14)^2 | AJ37: =$C37*$E37*(1+Hypothèses!$C$14)^2 | AK37: =$C37*$E37*(1+Hypothèses!$C$14)^2 | AL37: =$C37*$E37*(1+Hypothèses!$C$14)^2 | ... AP37: =$C37*$E37*(1+Hypothèses!$C$14)^2 | AQ37: =SUM(G37:R37) | AR37: =SUM(S37:AD37) | AS37: =SUM(AE37:AP37) | AT37: =SUM(AQ37:AS37)
A38: Charges fixes | B38: Impôts & taxes (CFE et autres) | C38: 1 | D38: forfait/mois | E38: 280 | F38: Estimé — barème CFE artisan | G38: =$C38*$E38*(1+Hypothèses!$C$14)^0 | H38: =$C38*$E38*(1+Hypothèses!$C$14)^0 | I38: =$C38*$E38*(1+Hypothèses!$C$14)^0 | J38: =$C38*$E38*(1+Hypothèses!$C$14)^0 | K38: =$C38*$E38*(1+Hypothèses!$C$14)^0 | L38: =$C38*$E38*(1+Hypothèses!$C$14)^0 | M38: =$C38*$E38*(1+Hypothèses!$C$14)^0 | N38: =$C38*$E38*(1+Hypothèses!$C$14)^0 | ... R38: =$C38*$E38*(1+Hypothèses!$C$14)^0 | S38: =$C38*$E38*(1+Hypothèses!$C$14)^1 | T38: =$C38*$E38*(1+Hypothèses!$C$14)^1 | U38: =$C38*$E38*(1+Hypothèses!$C$14)^1 | V38: =$C38*$E38*(1+Hypothèses!$C$14)^1 | W38: =$C38*$E38*(1+Hypothèses!$C$14)^1 | X38: =$C38*$E38*(1+Hypothèses!$C$14)^1 | Y38: =$C38*$E38*(1+Hypothèses!$C$14)^1 | Z38: =$C38*$E38*(1+Hypothèses!$C$14)^1 | ... AD38: =$C38*$E38*(1+Hypothèses!$C$14)^1 | AE38: =$C38*$E38*(1+Hypothèses!$C$14)^2 | AF38: =$C38*$E38*(1+Hypothèses!$C$14)^2 | AG38: =$C38*$E38*(1+Hypothèses!$C$14)^2 | AH38: =$C38*$E38*(1+Hypothèses!$C$14)^2 | AI38: =$C38*$E38*(1+Hypothèses!$C$14)^2 | AJ38: =$C38*$E38*(1+Hypothèses!$C$14)^2 | AK38: =$C38*$E38*(1+Hypothèses!$C$14)^2 | AL38: =$C38*$E38*(1+Hypothèses!$C$14)^2 | ... AP38: =$C38*$E38*(1+Hypothèses!$C$14)^2 | AQ38: =SUM(G38:R38) | AR38: =SUM(S38:AD38) | AS38: =SUM(AE38:AP38) | AT38: =SUM(AQ38:AS38)
A39: Charges fixes | B39: Petit matériel & consommables (papier cuisson, gants, entretien) | C39: 1 | D39: forfait/mois | E39: 300 | F39: Estimé | G39: =$C39*$E39*(1+Hypothèses!$C$14)^0 | H39: =$C39*$E39*(1+Hypothèses!$C$14)^0 | I39: =$C39*$E39*(1+Hypothèses!$C$14)^0 | J39: =$C39*$E39*(1+Hypothèses!$C$14)^0 | K39: =$C39*$E39*(1+Hypothèses!$C$14)^0 | L39: =$C39*$E39*(1+Hypothèses!$C$14)^0 | M39: =$C39*$E39*(1+Hypothèses!$C$14)^0 | N39: =$C39*$E39*(1+Hypothèses!$C$14)^0 | ... R39: =$C39*$E39*(1+Hypothèses!$C$14)^0 | S39: =$C39*$E39*(1+Hypothèses!$C$14)^1 | T39: =$C39*$E39*(1+Hypothèses!$C$14)^1 | U39: =$C39*$E39*(1+Hypothèses!$C$14)^1 | V39: =$C39*$E39*(1+Hypothèses!$C$14)^1 | W39: =$C39*$E39*(1+Hypothèses!$C$14)^1 | X39: =$C39*$E39*(1+Hypothèses!$C$14)^1 | Y39: =$C39*$E39*(1+Hypothèses!$C$14)^1 | Z39: =$C39*$E39*(1+Hypothèses!$C$14)^1 | ... AD39: =$C39*$E39*(1+Hypothèses!$C$14)^1 | AE39: =$C39*$E39*(1+Hypothèses!$C$14)^2 | AF39: =$C39*$E39*(1+Hypothèses!$C$14)^2 | AG39: =$C39*$E39*(1+Hypothèses!$C$14)^2 | AH39: =$C39*$E39*(1+Hypothèses!$C$14)^2 | AI39: =$C39*$E39*(1+Hypothèses!$C$14)^2 | AJ39: =$C39*$E39*(1+Hypothèses!$C$14)^2 | AK39: =$C39*$E39*(1+Hypothèses!$C$14)^2 | AL39: =$C39*$E39*(1+Hypothèses!$C$14)^2 | ... AP39: =$C39*$E39*(1+Hypothèses!$C$14)^2 | AQ39: =SUM(G39:R39) | AR39: =SUM(S39:AD39) | AS39: =SUM(AE39:AP39) | AT39: =SUM(AQ39:AS39)
A40: Charges fixes | B40: Abonnements logiciels (caisse, paie, gestion) | C40: 1 | D40: forfait/mois | E40: 90 | F40: Estimé | G40: =$C40*$E40*(1+Hypothèses!$C$14)^0 | H40: =$C40*$E40*(1+Hypothèses!$C$14)^0 | I40: =$C40*$E40*(1+Hypothèses!$C$14)^0 | J40: =$C40*$E40*(1+Hypothèses!$C$14)^0 | K40: =$C40*$E40*(1+Hypothèses!$C$14)^0 | L40: =$C40*$E40*(1+Hypothèses!$C$14)^0 | M40: =$C40*$E40*(1+Hypothèses!$C$14)^0 | N40: =$C40*$E40*(1+Hypothèses!$C$14)^0 | ... R40: =$C40*$E40*(1+Hypothèses!$C$14)^0 | S40: =$C40*$E40*(1+Hypothèses!$C$14)^1 | T40: =$C40*$E40*(1+Hypothèses!$C$14)^1 | U40: =$C40*$E40*(1+Hypothèses!$C$14)^1 | V40: =$C40*$E40*(1+Hypothèses!$C$14)^1 | W40: =$C40*$E40*(1+Hypothèses!$C$14)^1 | X40: =$C40*$E40*(1+Hypothèses!$C$14)^1 | Y40: =$C40*$E40*(1+Hypothèses!$C$14)^1 | Z40: =$C40*$E40*(1+Hypothèses!$C$14)^1 | ... AD40: =$C40*$E40*(1+Hypothèses!$C$14)^1 | AE40: =$C40*$E40*(1+Hypothèses!$C$14)^2 | AF40: =$C40*$E40*(1+Hypothèses!$C$14)^2 | AG40: =$C40*$E40*(1+Hypothèses!$C$14)^2 | AH40: =$C40*$E40*(1+Hypothèses!$C$14)^2 | AI40: =$C40*$E40*(1+Hypothèses!$C$14)^2 | AJ40: =$C40*$E40*(1+Hypothèses!$C$14)^2 | AK40: =$C40*$E40*(1+Hypothèses!$C$14)^2 | AL40: =$C40*$E40*(1+Hypothèses!$C$14)^2 | ... AP40: =$C40*$E40*(1+Hypothèses!$C$14)^2 | AQ40: =SUM(G40:R40) | AR40: =SUM(S40:AD40) | AS40: =SUM(AE40:AP40) | AT40: =SUM(AQ40:AS40)
...

Sheet Plan de trésorerie
A1: Boulangerie — Plan de trésorerie mensuel (3 ans)
A2: Trésorerie début + encaissements − décaissements = trésorerie fin. Chaque poste reprend directement le détail mensuel de l'onglet Dépenses détaillées.
C3: ANNÉE 1 | O3: ANNÉE 2 | AA3: ANNÉE 3
