Workbook

Sheet Hypothèses
A1: Entreprise de BTP (gros œuvre / maçonnerie) — Hypothèses
A2: Métier : petite entreprise de gros œuvre/maçonnerie | CA cible ≈ 1,5 M€ en Année 1, sur 3 ans | Cellules bleues = modifiables
A4: Chiffre d'affaires annuel HT — Année 1 (€) | C4: 1500000
A5: Taux de TVA moyen sur les ventes (%) | C5: 0.2
A6: Taux de TVA moyen sur les achats (%) | C6: 0.2
A7: Trésorerie disponible au 1er janvier Année 1 (€) | C7: 40000
A8: Cotisations sociales du dirigeant (TNS) — par trimestre, Année 1 (€) | C8: 4500
A9: Remboursement emprunts matériel/véhicules — mensualité fixe (€) | C9: 1200
A10: Part du CA encaissée le mois même (%) | C10: 0
A11: Part du CA encaissée à M-1 (30 jours) (%) | C11: 0.5
A12: Part du CA encaissée à M-2 (60 jours) (%) | C12: 0.5 | D12: Contrôle (doit = 100%) | E12: =C10+C11+C12
A13: Taux de croissance du CA — par an (%) | C13: 0.025
A14: Taux d'inflation des prix d'achat — par an (%) | C14: 0.035
A15: CA TTC mensuel moyen — amorçage M-1/M-2 avant janvier Année 1 (€) | C15: =Revenus!$AM$12/12
A17: Mois (motif répété chaque année) | C17: Jan | D17: Fév | E17: Mar | F17: Avr | G17: Mai | H17: Jui | I17: Jui | J17: Aoû | K17: Sep | L17: Oct | M17: Nov | N17: Déc
A18: Indice de saisonnalité (1 = mois moyen) | C18: 0.85 | D18: 0.9 | E18: 1 | F18: 1.05 | G18: 1.05 | H18: 1.1 | I18: 1.05 | J18: 0.55 | K18: 1.05 | L18: 1.1 | M18: 1.05 | N18: 0.8
A19: Poids du mois dans l'année (%, normalisé) | C19: =C18/SUM($C$18:$N$18) | D19: =D18/SUM($C$18:$N$18) | E19: =E18/SUM($C$18:$N$18) | F19: =F18/SUM($C$18:$N$18) | G19: =G18/SUM($C$18:$N$18) | H19: =H18/SUM($C$18:$N$18) | I19: =I18/SUM($C$18:$N$18) | J19: =J18/SUM($C$18:$N$18) | ... N19: =N18/SUM($C$18:$N$18)
A21: Note saisonnalité : -45% en août (congés BTP traditionnels), -20% en janvier et -15% en décembre (intempéries, jours fériés, fin de chantiers). Motif répété chaque année.
A22: Note délai de paiement : 45 jours en moyenne (entre 30 et 60j net) → modélisé par un encaissement réparti 50%/50% sur M-1 et M-2. C'est le principal facteur de tension de trésorerie du BTP.
A23: Note évolution 3 ans : le CA croît de 2,5%/an mais les prix d'achat augmentent de 3,5%/an → compression progressive de la marge. Les lignes acier, carburants et électricité utilisent une simulation de fluctuation mensuelle réaliste (pas une inflation lissée).
A25: Légende
A26: ■ | B26: Saisie modifiable (hypothèse)
A27: ■ | B27: Formule calculée automatiquement
A28: ■ | B28: Lien vers un autre onglet
A29: ■ | B29: Prix indicatif en attente de connexion à une API de prix de marché (voir onglet Benchmarks & sources)

Sheet Revenus
A1: BTP — Revenus mensuels (facturation travaux, 3 ans)
A2: Répartition du CA par type de chantier × saisonnalité de l'activité × croissance annuelle
C3: ANNÉE 1 | O3: ANNÉE 2 | AA3: ANNÉE 3
A4: Source de revenus | B4: % du CA annuel | C4: Jan A1 | D4: Fév A1 | E4: Mar A1 | F4: Avr A1 | G4: Mai A1 | H4: Jui A1 | I4: Jui A1 | J4: Aoû A1 | K4: Sep A1 | L4: Oct A1 | M4: Nov A1 | N4: Déc A1 | O4: Jan A2 | P4: Fév A2 | Q4: Mar A2 | R4: Avr A2 | S4: Mai A2 | T4: Jui A2 | U4: Jui A2 | V4: Aoû A2 | W4: Sep A2 | X4: Oct A2 | Y4: Nov A2 | Z4: Déc A2 | AA4: Jan A3 | AB4: Fév A3 | AC4: Mar A3 | AD4: Avr A3 | AE4: Mai A3 | AF4: Jui A3 | AG4: Jui A3 | AH4: Aoû A3 | AI4: Sep A3 | AJ4: Oct A3 | AK4: Nov A3 | AL4: Déc A3 | AM4: Total A1 | AN4: Total A2 | AO4: Total A3 | AP4: Total 3 ans
A5: Gros œuvre — maisons individuelles (neuf) | B5: 0.45 | C5: =Hypothèses!$C$4*$B5*Hypothèses!C$19*(1+Hypothèses!$C$13)^0 | D5: =Hypothèses!$C$4*$B5*Hypothèses!D$19*(1+Hypothèses!$C$13)^0 | E5: =Hypothèses!$C$4*$B5*Hypothèses!E$19*(1+Hypothèses!$C$13)^0 | F5: =Hypothèses!$C$4*$B5*Hypothèses!F$19*(1+Hypothèses!$C$13)^0 | G5: =Hypothèses!$C$4*$B5*Hypothèses!G$19*(1+Hypothèses!$C$13)^0 | H5: =Hypothèses!$C$4*$B5*Hypothèses!H$19*(1+Hypothèses!$C$13)^0 | I5: =Hypothèses!$C$4*$B5*Hypothèses!I$19*(1+Hypothèses!$C$13)^0 | J5: =Hypothèses!$C$4*$B5*Hypothèses!J$19*(1+Hypothèses!$C$13)^0 | ... N5: =Hypothèses!$C$4*$B5*Hypothèses!N$19*(1+Hypothèses!$C$13)^0 | O5: =Hypothèses!$C$4*$B5*Hypothèses!C$19*(1+Hypothèses!$C$13)^1 | P5: =Hypothèses!$C$4*$B5*Hypothèses!D$19*(1+Hypothèses!$C$13)^1 | Q5: =Hypothèses!$C$4*$B5*Hypothèses!E$19*(1+Hypothèses!$C$13)^1 | R5: =Hypothèses!$C$4*$B5*Hypothèses!F$19*(1+Hypothèses!$C$13)^1 | S5: =Hypothèses!$C$4*$B5*Hypothèses!G$19*(1+Hypothèses!$C$13)^1 | T5: =Hypothèses!$C$4*$B5*Hypothèses!H$19*(1+Hypothèses!$C$13)^1 | U5: =Hypothèses!$C$4*$B5*Hypothèses!I$19*(1+Hypothèses!$C$13)^1 | V5: =Hypothèses!$C$4*$B5*Hypothèses!J$19*(1+Hypothèses!$C$13)^1 | ... Z5: =Hypothèses!$C$4*$B5*Hypothèses!N$19*(1+Hypothèses!$C$13)^1 | AA5: =Hypothèses!$C$4*$B5*Hypothèses!C$19*(1+Hypothèses!$C$13)^2 | AB5: =Hypothèses!$C$4*$B5*Hypothèses!D$19*(1+Hypothèses!$C$13)^2 | AC5: =Hypothèses!$C$4*$B5*Hypothèses!E$19*(1+Hypothèses!$C$13)^2 | AD5: =Hypothèses!$C$4*$B5*Hypothèses!F$19*(1+Hypothèses!$C$13)^2 | AE5: =Hypothèses!$C$4*$B5*Hypothèses!G$19*(1+Hypothèses!$C$13)^2 | AF5: =Hypothèses!$C$4*$B5*Hypothèses!H$19*(1+Hypothèses!$C$13)^2 | AG5: =Hypothèses!$C$4*$B5*Hypothèses!I$19*(1+Hypothèses!$C$13)^2 | AH5: =Hypothèses!$C$4*$B5*Hypothèses!J$19*(1+Hypothèses!$C$13)^2 | ... AL5: =Hypothèses!$C$4*$B5*Hypothèses!N$19*(1+Hypothèses!$C$13)^2 | AM5: =SUM(C5:N5) | AN5: =SUM(O5:Z5) | AO5: =SUM(AA5:AL5) | AP5: =SUM(AM5:AO5)
A6: Gros œuvre — logements collectifs / marchés | B6: 0.3 | C6: =Hypothèses!$C$4*$B6*Hypothèses!C$19*(1+Hypothèses!$C$13)^0 | D6: =Hypothèses!$C$4*$B6*Hypothèses!D$19*(1+Hypothèses!$C$13)^0 | E6: =Hypothèses!$C$4*$B6*Hypothèses!E$19*(1+Hypothèses!$C$13)^0 | F6: =Hypothèses!$C$4*$B6*Hypothèses!F$19*(1+Hypothèses!$C$13)^0 | G6: =Hypothèses!$C$4*$B6*Hypothèses!G$19*(1+Hypothèses!$C$13)^0 | H6: =Hypothèses!$C$4*$B6*Hypothèses!H$19*(1+Hypothèses!$C$13)^0 | I6: =Hypothèses!$C$4*$B6*Hypothèses!I$19*(1+Hypothèses!$C$13)^0 | J6: =Hypothèses!$C$4*$B6*Hypothèses!J$19*(1+Hypothèses!$C$13)^0 | ... N6: =Hypothèses!$C$4*$B6*Hypothèses!N$19*(1+Hypothèses!$C$13)^0 | O6: =Hypothèses!$C$4*$B6*Hypothèses!C$19*(1+Hypothèses!$C$13)^1 | P6: =Hypothèses!$C$4*$B6*Hypothèses!D$19*(1+Hypothèses!$C$13)^1 | Q6: =Hypothèses!$C$4*$B6*Hypothèses!E$19*(1+Hypothèses!$C$13)^1 | R6: =Hypothèses!$C$4*$B6*Hypothèses!F$19*(1+Hypothèses!$C$13)^1 | S6: =Hypothèses!$C$4*$B6*Hypothèses!G$19*(1+Hypothèses!$C$13)^1 | T6: =Hypothèses!$C$4*$B6*Hypothèses!H$19*(1+Hypothèses!$C$13)^1 | U6: =Hypothèses!$C$4*$B6*Hypothèses!I$19*(1+Hypothèses!$C$13)^1 | V6: =Hypothèses!$C$4*$B6*Hypothèses!J$19*(1+Hypothèses!$C$13)^1 | ... Z6: =Hypothèses!$C$4*$B6*Hypothèses!N$19*(1+Hypothèses!$C$13)^1 | AA6: =Hypothèses!$C$4*$B6*Hypothèses!C$19*(1+Hypothèses!$C$13)^2 | AB6: =Hypothèses!$C$4*$B6*Hypothèses!D$19*(1+Hypothèses!$C$13)^2 | AC6: =Hypothèses!$C$4*$B6*Hypothèses!E$19*(1+Hypothèses!$C$13)^2 | AD6: =Hypothèses!$C$4*$B6*Hypothèses!F$19*(1+Hypothèses!$C$13)^2 | AE6: =Hypothèses!$C$4*$B6*Hypothèses!G$19*(1+Hypothèses!$C$13)^2 | AF6: =Hypothèses!$C$4*$B6*Hypothèses!H$19*(1+Hypothèses!$C$13)^2 | AG6: =Hypothèses!$C$4*$B6*Hypothèses!I$19*(1+Hypothèses!$C$13)^2 | AH6: =Hypothèses!$C$4*$B6*Hypothèses!J$19*(1+Hypothèses!$C$13)^2 | ... AL6: =Hypothèses!$C$4*$B6*Hypothèses!N$19*(1+Hypothèses!$C$13)^2 | AM6: =SUM(C6:N6) | AN6: =SUM(O6:Z6) | AO6: =SUM(AA6:AL6) | AP6: =SUM(AM6:AO6)
A7: Rénovation / extension / réhabilitation | B7: 0.2 | C7: =Hypothèses!$C$4*$B7*Hypothèses!C$19*(1+Hypothèses!$C$13)^0 | D7: =Hypothèses!$C$4*$B7*Hypothèses!D$19*(1+Hypothèses!$C$13)^0 | E7: =Hypothèses!$C$4*$B7*Hypothèses!E$19*(1+Hypothèses!$C$13)^0 | F7: =Hypothèses!$C$4*$B7*Hypothèses!F$19*(1+Hypothèses!$C$13)^0 | G7: =Hypothèses!$C$4*$B7*Hypothèses!G$19*(1+Hypothèses!$C$13)^0 | H7: =Hypothèses!$C$4*$B7*Hypothèses!H$19*(1+Hypothèses!$C$13)^0 | I7: =Hypothèses!$C$4*$B7*Hypothèses!I$19*(1+Hypothèses!$C$13)^0 | J7: =Hypothèses!$C$4*$B7*Hypothèses!J$19*(1+Hypothèses!$C$13)^0 | ... N7: =Hypothèses!$C$4*$B7*Hypothèses!N$19*(1+Hypothèses!$C$13)^0 | O7: =Hypothèses!$C$4*$B7*Hypothèses!C$19*(1+Hypothèses!$C$13)^1 | P7: =Hypothèses!$C$4*$B7*Hypothèses!D$19*(1+Hypothèses!$C$13)^1 | Q7: =Hypothèses!$C$4*$B7*Hypothèses!E$19*(1+Hypothèses!$C$13)^1 | R7: =Hypothèses!$C$4*$B7*Hypothèses!F$19*(1+Hypothèses!$C$13)^1 | S7: =Hypothèses!$C$4*$B7*Hypothèses!G$19*(1+Hypothèses!$C$13)^1 | T7: =Hypothèses!$C$4*$B7*Hypothèses!H$19*(1+Hypothèses!$C$13)^1 | U7: =Hypothèses!$C$4*$B7*Hypothèses!I$19*(1+Hypothèses!$C$13)^1 | V7: =Hypothèses!$C$4*$B7*Hypothèses!J$19*(1+Hypothèses!$C$13)^1 | ... Z7: =Hypothèses!$C$4*$B7*Hypothèses!N$19*(1+Hypothèses!$C$13)^1 | AA7: =Hypothèses!$C$4*$B7*Hypothèses!C$19*(1+Hypothèses!$C$13)^2 | AB7: =Hypothèses!$C$4*$B7*Hypothèses!D$19*(1+Hypothèses!$C$13)^2 | AC7: =Hypothèses!$C$4*$B7*Hypothèses!E$19*(1+Hypothèses!$C$13)^2 | AD7: =Hypothèses!$C$4*$B7*Hypothèses!F$19*(1+Hypothèses!$C$13)^2 | AE7: =Hypothèses!$C$4*$B7*Hypothèses!G$19*(1+Hypothèses!$C$13)^2 | AF7: =Hypothèses!$C$4*$B7*Hypothèses!H$19*(1+Hypothèses!$C$13)^2 | AG7: =Hypothèses!$C$4*$B7*Hypothèses!I$19*(1+Hypothèses!$C$13)^2 | AH7: =Hypothèses!$C$4*$B7*Hypothèses!J$19*(1+Hypothèses!$C$13)^2 | ... AL7: =Hypothèses!$C$4*$B7*Hypothèses!N$19*(1+Hypothèses!$C$13)^2 | AM7: =SUM(C7:N7) | AN7: =SUM(O7:Z7) | AO7: =SUM(AA7:AL7) | AP7: =SUM(AM7:AO7)
A8: Travaux divers (VRD, dépannage) | B8: 0.05 | C8: =Hypothèses!$C$4*$B8*Hypothèses!C$19*(1+Hypothèses!$C$13)^0 | D8: =Hypothèses!$C$4*$B8*Hypothèses!D$19*(1+Hypothèses!$C$13)^0 | E8: =Hypothèses!$C$4*$B8*Hypothèses!E$19*(1+Hypothèses!$C$13)^0 | F8: =Hypothèses!$C$4*$B8*Hypothèses!F$19*(1+Hypothèses!$C$13)^0 | G8: =Hypothèses!$C$4*$B8*Hypothèses!G$19*(1+Hypothèses!$C$13)^0 | H8: =Hypothèses!$C$4*$B8*Hypothèses!H$19*(1+Hypothèses!$C$13)^0 | I8: =Hypothèses!$C$4*$B8*Hypothèses!I$19*(1+Hypothèses!$C$13)^0 | J8: =Hypothèses!$C$4*$B8*Hypothèses!J$19*(1+Hypothèses!$C$13)^0 | ... N8: =Hypothèses!$C$4*$B8*Hypothèses!N$19*(1+Hypothèses!$C$13)^0 | O8: =Hypothèses!$C$4*$B8*Hypothèses!C$19*(1+Hypothèses!$C$13)^1 | P8: =Hypothèses!$C$4*$B8*Hypothèses!D$19*(1+Hypothèses!$C$13)^1 | Q8: =Hypothèses!$C$4*$B8*Hypothèses!E$19*(1+Hypothèses!$C$13)^1 | R8: =Hypothèses!$C$4*$B8*Hypothèses!F$19*(1+Hypothèses!$C$13)^1 | S8: =Hypothèses!$C$4*$B8*Hypothèses!G$19*(1+Hypothèses!$C$13)^1 | T8: =Hypothèses!$C$4*$B8*Hypothèses!H$19*(1+Hypothèses!$C$13)^1 | U8: =Hypothèses!$C$4*$B8*Hypothèses!I$19*(1+Hypothèses!$C$13)^1 | V8: =Hypothèses!$C$4*$B8*Hypothèses!J$19*(1+Hypothèses!$C$13)^1 | ... Z8: =Hypothèses!$C$4*$B8*Hypothèses!N$19*(1+Hypothèses!$C$13)^1 | AA8: =Hypothèses!$C$4*$B8*Hypothèses!C$19*(1+Hypothèses!$C$13)^2 | AB8: =Hypothèses!$C$4*$B8*Hypothèses!D$19*(1+Hypothèses!$C$13)^2 | AC8: =Hypothèses!$C$4*$B8*Hypothèses!E$19*(1+Hypothèses!$C$13)^2 | AD8: =Hypothèses!$C$4*$B8*Hypothèses!F$19*(1+Hypothèses!$C$13)^2 | AE8: =Hypothèses!$C$4*$B8*Hypothèses!G$19*(1+Hypothèses!$C$13)^2 | AF8: =Hypothèses!$C$4*$B8*Hypothèses!H$19*(1+Hypothèses!$C$13)^2 | AG8: =Hypothèses!$C$4*$B8*Hypothèses!I$19*(1+Hypothèses!$C$13)^2 | AH8: =Hypothèses!$C$4*$B8*Hypothèses!J$19*(1+Hypothèses!$C$13)^2 | ... AL8: =Hypothèses!$C$4*$B8*Hypothèses!N$19*(1+Hypothèses!$C$13)^2 | AM8: =SUM(C8:N8) | AN8: =SUM(O8:Z8) | AO8: =SUM(AA8:AL8) | AP8: =SUM(AM8:AO8)
A9: TOTAL CA HT | C9: =SUM(C5:C8) | D9: =SUM(D5:D8) | E9: =SUM(E5:E8) | F9: =SUM(F5:F8) | G9: =SUM(G5:G8) | H9: =SUM(H5:H8) | I9: =SUM(I5:I8) | J9: =SUM(J5:J8) | ... AL9: =SUM(AL5:AL8) | AM9: =SUM(C9:N9) | AN9: =SUM(O9:Z9) | AO9: =SUM(AA9:AL9) | AP9: =SUM(AM9:AO9)
A10: Contrôle Σ % répartition (doit = 100%) | B10: =SUM(B5:B8)
A11: TVA collectée sur les ventes | C11: =C9*Hypothèses!$C$5 | D11: =D9*Hypothèses!$C$5 | E11: =E9*Hypothèses!$C$5 | F11: =F9*Hypothèses!$C$5 | G11: =G9*Hypothèses!$C$5 | H11: =H9*Hypothèses!$C$5 | I11: =I9*Hypothèses!$C$5 | J11: =J9*Hypothèses!$C$5 | ... AL11: =AL9*Hypothèses!$C$5 | AM11: =SUM(C11:N11) | AN11: =SUM(O11:Z11) | AO11: =SUM(AA11:AL11) | AP11: =SUM(AM11:AO11)
A12: CA TTC facturé (avant délai de paiement) | C12: =C9+C11 | D12: =D9+D11 | E12: =E9+E11 | F12: =F9+F11 | G12: =G9+G11 | H12: =H9+H11 | I12: =I9+I11 | J12: =J9+J11 | ... AL12: =AL9+AL11 | AM12: =SUM(C12:N12) | AN12: =SUM(O12:Z12) | AO12: =SUM(AA12:AL12) | AP12: =SUM(AM12:AO12)

Sheet Dépenses détaillées
A1: BTP — Dépenses détaillées (3 ans, mois par mois)
A2: Quantité de base × indice de saisonnalité × Prix (de base inflaté, ou simulé mois par mois pour les commodités) = Coût du mois.
G3: ANNÉE 1 | S3: ANNÉE 2 | AE3: ANNÉE 3
A4: Catégorie | B4: Poste | C4: Qté base/mois (A1) | D4: Unité | E4: Prix unitaire base (A1, €) | F4: Source prix | G4: Jan A1 | H4: Fév A1 | I4: Mar A1 | J4: Avr A1 | K4: Mai A1 | L4: Jui A1 | M4: Jui A1 | N4: Aoû A1 | O4: Sep A1 | P4: Oct A1 | Q4: Nov A1 | R4: Déc A1 | S4: Jan A2 | T4: Fév A2 | U4: Mar A2 | V4: Avr A2 | W4: Mai A2 | X4: Jui A2 | Y4: Jui A2 | Z4: Aoû A2 | AA4: Sep A2 | AB4: Oct A2 | AC4: Nov A2 | AD4: Déc A2 | AE4: Jan A3 | AF4: Fév A3 | AG4: Mar A3 | AH4: Avr A3 | AI4: Mai A3 | AJ4: Jui A3 | AK4: Jui A3 | AL4: Aoû A3 | AM4: Sep A3 | AN4: Oct A3 | AO4: Nov A3 | AP4: Déc A3 | AQ4: Total A1 | AR4: Total A2 | AS4: Total A3 | AT4: Total 3 ans
A5: Matériaux | B5: Ciment (CEM I/II, sacs et vrac) | C5: 25 | D5: tonnes | E5: 115.5 | F5: Sourcé — prix négoce matériaux 2025 (~115€/t HT) | G5: =$C5*Hypothèses!C$18*$E5*(1+Hypothèses!$C$14)^0 | H5: =$C5*Hypothèses!D$18*$E5*(1+Hypothèses!$C$14)^0 | I5: =$C5*Hypothèses!E$18*$E5*(1+Hypothèses!$C$14)^0 | J5: =$C5*Hypothèses!F$18*$E5*(1+Hypothèses!$C$14)^0 | K5: =$C5*Hypothèses!G$18*$E5*(1+Hypothèses!$C$14)^0 | L5: =$C5*Hypothèses!H$18*$E5*(1+Hypothèses!$C$14)^0 | M5: =$C5*Hypothèses!I$18*$E5*(1+Hypothèses!$C$14)^0 | N5: =$C5*Hypothèses!J$18*$E5*(1+Hypothèses!$C$14)^0 | ... R5: =$C5*Hypothèses!N$18*$E5*(1+Hypothèses!$C$14)^0 | S5: =$C5*Hypothèses!C$18*$E5*(1+Hypothèses!$C$14)^1 | T5: =$C5*Hypothèses!D$18*$E5*(1+Hypothèses!$C$14)^1 | U5: =$C5*Hypothèses!E$18*$E5*(1+Hypothèses!$C$14)^1 | V5: =$C5*Hypothèses!F$18*$E5*(1+Hypothèses!$C$14)^1 | W5: =$C5*Hypothèses!G$18*$E5*(1+Hypothèses!$C$14)^1 | X5: =$C5*Hypothèses!H$18*$E5*(1+Hypothèses!$C$14)^1 | Y5: =$C5*Hypothèses!I$18*$E5*(1+Hypothèses!$C$14)^1 | Z5: =$C5*Hypothèses!J$18*$E5*(1+Hypothèses!$C$14)^1 | ... AD5: =$C5*Hypothèses!N$18*$E5*(1+Hypothèses!$C$14)^1 | AE5: =$C5*Hypothèses!C$18*$E5*(1+Hypothèses!$C$14)^2 | AF5: =$C5*Hypothèses!D$18*$E5*(1+Hypothèses!$C$14)^2 | AG5: =$C5*Hypothèses!E$18*$E5*(1+Hypothèses!$C$14)^2 | AH5: =$C5*Hypothèses!F$18*$E5*(1+Hypothèses!$C$14)^2 | AI5: =$C5*Hypothèses!G$18*$E5*(1+Hypothèses!$C$14)^2 | AJ5: =$C5*Hypothèses!H$18*$E5*(1+Hypothèses!$C$14)^2 | AK5: =$C5*Hypothèses!I$18*$E5*(1+Hypothèses!$C$14)^2 | AL5: =$C5*Hypothèses!J$18*$E5*(1+Hypothèses!$C$14)^2 | ... AP5: =$C5*Hypothèses!N$18*$E5*(1+Hypothèses!$C$14)^2 | AQ5: =SUM(G5:R5) | AR5: =SUM(S5:AD5) | AS5: =SUM(AE5:AP5) | AT5: =SUM(AQ5:AS5)
A6: Matériaux | B6: Sable & granulats | C6: 70 | D6: tonnes | E6: 25 | F6: Estimé — carrière/négoce régional | G6: =$C6*Hypothèses!C$18*$E6*(1+Hypothèses!$C$14)^0 | H6: =$C6*Hypothèses!D$18*$E6*(1+Hypothèses!$C$14)^0 | I6: =$C6*Hypothèses!E$18*$E6*(1+Hypothèses!$C$14)^0 | J6: =$C6*Hypothèses!F$18*$E6*(1+Hypothèses!$C$14)^0 | K6: =$C6*Hypothèses!G$18*$E6*(1+Hypothèses!$C$14)^0 | L6: =$C6*Hypothèses!H$18*$E6*(1+Hypothèses!$C$14)^0 | M6: =$C6*Hypothèses!I$18*$E6*(1+Hypothèses!$C$14)^0 | N6: =$C6*Hypothèses!J$18*$E6*(1+Hypothèses!$C$14)^0 | ... R6: =$C6*Hypothèses!N$18*$E6*(1+Hypothèses!$C$14)^0 | S6: =$C6*Hypothèses!C$18*$E6*(1+Hypothèses!$C$14)^1 | T6: =$C6*Hypothèses!D$18*$E6*(1+Hypothèses!$C$14)^1 | U6: =$C6*Hypothèses!E$18*$E6*(1+Hypothèses!$C$14)^1 | V6: =$C6*Hypothèses!F$18*$E6*(1+Hypothèses!$C$14)^1 | W6: =$C6*Hypothèses!G$18*$E6*(1+Hypothèses!$C$14)^1 | X6: =$C6*Hypothèses!H$18*$E6*(1+Hypothèses!$C$14)^1 | Y6: =$C6*Hypothèses!I$18*$E6*(1+Hypothèses!$C$14)^1 | Z6: =$C6*Hypothèses!J$18*$E6*(1+Hypothèses!$C$14)^1 | ... AD6: =$C6*Hypothèses!N$18*$E6*(1+Hypothèses!$C$14)^1 | AE6: =$C6*Hypothèses!C$18*$E6*(1+Hypothèses!$C$14)^2 | AF6: =$C6*Hypothèses!D$18*$E6*(1+Hypothèses!$C$14)^2 | AG6: =$C6*Hypothèses!E$18*$E6*(1+Hypothèses!$C$14)^2 | AH6: =$C6*Hypothèses!F$18*$E6*(1+Hypothèses!$C$14)^2 | AI6: =$C6*Hypothèses!G$18*$E6*(1+Hypothèses!$C$14)^2 | AJ6: =$C6*Hypothèses!H$18*$E6*(1+Hypothèses!$C$14)^2 | AK6: =$C6*Hypothèses!I$18*$E6*(1+Hypothèses!$C$14)^2 | AL6: =$C6*Hypothèses!J$18*$E6*(1+Hypothèses!$C$14)^2 | ... AP6: =$C6*Hypothèses!N$18*$E6*(1+Hypothèses!$C$14)^2 | AQ6: =SUM(G6:R6) | AR6: =SUM(S6:AD6) | AS6: =SUM(AE6:AP6) | AT6: =SUM(AQ6:AS6)
A7: Matériaux | B7: Béton prêt à l'emploi (BPE) | C7: 120 | D7: m³ | E7: 140 | F7: Sourcé — fourchette 120-180€/m³ livré 2025 | G7: =$C7*Hypothèses!C$18*$E7*(1+Hypothèses!$C$14)^0 | H7: =$C7*Hypothèses!D$18*$E7*(1+Hypothèses!$C$14)^0 | I7: =$C7*Hypothèses!E$18*$E7*(1+Hypothèses!$C$14)^0 | J7: =$C7*Hypothèses!F$18*$E7*(1+Hypothèses!$C$14)^0 | K7: =$C7*Hypothèses!G$18*$E7*(1+Hypothèses!$C$14)^0 | L7: =$C7*Hypothèses!H$18*$E7*(1+Hypothèses!$C$14)^0 | M7: =$C7*Hypothèses!I$18*$E7*(1+Hypothèses!$C$14)^0 | N7: =$C7*Hypothèses!J$18*$E7*(1+Hypothèses!$C$14)^0 | ... R7: =$C7*Hypothèses!N$18*$E7*(1+Hypothèses!$C$14)^0 | S7: =$C7*Hypothèses!C$18*$E7*(1+Hypothèses!$C$14)^1 | T7: =$C7*Hypothèses!D$18*$E7*(1+Hypothèses!$C$14)^1 | U7: =$C7*Hypothèses!E$18*$E7*(1+Hypothèses!$C$14)^1 | V7: =$C7*Hypothèses!F$18*$E7*(1+Hypothèses!$C$14)^1 | W7: =$C7*Hypothèses!G$18*$E7*(1+Hypothèses!$C$14)^1 | X7: =$C7*Hypothèses!H$18*$E7*(1+Hypothèses!$C$14)^1 | Y7: =$C7*Hypothèses!I$18*$E7*(1+Hypothèses!$C$14)^1 | Z7: =$C7*Hypothèses!J$18*$E7*(1+Hypothèses!$C$14)^1 | ... AD7: =$C7*Hypothèses!N$18*$E7*(1+Hypothèses!$C$14)^1 | AE7: =$C7*Hypothèses!C$18*$E7*(1+Hypothèses!$C$14)^2 | AF7: =$C7*Hypothèses!D$18*$E7*(1+Hypothèses!$C$14)^2 | AG7: =$C7*Hypothèses!E$18*$E7*(1+Hypothèses!$C$14)^2 | AH7: =$C7*Hypothèses!F$18*$E7*(1+Hypothèses!$C$14)^2 | AI7: =$C7*Hypothèses!G$18*$E7*(1+Hypothèses!$C$14)^2 | AJ7: =$C7*Hypothèses!H$18*$E7*(1+Hypothèses!$C$14)^2 | AK7: =$C7*Hypothèses!I$18*$E7*(1+Hypothèses!$C$14)^2 | AL7: =$C7*Hypothèses!J$18*$E7*(1+Hypothèses!$C$14)^2 | ... AP7: =$C7*Hypothèses!N$18*$E7*(1+Hypothèses!$C$14)^2 | AQ7: =SUM(G7:R7) | AR7: =SUM(S7:AD7) | AS7: =SUM(AE7:AP7) | AT7: =SUM(AQ7:AS7)
A8: Matériaux | B8: Acier / ferraillage (armatures) — prix de marché simulé (€/unité) | D8: tonnes | E8: =AVERAGE(G8:AP8) | F8: API marché (proxy LME/Eurofer, non couvert par Alpha Vantage gratuit) — simulation calibrée | G8: 778.8337 | H8: 793.1221 | I8: 823.8009 | J8: 826.1464 | K8: 828.7667 | L8: 773.0482 | M8: 717.4002 | N8: 729.0043 | O8: 667.9341 | P8: 687.4787 | Q8: 675.7819 | R8: 666.5007 | S8: 636.6521 | T8: 624.6523 | U8: 606.8311 | V8: 603.8098 | W8: 599.0931 | X8: 583.8696 | Y8: 579.0847 | Z8: 598.6054 | AA8: 598.0031 | AB8: 616.0962 | AC8: 618.1391 | AD8: 578.2141 | AE8: 612.8115 | AF8: 620.8956 | AG8: 657.5317 | AH8: 678.877 | AI8: 648.4947 | AJ8: 669.7428 | AK8: 674.9055 | AL8: 623.6398 | AM8: 615.299 | AN8: 595.479 | AO8: 626.0723 | AP8: 648.1921
A9: Matériaux | B9: ↳ Coût (Acier / ferraillage (armatures)) | C9: 18 | D9: tonnes | F9: Coût = Qté de base × saisonnalité × prix simulé ci-dessus | G9: =$C9*Hypothèses!C$18*G8 | H9: =$C9*Hypothèses!D$18*H8 | I9: =$C9*Hypothèses!E$18*I8 | J9: =$C9*Hypothèses!F$18*J8 | K9: =$C9*Hypothèses!G$18*K8 | L9: =$C9*Hypothèses!H$18*L8 | M9: =$C9*Hypothèses!I$18*M8 | N9: =$C9*Hypothèses!J$18*N8 | ... R9: =$C9*Hypothèses!N$18*R8 | S9: =$C9*Hypothèses!C$18*S8 | T9: =$C9*Hypothèses!D$18*T8 | U9: =$C9*Hypothèses!E$18*U8 | V9: =$C9*Hypothèses!F$18*V8 | W9: =$C9*Hypothèses!G$18*W8 | X9: =$C9*Hypothèses!H$18*X8 | Y9: =$C9*Hypothèses!I$18*Y8 | Z9: =$C9*Hypothèses!J$18*Z8 | ... AD9: =$C9*Hypothèses!N$18*AD8 | AE9: =$C9*Hypothèses!C$18*AE8 | AF9: =$C9*Hypothèses!D$18*AF8 | AG9: =$C9*Hypothèses!E$18*AG8 | AH9: =$C9*Hypothèses!F$18*AH8 | AI9: =$C9*Hypothèses!G$18*AI8 | AJ9: =$C9*Hypothèses!H$18*AJ8 | AK9: =$C9*Hypothèses!I$18*AK8 | AL9: =$C9*Hypothèses!J$18*AL8 | ... AP9: =$C9*Hypothèses!N$18*AP8 | AQ9: =SUM(G9:R9) | AR9: =SUM(S9:AD9) | AS9: =SUM(AE9:AP9) | AT9: =SUM(AQ9:AS9)
A10: Matériaux | B10: Parpaings / briques | C10: 6000 | D10: unités | E10: 0.95 | F10: Estimé — négoce matériaux | G10: =$C10*Hypothèses!C$18*$E10*(1+Hypothèses!$C$14)^0 | H10: =$C10*Hypothèses!D$18*$E10*(1+Hypothèses!$C$14)^0 | I10: =$C10*Hypothèses!E$18*$E10*(1+Hypothèses!$C$14)^0 | J10: =$C10*Hypothèses!F$18*$E10*(1+Hypothèses!$C$14)^0 | K10: =$C10*Hypothèses!G$18*$E10*(1+Hypothèses!$C$14)^0 | L10: =$C10*Hypothèses!H$18*$E10*(1+Hypothèses!$C$14)^0 | M10: =$C10*Hypothèses!I$18*$E10*(1+Hypothèses!$C$14)^0 | N10: =$C10*Hypothèses!J$18*$E10*(1+Hypothèses!$C$14)^0 | ... R10: =$C10*Hypothèses!N$18*$E10*(1+Hypothèses!$C$14)^0 | S10: =$C10*Hypothèses!C$18*$E10*(1+Hypothèses!$C$14)^1 | T10: =$C10*Hypothèses!D$18*$E10*(1+Hypothèses!$C$14)^1 | U10: =$C10*Hypothèses!E$18*$E10*(1+Hypothèses!$C$14)^1 | V10: =$C10*Hypothèses!F$18*$E10*(1+Hypothèses!$C$14)^1 | W10: =$C10*Hypothèses!G$18*$E10*(1+Hypothèses!$C$14)^1 | X10: =$C10*Hypothèses!H$18*$E10*(1+Hypothèses!$C$14)^1 | Y10: =$C10*Hypothèses!I$18*$E10*(1+Hypothèses!$C$14)^1 | Z10: =$C10*Hypothèses!J$18*$E10*(1+Hypothèses!$C$14)^1 | ... AD10: =$C10*Hypothèses!N$18*$E10*(1+Hypothèses!$C$14)^1 | AE10: =$C10*Hypothèses!C$18*$E10*(1+Hypothèses!$C$14)^2 | AF10: =$C10*Hypothèses!D$18*$E10*(1+Hypothèses!$C$14)^2 | AG10: =$C10*Hypothèses!E$18*$E10*(1+Hypothèses!$C$14)^2 | AH10: =$C10*Hypothèses!F$18*$E10*(1+Hypothèses!$C$14)^2 | AI10: =$C10*Hypothèses!G$18*$E10*(1+Hypothèses!$C$14)^2 | AJ10: =$C10*Hypothèses!H$18*$E10*(1+Hypothèses!$C$14)^2 | AK10: =$C10*Hypothèses!I$18*$E10*(1+Hypothèses!$C$14)^2 | AL10: =$C10*Hypothèses!J$18*$E10*(1+Hypothèses!$C$14)^2 | ... AP10: =$C10*Hypothèses!N$18*$E10*(1+Hypothèses!$C$14)^2 | AQ10: =SUM(G10:R10) | AR10: =SUM(S10:AD10) | AS10: =SUM(AE10:AP10) | AT10: =SUM(AQ10:AS10)
A11: Matériaux | B11: Bois de coffrage | C11: 12 | D11: m³ | E11: 420 | F11: Estimé — négoce bois | G11: =$C11*Hypothèses!C$18*$E11*(1+Hypothèses!$C$14)^0 | H11: =$C11*Hypothèses!D$18*$E11*(1+Hypothèses!$C$14)^0 | I11: =$C11*Hypothèses!E$18*$E11*(1+Hypothèses!$C$14)^0 | J11: =$C11*Hypothèses!F$18*$E11*(1+Hypothèses!$C$14)^0 | K11: =$C11*Hypothèses!G$18*$E11*(1+Hypothèses!$C$14)^0 | L11: =$C11*Hypothèses!H$18*$E11*(1+Hypothèses!$C$14)^0 | M11: =$C11*Hypothèses!I$18*$E11*(1+Hypothèses!$C$14)^0 | N11: =$C11*Hypothèses!J$18*$E11*(1+Hypothèses!$C$14)^0 | ... R11: =$C11*Hypothèses!N$18*$E11*(1+Hypothèses!$C$14)^0 | S11: =$C11*Hypothèses!C$18*$E11*(1+Hypothèses!$C$14)^1 | T11: =$C11*Hypothèses!D$18*$E11*(1+Hypothèses!$C$14)^1 | U11: =$C11*Hypothèses!E$18*$E11*(1+Hypothèses!$C$14)^1 | V11: =$C11*Hypothèses!F$18*$E11*(1+Hypothèses!$C$14)^1 | W11: =$C11*Hypothèses!G$18*$E11*(1+Hypothèses!$C$14)^1 | X11: =$C11*Hypothèses!H$18*$E11*(1+Hypothèses!$C$14)^1 | Y11: =$C11*Hypothèses!I$18*$E11*(1+Hypothèses!$C$14)^1 | Z11: =$C11*Hypothèses!J$18*$E11*(1+Hypothèses!$C$14)^1 | ... AD11: =$C11*Hypothèses!N$18*$E11*(1+Hypothèses!$C$14)^1 | AE11: =$C11*Hypothèses!C$18*$E11*(1+Hypothèses!$C$14)^2 | AF11: =$C11*Hypothèses!D$18*$E11*(1+Hypothèses!$C$14)^2 | AG11: =$C11*Hypothèses!E$18*$E11*(1+Hypothèses!$C$14)^2 | AH11: =$C11*Hypothèses!F$18*$E11*(1+Hypothèses!$C$14)^2 | AI11: =$C11*Hypothèses!G$18*$E11*(1+Hypothèses!$C$14)^2 | AJ11: =$C11*Hypothèses!H$18*$E11*(1+Hypothèses!$C$14)^2 | AK11: =$C11*Hypothèses!I$18*$E11*(1+Hypothèses!$C$14)^2 | AL11: =$C11*Hypothèses!J$18*$E11*(1+Hypothèses!$C$14)^2 | ... AP11: =$C11*Hypothèses!N$18*$E11*(1+Hypothèses!$C$14)^2 | AQ11: =SUM(G11:R11) | AR11: =SUM(S11:AD11) | AS11: =SUM(AE11:AP11) | AT11: =SUM(AQ11:AS11)
A12: Matériaux | B12: Isolants (laine, PSE...) | C12: 200 | D12: m² | E12: 9 | F12: Estimé — négoce matériaux | G12: =$C12*Hypothèses!C$18*$E12*(1+Hypothèses!$C$14)^0 | H12: =$C12*Hypothèses!D$18*$E12*(1+Hypothèses!$C$14)^0 | I12: =$C12*Hypothèses!E$18*$E12*(1+Hypothèses!$C$14)^0 | J12: =$C12*Hypothèses!F$18*$E12*(1+Hypothèses!$C$14)^0 | K12: =$C12*Hypothèses!G$18*$E12*(1+Hypothèses!$C$14)^0 | L12: =$C12*Hypothèses!H$18*$E12*(1+Hypothèses!$C$14)^0 | M12: =$C12*Hypothèses!I$18*$E12*(1+Hypothèses!$C$14)^0 | N12: =$C12*Hypothèses!J$18*$E12*(1+Hypothèses!$C$14)^0 | ... R12: =$C12*Hypothèses!N$18*$E12*(1+Hypothèses!$C$14)^0 | S12: =$C12*Hypothèses!C$18*$E12*(1+Hypothèses!$C$14)^1 | T12: =$C12*Hypothèses!D$18*$E12*(1+Hypothèses!$C$14)^1 | U12: =$C12*Hypothèses!E$18*$E12*(1+Hypothèses!$C$14)^1 | V12: =$C12*Hypothèses!F$18*$E12*(1+Hypothèses!$C$14)^1 | W12: =$C12*Hypothèses!G$18*$E12*(1+Hypothèses!$C$14)^1 | X12: =$C12*Hypothèses!H$18*$E12*(1+Hypothèses!$C$14)^1 | Y12: =$C12*Hypothèses!I$18*$E12*(1+Hypothèses!$C$14)^1 | Z12: =$C12*Hypothèses!J$18*$E12*(1+Hypothèses!$C$14)^1 | ... AD12: =$C12*Hypothèses!N$18*$E12*(1+Hypothèses!$C$14)^1 | AE12: =$C12*Hypothèses!C$18*$E12*(1+Hypothèses!$C$14)^2 | AF12: =$C12*Hypothèses!D$18*$E12*(1+Hypothèses!$C$14)^2 | AG12: =$C12*Hypothèses!E$18*$E12*(1+Hypothèses!$C$14)^2 | AH12: =$C12*Hypothèses!F$18*$E12*(1+Hypothèses!$C$14)^2 | AI12: =$C12*Hypothèses!G$18*$E12*(1+Hypothèses!$C$14)^2 | AJ12: =$C12*Hypothèses!H$18*$E12*(1+Hypothèses!$C$14)^2 | AK12: =$C12*Hypothèses!I$18*$E12*(1+Hypothèses!$C$14)^2 | AL12: =$C12*Hypothèses!J$18*$E12*(1+Hypothèses!$C$14)^2 | ... AP12: =$C12*Hypothèses!N$18*$E12*(1+Hypothèses!$C$14)^2 | AQ12: =SUM(G12:R12) | AR12: =SUM(S12:AD12) | AS12: =SUM(AE12:AP12) | AT12: =SUM(AQ12:AS12)
A13: SOUS-TOTAL Matériaux | G13: =G5+G6+G7+G9+G10+G11+G12 | H13: =H5+H6+H7+H9+H10+H11+H12 | I13: =I5+I6+I7+I9+I10+I11+I12 | J13: =J5+J6+J7+J9+J10+J11+J12 | K13: =K5+K6+K7+K9+K10+K11+K12 | L13: =L5+L6+L7+L9+L10+L11+L12 | M13: =M5+M6+M7+M9+M10+M11+M12 | N13: =N5+N6+N7+N9+N10+N11+N12 | ... AP13: =AP5+AP6+AP7+AP9+AP10+AP11+AP12 | AQ13: =SUM(G13:R13) | AR13: =SUM(S13:AD13) | AS13: =SUM(AE13:AP13) | AT13: =SUM(AQ13:AS13)
A14: Sous-traitance | B14: Sous-traitance gros œuvre spécialisé (charpente, étanchéité, terrassement) | C14: 1 | D14: forfait/mois | E14: 15000 | F14: Estimé — devis sous-traitants habituels | G14: =$C14*Hypothèses!C$18*$E14*(1+Hypothèses!$C$14)^0 | H14: =$C14*Hypothèses!D$18*$E14*(1+Hypothèses!$C$14)^0 | I14: =$C14*Hypothèses!E$18*$E14*(1+Hypothèses!$C$14)^0 | J14: =$C14*Hypothèses!F$18*$E14*(1+Hypothèses!$C$14)^0 | K14: =$C14*Hypothèses!G$18*$E14*(1+Hypothèses!$C$14)^0 | L14: =$C14*Hypothèses!H$18*$E14*(1+Hypothèses!$C$14)^0 | M14: =$C14*Hypothèses!I$18*$E14*(1+Hypothèses!$C$14)^0 | N14: =$C14*Hypothèses!J$18*$E14*(1+Hypothèses!$C$14)^0 | ... R14: =$C14*Hypothèses!N$18*$E14*(1+Hypothèses!$C$14)^0 | S14: =$C14*Hypothèses!C$18*$E14*(1+Hypothèses!$C$14)^1 | T14: =$C14*Hypothèses!D$18*$E14*(1+Hypothèses!$C$14)^1 | U14: =$C14*Hypothèses!E$18*$E14*(1+Hypothèses!$C$14)^1 | V14: =$C14*Hypothèses!F$18*$E14*(1+Hypothèses!$C$14)^1 | W14: =$C14*Hypothèses!G$18*$E14*(1+Hypothèses!$C$14)^1 | X14: =$C14*Hypothèses!H$18*$E14*(1+Hypothèses!$C$14)^1 | Y14: =$C14*Hypothèses!I$18*$E14*(1+Hypothèses!$C$14)^1 | Z14: =$C14*Hypothèses!J$18*$E14*(1+Hypothèses!$C$14)^1 | ... AD14: =$C14*Hypothèses!N$18*$E14*(1+Hypothèses!$C$14)^1 | AE14: =$C14*Hypothèses!C$18*$E14*(1+Hypothèses!$C$14)^2 | AF14: =$C14*Hypothèses!D$18*$E14*(1+Hypothèses!$C$14)^2 | AG14: =$C14*Hypothèses!E$18*$E14*(1+Hypothèses!$C$14)^2 | AH14: =$C14*Hypothèses!F$18*$E14*(1+Hypothèses!$C$14)^2 | AI14: =$C14*Hypothèses!G$18*$E14*(1+Hypothèses!$C$14)^2 | AJ14: =$C14*Hypothèses!H$18*$E14*(1+Hypothèses!$C$14)^2 | AK14: =$C14*Hypothèses!I$18*$E14*(1+Hypothèses!$C$14)^2 | AL14: =$C14*Hypothèses!J$18*$E14*(1+Hypothèses!$C$14)^2 | ... AP14: =$C14*Hypothèses!N$18*$E14*(1+Hypothèses!$C$14)^2 | AQ14: =SUM(G14:R14) | AR14: =SUM(S14:AD14) | AS14: =SUM(AE14:AP14) | AT14: =SUM(AQ14:AS14)
A15: Sous-traitance | B15: Sous-traitance second œuvre / ponctuelle | C15: 1 | D15: forfait/mois | E15: 4000 | F15: Estimé | G15: =$C15*Hypothèses!C$18*$E15*(1+Hypothèses!$C$14)^0 | H15: =$C15*Hypothèses!D$18*$E15*(1+Hypothèses!$C$14)^0 | I15: =$C15*Hypothèses!E$18*$E15*(1+Hypothèses!$C$14)^0 | J15: =$C15*Hypothèses!F$18*$E15*(1+Hypothèses!$C$14)^0 | K15: =$C15*Hypothèses!G$18*$E15*(1+Hypothèses!$C$14)^0 | L15: =$C15*Hypothèses!H$18*$E15*(1+Hypothèses!$C$14)^0 | M15: =$C15*Hypothèses!I$18*$E15*(1+Hypothèses!$C$14)^0 | N15: =$C15*Hypothèses!J$18*$E15*(1+Hypothèses!$C$14)^0 | ... R15: =$C15*Hypothèses!N$18*$E15*(1+Hypothèses!$C$14)^0 | S15: =$C15*Hypothèses!C$18*$E15*(1+Hypothèses!$C$14)^1 | T15: =$C15*Hypothèses!D$18*$E15*(1+Hypothèses!$C$14)^1 | U15: =$C15*Hypothèses!E$18*$E15*(1+Hypothèses!$C$14)^1 | V15: =$C15*Hypothèses!F$18*$E15*(1+Hypothèses!$C$14)^1 | W15: =$C15*Hypothèses!G$18*$E15*(1+Hypothèses!$C$14)^1 | X15: =$C15*Hypothèses!H$18*$E15*(1+Hypothèses!$C$14)^1 | Y15: =$C15*Hypothèses!I$18*$E15*(1+Hypothèses!$C$14)^1 | Z15: =$C15*Hypothèses!J$18*$E15*(1+Hypothèses!$C$14)^1 | ... AD15: =$C15*Hypothèses!N$18*$E15*(1+Hypothèses!$C$14)^1 | AE15: =$C15*Hypothèses!C$18*$E15*(1+Hypothèses!$C$14)^2 | AF15: =$C15*Hypothèses!D$18*$E15*(1+Hypothèses!$C$14)^2 | AG15: =$C15*Hypothèses!E$18*$E15*(1+Hypothèses!$C$14)^2 | AH15: =$C15*Hypothèses!F$18*$E15*(1+Hypothèses!$C$14)^2 | AI15: =$C15*Hypothèses!G$18*$E15*(1+Hypothèses!$C$14)^2 | AJ15: =$C15*Hypothèses!H$18*$E15*(1+Hypothèses!$C$14)^2 | AK15: =$C15*Hypothèses!I$18*$E15*(1+Hypothèses!$C$14)^2 | AL15: =$C15*Hypothèses!J$18*$E15*(1+Hypothèses!$C$14)^2 | ... AP15: =$C15*Hypothèses!N$18*$E15*(1+Hypothèses!$C$14)^2 | AQ15: =SUM(G15:R15) | AR15: =SUM(S15:AD15) | AS15: =SUM(AE15:AP15) | AT15: =SUM(AQ15:AS15)
A16: SOUS-TOTAL Sous-traitance | G16: =G14+G15 | H16: =H14+H15 | I16: =I14+I15 | J16: =J14+J15 | K16: =K14+K15 | L16: =L14+L15 | M16: =M14+M15 | N16: =N14+N15 | ... AP16: =AP14+AP15 | AQ16: =SUM(G16:R16) | AR16: =SUM(S16:AD16) | AS16: =SUM(AE16:AP16) | AT16: =SUM(AQ16:AS16)
A17: Carburant & engins | B17: Gazole non routier (GNR) — engins de chantier — prix de marché simulé (€/unité) | D17: litres | E17: =AVERAGE(G17:AP17) | F17: API marché (proxy WTI/BRENT, Alpha Vantage) — simulation calibrée | G17: 1.0608 | H17: 0.9559 | I17: 0.9199 | J17: 0.9444 | K17: 0.8682 | L17: 0.7258 | M17: 0.6378 | N17: 0.677 | O17: 0.7346 | P17: 0.7498 | Q17: 0.7693 | R17: 0.8305 | S17: 0.7441 | T17: 0.6793 | U17: 0.5855 | V17: 0.5775 | W17: 0.5775 | X17: 0.5971 | Y17: 0.5775 | Z17: 0.5924 | AA17: 0.5903 | AB17: 0.5803 | AC17: 0.5814 | AD17: 0.6135 | AE17: 0.5775 | AF17: 0.5926 | AG17: 0.5919 | AH17: 0.6053 | AI17: 0.6748 | AJ17: 0.6189 | AK17: 0.6214 | AL17: 0.6102 | AM17: 0.6093 | AN17: 0.6368 | AO17: 0.6575 | AP17: 0.6464
A18: Carburant & engins | B18: ↳ Coût (Gazole non routier (GNR) — engins de chantier) | C18: 4500 | D18: litres | F18: Coût = Qté de base × saisonnalité × prix simulé ci-dessus | G18: =$C18*Hypothèses!C$18*G17 | H18: =$C18*Hypothèses!D$18*H17 | I18: =$C18*Hypothèses!E$18*I17 | J18: =$C18*Hypothèses!F$18*J17 | K18: =$C18*Hypothèses!G$18*K17 | L18: =$C18*Hypothèses!H$18*L17 | M18: =$C18*Hypothèses!I$18*M17 | N18: =$C18*Hypothèses!J$18*N17 | ... R18: =$C18*Hypothèses!N$18*R17 | S18: =$C18*Hypothèses!C$18*S17 | T18: =$C18*Hypothèses!D$18*T17 | U18: =$C18*Hypothèses!E$18*U17 | V18: =$C18*Hypothèses!F$18*V17 | W18: =$C18*Hypothèses!G$18*W17 | X18: =$C18*Hypothèses!H$18*X17 | Y18: =$C18*Hypothèses!I$18*Y17 | Z18: =$C18*Hypothèses!J$18*Z17 | ... AD18: =$C18*Hypothèses!N$18*AD17 | AE18: =$C18*Hypothèses!C$18*AE17 | AF18: =$C18*Hypothèses!D$18*AF17 | AG18: =$C18*Hypothèses!E$18*AG17 | AH18: =$C18*Hypothèses!F$18*AH17 | AI18: =$C18*Hypothèses!G$18*AI17 | AJ18: =$C18*Hypothèses!H$18*AJ17 | AK18: =$C18*Hypothèses!I$18*AK17 | AL18: =$C18*Hypothèses!J$18*AL17 | ... AP18: =$C18*Hypothèses!N$18*AP17 | AQ18: =SUM(G18:R18) | AR18: =SUM(S18:AD18) | AS18: =SUM(AE18:AP18) | AT18: =SUM(AQ18:AS18)
A19: Carburant & engins | B19: Carburant véhicules utilitaires (camions, fourgons) — prix de marché simulé (€/unité) | D19: litres | E19: =AVERAGE(G19:AP19) | F19: API marché (proxy WTI/BRENT, Alpha Vantage) — simulation calibrée | G19: 1.9224 | H19: 2.045 | I19: 1.9795 | J19: 1.9341 | K19: 1.9659 | L19: 1.8131 | M19: 1.8863 | N19: 1.7518 | O19: 1.724 | P19: 1.5504 | Q19: 1.5295 | R19: 1.566 | S19: 1.6059 | T19: 1.5795 | U19: 1.3083 | V19: 1.2258 | W19: 1.1938 | X19: 1.2406 | Y19: 1.2055 | Z19: 1.24 | AA19: 1.2418 | AB19: 1.181 | AC19: 1.2682 | AD19: 1.3156 | AE19: 1.3147 | AF19: 1.3661 | AG19: 1.5239 | AH19: 1.5446 | AI19: 1.4567 | AJ19: 1.5411 | AK19: 1.3582 | AL19: 1.3802 | AM19: 1.4893 | AN19: 1.5435 | AO19: 1.582 | AP19: 1.5166
A20: Carburant & engins | B20: ↳ Coût (Carburant véhicules utilitaires (camions, fourgons)) | C20: 1800 | D20: litres | F20: Coût = Qté de base × saisonnalité × prix simulé ci-dessus | G20: =$C20*Hypothèses!C$18*G19 | H20: =$C20*Hypothèses!D$18*H19 | I20: =$C20*Hypothèses!E$18*I19 | J20: =$C20*Hypothèses!F$18*J19 | K20: =$C20*Hypothèses!G$18*K19 | L20: =$C20*Hypothèses!H$18*L19 | M20: =$C20*Hypothèses!I$18*M19 | N20: =$C20*Hypothèses!J$18*N19 | ... R20: =$C20*Hypothèses!N$18*R19 | S20: =$C20*Hypothèses!C$18*S19 | T20: =$C20*Hypothèses!D$18*T19 | U20: =$C20*Hypothèses!E$18*U19 | V20: =$C20*Hypothèses!F$18*V19 | W20: =$C20*Hypothèses!G$18*W19 | X20: =$C20*Hypothèses!H$18*X19 | Y20: =$C20*Hypothèses!I$18*Y19 | Z20: =$C20*Hypothèses!J$18*Z19 | ... AD20: =$C20*Hypothèses!N$18*AD19 | AE20: =$C20*Hypothèses!C$18*AE19 | AF20: =$C20*Hypothèses!D$18*AF19 | AG20: =$C20*Hypothèses!E$18*AG19 | AH20: =$C20*Hypothèses!F$18*AH19 | AI20: =$C20*Hypothèses!G$18*AI19 | AJ20: =$C20*Hypothèses!H$18*AJ19 | AK20: =$C20*Hypothèses!I$18*AK19 | AL20: =$C20*Hypothèses!J$18*AL19 | ... AP20: =$C20*Hypothèses!N$18*AP19 | AQ20: =SUM(G20:R20) | AR20: =SUM(S20:AD20) | AS20: =SUM(AE20:AP20) | AT20: =SUM(AQ20:AS20)
A21: SOUS-TOTAL Carburant & engins | G21: =G18+G20 | H21: =H18+H20 | I21: =I18+I20 | J21: =J18+J20 | K21: =K18+K20 | L21: =L18+L20 | M21: =M18+M20 | N21: =N18+N20 | ... AP21: =AP18+AP20 | AQ21: =SUM(G21:R21) | AR21: =SUM(S21:AD21) | AS21: =SUM(AE21:AP21) | AT21: =SUM(AQ21:AS21)
A22: Location matériel | B22: Location engins (pelleteuse, nacelle, compacteur) | C22: 1 | D22: forfait/mois | E22: 3500 | F22: Estimé — tarif loueur régional | G22: =$C22*Hypothèses!C$18*$E22*(1+Hypothèses!$C$14)^0 | H22: =$C22*Hypothèses!D$18*$E22*(1+Hypothèses!$C$14)^0 | I22: =$C22*Hypothèses!E$18*$E22*(1+Hypothèses!$C$14)^0 | J22: =$C22*Hypothèses!F$18*$E22*(1+Hypothèses!$C$14)^0 | K22: =$C22*Hypothèses!G$18*$E22*(1+Hypothèses!$C$14)^0 | L22: =$C22*Hypothèses!H$18*$E22*(1+Hypothèses!$C$14)^0 | M22: =$C22*Hypothèses!I$18*$E22*(1+Hypothèses!$C$14)^0 | N22: =$C22*Hypothèses!J$18*$E22*(1+Hypothèses!$C$14)^0 | ... R22: =$C22*Hypothèses!N$18*$E22*(1+Hypothèses!$C$14)^0 | S22: =$C22*Hypothèses!C$18*$E22*(1+Hypothèses!$C$14)^1 | T22: =$C22*Hypothèses!D$18*$E22*(1+Hypothèses!$C$14)^1 | U22: =$C22*Hypothèses!E$18*$E22*(1+Hypothèses!$C$14)^1 | V22: =$C22*Hypothèses!F$18*$E22*(1+Hypothèses!$C$14)^1 | W22: =$C22*Hypothèses!G$18*$E22*(1+Hypothèses!$C$14)^1 | X22: =$C22*Hypothèses!H$18*$E22*(1+Hypothèses!$C$14)^1 | Y22: =$C22*Hypothèses!I$18*$E22*(1+Hypothèses!$C$14)^1 | Z22: =$C22*Hypothèses!J$18*$E22*(1+Hypothèses!$C$14)^1 | ... AD22: =$C22*Hypothèses!N$18*$E22*(1+Hypothèses!$C$14)^1 | AE22: =$C22*Hypothèses!C$18*$E22*(1+Hypothèses!$C$14)^2 | AF22: =$C22*Hypothèses!D$18*$E22*(1+Hypothèses!$C$14)^2 | AG22: =$C22*Hypothèses!E$18*$E22*(1+Hypothèses!$C$14)^2 | AH22: =$C22*Hypothèses!F$18*$E22*(1+Hypothèses!$C$14)^2 | AI22: =$C22*Hypothèses!G$18*$E22*(1+Hypothèses!$C$14)^2 | AJ22: =$C22*Hypothèses!H$18*$E22*(1+Hypothèses!$C$14)^2 | AK22: =$C22*Hypothèses!I$18*$E22*(1+Hypothèses!$C$14)^2 | AL22: =$C22*Hypothèses!J$18*$E22*(1+Hypothèses!$C$14)^2 | ... AP22: =$C22*Hypothèses!N$18*$E22*(1+Hypothèses!$C$14)^2 | AQ22: =SUM(G22:R22) | AR22: =SUM(S22:AD22) | AS22: =SUM(AE22:AP22) | AT22: =SUM(AQ22:AS22)
A23: Location matériel | B23: Location matériel divers (étais, bennes, échafaudages) | C23: 1 | D23: forfait/mois | E23: 1800 | F23: Estimé | G23: =$C23*Hypothèses!C$18*$E23*(1+Hypothèses!$C$14)^0 | H23: =$C23*Hypothèses!D$18*$E23*(1+Hypothèses!$C$14)^0 | I23: =$C23*Hypothèses!E$18*$E23*(1+Hypothèses!$C$14)^0 | J23: =$C23*Hypothèses!F$18*$E23*(1+Hypothèses!$C$14)^0 | K23: =$C23*Hypothèses!G$18*$E23*(1+Hypothèses!$C$14)^0 | L23: =$C23*Hypothèses!H$18*$E23*(1+Hypothèses!$C$14)^0 | M23: =$C23*Hypothèses!I$18*$E23*(1+Hypothèses!$C$14)^0 | N23: =$C23*Hypothèses!J$18*$E23*(1+Hypothèses!$C$14)^0 | ... R23: =$C23*Hypothèses!N$18*$E23*(1+Hypothèses!$C$14)^0 | S23: =$C23*Hypothèses!C$18*$E23*(1+Hypothèses!$C$14)^1 | T23: =$C23*Hypothèses!D$18*$E23*(1+Hypothèses!$C$14)^1 | U23: =$C23*Hypothèses!E$18*$E23*(1+Hypothèses!$C$14)^1 | V23: =$C23*Hypothèses!F$18*$E23*(1+Hypothèses!$C$14)^1 | W23: =$C23*Hypothèses!G$18*$E23*(1+Hypothèses!$C$14)^1 | X23: =$C23*Hypothèses!H$18*$E23*(1+Hypothèses!$C$14)^1 | Y23: =$C23*Hypothèses!I$18*$E23*(1+Hypothèses!$C$14)^1 | Z23: =$C23*Hypothèses!J$18*$E23*(1+Hypothèses!$C$14)^1 | ... AD23: =$C23*Hypothèses!N$18*$E23*(1+Hypothèses!$C$14)^1 | AE23: =$C23*Hypothèses!C$18*$E23*(1+Hypothèses!$C$14)^2 | AF23: =$C23*Hypothèses!D$18*$E23*(1+Hypothèses!$C$14)^2 | AG23: =$C23*Hypothèses!E$18*$E23*(1+Hypothèses!$C$14)^2 | AH23: =$C23*Hypothèses!F$18*$E23*(1+Hypothèses!$C$14)^2 | AI23: =$C23*Hypothèses!G$18*$E23*(1+Hypothèses!$C$14)^2 | AJ23: =$C23*Hypothèses!H$18*$E23*(1+Hypothèses!$C$14)^2 | AK23: =$C23*Hypothèses!I$18*$E23*(1+Hypothèses!$C$14)^2 | AL23: =$C23*Hypothèses!J$18*$E23*(1+Hypothèses!$C$14)^2 | ... AP23: =$C23*Hypothèses!N$18*$E23*(1+Hypothèses!$C$14)^2 | AQ23: =SUM(G23:R23) | AR23: =SUM(S23:AD23) | AS23: =SUM(AE23:AP23) | AT23: =SUM(AQ23:AS23)
A24: SOUS-TOTAL Location matériel | G24: =G22+G23 | H24: =H22+H23 | I24: =I22+I23 | J24: =J22+J23 | K24: =K22+K23 | L24: =L22+L23 | M24: =M22+M23 | N24: =N22+N23 | ... AP24: =AP22+AP23 | AQ24: =SUM(G24:R24) | AR24: =SUM(S24:AD24) | AS24: =SUM(AE24:AP24) | AT24: =SUM(AQ24:AS24)
A25: Personnel | B25: Rémunération nette du dirigeant (gérant, TNS) | C25: 1 | D25: forfait/mois | E25: 4500 | F25: Estimé | G25: =$C25*$E25*(1+Hypothèses!$C$14)^0 | H25: =$C25*$E25*(1+Hypothèses!$C$14)^0 | I25: =$C25*$E25*(1+Hypothèses!$C$14)^0 | J25: =$C25*$E25*(1+Hypothèses!$C$14)^0 | K25: =$C25*$E25*(1+Hypothèses!$C$14)^0 | L25: =$C25*$E25*(1+Hypothèses!$C$14)^0 | M25: =$C25*$E25*(1+Hypothèses!$C$14)^0 | N25: =$C25*$E25*(1+Hypothèses!$C$14)^0 | ... R25: =$C25*$E25*(1+Hypothèses!$C$14)^0 | S25: =$C25*$E25*(1+Hypothèses!$C$14)^1 | T25: =$C25*$E25*(1+Hypothèses!$C$14)^1 | U25: =$C25*$E25*(1+Hypothèses!$C$14)^1 | V25: =$C25*$E25*(1+Hypothèses!$C$14)^1 | W25: =$C25*$E25*(1+Hypothèses!$C$14)^1 | X25: =$C25*$E25*(1+Hypothèses!$C$14)^1 | Y25: =$C25*$E25*(1+Hypothèses!$C$14)^1 | Z25: =$C25*$E25*(1+Hypothèses!$C$14)^1 | ... AD25: =$C25*$E25*(1+Hypothèses!$C$14)^1 | AE25: =$C25*$E25*(1+Hypothèses!$C$14)^2 | AF25: =$C25*$E25*(1+Hypothèses!$C$14)^2 | AG25: =$C25*$E25*(1+Hypothèses!$C$14)^2 | AH25: =$C25*$E25*(1+Hypothèses!$C$14)^2 | AI25: =$C25*$E25*(1+Hypothèses!$C$14)^2 | AJ25: =$C25*$E25*(1+Hypothèses!$C$14)^2 | AK25: =$C25*$E25*(1+Hypothèses!$C$14)^2 | AL25: =$C25*$E25*(1+Hypothèses!$C$14)^2 | ... AP25: =$C25*$E25*(1+Hypothèses!$C$14)^2 | AQ25: =SUM(G25:R25) | AR25: =SUM(S25:AD25) | AS25: =SUM(AE25:AP25) | AT25: =SUM(AQ25:AS25)
A26: Personnel | B26: Salaires & charges — chef de chantier | C26: 1 | D26: forfait/mois | E26: 5300 | F26: Estimé — grille BTP | G26: =$C26*$E26*(1+Hypothèses!$C$14)^0 | H26: =$C26*$E26*(1+Hypothèses!$C$14)^0 | I26: =$C26*$E26*(1+Hypothèses!$C$14)^0 | J26: =$C26*$E26*(1+Hypothèses!$C$14)^0 | K26: =$C26*$E26*(1+Hypothèses!$C$14)^0 | L26: =$C26*$E26*(1+Hypothèses!$C$14)^0 | M26: =$C26*$E26*(1+Hypothèses!$C$14)^0 | N26: =$C26*$E26*(1+Hypothèses!$C$14)^0 | ... R26: =$C26*$E26*(1+Hypothèses!$C$14)^0 | S26: =$C26*$E26*(1+Hypothèses!$C$14)^1 | T26: =$C26*$E26*(1+Hypothèses!$C$14)^1 | U26: =$C26*$E26*(1+Hypothèses!$C$14)^1 | V26: =$C26*$E26*(1+Hypothèses!$C$14)^1 | W26: =$C26*$E26*(1+Hypothèses!$C$14)^1 | X26: =$C26*$E26*(1+Hypothèses!$C$14)^1 | Y26: =$C26*$E26*(1+Hypothèses!$C$14)^1 | Z26: =$C26*$E26*(1+Hypothèses!$C$14)^1 | ... AD26: =$C26*$E26*(1+Hypothèses!$C$14)^1 | AE26: =$C26*$E26*(1+Hypothèses!$C$14)^2 | AF26: =$C26*$E26*(1+Hypothèses!$C$14)^2 | AG26: =$C26*$E26*(1+Hypothèses!$C$14)^2 | AH26: =$C26*$E26*(1+Hypothèses!$C$14)^2 | AI26: =$C26*$E26*(1+Hypothèses!$C$14)^2 | AJ26: =$C26*$E26*(1+Hypothèses!$C$14)^2 | AK26: =$C26*$E26*(1+Hypothèses!$C$14)^2 | AL26: =$C26*$E26*(1+Hypothèses!$C$14)^2 | ... AP26: =$C26*$E26*(1+Hypothèses!$C$14)^2 | AQ26: =SUM(G26:R26) | AR26: =SUM(S26:AD26) | AS26: =SUM(AE26:AP26) | AT26: =SUM(AQ26:AS26)
A27: Personnel | B27: Salaires & charges — équipe maçons/ouvriers qualifiés (x4) | C27: 1 | D27: forfait/mois | E27: 18400 | F27: Estimé — grille BTP (4 ETP) | G27: =$C27*$E27*(1+Hypothèses!$C$14)^0 | H27: =$C27*$E27*(1+Hypothèses!$C$14)^0 | I27: =$C27*$E27*(1+Hypothèses!$C$14)^0 | J27: =$C27*$E27*(1+Hypothèses!$C$14)^0 | K27: =$C27*$E27*(1+Hypothèses!$C$14)^0 | L27: =$C27*$E27*(1+Hypothèses!$C$14)^0 | M27: =$C27*$E27*(1+Hypothèses!$C$14)^0 | N27: =$C27*$E27*(1+Hypothèses!$C$14)^0 | ... R27: =$C27*$E27*(1+Hypothèses!$C$14)^0 | S27: =$C27*$E27*(1+Hypothèses!$C$14)^1 | T27: =$C27*$E27*(1+Hypothèses!$C$14)^1 | U27: =$C27*$E27*(1+Hypothèses!$C$14)^1 | V27: =$C27*$E27*(1+Hypothèses!$C$14)^1 | W27: =$C27*$E27*(1+Hypothèses!$C$14)^1 | X27: =$C27*$E27*(1+Hypothèses!$C$14)^1 | Y27: =$C27*$E27*(1+Hypothèses!$C$14)^1 | Z27: =$C27*$E27*(1+Hypothèses!$C$14)^1 | ... AD27: =$C27*$E27*(1+Hypothèses!$C$14)^1 | AE27: =$C27*$E27*(1+Hypothèses!$C$14)^2 | AF27: =$C27*$E27*(1+Hypothèses!$C$14)^2 | AG27: =$C27*$E27*(1+Hypothèses!$C$14)^2 | AH27: =$C27*$E27*(1+Hypothèses!$C$14)^2 | AI27: =$C27*$E27*(1+Hypothèses!$C$14)^2 | AJ27: =$C27*$E27*(1+Hypothèses!$C$14)^2 | AK27: =$C27*$E27*(1+Hypothèses!$C$14)^2 | AL27: =$C27*$E27*(1+Hypothèses!$C$14)^2 | ... AP27: =$C27*$E27*(1+Hypothèses!$C$14)^2 | AQ27: =SUM(G27:R27) | AR27: =SUM(S27:AD27) | AS27: =SUM(AE27:AP27) | AT27: =SUM(AQ27:AS27)
A28: Personnel | B28: Salaires & charges — manœuvres/apprentis (x2) | C28: 1 | D28: forfait/mois | E28: 6200 | F28: Estimé — grille BTP (2 ETP) | G28: =$C28*$E28*(1+Hypothèses!$C$14)^0 | H28: =$C28*$E28*(1+Hypothèses!$C$14)^0 | I28: =$C28*$E28*(1+Hypothèses!$C$14)^0 | J28: =$C28*$E28*(1+Hypothèses!$C$14)^0 | K28: =$C28*$E28*(1+Hypothèses!$C$14)^0 | L28: =$C28*$E28*(1+Hypothèses!$C$14)^0 | M28: =$C28*$E28*(1+Hypothèses!$C$14)^0 | N28: =$C28*$E28*(1+Hypothèses!$C$14)^0 | ... R28: =$C28*$E28*(1+Hypothèses!$C$14)^0 | S28: =$C28*$E28*(1+Hypothèses!$C$14)^1 | T28: =$C28*$E28*(1+Hypothèses!$C$14)^1 | U28: =$C28*$E28*(1+Hypothèses!$C$14)^1 | V28: =$C28*$E28*(1+Hypothèses!$C$14)^1 | W28: =$C28*$E28*(1+Hypothèses!$C$14)^1 | X28: =$C28*$E28*(1+Hypothèses!$C$14)^1 | Y28: =$C28*$E28*(1+Hypothèses!$C$14)^1 | Z28: =$C28*$E28*(1+Hypothèses!$C$14)^1 | ... AD28: =$C28*$E28*(1+Hypothèses!$C$14)^1 | AE28: =$C28*$E28*(1+Hypothèses!$C$14)^2 | AF28: =$C28*$E28*(1+Hypothèses!$C$14)^2 | AG28: =$C28*$E28*(1+Hypothèses!$C$14)^2 | AH28: =$C28*$E28*(1+Hypothèses!$C$14)^2 | AI28: =$C28*$E28*(1+Hypothèses!$C$14)^2 | AJ28: =$C28*$E28*(1+Hypothèses!$C$14)^2 | AK28: =$C28*$E28*(1+Hypothèses!$C$14)^2 | AL28: =$C28*$E28*(1+Hypothèses!$C$14)^2 | ... AP28: =$C28*$E28*(1+Hypothèses!$C$14)^2 | AQ28: =SUM(G28:R28) | AR28: =SUM(S28:AD28) | AS28: =SUM(AE28:AP28) | AT28: =SUM(AQ28:AS28)
A29: SOUS-TOTAL Personnel | G29: =G25+G26+G27+G28 | H29: =H25+H26+H27+H28 | I29: =I25+I26+I27+I28 | J29: =J25+J26+J27+J28 | K29: =K25+K26+K27+K28 | L29: =L25+L26+L27+L28 | M29: =M25+M26+M27+M28 | N29: =N25+N26+N27+N28 | ... AP29: =AP25+AP26+AP27+AP28 | AQ29: =SUM(G29:R29) | AR29: =SUM(S29:AD29) | AS29: =SUM(AE29:AP29) | AT29: =SUM(AQ29:AS29)
A30: Charges sociales dirigeant | B30: Cotisations URSSAF (TNS) du dirigeant — lissé mensuel (versées par trimestre, cf. Hypothèses C8) | C30: 1 | D30: forfait/mois (moy.) | E30: 1500 | F30: Calculé — Hypothèses!C8 (cotisation trimestrielle) ÷ 3 | G30: =$C30*$E30*(1+Hypothèses!$C$14)^0 | H30: =$C30*$E30*(1+Hypothèses!$C$14)^0 | I30: =$C30*$E30*(1+Hypothèses!$C$14)^0 | J30: =$C30*$E30*(1+Hypothèses!$C$14)^0 | K30: =$C30*$E30*(1+Hypothèses!$C$14)^0 | L30: =$C30*$E30*(1+Hypothèses!$C$14)^0 | M30: =$C30*$E30*(1+Hypothèses!$C$14)^0 | N30: =$C30*$E30*(1+Hypothèses!$C$14)^0 | ... R30: =$C30*$E30*(1+Hypothèses!$C$14)^0 | S30: =$C30*$E30*(1+Hypothèses!$C$14)^1 | T30: =$C30*$E30*(1+Hypothèses!$C$14)^1 | U30: =$C30*$E30*(1+Hypothèses!$C$14)^1 | V30: =$C30*$E30*(1+Hypothèses!$C$14)^1 | W30: =$C30*$E30*(1+Hypothèses!$C$14)^1 | X30: =$C30*$E30*(1+Hypothèses!$C$14)^1 | Y30: =$C30*$E30*(1+Hypothèses!$C$14)^1 | Z30: =$C30*$E30*(1+Hypothèses!$C$14)^1 | ... AD30: =$C30*$E30*(1+Hypothèses!$C$14)^1 | AE30: =$C30*$E30*(1+Hypothèses!$C$14)^2 | AF30: =$C30*$E30*(1+Hypothèses!$C$14)^2 | AG30: =$C30*$E30*(1+Hypothèses!$C$14)^2 | AH30: =$C30*$E30*(1+Hypothèses!$C$14)^2 | AI30: =$C30*$E30*(1+Hypothèses!$C$14)^2 | AJ30: =$C30*$E30*(1+Hypothèses!$C$14)^2 | AK30: =$C30*$E30*(1+Hypothèses!$C$14)^2 | AL30: =$C30*$E30*(1+Hypothèses!$C$14)^2 | ... AP30: =$C30*$E30*(1+Hypothèses!$C$14)^2 | AQ30: =SUM(G30:R30) | AR30: =SUM(S30:AD30) | AS30: =SUM(AE30:AP30) | AT30: =SUM(AQ30:AS30)
A31: SOUS-TOTAL Charges sociales dirigeant | G31: =G30 | H31: =H30 | I31: =I30 | J31: =J30 | K31: =K30 | L31: =L30 | M31: =M30 | N31: =N30 | ... AP31: =AP30 | AQ31: =SUM(G31:R31) | AR31: =SUM(S31:AD31) | AS31: =SUM(AE31:AP31) | AT31: =SUM(AQ31:AS31)
A32: Énergie | B32: Électricité (dépôt, atelier, bureaux) — prix de marché simulé (€/unité) | D32: kWh | E32: =AVERAGE(G32:AP32) | F32: API/marché (Tarif Bleu Pro EDF — simulation calibrée, à actualiser via SDES) | G32: 0.1577 | H32: 0.1584 | I32: 0.1575 | J32: 0.157 | K32: 0.1551 | L32: 0.1508 | M32: 0.1498 | N32: 0.152 | O32: 0.1498 | P32: 0.1509 | Q32: 0.1532 | R32: 0.156 | S32: 0.1567 | T32: 0.1557 | U32: 0.1565 | V32: 0.1585 | W32: 0.1588 | X32: 0.1652 | Y32: 0.1638 | Z32: 0.1644 | AA32: 0.1685 | AB32: 0.1676 | AC32: 0.1675 | AD32: 0.1651 | AE32: 0.1655 | AF32: 0.1644 | AG32: 0.162 | AH32: 0.1613 | AI32: 0.157 | AJ32: 0.1568 | AK32: 0.1516 | AL32: 0.1538 | AM32: 0.155 | AN32: 0.1576 | AO32: 0.1618 | AP32: 0.1551
A33: Énergie | B33: ↳ Coût (Électricité (dépôt, atelier, bureaux)) | C33: 1800 | D33: kWh | F33: Coût = Qté de base × saisonnalité × prix simulé ci-dessus | G33: =$C33*Hypothèses!C$18*G32 | H33: =$C33*Hypothèses!D$18*H32 | I33: =$C33*Hypothèses!E$18*I32 | J33: =$C33*Hypothèses!F$18*J32 | K33: =$C33*Hypothèses!G$18*K32 | L33: =$C33*Hypothèses!H$18*L32 | M33: =$C33*Hypothèses!I$18*M32 | N33: =$C33*Hypothèses!J$18*N32 | ... R33: =$C33*Hypothèses!N$18*R32 | S33: =$C33*Hypothèses!C$18*S32 | T33: =$C33*Hypothèses!D$18*T32 | U33: =$C33*Hypothèses!E$18*U32 | V33: =$C33*Hypothèses!F$18*V32 | W33: =$C33*Hypothèses!G$18*W32 | X33: =$C33*Hypothèses!H$18*X32 | Y33: =$C33*Hypothèses!I$18*Y32 | Z33: =$C33*Hypothèses!J$18*Z32 | ... AD33: =$C33*Hypothèses!N$18*AD32 | AE33: =$C33*Hypothèses!C$18*AE32 | AF33: =$C33*Hypothèses!D$18*AF32 | AG33: =$C33*Hypothèses!E$18*AG32 | AH33: =$C33*Hypothèses!F$18*AH32 | AI33: =$C33*Hypothèses!G$18*AI32 | AJ33: =$C33*Hypothèses!H$18*AJ32 | AK33: =$C33*Hypothèses!I$18*AK32 | AL33: =$C33*Hypothèses!J$18*AL32 | ... AP33: =$C33*Hypothèses!N$18*AP32 | AQ33: =SUM(G33:R33) | AR33: =SUM(S33:AD33) | AS33: =SUM(AE33:AP33) | AT33: =SUM(AQ33:AS33)
A34: SOUS-TOTAL Énergie | G34: =G33 | H34: =H33 | I34: =I33 | J34: =J33 | K34: =K33 | L34: =L33 | M34: =M33 | N34: =N33 | ... AP34: =AP33 | AQ34: =SUM(G34:R34) | AR34: =SUM(S34:AD34) | AS34: =SUM(AE34:AP34) | AT34: =SUM(AQ34:AS34)
A35: Charges fixes | B35: Loyer dépôt / atelier | C35: 1 | D35: forfait/mois | E35: 1200 | F35: Estimé | G35: =$C35*$E35*(1+Hypothèses!$C$14)^0 | H35: =$C35*$E35*(1+Hypothèses!$C$14)^0 | I35: =$C35*$E35*(1+Hypothèses!$C$14)^0 | J35: =$C35*$E35*(1+Hypothèses!$C$14)^0 | K35: =$C35*$E35*(1+Hypothèses!$C$14)^0 | L35: =$C35*$E35*(1+Hypothèses!$C$14)^0 | M35: =$C35*$E35*(1+Hypothèses!$C$14)^0 | N35: =$C35*$E35*(1+Hypothèses!$C$14)^0 | ... R35: =$C35*$E35*(1+Hypothèses!$C$14)^0 | S35: =$C35*$E35*(1+Hypothèses!$C$14)^1 | T35: =$C35*$E35*(1+Hypothèses!$C$14)^1 | U35: =$C35*$E35*(1+Hypothèses!$C$14)^1 | V35: =$C35*$E35*(1+Hypothèses!$C$14)^1 | W35: =$C35*$E35*(1+Hypothèses!$C$14)^1 | X35: =$C35*$E35*(1+Hypothèses!$C$14)^1 | Y35: =$C35*$E35*(1+Hypothèses!$C$14)^1 | Z35: =$C35*$E35*(1+Hypothèses!$C$14)^1 | ... AD35: =$C35*$E35*(1+Hypothèses!$C$14)^1 | AE35: =$C35*$E35*(1+Hypothèses!$C$14)^2 | AF35: =$C35*$E35*(1+Hypothèses!$C$14)^2 | AG35: =$C35*$E35*(1+Hypothèses!$C$14)^2 | AH35: =$C35*$E35*(1+Hypothèses!$C$14)^2 | AI35: =$C35*$E35*(1+Hypothèses!$C$14)^2 | AJ35: =$C35*$E35*(1+Hypothèses!$C$14)^2 | AK35: =$C35*$E35*(1+Hypothèses!$C$14)^2 | AL35: =$C35*$E35*(1+Hypothèses!$C$14)^2 | ... AP35: =$C35*$E35*(1+Hypothèses!$C$14)^2 | AQ35: =SUM(G35:R35) | AR35: =SUM(S35:AD35) | AS35: =SUM(AE35:AP35) | AT35: =SUM(AQ35:AS35)
A36: Charges fixes | B36: Assurance décennale | C36: 1 | D36: forfait/mois | E36: 750 | F36: Sourcé — exemple de prime annuelle ≈2 440€ pour artisan ; majoré ici pour CA 1,5M€ | G36: =$C36*$E36*(1+Hypothèses!$C$14)^0 | H36: =$C36*$E36*(1+Hypothèses!$C$14)^0 | I36: =$C36*$E36*(1+Hypothèses!$C$14)^0 | J36: =$C36*$E36*(1+Hypothèses!$C$14)^0 | K36: =$C36*$E36*(1+Hypothèses!$C$14)^0 | L36: =$C36*$E36*(1+Hypothèses!$C$14)^0 | M36: =$C36*$E36*(1+Hypothèses!$C$14)^0 | N36: =$C36*$E36*(1+Hypothèses!$C$14)^0 | ... R36: =$C36*$E36*(1+Hypothèses!$C$14)^0 | S36: =$C36*$E36*(1+Hypothèses!$C$14)^1 | T36: =$C36*$E36*(1+Hypothèses!$C$14)^1 | U36: =$C36*$E36*(1+Hypothèses!$C$14)^1 | V36: =$C36*$E36*(1+Hypothèses!$C$14)^1 | W36: =$C36*$E36*(1+Hypothèses!$C$14)^1 | X36: =$C36*$E36*(1+Hypothèses!$C$14)^1 | Y36: =$C36*$E36*(1+Hypothèses!$C$14)^1 | Z36: =$C36*$E36*(1+Hypothèses!$C$14)^1 | ... AD36: =$C36*$E36*(1+Hypothèses!$C$14)^1 | AE36: =$C36*$E36*(1+Hypothèses!$C$14)^2 | AF36: =$C36*$E36*(1+Hypothèses!$C$14)^2 | AG36: =$C36*$E36*(1+Hypothèses!$C$14)^2 | AH36: =$C36*$E36*(1+Hypothèses!$C$14)^2 | AI36: =$C36*$E36*(1+Hypothèses!$C$14)^2 | AJ36: =$C36*$E36*(1+Hypothèses!$C$14)^2 | AK36: =$C36*$E36*(1+Hypothèses!$C$14)^2 | AL36: =$C36*$E36*(1+Hypothèses!$C$14)^2 | ... AP36: =$C36*$E36*(1+Hypothèses!$C$14)^2 | AQ36: =SUM(G36:R36) | AR36: =SUM(S36:AD36) | AS36: =SUM(AE36:AP36) | AT36: =SUM(AQ36:AS36)
A37: Charges fixes | B37: Assurance RC professionnelle & flotte véhicules | C37: 1 | D37: forfait/mois | E37: 450 | F37: Estimé — devis assureur pro | G37: =$C37*$E37*(1+Hypothèses!$C$14)^0 | H37: =$C37*$E37*(1+Hypothèses!$C$14)^0 | I37: =$C37*$E37*(1+Hypothèses!$C$14)^0 | J37: =$C37*$E37*(1+Hypothèses!$C$14)^0 | K37: =$C37*$E37*(1+Hypothèses!$C$14)^0 | L37: =$C37*$E37*(1+Hypothèses!$C$14)^0 | M37: =$C37*$E37*(1+Hypothèses!$C$14)^0 | N37: =$C37*$E37*(1+Hypothèses!$C$14)^0 | ... R37: =$C37*$E37*(1+Hypothèses!$C$14)^0 | S37: =$C37*$E37*(1+Hypothèses!$C$14)^1 | T37: =$C37*$E37*(1+Hypothèses!$C$14)^1 | U37: =$C37*$E37*(1+Hypothèses!$C$14)^1 | V37: =$C37*$E37*(1+Hypothèses!$C$14)^1 | W37: =$C37*$E37*(1+Hypothèses!$C$14)^1 | X37: =$C37*$E37*(1+Hypothèses!$C$14)^1 | Y37: =$C37*$E37*(1+Hypothèses!$C$14)^1 | Z37: =$C37*$E37*(1+Hypothèses!$C$14)^1 | ... AD37: =$C37*$E37*(1+Hypothèses!$C$14)^1 | AE37: =$C37*$E37*(1+Hypothèses!$C$14)^2 | AF37: =$C37*$E37*(1+Hypothèses!$C$14)^2 | AG37: =$C37*$E37*(1+Hypothèses!$C$14)^2 | AH37: =$C37*$E37*(1+Hypothèses!$C$14)^2 | AI37: =$C37*$E37*(1+Hypothèses!$C$14)^2 | AJ37: =$C37*$E37*(1+Hypothèses!$C$14)^2 | AK37: =$C37*$E37*(1+Hypothèses!$C$14)^2 | AL37: =$C37*$E37*(1+Hypothèses!$C$14)^2 | ... AP37: =$C37*$E37*(1+Hypothèses!$C$14)^2 | AQ37: =SUM(G37:R37) | AR37: =SUM(S37:AD37) | AS37: =SUM(AE37:AP37) | AT37: =SUM(AQ37:AS37)
A38: Charges fixes | B38: Honoraires comptable | C38: 1 | D38: forfait/mois | E38: 600 | F38: Estimé | G38: =$C38*$E38*(1+Hypothèses!$C$14)^0 | H38: =$C38*$E38*(1+Hypothèses!$C$14)^0 | I38: =$C38*$E38*(1+Hypothèses!$C$14)^0 | J38: =$C38*$E38*(1+Hypothèses!$C$14)^0 | K38: =$C38*$E38*(1+Hypothèses!$C$14)^0 | L38: =$C38*$E38*(1+Hypothèses!$C$14)^0 | M38: =$C38*$E38*(1+Hypothèses!$C$14)^0 | N38: =$C38*$E38*(1+Hypothèses!$C$14)^0 | ... R38: =$C38*$E38*(1+Hypothèses!$C$14)^0 | S38: =$C38*$E38*(1+Hypothèses!$C$14)^1 | T38: =$C38*$E38*(1+Hypothèses!$C$14)^1 | U38: =$C38*$E38*(1+Hypothèses!$C$14)^1 | V38: =$C38*$E38*(1+Hypothèses!$C$14)^1 | W38: =$C38*$E38*(1+Hypothèses!$C$14)^1 | X38: =$C38*$E38*(1+Hypothèses!$C$14)^1 | Y38: =$C38*$E38*(1+Hypothèses!$C$14)^1 | Z38: =$C38*$E38*(1+Hypothèses!$C$14)^1 | ... AD38: =$C38*$E38*(1+Hypothèses!$C$14)^1 | AE38: =$C38*$E38*(1+Hypothèses!$C$14)^2 | AF38: =$C38*$E38*(1+Hypothèses!$C$14)^2 | AG38: =$C38*$E38*(1+Hypothèses!$C$14)^2 | AH38: =$C38*$E38*(1+Hypothèses!$C$14)^2 | AI38: =$C38*$E38*(1+Hypothèses!$C$14)^2 | AJ38: =$C38*$E38*(1+Hypothèses!$C$14)^2 | AK38: =$C38*$E38*(1+Hypothèses!$C$14)^2 | AL38: =$C38*$E38*(1+Hypothèses!$C$14)^2 | ... AP38: =$C38*$E38*(1+Hypothèses!$C$14)^2 | AQ38: =SUM(G38:R38) | AR38: =SUM(S38:AD38) | AS38: =SUM(AE38:AP38) | AT38: =SUM(AQ38:AS38)
A39: Charges fixes | B39: Téléphonie / internet / logiciels de gestion chantier | C39: 1 | D39: forfait/mois | E39: 200 | F39: Estimé | G39: =$C39*$E39*(1+Hypothèses!$C$14)^0 | H39: =$C39*$E39*(1+Hypothèses!$C$14)^0 | I39: =$C39*$E39*(1+Hypothèses!$C$14)^0 | J39: =$C39*$E39*(1+Hypothèses!$C$14)^0 | K39: =$C39*$E39*(1+Hypothèses!$C$14)^0 | L39: =$C39*$E39*(1+Hypothèses!$C$14)^0 | M39: =$C39*$E39*(1+Hypothèses!$C$14)^0 | N39: =$C39*$E39*(1+Hypothèses!$C$14)^0 | ... R39: =$C39*$E39*(1+Hypothèses!$C$14)^0 | S39: =$C39*$E39*(1+Hypothèses!$C$14)^1 | T39: =$C39*$E39*(1+Hypothèses!$C$14)^1 | U39: =$C39*$E39*(1+Hypothèses!$C$14)^1 | V39: =$C39*$E39*(1+Hypothèses!$C$14)^1 | W39: =$C39*$E39*(1+Hypothèses!$C$14)^1 | X39: =$C39*$E39*(1+Hypothèses!$C$14)^1 | Y39: =$C39*$E39*(1+Hypothèses!$C$14)^1 | Z39: =$C39*$E39*(1+Hypothèses!$C$14)^1 | ... AD39: =$C39*$E39*(1+Hypothèses!$C$14)^1 | AE39: =$C39*$E39*(1+Hypothèses!$C$14)^2 | AF39: =$C39*$E39*(1+Hypothèses!$C$14)^2 | AG39: =$C39*$E39*(1+Hypothèses!$C$14)^2 | AH39: =$C39*$E39*(1+Hypothèses!$C$14)^2 | AI39: =$C39*$E39*(1+Hypothèses!$C$14)^2 | AJ39: =$C39*$E39*(1+Hypothèses!$C$14)^2 | AK39: =$C39*$E39*(1+Hypothèses!$C$14)^2 | AL39: =$C39*$E39*(1+Hypothèses!$C$14)^2 | ... AP39: =$C39*$E39*(1+Hypothèses!$C$14)^2 | AQ39: =SUM(G39:R39) | AR39: =SUM(S39:AD39) | AS39: =SUM(AE39:AP39) | AT39: =SUM(AQ39:AS39)
A40: Charges fixes | B40: Fournitures & équipements de protection individuelle (EPI) | C40: 1 | D40: forfait/mois | E40: 350 | F40: Estimé | G40: =$C40*$E40*(1+Hypothèses!$C$14)^0 | H40: =$C40*$E40*(1+Hypothèses!$C$14)^0 | I40: =$C40*$E40*(1+Hypothèses!$C$14)^0 | J40: =$C40*$E40*(1+Hypothèses!$C$14)^0 | K40: =$C40*$E40*(1+Hypothèses!$C$14)^0 | L40: =$C40*$E40*(1+Hypothèses!$C$14)^0 | M40: =$C40*$E40*(1+Hypothèses!$C$14)^0 | N40: =$C40*$E40*(1+Hypothèses!$C$14)^0 | ... R40: =$C40*$E40*(1+Hypothèses!$C$14)^0 | S40: =$C40*$E40*(1+Hypothèses!$C$14)^1 | T40: =$C40*$E40*(1+Hypothèses!$C$14)^1 | U40: =$C40*$E40*(1+Hypothèses!$C$14)^1 | V40: =$C40*$E40*(1+Hypothèses!$C$14)^1 | W40: =$C40*$E40*(1+Hypothèses!$C$14)^1 | X40: =$C40*$E40*(1+Hypothèses!$C$14)^1 | Y40: =$C40*$E40*(1+Hypothèses!$C$14)^1 | Z40: =$C40*$E40*(1+Hypothèses!$C$14)^1 | ... AD40: =$C40*$E40*(1+Hypothèses!$C$14)^1 | AE40: =$C40*$E40*(1+Hypothèses!$C$14)^2 | AF40: =$C40*$E40*(1+Hypothèses!$C$14)^2 | AG40: =$C40*$E40*(1+Hypothèses!$C$14)^2 | AH40: =$C40*$E40*(1+Hypothèses!$C$14)^2 | AI40: =$C40*$E40*(1+Hypothèses!$C$14)^2 | AJ40: =$C40*$E40*(1+Hypothèses!$C$14)^2 | AK40: =$C40*$E40*(1+Hypothèses!$C$14)^2 | AL40: =$C40*$E40*(1+Hypothèses!$C$14)^2 | ... AP40: =$C40*$E40*(1+Hypothèses!$C$14)^2 | AQ40: =SUM(G40:R40) | AR40: =SUM(S40:AD40) | AS40: =SUM(AE40:AP40) | AT40: =SUM(AQ40:AS40)
...

Sheet Plan de trésorerie
A1: BTP — Plan de trésorerie mensuel (3 ans)
A2: ⚠️ Le décalage de paiement client (45j en moyenne) est modélisé. Chaque poste reprend le détail mensuel de l'onglet Dépenses détaillées.
C3: ANNÉE 1 | O3: ANNÉE 2 | AA3: ANNÉE 3
A4: Mois | C4: Jan A1 | D4: Fév A1 | E4: Mar A1 | F4: Avr A1 | G4: Mai A1 | H4: Jui A1 | I4: Jui A1 | J4: Aoû A1 | K4: Sep A1 | L4: Oct A1 | M4: Nov A1 | N4: Déc A1 | O4: Jan A2 | P4: Fév A2 | Q4: Mar A2 | R4: Avr A2 | S4: Mai A2 | T4: Jui A2 | U4: Jui A2 | V4: Aoû A2 | W4: Sep A2 | X4: Oct A2 | Y4: Nov A2 | Z4: Déc A2 | AA4: Jan A3 | AB4: Fév A3 | AC4: Mar A3 | AD4: Avr A3 | AE4: Mai A3 | AF4: Jui A3 | AG4: Jui A3 | AH4: Aoû A3 | AI4: Sep A3 | AJ4: Oct A3 | AK4: Nov A3 | AL4: Déc A3 | AM4: Total A1 | AN4: Total A2 | AO4: Total A3 | AP4: Total 3 ans
A5: Trésorerie en début de mois | C5: =Hypothèses!$C$7 | D5: =C21 | E5: =D21 | F5: =E21 | G5: =F21 | H5: =G21 | I5: =H21 | J5: =I21 | K5: =J21 | ... AL5: =AK21
A6: ENCAISSEMENTS
A7: Encaissements clients (CA TTC, après délai de paiement 50%/50% M-1/M-2) | C7: =Revenus!C12*Hypothèses!$C$10+Hypothèses!$C$15*Hypothèses!$C$11+Hypothèses!$C$15*Hypothèses!$C$12 | D7: =Revenus!D12*Hypothèses!$C$10+Revenus!C12*Hypothèses!$C$11+Hypothèses!$C$15*Hypothèses!$C$12 | E7: =Revenus!E12*Hypothèses!$C$10+Revenus!D12*Hypothèses!$C$11+Revenus!C12*Hypothèses!$C$12 | F7: =Revenus!F12*Hypothèses!$C$10+Revenus!E12*Hypothèses!$C$11+Revenus!D12*Hypothèses!$C$12 | G7: =Revenus!G12*Hypothèses!$C$10+Revenus!F12*Hypothèses!$C$11+Revenus!E12*Hypothèses!$C$12 | H7: =Revenus!H12*Hypothèses!$C$10+Revenus!G12*Hypothèses!$C$11+Revenus!F12*Hypothèses!$C$12 | I7: =Revenus!I12*Hypothèses!$C$10+Revenus!H12*Hypothèses!$C$11+Revenus!G12*Hypothèses!$C$12 | J7: =Revenus!J12*Hypothèses!$C$10+Revenus!I12*Hypothèses!$C$11+Revenus!H12*Hypothèses!$C$12 | K7: =Revenus!K12*Hypothèses!$C$10+Revenus!J12*Hypothèses!$C$11+Revenus!I12*Hypothèses!$C$12 | L7: =Revenus!L12*Hypothèses!$C$10+Revenus!K12*Hypothèses!$C$11+Revenus!J12*Hypothèses!$C$12 | ... AL7: =Revenus!AL12*Hypothèses!$C$10+Revenus!AK12*Hypothèses!$C$11+Revenus!AJ12*Hypothèses!$C$12 | AM7: =SUM(C7:N7) | AN7: =SUM(O7:Z7) | AO7: =SUM(AA7:AL7) | AP7: =SUM(AM7:AO7)
A8: TOTAL ENCAISSEMENTS | C8: =C7 | D8: =D7 | E8: =E7 | F8: =F7 | G8: =G7 | H8: =H7 | I8: =I7 | J8: =J7 | ... AL8: =AL7 | AM8: =SUM(C8:N8) | AN8: =SUM(O8:Z8) | AO8: =SUM(AA8:AL8) | AP8: =SUM(AM8:AO8)
A9: DÉCAISSEMENTS
A10: Matériaux (détail mensuel — onglet Dépenses) | C10: ='Dépenses détaillées'!G13 | D10: ='Dépenses détaillées'!H13 | E10: ='Dépenses détaillées'!I13 | F10: ='Dépenses détaillées'!J13 | G10: ='Dépenses détaillées'!K13 | H10: ='Dépenses détaillées'!L13 | I10: ='Dépenses détaillées'!M13 | J10: ='Dépenses détaillées'!N13 | ... AL10: ='Dépenses détaillées'!AP13 | AM10: =SUM(C10:N10) | AN10: =SUM(O10:Z10) | AO10: =SUM(AA10:AL10) | AP10: =SUM(AM10:AO10)
A11: Sous-traitance (détail mensuel — onglet Dépenses) | C11: ='Dépenses détaillées'!G16 | D11: ='Dépenses détaillées'!H16 | E11: ='Dépenses détaillées'!I16 | F11: ='Dépenses détaillées'!J16 | G11: ='Dépenses détaillées'!K16 | H11: ='Dépenses détaillées'!L16 | I11: ='Dépenses détaillées'!M16 | J11: ='Dépenses détaillées'!N16 | ... AL11: ='Dépenses détaillées'!AP16 | AM11: =SUM(C11:N11) | AN11: =SUM(O11:Z11) | AO11: =SUM(AA11:AL11) | AP11: =SUM(AM11:AO11)
A12: Carburant & engins (détail mensuel — onglet Dépenses) | C12: ='Dépenses détaillées'!G21 | D12: ='Dépenses détaillées'!H21 | E12: ='Dépenses détaillées'!I21 | F12: ='Dépenses détaillées'!J21 | G12: ='Dépenses détaillées'!K21 | H12: ='Dépenses détaillées'!L21 | I12: ='Dépenses détaillées'!M21 | J12: ='Dépenses détaillées'!N21 | ... AL12: ='Dépenses détaillées'!AP21 | AM12: =SUM(C12:N12) | AN12: =SUM(O12:Z12) | AO12: =SUM(AA12:AL12) | AP12: =SUM(AM12:AO12)
A13: Location matériel (détail mensuel — onglet Dépenses) | C13: ='Dépenses détaillées'!G24 | D13: ='Dépenses détaillées'!H24 | E13: ='Dépenses détaillées'!I24 | F13: ='Dépenses détaillées'!J24 | G13: ='Dépenses détaillées'!K24 | H13: ='Dépenses détaillées'!L24 | I13: ='Dépenses détaillées'!M24 | J13: ='Dépenses détaillées'!N24 | ... AL13: ='Dépenses détaillées'!AP24 | AM13: =SUM(C13:N13) | AN13: =SUM(O13:Z13) | AO13: =SUM(AA13:AL13) | AP13: =SUM(AM13:AO13)
