Workbook

Sheet Hypotheses
A1: Boulangerie Artisanale - Hypotheses
A2: Metier: Artisanal bakery and pastry shop. | Archetype: bakery | CA cible A1: 310,000 EUR | Blue cells are editable
A4: Chiffre d'affaires annuel HT - Annee 1 (EUR) | C4: 310000
A5: Taux de TVA moyen sur les ventes | C5: 0.055
A6: Taux de TVA moyen sur les achats | C6: 0.11
A7: Tresorerie disponible au 1er janvier A1 (EUR) | C7: 12000
A8: Cotisations sociales dirigeant - par trimestre A1 (EUR) | C8: 3200
A9: Remboursement emprunt materiel - mensualite fixe (EUR) | C9: 480
A10: Part du CA encaissee le mois meme | C10: 1
A11: Part du CA encaissee a M-1 | C11: 0
A12: Part du CA encaissee a M-2 | C12: 0 | D12: Control should equal 100% | E12: =SUM(C10:C12)
A13: Taux de croissance du CA - par an | C13: 0.025
A14: Taux d'inflation des prix d'achat - par an | C14: 0.03
A16: Month pattern repeated every year | C16: Jan | D16: Feb | E16: Mar | F16: Apr | G16: May | H16: Jun | I16: Jul | J16: Aug | K16: Sep | L16: Oct | M16: Nov | N16: Dec
A17: Seasonality index (1 = average month) | C17: 1.08 | D17: 0.97 | E17: 0.98 | F17: 1.03 | G17: 1 | H17: 0.97 | I17: 0.95 | J17: 0.75 | K17: 1.02 | L17: 1.05 | M17: 1.02 | N17: 1.18
A18: Month weight in year (normalized) | C18: =C17/SUM($C$17:$N$17) | D18: =D17/SUM($C$17:$N$17) | E18: =E17/SUM($C$17:$N$17) | F18: =F17/SUM($C$17:$N$17) | G18: =G17/SUM($C$17:$N$17) | H18: =H17/SUM($C$17:$N$17) | I18: =I17/SUM($C$17:$N$17) | J18: =J17/SUM($C$17:$N$17) | ... N18: =N17/SUM($C$17:$N$17)
A21: v1 note: ratios and quantities are synthetic benchmark assumptions unless a source/API is explicitly listed.
A22: Commodity-linked rows preserve realistic monthly variation. External series are normalized to the model unit price.
A23: INSEE support is intentionally configurable by URL/series because exact indicators depend on the sector and use case.
A25: Legend
A26: Blue | B26: Editable assumption
A27: Gray | B27: Formula calculated automatically
A28: Light blue | B28: Link to another sheet
A29: Yellow | B29: Source/API note

Sheet Revenus
A1: Boulangerie Artisanale - Revenus mensuels
A2: Revenue streams x annual mix x seasonality x annual growth.
C3: ANNEE 1 | O3: ANNEE 2 | AA3: ANNEE 3
A4: Source de revenus | B4: % du CA annuel | C4: Jan A1 | D4: Feb A1 | E4: Mar A1 | F4: Apr A1 | G4: May A1 | H4: Jun A1 | I4: Jul A1 | J4: Aug A1 | K4: Sep A1 | L4: Oct A1 | M4: Nov A1 | N4: Dec A1 | O4: Jan A2 | P4: Feb A2 | Q4: Mar A2 | R4: Apr A2 | S4: May A2 | T4: Jun A2 | U4: Jul A2 | V4: Aug A2 | W4: Sep A2 | X4: Oct A2 | Y4: Nov A2 | Z4: Dec A2 | AA4: Jan A3 | AB4: Feb A3 | AC4: Mar A3 | AD4: Apr A3 | AE4: May A3 | AF4: Jun A3 | AG4: Jul A3 | AH4: Aug A3 | AI4: Sep A3 | AJ4: Oct A3 | AK4: Nov A3 | AL4: Dec A3
A5: Bread | B5: 0.45 | C5: ='Hypotheses'!$C$4*$B5*'Hypotheses'!C$18*(1+'Hypotheses'!$C$13)^0 | D5: ='Hypotheses'!$C$4*$B5*'Hypotheses'!D$18*(1+'Hypotheses'!$C$13)^0 | E5: ='Hypotheses'!$C$4*$B5*'Hypotheses'!E$18*(1+'Hypotheses'!$C$13)^0 | F5: ='Hypotheses'!$C$4*$B5*'Hypotheses'!F$18*(1+'Hypotheses'!$C$13)^0 | G5: ='Hypotheses'!$C$4*$B5*'Hypotheses'!G$18*(1+'Hypotheses'!$C$13)^0 | H5: ='Hypotheses'!$C$4*$B5*'Hypotheses'!H$18*(1+'Hypotheses'!$C$13)^0 | I5: ='Hypotheses'!$C$4*$B5*'Hypotheses'!I$18*(1+'Hypotheses'!$C$13)^0 | J5: ='Hypotheses'!$C$4*$B5*'Hypotheses'!J$18*(1+'Hypotheses'!$C$13)^0 | ... N5: ='Hypotheses'!$C$4*$B5*'Hypotheses'!N$18*(1+'Hypotheses'!$C$13)^0 | O5: ='Hypotheses'!$C$4*$B5*'Hypotheses'!C$18*(1+'Hypotheses'!$C$13)^1 | P5: ='Hypotheses'!$C$4*$B5*'Hypotheses'!D$18*(1+'Hypotheses'!$C$13)^1 | Q5: ='Hypotheses'!$C$4*$B5*'Hypotheses'!E$18*(1+'Hypotheses'!$C$13)^1 | R5: ='Hypotheses'!$C$4*$B5*'Hypotheses'!F$18*(1+'Hypotheses'!$C$13)^1 | S5: ='Hypotheses'!$C$4*$B5*'Hypotheses'!G$18*(1+'Hypotheses'!$C$13)^1 | T5: ='Hypotheses'!$C$4*$B5*'Hypotheses'!H$18*(1+'Hypotheses'!$C$13)^1 | U5: ='Hypotheses'!$C$4*$B5*'Hypotheses'!I$18*(1+'Hypotheses'!$C$13)^1 | V5: ='Hypotheses'!$C$4*$B5*'Hypotheses'!J$18*(1+'Hypotheses'!$C$13)^1 | ... Z5: ='Hypotheses'!$C$4*$B5*'Hypotheses'!N$18*(1+'Hypotheses'!$C$13)^1 | AA5: ='Hypotheses'!$C$4*$B5*'Hypotheses'!C$18*(1+'Hypotheses'!$C$13)^2 | AB5: ='Hypotheses'!$C$4*$B5*'Hypotheses'!D$18*(1+'Hypotheses'!$C$13)^2 | AC5: ='Hypotheses'!$C$4*$B5*'Hypotheses'!E$18*(1+'Hypotheses'!$C$13)^2 | AD5: ='Hypotheses'!$C$4*$B5*'Hypotheses'!F$18*(1+'Hypotheses'!$C$13)^2 | AE5: ='Hypotheses'!$C$4*$B5*'Hypotheses'!G$18*(1+'Hypotheses'!$C$13)^2 | AF5: ='Hypotheses'!$C$4*$B5*'Hypotheses'!H$18*(1+'Hypotheses'!$C$13)^2 | AG5: ='Hypotheses'!$C$4*$B5*'Hypotheses'!I$18*(1+'Hypotheses'!$C$13)^2 | AH5: ='Hypotheses'!$C$4*$B5*'Hypotheses'!J$18*(1+'Hypotheses'!$C$13)^2 | ... AL5: ='Hypotheses'!$C$4*$B5*'Hypotheses'!N$18*(1+'Hypotheses'!$C$13)^2
A6: Viennoiserie | B6: 0.2 | C6: ='Hypotheses'!$C$4*$B6*'Hypotheses'!C$18*(1+'Hypotheses'!$C$13)^0 | D6: ='Hypotheses'!$C$4*$B6*'Hypotheses'!D$18*(1+'Hypotheses'!$C$13)^0 | E6: ='Hypotheses'!$C$4*$B6*'Hypotheses'!E$18*(1+'Hypotheses'!$C$13)^0 | F6: ='Hypotheses'!$C$4*$B6*'Hypotheses'!F$18*(1+'Hypotheses'!$C$13)^0 | G6: ='Hypotheses'!$C$4*$B6*'Hypotheses'!G$18*(1+'Hypotheses'!$C$13)^0 | H6: ='Hypotheses'!$C$4*$B6*'Hypotheses'!H$18*(1+'Hypotheses'!$C$13)^0 | I6: ='Hypotheses'!$C$4*$B6*'Hypotheses'!I$18*(1+'Hypotheses'!$C$13)^0 | J6: ='Hypotheses'!$C$4*$B6*'Hypotheses'!J$18*(1+'Hypotheses'!$C$13)^0 | ... N6: ='Hypotheses'!$C$4*$B6*'Hypotheses'!N$18*(1+'Hypotheses'!$C$13)^0 | O6: ='Hypotheses'!$C$4*$B6*'Hypotheses'!C$18*(1+'Hypotheses'!$C$13)^1 | P6: ='Hypotheses'!$C$4*$B6*'Hypotheses'!D$18*(1+'Hypotheses'!$C$13)^1 | Q6: ='Hypotheses'!$C$4*$B6*'Hypotheses'!E$18*(1+'Hypotheses'!$C$13)^1 | R6: ='Hypotheses'!$C$4*$B6*'Hypotheses'!F$18*(1+'Hypotheses'!$C$13)^1 | S6: ='Hypotheses'!$C$4*$B6*'Hypotheses'!G$18*(1+'Hypotheses'!$C$13)^1 | T6: ='Hypotheses'!$C$4*$B6*'Hypotheses'!H$18*(1+'Hypotheses'!$C$13)^1 | U6: ='Hypotheses'!$C$4*$B6*'Hypotheses'!I$18*(1+'Hypotheses'!$C$13)^1 | V6: ='Hypotheses'!$C$4*$B6*'Hypotheses'!J$18*(1+'Hypotheses'!$C$13)^1 | ... Z6: ='Hypotheses'!$C$4*$B6*'Hypotheses'!N$18*(1+'Hypotheses'!$C$13)^1 | AA6: ='Hypotheses'!$C$4*$B6*'Hypotheses'!C$18*(1+'Hypotheses'!$C$13)^2 | AB6: ='Hypotheses'!$C$4*$B6*'Hypotheses'!D$18*(1+'Hypotheses'!$C$13)^2 | AC6: ='Hypotheses'!$C$4*$B6*'Hypotheses'!E$18*(1+'Hypotheses'!$C$13)^2 | AD6: ='Hypotheses'!$C$4*$B6*'Hypotheses'!F$18*(1+'Hypotheses'!$C$13)^2 | AE6: ='Hypotheses'!$C$4*$B6*'Hypotheses'!G$18*(1+'Hypotheses'!$C$13)^2 | AF6: ='Hypotheses'!$C$4*$B6*'Hypotheses'!H$18*(1+'Hypotheses'!$C$13)^2 | AG6: ='Hypotheses'!$C$4*$B6*'Hypotheses'!I$18*(1+'Hypotheses'!$C$13)^2 | AH6: ='Hypotheses'!$C$4*$B6*'Hypotheses'!J$18*(1+'Hypotheses'!$C$13)^2 | ... AL6: ='Hypotheses'!$C$4*$B6*'Hypotheses'!N$18*(1+'Hypotheses'!$C$13)^2
A7: Pastry | B7: 0.15 | C7: ='Hypotheses'!$C$4*$B7*'Hypotheses'!C$18*(1+'Hypotheses'!$C$13)^0 | D7: ='Hypotheses'!$C$4*$B7*'Hypotheses'!D$18*(1+'Hypotheses'!$C$13)^0 | E7: ='Hypotheses'!$C$4*$B7*'Hypotheses'!E$18*(1+'Hypotheses'!$C$13)^0 | F7: ='Hypotheses'!$C$4*$B7*'Hypotheses'!F$18*(1+'Hypotheses'!$C$13)^0 | G7: ='Hypotheses'!$C$4*$B7*'Hypotheses'!G$18*(1+'Hypotheses'!$C$13)^0 | H7: ='Hypotheses'!$C$4*$B7*'Hypotheses'!H$18*(1+'Hypotheses'!$C$13)^0 | I7: ='Hypotheses'!$C$4*$B7*'Hypotheses'!I$18*(1+'Hypotheses'!$C$13)^0 | J7: ='Hypotheses'!$C$4*$B7*'Hypotheses'!J$18*(1+'Hypotheses'!$C$13)^0 | ... N7: ='Hypotheses'!$C$4*$B7*'Hypotheses'!N$18*(1+'Hypotheses'!$C$13)^0 | O7: ='Hypotheses'!$C$4*$B7*'Hypotheses'!C$18*(1+'Hypotheses'!$C$13)^1 | P7: ='Hypotheses'!$C$4*$B7*'Hypotheses'!D$18*(1+'Hypotheses'!$C$13)^1 | Q7: ='Hypotheses'!$C$4*$B7*'Hypotheses'!E$18*(1+'Hypotheses'!$C$13)^1 | R7: ='Hypotheses'!$C$4*$B7*'Hypotheses'!F$18*(1+'Hypotheses'!$C$13)^1 | S7: ='Hypotheses'!$C$4*$B7*'Hypotheses'!G$18*(1+'Hypotheses'!$C$13)^1 | T7: ='Hypotheses'!$C$4*$B7*'Hypotheses'!H$18*(1+'Hypotheses'!$C$13)^1 | U7: ='Hypotheses'!$C$4*$B7*'Hypotheses'!I$18*(1+'Hypotheses'!$C$13)^1 | V7: ='Hypotheses'!$C$4*$B7*'Hypotheses'!J$18*(1+'Hypotheses'!$C$13)^1 | ... Z7: ='Hypotheses'!$C$4*$B7*'Hypotheses'!N$18*(1+'Hypotheses'!$C$13)^1 | AA7: ='Hypotheses'!$C$4*$B7*'Hypotheses'!C$18*(1+'Hypotheses'!$C$13)^2 | AB7: ='Hypotheses'!$C$4*$B7*'Hypotheses'!D$18*(1+'Hypotheses'!$C$13)^2 | AC7: ='Hypotheses'!$C$4*$B7*'Hypotheses'!E$18*(1+'Hypotheses'!$C$13)^2 | AD7: ='Hypotheses'!$C$4*$B7*'Hypotheses'!F$18*(1+'Hypotheses'!$C$13)^2 | AE7: ='Hypotheses'!$C$4*$B7*'Hypotheses'!G$18*(1+'Hypotheses'!$C$13)^2 | AF7: ='Hypotheses'!$C$4*$B7*'Hypotheses'!H$18*(1+'Hypotheses'!$C$13)^2 | AG7: ='Hypotheses'!$C$4*$B7*'Hypotheses'!I$18*(1+'Hypotheses'!$C$13)^2 | AH7: ='Hypotheses'!$C$4*$B7*'Hypotheses'!J$18*(1+'Hypotheses'!$C$13)^2 | ... AL7: ='Hypotheses'!$C$4*$B7*'Hypotheses'!N$18*(1+'Hypotheses'!$C$13)^2
A8: Snacking and catering | B8: 0.15 | C8: ='Hypotheses'!$C$4*$B8*'Hypotheses'!C$18*(1+'Hypotheses'!$C$13)^0 | D8: ='Hypotheses'!$C$4*$B8*'Hypotheses'!D$18*(1+'Hypotheses'!$C$13)^0 | E8: ='Hypotheses'!$C$4*$B8*'Hypotheses'!E$18*(1+'Hypotheses'!$C$13)^0 | F8: ='Hypotheses'!$C$4*$B8*'Hypotheses'!F$18*(1+'Hypotheses'!$C$13)^0 | G8: ='Hypotheses'!$C$4*$B8*'Hypotheses'!G$18*(1+'Hypotheses'!$C$13)^0 | H8: ='Hypotheses'!$C$4*$B8*'Hypotheses'!H$18*(1+'Hypotheses'!$C$13)^0 | I8: ='Hypotheses'!$C$4*$B8*'Hypotheses'!I$18*(1+'Hypotheses'!$C$13)^0 | J8: ='Hypotheses'!$C$4*$B8*'Hypotheses'!J$18*(1+'Hypotheses'!$C$13)^0 | ... N8: ='Hypotheses'!$C$4*$B8*'Hypotheses'!N$18*(1+'Hypotheses'!$C$13)^0 | O8: ='Hypotheses'!$C$4*$B8*'Hypotheses'!C$18*(1+'Hypotheses'!$C$13)^1 | P8: ='Hypotheses'!$C$4*$B8*'Hypotheses'!D$18*(1+'Hypotheses'!$C$13)^1 | Q8: ='Hypotheses'!$C$4*$B8*'Hypotheses'!E$18*(1+'Hypotheses'!$C$13)^1 | R8: ='Hypotheses'!$C$4*$B8*'Hypotheses'!F$18*(1+'Hypotheses'!$C$13)^1 | S8: ='Hypotheses'!$C$4*$B8*'Hypotheses'!G$18*(1+'Hypotheses'!$C$13)^1 | T8: ='Hypotheses'!$C$4*$B8*'Hypotheses'!H$18*(1+'Hypotheses'!$C$13)^1 | U8: ='Hypotheses'!$C$4*$B8*'Hypotheses'!I$18*(1+'Hypotheses'!$C$13)^1 | V8: ='Hypotheses'!$C$4*$B8*'Hypotheses'!J$18*(1+'Hypotheses'!$C$13)^1 | ... Z8: ='Hypotheses'!$C$4*$B8*'Hypotheses'!N$18*(1+'Hypotheses'!$C$13)^1 | AA8: ='Hypotheses'!$C$4*$B8*'Hypotheses'!C$18*(1+'Hypotheses'!$C$13)^2 | AB8: ='Hypotheses'!$C$4*$B8*'Hypotheses'!D$18*(1+'Hypotheses'!$C$13)^2 | AC8: ='Hypotheses'!$C$4*$B8*'Hypotheses'!E$18*(1+'Hypotheses'!$C$13)^2 | AD8: ='Hypotheses'!$C$4*$B8*'Hypotheses'!F$18*(1+'Hypotheses'!$C$13)^2 | AE8: ='Hypotheses'!$C$4*$B8*'Hypotheses'!G$18*(1+'Hypotheses'!$C$13)^2 | AF8: ='Hypotheses'!$C$4*$B8*'Hypotheses'!H$18*(1+'Hypotheses'!$C$13)^2 | AG8: ='Hypotheses'!$C$4*$B8*'Hypotheses'!I$18*(1+'Hypotheses'!$C$13)^2 | AH8: ='Hypotheses'!$C$4*$B8*'Hypotheses'!J$18*(1+'Hypotheses'!$C$13)^2 | ... AL8: ='Hypotheses'!$C$4*$B8*'Hypotheses'!N$18*(1+'Hypotheses'!$C$13)^2
A9: Drinks and other | B9: 0.05 | C9: ='Hypotheses'!$C$4*$B9*'Hypotheses'!C$18*(1+'Hypotheses'!$C$13)^0 | D9: ='Hypotheses'!$C$4*$B9*'Hypotheses'!D$18*(1+'Hypotheses'!$C$13)^0 | E9: ='Hypotheses'!$C$4*$B9*'Hypotheses'!E$18*(1+'Hypotheses'!$C$13)^0 | F9: ='Hypotheses'!$C$4*$B9*'Hypotheses'!F$18*(1+'Hypotheses'!$C$13)^0 | G9: ='Hypotheses'!$C$4*$B9*'Hypotheses'!G$18*(1+'Hypotheses'!$C$13)^0 | H9: ='Hypotheses'!$C$4*$B9*'Hypotheses'!H$18*(1+'Hypotheses'!$C$13)^0 | I9: ='Hypotheses'!$C$4*$B9*'Hypotheses'!I$18*(1+'Hypotheses'!$C$13)^0 | J9: ='Hypotheses'!$C$4*$B9*'Hypotheses'!J$18*(1+'Hypotheses'!$C$13)^0 | ... N9: ='Hypotheses'!$C$4*$B9*'Hypotheses'!N$18*(1+'Hypotheses'!$C$13)^0 | O9: ='Hypotheses'!$C$4*$B9*'Hypotheses'!C$18*(1+'Hypotheses'!$C$13)^1 | P9: ='Hypotheses'!$C$4*$B9*'Hypotheses'!D$18*(1+'Hypotheses'!$C$13)^1 | Q9: ='Hypotheses'!$C$4*$B9*'Hypotheses'!E$18*(1+'Hypotheses'!$C$13)^1 | R9: ='Hypotheses'!$C$4*$B9*'Hypotheses'!F$18*(1+'Hypotheses'!$C$13)^1 | S9: ='Hypotheses'!$C$4*$B9*'Hypotheses'!G$18*(1+'Hypotheses'!$C$13)^1 | T9: ='Hypotheses'!$C$4*$B9*'Hypotheses'!H$18*(1+'Hypotheses'!$C$13)^1 | U9: ='Hypotheses'!$C$4*$B9*'Hypotheses'!I$18*(1+'Hypotheses'!$C$13)^1 | V9: ='Hypotheses'!$C$4*$B9*'Hypotheses'!J$18*(1+'Hypotheses'!$C$13)^1 | ... Z9: ='Hypotheses'!$C$4*$B9*'Hypotheses'!N$18*(1+'Hypotheses'!$C$13)^1 | AA9: ='Hypotheses'!$C$4*$B9*'Hypotheses'!C$18*(1+'Hypotheses'!$C$13)^2 | AB9: ='Hypotheses'!$C$4*$B9*'Hypotheses'!D$18*(1+'Hypotheses'!$C$13)^2 | AC9: ='Hypotheses'!$C$4*$B9*'Hypotheses'!E$18*(1+'Hypotheses'!$C$13)^2 | AD9: ='Hypotheses'!$C$4*$B9*'Hypotheses'!F$18*(1+'Hypotheses'!$C$13)^2 | AE9: ='Hypotheses'!$C$4*$B9*'Hypotheses'!G$18*(1+'Hypotheses'!$C$13)^2 | AF9: ='Hypotheses'!$C$4*$B9*'Hypotheses'!H$18*(1+'Hypotheses'!$C$13)^2 | AG9: ='Hypotheses'!$C$4*$B9*'Hypotheses'!I$18*(1+'Hypotheses'!$C$13)^2 | AH9: ='Hypotheses'!$C$4*$B9*'Hypotheses'!J$18*(1+'Hypotheses'!$C$13)^2 | ... AL9: ='Hypotheses'!$C$4*$B9*'Hypotheses'!N$18*(1+'Hypotheses'!$C$13)^2
A10: TOTAL CA HT | C10: =SUM(C5:C9) | D10: =SUM(D5:D9) | E10: =SUM(E5:E9) | F10: =SUM(F5:F9) | G10: =SUM(G5:G9) | H10: =SUM(H5:H9) | I10: =SUM(I5:I9) | J10: =SUM(J5:J9) | ... AL10: =SUM(AL5:AL9)
A11: Control sum revenue mix | B11: =SUM(B5:B9)
A12: TVA collectee sur les ventes | C12: =C10*'Hypotheses'!$C$5 | D12: =D10*'Hypotheses'!$C$5 | E12: =E10*'Hypotheses'!$C$5 | F12: =F10*'Hypotheses'!$C$5 | G12: =G10*'Hypotheses'!$C$5 | H12: =H10*'Hypotheses'!$C$5 | I12: =I10*'Hypotheses'!$C$5 | J12: =J10*'Hypotheses'!$C$5 | ... AL12: =AL10*'Hypotheses'!$C$5
A13: CA TTC encaissable | C13: =C10+C12 | D13: =D10+D12 | E13: =E10+E12 | F13: =F10+F12 | G13: =G10+G12 | H13: =H10+H12 | I13: =I10+I12 | J13: =J10+J12 | ... AL13: =AL10+AL12

Sheet Depenses detaillees
A1: Boulangerie Artisanale - Depenses detaillees
A2: Quantity x seasonality x unit price x inflation = monthly cost. Market rows use monthly price series.
H3: ANNEE 1 | T3: ANNEE 2 | AF3: ANNEE 3
A4: Categorie | B4: Poste | C4: Qte base/mois A1 | D4: Unite | E4: Prix unitaire A1 | F4: Underlying | G4: Source prix | H4: Jan A1 | I4: Feb A1 | J4: Mar A1 | K4: Apr A1 | L4: May A1 | M4: Jun A1 | N4: Jul A1 | O4: Aug A1 | P4: Sep A1 | Q4: Oct A1 | R4: Nov A1 | S4: Dec A1 | T4: Jan A2 | U4: Feb A2 | V4: Mar A2 | W4: Apr A2 | X4: May A2 | Y4: Jun A2 | Z4: Jul A2 | AA4: Aug A2 | AB4: Sep A2 | AC4: Oct A2 | AD4: Nov A2 | AE4: Dec A2 | AF4: Jan A3 | AG4: Feb A3 | AH4: Mar A3 | AI4: Apr A3 | AJ4: May A3 | AK4: Jun A3 | AL4: Jul A3 | AM4: Aug A3 | AN4: Sep A3 | AO4: Oct A3 | AP4: Nov A3 | AQ4: Dec A3
A5: Raw materials | B5: Wheat flour T55/T65 - market price | C5: 5000 | D5: kg | E5: =AVERAGE(H5:AQ5) | F5: Wheat | G5: INSEE BDM 010002046: Cours des matières premières importées - Blé de force rouge d'hiver, contrat à terme à la 1ère échéance, CME (Chicago Mercantile Exchange) - Prix en cents US par boisseau; normalized to model unit price | H5: 0.56 | I5: 0.5668 | J5: 0.5356 | K5: 0.5604 | L5: 0.592 | M5: 0.5584 | N5: 0.5701 | O5: 0.6401 | P5: 0.6344 | Q5: 0.6788 | R5: 0.7419 | S5: 0.7376 | T5: 0.7102 | U5: 0.7503 | V5: 0.9894 | W5: 1.0118 | X5: 1.0976 | Y5: 0.9787 | Z5: 0.7848 | AA5: 0.7827 | AB5: 0.8399 | AC5: 0.8657 | AD5: 0.8442 | AE5: 0.7794 | AF5: 0.7595 | AG5: 0.792 | AH5: 0.7463 | AI5: 0.7654 | AJ5: 0.7622 | AK5: 0.7376 | AL5: 0.7582 | AM5: 0.6765 | AN5: 0.6475 | AO5: 0.5998 | AP5: 0.5673 | AQ5: 0.5765
A6: Raw materials | B6: Cost (Wheat flour T55/T65) | C6: 5000 | D6: kg | E6: =E5 | F6: Wheat | G6: Cost = quantity x seasonality x monthly market price | H6: =$C6*'Hypotheses'!C$17*H5 | I6: =$C6*'Hypotheses'!D$17*I5 | J6: =$C6*'Hypotheses'!E$17*J5 | K6: =$C6*'Hypotheses'!F$17*K5 | L6: =$C6*'Hypotheses'!G$17*L5 | M6: =$C6*'Hypotheses'!H$17*M5 | N6: =$C6*'Hypotheses'!I$17*N5 | O6: =$C6*'Hypotheses'!J$17*O5 | ... S6: =$C6*'Hypotheses'!N$17*S5 | T6: =$C6*'Hypotheses'!C$17*T5 | U6: =$C6*'Hypotheses'!D$17*U5 | V6: =$C6*'Hypotheses'!E$17*V5 | W6: =$C6*'Hypotheses'!F$17*W5 | X6: =$C6*'Hypotheses'!G$17*X5 | Y6: =$C6*'Hypotheses'!H$17*Y5 | Z6: =$C6*'Hypotheses'!I$17*Z5 | AA6: =$C6*'Hypotheses'!J$17*AA5 | ... AE6: =$C6*'Hypotheses'!N$17*AE5 | AF6: =$C6*'Hypotheses'!C$17*AF5 | AG6: =$C6*'Hypotheses'!D$17*AG5 | AH6: =$C6*'Hypotheses'!E$17*AH5 | AI6: =$C6*'Hypotheses'!F$17*AI5 | AJ6: =$C6*'Hypotheses'!G$17*AJ5 | AK6: =$C6*'Hypotheses'!H$17*AK5 | AL6: =$C6*'Hypotheses'!I$17*AL5 | AM6: =$C6*'Hypotheses'!J$17*AM5 | ... AQ6: =$C6*'Hypotheses'!N$17*AQ5
A7: Raw materials | B7: Tourage butter - market price | C7: 280 | D7: kg | E7: =AVERAGE(H7:AQ7) | F7: Fats | G7: INSEE BDM 010763694: Indice de prix de production de l'industrie française pour le marché français − CPF 10.51 − Beurre conditionné ; normalized to model unit price | H7: 6.2 | I7: 6.2442 | J7: 6.2442 | K7: 6.3264 | L7: 6.3201 | M7: 6.2695 | N7: 6.3454 | O7: 6.3138 | P7: 6.2948 | Q7: 6.3517 | R7: 6.3896 | S7: 6.5413 | T7: 6.6045 | U7: 6.6424 | V7: 6.9268 | W7: 7.1101 | X7: 7.2175 | Y7: 7.2934 | Z7: 7.7295 | AA7: 7.7674 | AB7: 7.8875 | AC7: 7.8495 | AD7: 7.7737 | AE7: 7.9001 | AF7: 7.9633 | AG7: 7.9317 | AH7: 8.1908 | AI7: 8.3425 | AJ7: 8.3299 | AK7: 8.2098 | AL7: 8.1655 | AM7: 8.1529 | AN7: 8.1466 | AO7: 8.1466 | AP7: 8.1655 | AQ7: 8.3299
A8: Raw materials | B8: Cost (Tourage butter) | C8: 280 | D8: kg | E8: =E7 | F8: Fats | G8: Cost = quantity x seasonality x monthly market price | H8: =$C8*'Hypotheses'!C$17*H7 | I8: =$C8*'Hypotheses'!D$17*I7 | J8: =$C8*'Hypotheses'!E$17*J7 | K8: =$C8*'Hypotheses'!F$17*K7 | L8: =$C8*'Hypotheses'!G$17*L7 | M8: =$C8*'Hypotheses'!H$17*M7 | N8: =$C8*'Hypotheses'!I$17*N7 | O8: =$C8*'Hypotheses'!J$17*O7 | ... S8: =$C8*'Hypotheses'!N$17*S7 | T8: =$C8*'Hypotheses'!C$17*T7 | U8: =$C8*'Hypotheses'!D$17*U7 | V8: =$C8*'Hypotheses'!E$17*V7 | W8: =$C8*'Hypotheses'!F$17*W7 | X8: =$C8*'Hypotheses'!G$17*X7 | Y8: =$C8*'Hypotheses'!H$17*Y7 | Z8: =$C8*'Hypotheses'!I$17*Z7 | AA8: =$C8*'Hypotheses'!J$17*AA7 | ... AE8: =$C8*'Hypotheses'!N$17*AE7 | AF8: =$C8*'Hypotheses'!C$17*AF7 | AG8: =$C8*'Hypotheses'!D$17*AG7 | AH8: =$C8*'Hypotheses'!E$17*AH7 | AI8: =$C8*'Hypotheses'!F$17*AI7 | AJ8: =$C8*'Hypotheses'!G$17*AJ7 | AK8: =$C8*'Hypotheses'!H$17*AK7 | AL8: =$C8*'Hypotheses'!I$17*AL7 | AM8: =$C8*'Hypotheses'!J$17*AM7 | ... AQ8: =$C8*'Hypotheses'!N$17*AQ7
A9: Raw materials | B9: Incorporation butter - market price | C9: 110 | D9: kg | E9: =AVERAGE(H9:AQ9) | F9: Fats | G9: INSEE BDM 010763694: Indice de prix de production de l'industrie française pour le marché français − CPF 10.51 − Beurre conditionné ; normalized to model unit price | H9: 5.1 | I9: 5.1364 | J9: 5.1364 | K9: 5.204 | L9: 5.1988 | M9: 5.1572 | N9: 5.2196 | O9: 5.1936 | P9: 5.178 | Q9: 5.2248 | R9: 5.256 | S9: 5.3807 | T9: 5.4327 | U9: 5.4639 | V9: 5.6979 | W9: 5.8486 | X9: 5.937 | Y9: 5.9994 | Z9: 6.3581 | AA9: 6.3893 | AB9: 6.4881 | AC9: 6.4569 | AD9: 6.3945 | AE9: 6.4985 | AF9: 6.5505 | AG9: 6.5245 | AH9: 6.7376 | AI9: 6.8624 | AJ9: 6.852 | AK9: 6.7532 | AL9: 6.7168 | AM9: 6.7064 | AN9: 6.7012 | AO9: 6.7012 | AP9: 6.7168 | AQ9: 6.852
A10: Raw materials | B10: Cost (Incorporation butter) | C10: 110 | D10: kg | E10: =E9 | F10: Fats | G10: Cost = quantity x seasonality x monthly market price | H10: =$C10*'Hypotheses'!C$17*H9 | I10: =$C10*'Hypotheses'!D$17*I9 | J10: =$C10*'Hypotheses'!E$17*J9 | K10: =$C10*'Hypotheses'!F$17*K9 | L10: =$C10*'Hypotheses'!G$17*L9 | M10: =$C10*'Hypotheses'!H$17*M9 | N10: =$C10*'Hypotheses'!I$17*N9 | O10: =$C10*'Hypotheses'!J$17*O9 | ... S10: =$C10*'Hypotheses'!N$17*S9 | T10: =$C10*'Hypotheses'!C$17*T9 | U10: =$C10*'Hypotheses'!D$17*U9 | V10: =$C10*'Hypotheses'!E$17*V9 | W10: =$C10*'Hypotheses'!F$17*W9 | X10: =$C10*'Hypotheses'!G$17*X9 | Y10: =$C10*'Hypotheses'!H$17*Y9 | Z10: =$C10*'Hypotheses'!I$17*Z9 | AA10: =$C10*'Hypotheses'!J$17*AA9 | ... AE10: =$C10*'Hypotheses'!N$17*AE9 | AF10: =$C10*'Hypotheses'!C$17*AF9 | AG10: =$C10*'Hypotheses'!D$17*AG9 | AH10: =$C10*'Hypotheses'!E$17*AH9 | AI10: =$C10*'Hypotheses'!F$17*AI9 | AJ10: =$C10*'Hypotheses'!G$17*AJ9 | AK10: =$C10*'Hypotheses'!H$17*AK9 | AL10: =$C10*'Hypotheses'!I$17*AL9 | AM10: =$C10*'Hypotheses'!J$17*AM9 | ... AQ10: =$C10*'Hypotheses'!N$17*AQ9
A11: Raw materials | B11: Baker's yeast - market price | C11: 65 | D11: kg | E11: =AVERAGE(H11:AQ11) | G11: INSEE BDM 010763751: Indice de prix de production de l'industrie française pour le marché français − CPF 10.89 − Autres produits alimentaires n.c.a. ; normalized to model unit price | H11: 3.6 | I11: 3.5568 | J11: 3.6072 | K11: 3.5892 | L11: 3.5892 | M11: 3.5928 | N11: 3.5459 | O11: 3.5784 | P11: 3.6072 | Q11: 3.6216 | R11: 3.6685 | S11: 3.6793 | T11: 3.7405 | U11: 3.8018 | V11: 3.964 | W11: 4.5333 | X11: 4.591 | Y11: 4.7063 | Z11: 4.6595 | AA11: 4.7279 | AB11: 4.7856 | AC11: 4.9369 | AD11: 5.0342 | AE11: 5.1243 | AF11: 5.2432 | AG11: 5.2757 | AH11: 5.3946 | AI11: 5.427 | AJ11: 5.3946 | AK11: 5.3838 | AL11: 5.164 | AM11: 5.164 | AN11: 5.1495 | AO11: 5.1387 | AP11: 5.1568 | AQ11: 5.1387
A12: Raw materials | B12: Cost (Baker's yeast) | C12: 65 | D12: kg | E12: =E11 | G12: Cost = quantity x seasonality x monthly market price | H12: =$C12*'Hypotheses'!C$17*H11 | I12: =$C12*'Hypotheses'!D$17*I11 | J12: =$C12*'Hypotheses'!E$17*J11 | K12: =$C12*'Hypotheses'!F$17*K11 | L12: =$C12*'Hypotheses'!G$17*L11 | M12: =$C12*'Hypotheses'!H$17*M11 | N12: =$C12*'Hypotheses'!I$17*N11 | O12: =$C12*'Hypotheses'!J$17*O11 | ... S12: =$C12*'Hypotheses'!N$17*S11 | T12: =$C12*'Hypotheses'!C$17*T11 | U12: =$C12*'Hypotheses'!D$17*U11 | V12: =$C12*'Hypotheses'!E$17*V11 | W12: =$C12*'Hypotheses'!F$17*W11 | X12: =$C12*'Hypotheses'!G$17*X11 | Y12: =$C12*'Hypotheses'!H$17*Y11 | Z12: =$C12*'Hypotheses'!I$17*Z11 | AA12: =$C12*'Hypotheses'!J$17*AA11 | ... AE12: =$C12*'Hypotheses'!N$17*AE11 | AF12: =$C12*'Hypotheses'!C$17*AF11 | AG12: =$C12*'Hypotheses'!D$17*AG11 | AH12: =$C12*'Hypotheses'!E$17*AH11 | AI12: =$C12*'Hypotheses'!F$17*AI11 | AJ12: =$C12*'Hypotheses'!G$17*AJ11 | AK12: =$C12*'Hypotheses'!H$17*AK11 | AL12: =$C12*'Hypotheses'!I$17*AL11 | AM12: =$C12*'Hypotheses'!J$17*AM11 | ... AQ12: =$C12*'Hypotheses'!N$17*AQ11
A13: Raw materials | B13: Salt - market price | C13: 55 | D13: kg | E13: =AVERAGE(H13:AQ13) | G13: INSEE BDM 010766282: Indice de prix de production de l'industrie française pour l'ensemble des marchés − CPF 08.93 − Sel et chlorure de sodium pur, eau de mer - Série arrêtée; normalized to model unit price | H13: 0.65 | I13: 0.652 | J13: 0.6514 | K13: 0.6657 | L13: 0.6657 | M13: 0.6657 | N13: 0.6869 | O13: 0.6855 | P13: 0.678 | Q13: 0.7039 | R13: 0.7312 | S13: 0.7565 | T13: 0.8794 | U13: 0.8152 | V13: 0.7408 | W13: 0.8186 | X13: 0.8193 | Y13: 0.8214 | Z13: 0.8439 | AA13: 0.8576 | AB13: 0.8733 | AC13: 0.8958 | AD13: 0.9436 | AE13: 0.9463 | AF13: 0.8733 | AG13: 0.8917 | AH13: 0.8917 | AI13: 0.906 | AJ13: 0.9026 | AK13: 0.876 | AL13: 0.8145 | AM13: 0.8234 | AN13: 0.8139 | AO13: 0.8043 | AP13: 0.8036 | AQ13: 0.8029
A14: Raw materials | B14: Cost (Salt) | C14: 55 | D14: kg | E14: =E13 | G14: Cost = quantity x seasonality x monthly market price | H14: =$C14*'Hypotheses'!C$17*H13 | I14: =$C14*'Hypotheses'!D$17*I13 | J14: =$C14*'Hypotheses'!E$17*J13 | K14: =$C14*'Hypotheses'!F$17*K13 | L14: =$C14*'Hypotheses'!G$17*L13 | M14: =$C14*'Hypotheses'!H$17*M13 | N14: =$C14*'Hypotheses'!I$17*N13 | O14: =$C14*'Hypotheses'!J$17*O13 | ... S14: =$C14*'Hypotheses'!N$17*S13 | T14: =$C14*'Hypotheses'!C$17*T13 | U14: =$C14*'Hypotheses'!D$17*U13 | V14: =$C14*'Hypotheses'!E$17*V13 | W14: =$C14*'Hypotheses'!F$17*W13 | X14: =$C14*'Hypotheses'!G$17*X13 | Y14: =$C14*'Hypotheses'!H$17*Y13 | Z14: =$C14*'Hypotheses'!I$17*Z13 | AA14: =$C14*'Hypotheses'!J$17*AA13 | ... AE14: =$C14*'Hypotheses'!N$17*AE13 | AF14: =$C14*'Hypotheses'!C$17*AF13 | AG14: =$C14*'Hypotheses'!D$17*AG13 | AH14: =$C14*'Hypotheses'!E$17*AH13 | AI14: =$C14*'Hypotheses'!F$17*AI13 | AJ14: =$C14*'Hypotheses'!G$17*AJ13 | AK14: =$C14*'Hypotheses'!H$17*AK13 | AL14: =$C14*'Hypotheses'!I$17*AL13 | AM14: =$C14*'Hypotheses'!J$17*AM13 | ... AQ14: =$C14*'Hypotheses'!N$17*AQ13
A15: Raw materials | B15: Eggs - market price | C15: 2200 | D15: unit | E15: =AVERAGE(H15:AQ15) | G15: INSEE BDM 010776696: Indice mensuel des prix agricoles à la production (IPPAP) - Oeufs; normalized to model unit price | H15: 0.25 | I15: 0.288 | J15: 0.322 | K15: 0.318 | L15: 0.3223 | M15: 0.3275 | N15: 0.2947 | O15: 0.3297 | P15: 0.3778 | Q15: 0.3857 | R15: 0.382 | S15: 0.4206 | T15: 0.4081 | U15: 0.4145 | V15: 0.4847 | W15: 0.5548 | X15: 0.5561 | Y15: 0.5389 | Z15: 0.5469 | AA15: 0.5784 | AB15: 0.6118 | AC15: 0.6526 | AD15: 0.6682 | AE15: 0.6777 | AF15: 0.6863 | AG15: 0.6973 | AH15: 0.7252 | AI15: 0.7289 | AJ15: 0.6949 | AK15: 0.598 | AL15: 0.4804 | AM15: 0.4268 | AN15: 0.4767 | AO15: 0.5254 | AP15: 0.5922 | AQ15: 0.6207
A16: Raw materials | B16: Cost (Eggs) | C16: 2200 | D16: unit | E16: =E15 | G16: Cost = quantity x seasonality x monthly market price | H16: =$C16*'Hypotheses'!C$17*H15 | I16: =$C16*'Hypotheses'!D$17*I15 | J16: =$C16*'Hypotheses'!E$17*J15 | K16: =$C16*'Hypotheses'!F$17*K15 | L16: =$C16*'Hypotheses'!G$17*L15 | M16: =$C16*'Hypotheses'!H$17*M15 | N16: =$C16*'Hypotheses'!I$17*N15 | O16: =$C16*'Hypotheses'!J$17*O15 | ... S16: =$C16*'Hypotheses'!N$17*S15 | T16: =$C16*'Hypotheses'!C$17*T15 | U16: =$C16*'Hypotheses'!D$17*U15 | V16: =$C16*'Hypotheses'!E$17*V15 | W16: =$C16*'Hypotheses'!F$17*W15 | X16: =$C16*'Hypotheses'!G$17*X15 | Y16: =$C16*'Hypotheses'!H$17*Y15 | Z16: =$C16*'Hypotheses'!I$17*Z15 | AA16: =$C16*'Hypotheses'!J$17*AA15 | ... AE16: =$C16*'Hypotheses'!N$17*AE15 | AF16: =$C16*'Hypotheses'!C$17*AF15 | AG16: =$C16*'Hypotheses'!D$17*AG15 | AH16: =$C16*'Hypotheses'!E$17*AH15 | AI16: =$C16*'Hypotheses'!F$17*AI15 | AJ16: =$C16*'Hypotheses'!G$17*AJ15 | AK16: =$C16*'Hypotheses'!H$17*AK15 | AL16: =$C16*'Hypotheses'!I$17*AL15 | AM16: =$C16*'Hypotheses'!J$17*AM15 | ... AQ16: =$C16*'Hypotheses'!N$17*AQ15
A17: Raw materials | B17: Cream - market price | C17: 160 | D17: L | E17: =AVERAGE(H17:AQ17) | F17: Fats | G17: INSEE BDM 010763691: Indice de prix de production de l'industrie française pour le marché français − CPF 10.51 − Crème de lait ; normalized to model unit price | H17: 3.6 | I17: 3.5893 | J17: 3.5893 | K17: 3.5857 | L17: 3.5785 | M17: 3.575 | N17: 3.5571 | O17: 3.5821 | P17: 3.5642 | Q17: 3.5785 | R17: 3.5928 | S17: 3.5535 | T17: 3.6322 | U17: 3.6215 | V17: 3.7467 | W17: 3.7646 | X17: 3.7789 | Y17: 3.8505 | Z17: 4.0187 | AA17: 4.1153 | AB17: 4.126 | AC17: 4.1869 | AD17: 4.2012 | AE17: 4.237 | AF17: 4.3264 | AG17: 4.4087 | AH17: 4.6091 | AI17: 4.7058 | AJ17: 4.7416 | AK17: 4.7129 | AL17: 4.6843 | AM17: 4.6592 | AN17: 4.6306 | AO17: 4.7093 | AP17: 4.6592 | AQ17: 4.6628
A18: Raw materials | B18: Cost (Cream) | C18: 160 | D18: L | E18: =E17 | F18: Fats | G18: Cost = quantity x seasonality x monthly market price | H18: =$C18*'Hypotheses'!C$17*H17 | I18: =$C18*'Hypotheses'!D$17*I17 | J18: =$C18*'Hypotheses'!E$17*J17 | K18: =$C18*'Hypotheses'!F$17*K17 | L18: =$C18*'Hypotheses'!G$17*L17 | M18: =$C18*'Hypotheses'!H$17*M17 | N18: =$C18*'Hypotheses'!I$17*N17 | O18: =$C18*'Hypotheses'!J$17*O17 | ... S18: =$C18*'Hypotheses'!N$17*S17 | T18: =$C18*'Hypotheses'!C$17*T17 | U18: =$C18*'Hypotheses'!D$17*U17 | V18: =$C18*'Hypotheses'!E$17*V17 | W18: =$C18*'Hypotheses'!F$17*W17 | X18: =$C18*'Hypotheses'!G$17*X17 | Y18: =$C18*'Hypotheses'!H$17*Y17 | Z18: =$C18*'Hypotheses'!I$17*Z17 | AA18: =$C18*'Hypotheses'!J$17*AA17 | ... AE18: =$C18*'Hypotheses'!N$17*AE17 | AF18: =$C18*'Hypotheses'!C$17*AF17 | AG18: =$C18*'Hypotheses'!D$17*AG17 | AH18: =$C18*'Hypotheses'!E$17*AH17 | AI18: =$C18*'Hypotheses'!F$17*AI17 | AJ18: =$C18*'Hypotheses'!G$17*AJ17 | AK18: =$C18*'Hypotheses'!H$17*AK17 | AL18: =$C18*'Hypotheses'!I$17*AL17 | AM18: =$C18*'Hypotheses'!J$17*AM17 | ... AQ18: =$C18*'Hypotheses'!N$17*AQ17
A19: Raw materials | B19: Packaging - market price | C19: 13000 | D19: unit | E19: =AVERAGE(H19:AQ19) | F19: Packaging | G19: INSEE BDM 010763805: Indice de prix de production de l'industrie française pour le marché français − CPF 17.21 − Papier et carton ondulés et emballages en papier ou en carton ; normalized to model unit price | H19: 0.06 | I19: 0.0605 | J19: 0.0603 | K19: 0.0612 | L19: 0.0616 | M19: 0.0621 | N19: 0.0633 | O19: 0.0639 | P19: 0.0657 | Q19: 0.0663 | R19: 0.0669 | S19: 0.0677 | T19: 0.0699 | U19: 0.0712 | V19: 0.0727 | W19: 0.0755 | X19: 0.0781 | Y19: 0.0798 | Z19: 0.0808 | AA19: 0.0813 | AB19: 0.0816 | AC19: 0.0827 | AD19: 0.0811 | AE19: 0.0809 | AF19: 0.0815 | AG19: 0.082 | AH19: 0.0801 | AI19: 0.0805 | AJ19: 0.079 | AK19: 0.0779 | AL19: 0.0768 | AM19: 0.0745 | AN19: 0.0739 | AO19: 0.0739 | AP19: 0.0732 | AQ19: 0.073
A20: Raw materials | B20: Cost (Packaging) | C20: 13000 | D20: unit | E20: =E19 | F20: Packaging | G20: Cost = quantity x seasonality x monthly market price | H20: =$C20*'Hypotheses'!C$17*H19 | I20: =$C20*'Hypotheses'!D$17*I19 | J20: =$C20*'Hypotheses'!E$17*J19 | K20: =$C20*'Hypotheses'!F$17*K19 | L20: =$C20*'Hypotheses'!G$17*L19 | M20: =$C20*'Hypotheses'!H$17*M19 | N20: =$C20*'Hypotheses'!I$17*N19 | O20: =$C20*'Hypotheses'!J$17*O19 | ... S20: =$C20*'Hypotheses'!N$17*S19 | T20: =$C20*'Hypotheses'!C$17*T19 | U20: =$C20*'Hypotheses'!D$17*U19 | V20: =$C20*'Hypotheses'!E$17*V19 | W20: =$C20*'Hypotheses'!F$17*W19 | X20: =$C20*'Hypotheses'!G$17*X19 | Y20: =$C20*'Hypotheses'!H$17*Y19 | Z20: =$C20*'Hypotheses'!I$17*Z19 | AA20: =$C20*'Hypotheses'!J$17*AA19 | ... AE20: =$C20*'Hypotheses'!N$17*AE19 | AF20: =$C20*'Hypotheses'!C$17*AF19 | AG20: =$C20*'Hypotheses'!D$17*AG19 | AH20: =$C20*'Hypotheses'!E$17*AH19 | AI20: =$C20*'Hypotheses'!F$17*AI19 | AJ20: =$C20*'Hypotheses'!G$17*AJ19 | AK20: =$C20*'Hypotheses'!H$17*AK19 | AL20: =$C20*'Hypotheses'!I$17*AL19 | AM20: =$C20*'Hypotheses'!J$17*AM19 | ... AQ20: =$C20*'Hypotheses'!N$17*AQ19
A21: SOUS-TOTAL Raw materials | H21: =SUM(H6,H8,H10,H12,H14,H16,H18,H20) | I21: =SUM(I6,I8,I10,I12,I14,I16,I18,I20) | J21: =SUM(J6,J8,J10,J12,J14,J16,J18,J20) | K21: =SUM(K6,K8,K10,K12,K14,K16,K18,K20) | L21: =SUM(L6,L8,L10,L12,L14,L16,L18,L20) | M21: =SUM(M6,M8,M10,M12,M14,M16,M18,M20) | N21: =SUM(N6,N8,N10,N12,N14,N16,N18,N20) | O21: =SUM(O6,O8,O10,O12,O14,O16,O18,O20) | ... AQ21: =SUM(AQ6,AQ8,AQ10,AQ12,AQ14,AQ16,AQ18,AQ20)
A22: Energy | B22: Electricity for ovens and refrigeration - market price | C22: 5800 | D22: kWh | E22: =AVERAGE(H22:AQ22) | F22: Electricity | G22: INSEE BDM 010777317: Indice mensuel des prix d'achat des moyens de production agricole (IPAMPA) - Electricité; normalized to model unit price | H22: 0.17 | I22: 0.1725 | J22: 0.1725 | K22: 0.1725 | L22: 0.1727 | M22: 0.1727 | N22: 0.1727 | O22: 0.1737 | P22: 0.1737 | Q22: 0.1742 | R22: 0.1754 | S22: 0.175 | T22: 0.1766 | U22: 0.1809 | V22: 0.1829 | W22: 0.1845 | X22: 0.1838 | Y22: 0.1858 | Z22: 0.187 | AA22: 0.1872 | AB22: 0.1922 | AC22: 0.1895 | AD22: 0.1927 | AE22: 0.1878 | AF22: 0.1821 | AG22: 0.1993 | AH22: 0.2031 | AI22: 0.2051 | AJ22: 0.2046 | AK22: 0.2045 | AL22: 0.2045 | AM22: 0.2208 | AN22: 0.2231 | AO22: 0.2245 | AP22: 0.2236 | AQ22: 0.2235
A23: Energy | B23: Cost (Electricity for ovens and refrigeration) | C23: 5800 | D23: kWh | E23: =E22 | F23: Electricity | G23: Cost = quantity x seasonality x monthly market price | H23: =$C23*'Hypotheses'!C$17*H22 | I23: =$C23*'Hypotheses'!D$17*I22 | J23: =$C23*'Hypotheses'!E$17*J22 | K23: =$C23*'Hypotheses'!F$17*K22 | L23: =$C23*'Hypotheses'!G$17*L22 | M23: =$C23*'Hypotheses'!H$17*M22 | N23: =$C23*'Hypotheses'!I$17*N22 | O23: =$C23*'Hypotheses'!J$17*O22 | ... S23: =$C23*'Hypotheses'!N$17*S22 | T23: =$C23*'Hypotheses'!C$17*T22 | U23: =$C23*'Hypotheses'!D$17*U22 | V23: =$C23*'Hypotheses'!E$17*V22 | W23: =$C23*'Hypotheses'!F$17*W22 | X23: =$C23*'Hypotheses'!G$17*X22 | Y23: =$C23*'Hypotheses'!H$17*Y22 | Z23: =$C23*'Hypotheses'!I$17*Z22 | AA23: =$C23*'Hypotheses'!J$17*AA22 | ... AE23: =$C23*'Hypotheses'!N$17*AE22 | AF23: =$C23*'Hypotheses'!C$17*AF22 | AG23: =$C23*'Hypotheses'!D$17*AG22 | AH23: =$C23*'Hypotheses'!E$17*AH22 | AI23: =$C23*'Hypotheses'!F$17*AI22 | AJ23: =$C23*'Hypotheses'!G$17*AJ22 | AK23: =$C23*'Hypotheses'!H$17*AK22 | AL23: =$C23*'Hypotheses'!I$17*AL22 | AM23: =$C23*'Hypotheses'!J$17*AM22 | ... AQ23: =$C23*'Hypotheses'!N$17*AQ22
A24: Energy | B24: Gas for heating - market price | C24: 2600 | D24: kWh | E24: =AVERAGE(H24:AQ24) | F24: Gas | G24: INSEE BDM 010767333: Gaz naturel TTF, contrats à terme à la première échéance aux Pays-Bas - ICE Futures Europe - Prix en euros par mégawattheure; normalized to model unit price | H24: 0.1 | I24: 0.0853 | J24: 0.0863 | K24: 0.1 | L24: 0.1225 | M24: 0.1431 | N24: 0.177 | O24: 0.2191 | P24: 0.3245 | Q24: 0.4475 | R24: 0.4049 | S24: 0.5627 | T24: 0.4176 | U24: 0.4015 | V24: 0.6436 | W24: 0.499 | X24: 0.4613 | Y24: 0.5309 | Z24: 0.8431 | AA24: 1.1569 | AB24: 0.9975 | AC24: 0.6642 | AD24: 0.5858 | AE24: 0.5696 | AF24: 0.3132 | AG24: 0.2578 | AH24: 0.2157 | AI24: 0.2064 | AJ24: 0.1554 | AK24: 0.1598 | AL24: 0.1446 | AM24: 0.1716 | AN24: 0.1809 | AO24: 0.2309 | AP24: 0.224 | AQ24: 0.1765
A25: Energy | B25: Cost (Gas for heating) | C25: 2600 | D25: kWh | E25: =E24 | F25: Gas | G25: Cost = quantity x seasonality x monthly market price | H25: =$C25*'Hypotheses'!C$17*H24 | I25: =$C25*'Hypotheses'!D$17*I24 | J25: =$C25*'Hypotheses'!E$17*J24 | K25: =$C25*'Hypotheses'!F$17*K24 | L25: =$C25*'Hypotheses'!G$17*L24 | M25: =$C25*'Hypotheses'!H$17*M24 | N25: =$C25*'Hypotheses'!I$17*N24 | O25: =$C25*'Hypotheses'!J$17*O24 | ... S25: =$C25*'Hypotheses'!N$17*S24 | T25: =$C25*'Hypotheses'!C$17*T24 | U25: =$C25*'Hypotheses'!D$17*U24 | V25: =$C25*'Hypotheses'!E$17*V24 | W25: =$C25*'Hypotheses'!F$17*W24 | X25: =$C25*'Hypotheses'!G$17*X24 | Y25: =$C25*'Hypotheses'!H$17*Y24 | Z25: =$C25*'Hypotheses'!I$17*Z24 | AA25: =$C25*'Hypotheses'!J$17*AA24 | ... AE25: =$C25*'Hypotheses'!N$17*AE24 | AF25: =$C25*'Hypotheses'!C$17*AF24 | AG25: =$C25*'Hypotheses'!D$17*AG24 | AH25: =$C25*'Hypotheses'!E$17*AH24 | AI25: =$C25*'Hypotheses'!F$17*AI24 | AJ25: =$C25*'Hypotheses'!G$17*AJ24 | AK25: =$C25*'Hypotheses'!H$17*AK24 | AL25: =$C25*'Hypotheses'!I$17*AL24 | AM25: =$C25*'Hypotheses'!J$17*AM24 | ... AQ25: =$C25*'Hypotheses'!N$17*AQ24
A26: SOUS-TOTAL Energy | H26: =SUM(H23,H25) | I26: =SUM(I23,I25) | J26: =SUM(J23,J25) | K26: =SUM(K23,K25) | L26: =SUM(L23,L25) | M26: =SUM(M23,M25) | N26: =SUM(N23,N25) | O26: =SUM(O23,O25) | ... AQ26: =SUM(AQ23,AQ25)
A27: Personnel | B27: Owner net compensation | C27: 1 | D27: monthly package | E27: 4200 | G27: Fixed owner draw assumption | H27: =$C27*1*$E27*(1+'Hypotheses'!$C$14)^0 | I27: =$C27*1*$E27*(1+'Hypotheses'!$C$14)^0 | J27: =$C27*1*$E27*(1+'Hypotheses'!$C$14)^0 | K27: =$C27*1*$E27*(1+'Hypotheses'!$C$14)^0 | L27: =$C27*1*$E27*(1+'Hypotheses'!$C$14)^0 | M27: =$C27*1*$E27*(1+'Hypotheses'!$C$14)^0 | N27: =$C27*1*$E27*(1+'Hypotheses'!$C$14)^0 | O27: =$C27*1*$E27*(1+'Hypotheses'!$C$14)^0 | ... S27: =$C27*1*$E27*(1+'Hypotheses'!$C$14)^0 | T27: =$C27*1*$E27*(1+'Hypotheses'!$C$14)^1 | U27: =$C27*1*$E27*(1+'Hypotheses'!$C$14)^1 | V27: =$C27*1*$E27*(1+'Hypotheses'!$C$14)^1 | W27: =$C27*1*$E27*(1+'Hypotheses'!$C$14)^1 | X27: =$C27*1*$E27*(1+'Hypotheses'!$C$14)^1 | Y27: =$C27*1*$E27*(1+'Hypotheses'!$C$14)^1 | Z27: =$C27*1*$E27*(1+'Hypotheses'!$C$14)^1 | AA27: =$C27*1*$E27*(1+'Hypotheses'!$C$14)^1 | ... AE27: =$C27*1*$E27*(1+'Hypotheses'!$C$14)^1 | AF27: =$C27*1*$E27*(1+'Hypotheses'!$C$14)^2 | AG27: =$C27*1*$E27*(1+'Hypotheses'!$C$14)^2 | AH27: =$C27*1*$E27*(1+'Hypotheses'!$C$14)^2 | AI27: =$C27*1*$E27*(1+'Hypotheses'!$C$14)^2 | AJ27: =$C27*1*$E27*(1+'Hypotheses'!$C$14)^2 | AK27: =$C27*1*$E27*(1+'Hypotheses'!$C$14)^2 | AL27: =$C27*1*$E27*(1+'Hypotheses'!$C$14)^2 | AM27: =$C27*1*$E27*(1+'Hypotheses'!$C$14)^2 | ... AQ27: =$C27*1*$E27*(1+'Hypotheses'!$C$14)^2
A28: Personnel | B28: Employee salary and charges - market price | C28: 1 | D28: monthly package | E28: =AVERAGE(H28:AQ28) | G28: INSEE BDM 010762009: Indice du coût du travail - Coût horaire - Hébergement, restauration (NAF rév. 2 section I) - Base 100 en 2020 ; normalized to model unit price | H28: 5600 | I28: 5600 | J28: 5600 | K28: 5600 | L28: 5600 | M28: 5600 | N28: 5600 | O28: 5600 | P28: 5600 | Q28: 5600 | R28: 5600 | S28: 5600 | T28: 5600 | U28: 5600 | V28: 5600 | W28: 5600 | X28: 5600 | Y28: 5600 | Z28: 5600 | AA28: 5600 | AB28: 5600 | AC28: 5600 | AD28: 5600 | AE28: 5600 | AF28: 5600 | AG28: 5600 | AH28: 5600 | AI28: 5600 | AJ28: 5600 | AK28: 5600 | AL28: 5600 | AM28: 5600 | AN28: 5600 | AO28: 5600 | AP28: 5600 | AQ28: 5600
A29: Personnel | B29: Cost (Employee salary and charges) | C29: 1 | D29: monthly package | E29: =E28 | G29: Cost = quantity x seasonality x monthly market price | H29: =$C29*H28 | I29: =$C29*I28 | J29: =$C29*J28 | K29: =$C29*K28 | L29: =$C29*L28 | M29: =$C29*M28 | N29: =$C29*N28 | O29: =$C29*O28 | ... AQ29: =$C29*AQ28
A30: SOUS-TOTAL Personnel | H30: =SUM(H27,H29) | I30: =SUM(I27,I29) | J30: =SUM(J27,J29) | K30: =SUM(K27,K29) | L30: =SUM(L27,L29) | M30: =SUM(M27,M29) | N30: =SUM(N27,N29) | O30: =SUM(O27,O29) | ... AQ30: =SUM(AQ27,AQ29)
A31: Fixed costs | B31: Commercial rent - market price | C31: 1 | D31: monthly package | E31: =AVERAGE(H31:AQ31) | G31: INSEE BDM 001532540: Indice des loyers commerciaux (ILC) - Base 100 au 1er trimestre 2008; normalized to model unit price | H31: 3200 | I31: 3200 | J31: 3200 | K31: 3200 | L31: 3200 | M31: 3200 | N31: 3200 | O31: 3200 | P31: 3200 | Q31: 3200 | R31: 3200 | S31: 3200 | T31: 3200 | U31: 3200 | V31: 3200 | W31: 3200 | X31: 3200 | Y31: 3200 | Z31: 3200 | AA31: 3200 | AB31: 3200 | AC31: 3200 | AD31: 3200 | AE31: 3200 | AF31: 3200 | AG31: 3200 | AH31: 3200 | AI31: 3200 | AJ31: 3200 | AK31: 3200 | AL31: 3200 | AM31: 3200 | AN31: 3200 | AO31: 3200 | AP31: 3200 | AQ31: 3200
A32: Fixed costs | B32: Cost (Commercial rent) | C32: 1 | D32: monthly package | E32: =E31 | G32: Cost = quantity x seasonality x monthly market price | H32: =$C32*H31 | I32: =$C32*I31 | J32: =$C32*J31 | K32: =$C32*K31 | L32: =$C32*L31 | M32: =$C32*M31 | N32: =$C32*N31 | O32: =$C32*O31 | ... AQ32: =$C32*AQ31
A33: Fixed costs | B33: Insurance | C33: 1 | D33: monthly package | E33: 250 | G33: Professional insurance estimate | H33: =$C33*1*$E33*(1+'Hypotheses'!$C$14)^0 | I33: =$C33*1*$E33*(1+'Hypotheses'!$C$14)^0 | J33: =$C33*1*$E33*(1+'Hypotheses'!$C$14)^0 | K33: =$C33*1*$E33*(1+'Hypotheses'!$C$14)^0 | L33: =$C33*1*$E33*(1+'Hypotheses'!$C$14)^0 | M33: =$C33*1*$E33*(1+'Hypotheses'!$C$14)^0 | N33: =$C33*1*$E33*(1+'Hypotheses'!$C$14)^0 | O33: =$C33*1*$E33*(1+'Hypotheses'!$C$14)^0 | ... S33: =$C33*1*$E33*(1+'Hypotheses'!$C$14)^0 | T33: =$C33*1*$E33*(1+'Hypotheses'!$C$14)^1 | U33: =$C33*1*$E33*(1+'Hypotheses'!$C$14)^1 | V33: =$C33*1*$E33*(1+'Hypotheses'!$C$14)^1 | W33: =$C33*1*$E33*(1+'Hypotheses'!$C$14)^1 | X33: =$C33*1*$E33*(1+'Hypotheses'!$C$14)^1 | Y33: =$C33*1*$E33*(1+'Hypotheses'!$C$14)^1 | Z33: =$C33*1*$E33*(1+'Hypotheses'!$C$14)^1 | AA33: =$C33*1*$E33*(1+'Hypotheses'!$C$14)^1 | ... AE33: =$C33*1*$E33*(1+'Hypotheses'!$C$14)^1 | AF33: =$C33*1*$E33*(1+'Hypotheses'!$C$14)^2 | AG33: =$C33*1*$E33*(1+'Hypotheses'!$C$14)^2 | AH33: =$C33*1*$E33*(1+'Hypotheses'!$C$14)^2 | AI33: =$C33*1*$E33*(1+'Hypotheses'!$C$14)^2 | AJ33: =$C33*1*$E33*(1+'Hypotheses'!$C$14)^2 | AK33: =$C33*1*$E33*(1+'Hypotheses'!$C$14)^2 | AL33: =$C33*1*$E33*(1+'Hypotheses'!$C$14)^2 | AM33: =$C33*1*$E33*(1+'Hypotheses'!$C$14)^2 | ... AQ33: =$C33*1*$E33*(1+'Hypotheses'!$C$14)^2
A34: Fixed costs | B34: Maintenance - market price | C34: 1 | D34: monthly package | E34: =AVERAGE(H34:AQ34) | G34: INSEE BDM 010777481: Indice mensuel des prix d'achat des moyens de production agricole (IPAMPA) - Entretien et réparation; normalized to model unit price | H34: 350 | I34: 350.3435 | J34: 351.7174 | K34: 350.6869 | L34: 351.3739 | M34: 352.4043 | N34: 353.7782 | O34: 353.7782 | P34: 354.4652 | Q34: 355.8391 | R34: 356.8695 | S34: 357.8999 | T34: 361.6781 | U34: 363.052 | V34: 365.1129 | W34: 367.5172 | X34: 369.9215 | Y34: 373.3562 | Z34: 376.4475 | AA34: 378.8518 | AB34: 380.5692 | AC34: 381.9431 | AD34: 383.317 | AE34: 384.6909 | AF34: 392.2473 | AG34: 396.0255 | AH34: 398.0864 | AI34: 400.1472 | AJ34: 401.1776 | AK34: 401.8646 | AL34: 402.895 | AM34: 403.9254 | AN34: 405.9863 | AO34: 408.0471 | AP34: 409.0775 | AQ34: 410.1079
A35: Fixed costs | B35: Cost (Maintenance) | C35: 1 | D35: monthly package | E35: =E34 | G35: Cost = quantity x seasonality x monthly market price | H35: =$C35*H34 | I35: =$C35*I34 | J35: =$C35*J34 | K35: =$C35*K34 | L35: =$C35*L34 | M35: =$C35*M34 | N35: =$C35*N34 | O35: =$C35*O34 | ... AQ35: =$C35*AQ34
A36: Fixed costs | B36: Accountant - market price | C36: 1 | D36: monthly package | E36: =AVERAGE(H36:AQ36) | G36: INSEE BDM 010766437: Indices des prix de production des services français aux entreprises françaises (BtoB) − CPF 69.20 − Services comptables, d'audits, et de conseil fiscal ; normalized to model unit price | H36: 500 | I36: 500 | J36: 500 | K36: 500 | L36: 500 | M36: 500 | N36: 500 | O36: 500 | P36: 500 | Q36: 500 | R36: 500 | S36: 500 | T36: 500 | U36: 500 | V36: 500 | W36: 500 | X36: 500 | Y36: 500 | Z36: 500 | AA36: 500 | AB36: 500 | AC36: 500 | AD36: 500 | AE36: 500 | AF36: 500 | AG36: 500 | AH36: 500 | AI36: 500 | AJ36: 500 | AK36: 500 | AL36: 500 | AM36: 500 | AN36: 500 | AO36: 500 | AP36: 500 | AQ36: 500
A37: Fixed costs | B37: Cost (Accountant) | C37: 1 | D37: monthly package | E37: =E36 | G37: Cost = quantity x seasonality x monthly market price | H37: =$C37*H36 | I37: =$C37*I36 | J37: =$C37*J36 | K37: =$C37*K36 | L37: =$C37*L36 | M37: =$C37*M36 | N37: =$C37*N36 | O37: =$C37*O36 | ... AQ37: =$C37*AQ36
A38: Fixed costs | B38: Water - market price | C38: 1 | D38: monthly package | E38: =AVERAGE(H38:AQ38) | G38: INSEE BDM 001634676: Prix moyens mensuels de vente au détail en métropole - Distribution de 120 m3 d'eau (abonnement inclus TTC), y.c. organismes publics (préservation des ressources, pollution et taxe VNF); normalized to model unit price | H38: 150 | I38: 150.1463 | J38: 150.286 | K38: 150.5787 | L38: 150.7316 | M38: 150.9777 | N38: 150.9844 | O38: 151.0908 | P38: 151.2172 | Q38: 151.1906 | R38: 151.4234 | S38: 151.4234 | T38: 151.9488 | U38: 152.6073 | V38: 152.9931 | W38: 153.2458 | X38: 153.186 | Y38: 153.2126 | Z38: 153.1926 | AA38: 153.585 | AB38: 153.6449 | AC38: 153.6582 | AD38: 153.8112 | AE38: 153.8112 | AF38: 154.6626 | AG38: 156.3719 | AH38: 157.7222 | AI38: 158.9726 | AJ38: 159.0724 | AK38: 159.3185 | AL38: 159.6045 | AM38: 159.8173 | AN38: 160.1033 | AO38: 160.1831 | AP38: 160.2563 | AQ38: 160.3162
A39: Fixed costs | B39: Cost (Water) | C39: 1 | D39: monthly package | E39: =E38 | G39: Cost = quantity x seasonality x monthly market price | H39: =$C39*H38 | I39: =$C39*I38 | J39: =$C39*J38 | K39: =$C39*K38 | L39: =$C39*L38 | M39: =$C39*M38 | N39: =$C39*N38 | O39: =$C39*O38 | ... AQ39: =$C39*AQ38
A40: Fixed costs | B40: Bank fees and payment terminal | C40: 1 | D40: monthly package | E40: 150 | G40: Bank tariff estimate | H40: =$C40*1*$E40*(1+'Hypotheses'!$C$14)^0 | I40: =$C40*1*$E40*(1+'Hypotheses'!$C$14)^0 | J40: =$C40*1*$E40*(1+'Hypotheses'!$C$14)^0 | K40: =$C40*1*$E40*(1+'Hypotheses'!$C$14)^0 | L40: =$C40*1*$E40*(1+'Hypotheses'!$C$14)^0 | M40: =$C40*1*$E40*(1+'Hypotheses'!$C$14)^0 | N40: =$C40*1*$E40*(1+'Hypotheses'!$C$14)^0 | O40: =$C40*1*$E40*(1+'Hypotheses'!$C$14)^0 | ... S40: =$C40*1*$E40*(1+'Hypotheses'!$C$14)^0 | T40: =$C40*1*$E40*(1+'Hypotheses'!$C$14)^1 | U40: =$C40*1*$E40*(1+'Hypotheses'!$C$14)^1 | V40: =$C40*1*$E40*(1+'Hypotheses'!$C$14)^1 | W40: =$C40*1*$E40*(1+'Hypotheses'!$C$14)^1 | X40: =$C40*1*$E40*(1+'Hypotheses'!$C$14)^1 | Y40: =$C40*1*$E40*(1+'Hypotheses'!$C$14)^1 | Z40: =$C40*1*$E40*(1+'Hypotheses'!$C$14)^1 | AA40: =$C40*1*$E40*(1+'Hypotheses'!$C$14)^1 | ... AE40: =$C40*1*$E40*(1+'Hypotheses'!$C$14)^1 | AF40: =$C40*1*$E40*(1+'Hypotheses'!$C$14)^2 | AG40: =$C40*1*$E40*(1+'Hypotheses'!$C$14)^2 | AH40: =$C40*1*$E40*(1+'Hypotheses'!$C$14)^2 | AI40: =$C40*1*$E40*(1+'Hypotheses'!$C$14)^2 | AJ40: =$C40*1*$E40*(1+'Hypotheses'!$C$14)^2 | AK40: =$C40*1*$E40*(1+'Hypotheses'!$C$14)^2 | AL40: =$C40*1*$E40*(1+'Hypotheses'!$C$14)^2 | AM40: =$C40*1*$E40*(1+'Hypotheses'!$C$14)^2 | ... AQ40: =$C40*1*$E40*(1+'Hypotheses'!$C$14)^2
...

Sheet Plan de tresorerie
A1: Boulangerie Artisanale - Plan de tresorerie mensuel
A2: Opening cash + collections - disbursements = ending cash.
C3: ANNEE 1 | O3: ANNEE 2 | AA3: ANNEE 3
A4: Mois | C4: Jan A1 | D4: Feb A1 | E4: Mar A1 | F4: Apr A1 | G4: May A1 | H4: Jun A1 | I4: Jul A1 | J4: Aug A1 | K4: Sep A1 | L4: Oct A1 | M4: Nov A1 | N4: Dec A1 | O4: Jan A2 | P4: Feb A2 | Q4: Mar A2 | R4: Apr A2 | S4: May A2 | T4: Jun A2 | U4: Jul A2 | V4: Aug A2 | W4: Sep A2 | X4: Oct A2 | Y4: Nov A2 | Z4: Dec A2 | AA4: Jan A3 | AB4: Feb A3 | AC4: Mar A3 | AD4: Apr A3 | AE4: May A3 | AF4: Jun A3 | AG4: Jul A3 | AH4: Aug A3 | AI4: Sep A3 | AJ4: Oct A3 | AK4: Nov A3 | AL4: Dec A3
A5: Tresorerie en debut de mois | C5: ='Hypotheses'!$C$7 | D5: =C18 | E5: =D18 | F5: =E18 | G5: =F18 | H5: =G18 | I5: =H18 | J5: =I18 | K5: =J18 | ... AL5: =AK18
A6: ENCAISSEMENTS
A7: Encaissements clients TTC | C7: ='Revenus'!C13*'Hypotheses'!$C$10+0+0 | D7: ='Revenus'!D13*'Hypotheses'!$C$10+'Revenus'!C13*'Hypotheses'!$C$11+0 | E7: ='Revenus'!E13*'Hypotheses'!$C$10+'Revenus'!D13*'Hypotheses'!$C$11+'Revenus'!C13*'Hypotheses'!$C$12 | F7: ='Revenus'!F13*'Hypotheses'!$C$10+'Revenus'!E13*'Hypotheses'!$C$11+'Revenus'!D13*'Hypotheses'!$C$12 | G7: ='Revenus'!G13*'Hypotheses'!$C$10+'Revenus'!F13*'Hypotheses'!$C$11+'Revenus'!E13*'Hypotheses'!$C$12 | H7: ='Revenus'!H13*'Hypotheses'!$C$10+'Revenus'!G13*'Hypotheses'!$C$11+'Revenus'!F13*'Hypotheses'!$C$12 | I7: ='Revenus'!I13*'Hypotheses'!$C$10+'Revenus'!H13*'Hypotheses'!$C$11+'Revenus'!G13*'Hypotheses'!$C$12 | J7: ='Revenus'!J13*'Hypotheses'!$C$10+'Revenus'!I13*'Hypotheses'!$C$11+'Revenus'!H13*'Hypotheses'!$C$12 | K7: ='Revenus'!K13*'Hypotheses'!$C$10+'Revenus'!J13*'Hypotheses'!$C$11+'Revenus'!I13*'Hypotheses'!$C$12 | L7: ='Revenus'!L13*'Hypotheses'!$C$10+'Revenus'!K13*'Hypotheses'!$C$11+'Revenus'!J13*'Hypotheses'!$C$12 | ... AL7: ='Revenus'!AL13*'Hypotheses'!$C$10+'Revenus'!AK13*'Hypotheses'!$C$11+'Revenus'!AJ13*'Hypotheses'!$C$12
A8: TOTAL ENCAISSEMENTS | C8: =C7 | D8: =D7 | E8: =E7 | F8: =F7 | G8: =G7 | H8: =H7 | I8: =I7 | J8: =J7 | ... AL8: =AL7
A9: DECAISSEMENTS
A10: Achats variables et commodity-linked | C10: =SUM('Depenses detaillees'!H21,'Depenses detaillees'!H26) | D10: =SUM('Depenses detaillees'!I21,'Depenses detaillees'!I26) | E10: =SUM('Depenses detaillees'!J21,'Depenses detaillees'!J26) | F10: =SUM('Depenses detaillees'!K21,'Depenses detaillees'!K26) | G10: =SUM('Depenses detaillees'!L21,'Depenses detaillees'!L26) | H10: =SUM('Depenses detaillees'!M21,'Depenses detaillees'!M26) | I10: =SUM('Depenses detaillees'!N21,'Depenses detaillees'!N26) | J10: =SUM('Depenses detaillees'!O21,'Depenses detaillees'!O26) | ... AL10: =SUM('Depenses detaillees'!AQ21,'Depenses detaillees'!AQ26)
A11: Personnel | C11: =SUM('Depenses detaillees'!H30) | D11: =SUM('Depenses detaillees'!I30) | E11: =SUM('Depenses detaillees'!J30) | F11: =SUM('Depenses detaillees'!K30) | G11: =SUM('Depenses detaillees'!L30) | H11: =SUM('Depenses detaillees'!M30) | I11: =SUM('Depenses detaillees'!N30) | J11: =SUM('Depenses detaillees'!O30) | ... AL11: =SUM('Depenses detaillees'!AQ30)
A12: Charges fixes et maintenance | C12: =SUM('Depenses detaillees'!H41) | D12: =SUM('Depenses detaillees'!I41) | E12: =SUM('Depenses detaillees'!J41) | F12: =SUM('Depenses detaillees'!K41) | G12: =SUM('Depenses detaillees'!L41) | H12: =SUM('Depenses detaillees'!M41) | I12: =SUM('Depenses detaillees'!N41) | J12: =SUM('Depenses detaillees'!O41) | ... AL12: =SUM('Depenses detaillees'!AQ41)
A13: Cotisations sociales dirigeant | C13: 0 | D13: 0 | E13: ='Hypotheses'!$C$8*(1+'Hypotheses'!$C$14)^0 | F13: 0 | G13: 0 | H13: ='Hypotheses'!$C$8*(1+'Hypotheses'!$C$14)^0 | I13: 0 | J13: 0 | K13: ='Hypotheses'!$C$8*(1+'Hypotheses'!$C$14)^0 | L13: 0 | M13: 0 | N13: ='Hypotheses'!$C$8*(1+'Hypotheses'!$C$14)^0 | O13: 0 | P13: 0 | Q13: ='Hypotheses'!$C$8*(1+'Hypotheses'!$C$14)^1 | R13: 0 | S13: 0 | T13: ='Hypotheses'!$C$8*(1+'Hypotheses'!$C$14)^1 | U13: 0 | V13: 0 | W13: ='Hypotheses'!$C$8*(1+'Hypotheses'!$C$14)^1 | X13: 0 | Y13: 0 | Z13: ='Hypotheses'!$C$8*(1+'Hypotheses'!$C$14)^1 | AA13: 0 | AB13: 0 | AC13: ='Hypotheses'!$C$8*(1+'Hypotheses'!$C$14)^2 | AD13: 0 | AE13: 0 | AF13: ='Hypotheses'!$C$8*(1+'Hypotheses'!$C$14)^2 | AG13: 0 | AH13: 0 | AI13: ='Hypotheses'!$C$8*(1+'Hypotheses'!$C$14)^2 | AJ13: 0 | AK13: 0 | AL13: ='Hypotheses'!$C$8*(1+'Hypotheses'!$C$14)^2
A14: TVA nette versee | C14: 0 | D14: 0 | E14: =MAX(0,SUM(C22:E22)) | F14: 0 | G14: 0 | H14: =MAX(0,SUM(F22:H22)) | I14: 0 | J14: 0 | K14: =MAX(0,SUM(I22:K22)) | L14: 0 | M14: 0 | N14: =MAX(0,SUM(L22:N22)) | O14: 0 | P14: 0 | Q14: =MAX(0,SUM(O22:Q22)) | R14: 0 | S14: 0 | T14: =MAX(0,SUM(R22:T22)) | U14: 0 | V14: 0 | W14: =MAX(0,SUM(U22:W22)) | X14: 0 | Y14: 0 | Z14: =MAX(0,SUM(X22:Z22)) | AA14: 0 | AB14: 0 | AC14: =MAX(0,SUM(AA22:AC22)) | AD14: 0 | AE14: 0 | AF14: =MAX(0,SUM(AD22:AF22)) | AG14: 0 | AH14: 0 | AI14: =MAX(0,SUM(AG22:AI22)) | AJ14: 0 | AK14: 0 | AL14: =MAX(0,SUM(AJ22:AL22))
A15: Remboursement emprunt materiel | C15: ='Hypotheses'!$C$9 | D15: ='Hypotheses'!$C$9 | E15: ='Hypotheses'!$C$9 | F15: ='Hypotheses'!$C$9 | G15: ='Hypotheses'!$C$9 | H15: ='Hypotheses'!$C$9 | I15: ='Hypotheses'!$C$9 | J15: ='Hypotheses'!$C$9 | ... AL15: ='Hypotheses'!$C$9
A16: TOTAL DECAISSEMENTS | C16: =SUM(C10:C15) | D16: =SUM(D10:D15) | E16: =SUM(E10:E15) | F16: =SUM(F10:F15) | G16: =SUM(G10:G15) | H16: =SUM(H10:H15) | I16: =SUM(I10:I15) | J16: =SUM(J10:J15) | ... AL16: =SUM(AL10:AL15)
A17: Variation de tresorerie du mois | C17: =C8-C16 | D17: =D8-D16 | E17: =E8-E16 | F17: =F8-F16 | G17: =G8-G16 | H17: =H8-H16 | I17: =I8-I16 | J17: =J8-J16 | ... AL17: =AL8-AL16
A18: TRESORERIE EN FIN DE MOIS | C18: =C5+C17 | D18: =D5+D17 | E18: =E5+E17 | F18: =F5+F17 | G18: =G5+G17 | H18: =H5+H17 | I18: =I5+I17 | J18: =J5+J17 | ... AL18: =AL5+AL17
A20: Memo - TVA collectee du mois | C20: ='Revenus'!C12 | D20: ='Revenus'!D12 | E20: ='Revenus'!E12 | F20: ='Revenus'!F12 | G20: ='Revenus'!G12 | H20: ='Revenus'!H12 | I20: ='Revenus'!I12 | J20: ='Revenus'!J12 | ... AL20: ='Revenus'!AL12
A21: Memo - TVA deductible du mois | C21: =(C10+C12)*'Hypotheses'!$C$6 | D21: =(D10+D12)*'Hypotheses'!$C$6 | E21: =(E10+E12)*'Hypotheses'!$C$6 | F21: =(F10+F12)*'Hypotheses'!$C$6 | G21: =(G10+G12)*'Hypotheses'!$C$6 | H21: =(H10+H12)*'Hypotheses'!$C$6 | I21: =(I10+I12)*'Hypotheses'!$C$6 | J21: =(J10+J12)*'Hypotheses'!$C$6 | ... AL21: =(AL10+AL12)*'Hypotheses'!$C$6
A22: Memo - TVA nette du mois | C22: =C20-C21 | D22: =D20-D21 | E22: =E20-E21 | F22: =F20-F21 | G22: =G20-G21 | H22: =H20-H21 | I22: =I20-I21 | J22: =J20-J21 | ... AL22: =AL20-AL21
A24: Minimum cash over period | C24: =MIN(C18:AL18)

Sheet Market data
A1: Market data used by model
A2: External series are normalized to each model unit price to preserve realistic movement without unit mismatch.
A4: Cost line | B4: Underlying | C4: Market code | D4: Source | E4: Model unit | F4: Model unit price | G4: Month | H4: Value
A5: Accountant | C5: ACCOUNTING_SERVICES | D5: INSEE BDM 010766437: Indices des prix de production des services français aux entreprises françaises (BtoB) − CPF 69.20 − Services comptables, d'audits, et de conseil fiscal | E5: monthly package | F5: 500 | G5: 2021-01 | H5: 500
A6: Accountant | C6: ACCOUNTING_SERVICES | D6: INSEE BDM 010766437: Indices des prix de production des services français aux entreprises françaises (BtoB) − CPF 69.20 − Services comptables, d'audits, et de conseil fiscal | E6: monthly package | F6: 500 | G6: 2021-02 | H6: 500
A7: Accountant | C7: ACCOUNTING_SERVICES | D7: INSEE BDM 010766437: Indices des prix de production des services français aux entreprises françaises (BtoB) − CPF 69.20 − Services comptables, d'audits, et de conseil fiscal | E7: monthly package | F7: 500 | G7: 2021-03 | H7: 500
A8: Accountant | C8: ACCOUNTING_SERVICES | D8: INSEE BDM 010766437: Indices des prix de production des services français aux entreprises françaises (BtoB) − CPF 69.20 − Services comptables, d'audits, et de conseil fiscal | E8: monthly package | F8: 500 | G8: 2021-04 | H8: 500
A9: Accountant | C9: ACCOUNTING_SERVICES | D9: INSEE BDM 010766437: Indices des prix de production des services français aux entreprises françaises (BtoB) − CPF 69.20 − Services comptables, d'audits, et de conseil fiscal | E9: monthly package | F9: 500 | G9: 2021-05 | H9: 500
A10: Accountant | C10: ACCOUNTING_SERVICES | D10: INSEE BDM 010766437: Indices des prix de production des services français aux entreprises françaises (BtoB) − CPF 69.20 − Services comptables, d'audits, et de conseil fiscal | E10: monthly package | F10: 500 | G10: 2021-06 | H10: 500
A11: Accountant | C11: ACCOUNTING_SERVICES | D11: INSEE BDM 010766437: Indices des prix de production des services français aux entreprises françaises (BtoB) − CPF 69.20 − Services comptables, d'audits, et de conseil fiscal | E11: monthly package | F11: 500 | G11: 2021-07 | H11: 500
A12: Accountant | C12: ACCOUNTING_SERVICES | D12: INSEE BDM 010766437: Indices des prix de production des services français aux entreprises françaises (BtoB) − CPF 69.20 − Services comptables, d'audits, et de conseil fiscal | E12: monthly package | F12: 500 | G12: 2021-08 | H12: 500
A13: Accountant | C13: ACCOUNTING_SERVICES | D13: INSEE BDM 010766437: Indices des prix de production des services français aux entreprises françaises (BtoB) − CPF 69.20 − Services comptables, d'audits, et de conseil fiscal | E13: monthly package | F13: 500 | G13: 2021-09 | H13: 500
A14: Accountant | C14: ACCOUNTING_SERVICES | D14: INSEE BDM 010766437: Indices des prix de production des services français aux entreprises françaises (BtoB) − CPF 69.20 − Services comptables, d'audits, et de conseil fiscal | E14: monthly package | F14: 500 | G14: 2021-10 | H14: 500
A15: Accountant | C15: ACCOUNTING_SERVICES | D15: INSEE BDM 010766437: Indices des prix de production des services français aux entreprises françaises (BtoB) − CPF 69.20 − Services comptables, d'audits, et de conseil fiscal | E15: monthly package | F15: 500 | G15: 2021-11 | H15: 500
A16: Accountant | C16: ACCOUNTING_SERVICES | D16: INSEE BDM 010766437: Indices des prix de production des services français aux entreprises françaises (BtoB) − CPF 69.20 − Services comptables, d'audits, et de conseil fiscal | E16: monthly package | F16: 500 | G16: 2021-12 | H16: 500
... A40: Accountant | C40: ACCOUNTING_SERVICES | D40: INSEE BDM 010766437: Indices des prix de production des services français aux entreprises françaises (BtoB) − CPF 69.20 − Services comptables, d'audits, et de conseil fiscal | E40: monthly package | F40: 500 | G40: 2023-12 | H40: 500
A41: Incorporation butter | B41: Fats | C41: BUTTER | D41: INSEE BDM 010763694: Indice de prix de production de l'industrie française pour le marché français − CPF 10.51 − Beurre conditionné | E41: kg | F41: 5.1 | G41: 2021-01 | H41: 5.1
A42: Incorporation butter | B42: Fats | C42: BUTTER | D42: INSEE BDM 010763694: Indice de prix de production de l'industrie française pour le marché français − CPF 10.51 − Beurre conditionné | E42: kg | F42: 5.1 | G42: 2021-02 | H42: 5.1364
A43: Incorporation butter | B43: Fats | C43: BUTTER | D43: INSEE BDM 010763694: Indice de prix de production de l'industrie française pour le marché français − CPF 10.51 − Beurre conditionné | E43: kg | F43: 5.1 | G43: 2021-03 | H43: 5.1364
A44: Incorporation butter | B44: Fats | C44: BUTTER | D44: INSEE BDM 010763694: Indice de prix de production de l'industrie française pour le marché français − CPF 10.51 − Beurre conditionné | E44: kg | F44: 5.1 | G44: 2021-04 | H44: 5.204
A45: Incorporation butter | B45: Fats | C45: BUTTER | D45: INSEE BDM 010763694: Indice de prix de production de l'industrie française pour le marché français − CPF 10.51 − Beurre conditionné | E45: kg | F45: 5.1 | G45: 2021-05 | H45: 5.1988
A46: Incorporation butter | B46: Fats | C46: BUTTER | D46: INSEE BDM 010763694: Indice de prix de production de l'industrie française pour le marché français − CPF 10.51 − Beurre conditionné | E46: kg | F46: 5.1 | G46: 2021-06 | H46: 5.1572
A47: Incorporation butter | B47: Fats | C47: BUTTER | D47: INSEE BDM 010763694: Indice de prix de production de l'industrie française pour le marché français − CPF 10.51 − Beurre conditionné | E47: kg | F47: 5.1 | G47: 2021-07 | H47: 5.2196
A48: Incorporation butter | B48: Fats | C48: BUTTER | D48: INSEE BDM 010763694: Indice de prix de production de l'industrie française pour le marché français − CPF 10.51 − Beurre conditionné | E48: kg | F48: 5.1 | G48: 2021-08 | H48: 5.1936
A49: Incorporation butter | B49: Fats | C49: BUTTER | D49: INSEE BDM 010763694: Indice de prix de production de l'industrie française pour le marché français − CPF 10.51 − Beurre conditionné | E49: kg | F49: 5.1 | G49: 2021-09 | H49: 5.178
A50: Incorporation butter | B50: Fats | C50: BUTTER | D50: INSEE BDM 010763694: Indice de prix de production de l'industrie française pour le marché français − CPF 10.51 − Beurre conditionné | E50: kg | F50: 5.1 | G50: 2021-10 | H50: 5.2248
A51: Incorporation butter | B51: Fats | C51: BUTTER | D51: INSEE BDM 010763694: Indice de prix de production de l'industrie française pour le marché français − CPF 10.51 − Beurre conditionné | E51: kg | F51: 5.1 | G51: 2021-11 | H51: 5.256
A52: Incorporation butter | B52: Fats | C52: BUTTER | D52: INSEE BDM 010763694: Indice de prix de production de l'industrie française pour le marché français − CPF 10.51 − Beurre conditionné | E52: kg | F52: 5.1 | G52: 2021-12 | H52: 5.3807
... A148: Cream | B148: Fats | C148: CREAM | D148: INSEE BDM 010763691: Indice de prix de production de l'industrie française pour le marché français − CPF 10.51 − Crème de lait | E148: L | F148: 3.6 | G148: 2023-12 | H148: 4.6628
A149: Eggs | C149: EGGS | D149: INSEE BDM 010776696: Indice mensuel des prix agricoles à la production (IPPAP) - Oeufs | E149: unit | F149: 0.25 | G149: 2021-01 | H149: 0.25
A150: Eggs | C150: EGGS | D150: INSEE BDM 010776696: Indice mensuel des prix agricoles à la production (IPPAP) - Oeufs | E150: unit | F150: 0.25 | G150: 2021-02 | H150: 0.288
A151: Eggs | C151: EGGS | D151: INSEE BDM 010776696: Indice mensuel des prix agricoles à la production (IPPAP) - Oeufs | E151: unit | F151: 0.25 | G151: 2021-03 | H151: 0.322
A152: Eggs | C152: EGGS | D152: INSEE BDM 010776696: Indice mensuel des prix agricoles à la production (IPPAP) - Oeufs | E152: unit | F152: 0.25 | G152: 2021-04 | H152: 0.318
A153: Eggs | C153: EGGS | D153: INSEE BDM 010776696: Indice mensuel des prix agricoles à la production (IPPAP) - Oeufs | E153: unit | F153: 0.25 | G153: 2021-05 | H153: 0.3223
A154: Eggs | C154: EGGS | D154: INSEE BDM 010776696: Indice mensuel des prix agricoles à la production (IPPAP) - Oeufs | E154: unit | F154: 0.25 | G154: 2021-06 | H154: 0.3275
A155: Eggs | C155: EGGS | D155: INSEE BDM 010776696: Indice mensuel des prix agricoles à la production (IPPAP) - Oeufs | E155: unit | F155: 0.25 | G155: 2021-07 | H155: 0.2947
A156: Eggs | C156: EGGS | D156: INSEE BDM 010776696: Indice mensuel des prix agricoles à la production (IPPAP) - Oeufs | E156: unit | F156: 0.25 | G156: 2021-08 | H156: 0.3297
A157: Eggs | C157: EGGS | D157: INSEE BDM 010776696: Indice mensuel des prix agricoles à la production (IPPAP) - Oeufs | E157: unit | F157: 0.25 | G157: 2021-09 | H157: 0.3778
A158: Eggs | C158: EGGS | D158: INSEE BDM 010776696: Indice mensuel des prix agricoles à la production (IPPAP) - Oeufs | E158: unit | F158: 0.25 | G158: 2021-10 | H158: 0.3857
A159: Eggs | C159: EGGS | D159: INSEE BDM 010776696: Indice mensuel des prix agricoles à la production (IPPAP) - Oeufs | E159: unit | F159: 0.25 | G159: 2021-11 | H159: 0.382
...

Sheet Benchmarks & sources
A1: Boulangerie Artisanale - Benchmarks & sources
A2: Ratios and API sources used to construct the synthetic cash-plan model.
A4: Item | B4: Value retained | C4: Source | D4: Comment
A5: Annual revenue A1 | B5: 310000 | C5: Generated profile | D5: Editable in Hypotheses
A6: Archetype | B6: bakery | C6: Local inference | D6: Selected from business description keywords
A7: Commodity API mode | B7: online | C7: Generator flag | D7: Offline mode uses deterministic synthetic series
