Workbook

Sheet Hypotheses
A1: Restaurant - Hypotheses
A2: Metier: Independent restaurant. | Archetype: restaurant | CA cible A1: 520,000 EUR | Blue cells are editable
A4: Chiffre d'affaires annuel HT - Annee 1 (EUR) | C4: 520000
A5: Taux de TVA moyen sur les ventes | C5: 0.1
A6: Taux de TVA moyen sur les achats | C6: 0.12
A7: Tresorerie disponible au 1er janvier A1 (EUR) | C7: 24000
A8: Cotisations sociales dirigeant - par trimestre A1 (EUR) | C8: 4400
A9: Remboursement emprunt materiel - mensualite fixe (EUR) | C9: 1200
A10: Part du CA encaissee le mois meme | C10: 1
A11: Part du CA encaissee a M-1 | C11: 0
A12: Part du CA encaissee a M-2 | C12: 0 | D12: Control should equal 100% | E12: =SUM(C10:C12)
A13: Taux de croissance du CA - par an | C13: 0.025
A14: Taux d'inflation des prix d'achat - par an | C14: 0.035
A16: Month pattern repeated every year | C16: Jan | D16: Feb | E16: Mar | F16: Apr | G16: May | H16: Jun | I16: Jul | J16: Aug | K16: Sep | L16: Oct | M16: Nov | N16: Dec
A17: Seasonality index (1 = average month) | C17: 0.9 | D17: 0.92 | E17: 0.98 | F17: 1.02 | G17: 1.05 | H17: 1.08 | I17: 1.12 | J17: 0.82 | K17: 1 | L17: 1.04 | M17: 1.06 | N17: 1.01
A18: Month weight in year (normalized) | C18: =C17/SUM($C$17:$N$17) | D18: =D17/SUM($C$17:$N$17) | E18: =E17/SUM($C$17:$N$17) | F18: =F17/SUM($C$17:$N$17) | G18: =G17/SUM($C$17:$N$17) | H18: =H17/SUM($C$17:$N$17) | I18: =I17/SUM($C$17:$N$17) | J18: =J17/SUM($C$17:$N$17) | ... N18: =N17/SUM($C$17:$N$17)
A21: v1 note: ratios and quantities are synthetic benchmark assumptions unless a source/API is explicitly listed.
A22: Commodity-linked rows preserve realistic monthly variation. External series are normalized to the model unit price.
A23: INSEE support is intentionally configurable by URL/series because exact indicators depend on the sector and use case.
A25: Legend
A26: Blue | B26: Editable assumption
A27: Gray | B27: Formula calculated automatically
A28: Light blue | B28: Link to another sheet
A29: Yellow | B29: Source/API note

Sheet Revenus
A1: Restaurant - Revenus mensuels
A2: Revenue streams x annual mix x seasonality x annual growth.
C3: ANNEE 1 | O3: ANNEE 2 | AA3: ANNEE 3
A4: Source de revenus | B4: % du CA annuel | C4: Jan A1 | D4: Feb A1 | E4: Mar A1 | F4: Apr A1 | G4: May A1 | H4: Jun A1 | I4: Jul A1 | J4: Aug A1 | K4: Sep A1 | L4: Oct A1 | M4: Nov A1 | N4: Dec A1 | O4: Jan A2 | P4: Feb A2 | Q4: Mar A2 | R4: Apr A2 | S4: May A2 | T4: Jun A2 | U4: Jul A2 | V4: Aug A2 | W4: Sep A2 | X4: Oct A2 | Y4: Nov A2 | Z4: Dec A2 | AA4: Jan A3 | AB4: Feb A3 | AC4: Mar A3 | AD4: Apr A3 | AE4: May A3 | AF4: Jun A3 | AG4: Jul A3 | AH4: Aug A3 | AI4: Sep A3 | AJ4: Oct A3 | AK4: Nov A3 | AL4: Dec A3
A5: Lunch service | B5: 0.38 | C5: ='Hypotheses'!$C$4*$B5*'Hypotheses'!C$18*(1+'Hypotheses'!$C$13)^0 | D5: ='Hypotheses'!$C$4*$B5*'Hypotheses'!D$18*(1+'Hypotheses'!$C$13)^0 | E5: ='Hypotheses'!$C$4*$B5*'Hypotheses'!E$18*(1+'Hypotheses'!$C$13)^0 | F5: ='Hypotheses'!$C$4*$B5*'Hypotheses'!F$18*(1+'Hypotheses'!$C$13)^0 | G5: ='Hypotheses'!$C$4*$B5*'Hypotheses'!G$18*(1+'Hypotheses'!$C$13)^0 | H5: ='Hypotheses'!$C$4*$B5*'Hypotheses'!H$18*(1+'Hypotheses'!$C$13)^0 | I5: ='Hypotheses'!$C$4*$B5*'Hypotheses'!I$18*(1+'Hypotheses'!$C$13)^0 | J5: ='Hypotheses'!$C$4*$B5*'Hypotheses'!J$18*(1+'Hypotheses'!$C$13)^0 | ... N5: ='Hypotheses'!$C$4*$B5*'Hypotheses'!N$18*(1+'Hypotheses'!$C$13)^0 | O5: ='Hypotheses'!$C$4*$B5*'Hypotheses'!C$18*(1+'Hypotheses'!$C$13)^1 | P5: ='Hypotheses'!$C$4*$B5*'Hypotheses'!D$18*(1+'Hypotheses'!$C$13)^1 | Q5: ='Hypotheses'!$C$4*$B5*'Hypotheses'!E$18*(1+'Hypotheses'!$C$13)^1 | R5: ='Hypotheses'!$C$4*$B5*'Hypotheses'!F$18*(1+'Hypotheses'!$C$13)^1 | S5: ='Hypotheses'!$C$4*$B5*'Hypotheses'!G$18*(1+'Hypotheses'!$C$13)^1 | T5: ='Hypotheses'!$C$4*$B5*'Hypotheses'!H$18*(1+'Hypotheses'!$C$13)^1 | U5: ='Hypotheses'!$C$4*$B5*'Hypotheses'!I$18*(1+'Hypotheses'!$C$13)^1 | V5: ='Hypotheses'!$C$4*$B5*'Hypotheses'!J$18*(1+'Hypotheses'!$C$13)^1 | ... Z5: ='Hypotheses'!$C$4*$B5*'Hypotheses'!N$18*(1+'Hypotheses'!$C$13)^1 | AA5: ='Hypotheses'!$C$4*$B5*'Hypotheses'!C$18*(1+'Hypotheses'!$C$13)^2 | AB5: ='Hypotheses'!$C$4*$B5*'Hypotheses'!D$18*(1+'Hypotheses'!$C$13)^2 | AC5: ='Hypotheses'!$C$4*$B5*'Hypotheses'!E$18*(1+'Hypotheses'!$C$13)^2 | AD5: ='Hypotheses'!$C$4*$B5*'Hypotheses'!F$18*(1+'Hypotheses'!$C$13)^2 | AE5: ='Hypotheses'!$C$4*$B5*'Hypotheses'!G$18*(1+'Hypotheses'!$C$13)^2 | AF5: ='Hypotheses'!$C$4*$B5*'Hypotheses'!H$18*(1+'Hypotheses'!$C$13)^2 | AG5: ='Hypotheses'!$C$4*$B5*'Hypotheses'!I$18*(1+'Hypotheses'!$C$13)^2 | AH5: ='Hypotheses'!$C$4*$B5*'Hypotheses'!J$18*(1+'Hypotheses'!$C$13)^2 | ... AL5: ='Hypotheses'!$C$4*$B5*'Hypotheses'!N$18*(1+'Hypotheses'!$C$13)^2
A6: Dinner service | B6: 0.44 | C6: ='Hypotheses'!$C$4*$B6*'Hypotheses'!C$18*(1+'Hypotheses'!$C$13)^0 | D6: ='Hypotheses'!$C$4*$B6*'Hypotheses'!D$18*(1+'Hypotheses'!$C$13)^0 | E6: ='Hypotheses'!$C$4*$B6*'Hypotheses'!E$18*(1+'Hypotheses'!$C$13)^0 | F6: ='Hypotheses'!$C$4*$B6*'Hypotheses'!F$18*(1+'Hypotheses'!$C$13)^0 | G6: ='Hypotheses'!$C$4*$B6*'Hypotheses'!G$18*(1+'Hypotheses'!$C$13)^0 | H6: ='Hypotheses'!$C$4*$B6*'Hypotheses'!H$18*(1+'Hypotheses'!$C$13)^0 | I6: ='Hypotheses'!$C$4*$B6*'Hypotheses'!I$18*(1+'Hypotheses'!$C$13)^0 | J6: ='Hypotheses'!$C$4*$B6*'Hypotheses'!J$18*(1+'Hypotheses'!$C$13)^0 | ... N6: ='Hypotheses'!$C$4*$B6*'Hypotheses'!N$18*(1+'Hypotheses'!$C$13)^0 | O6: ='Hypotheses'!$C$4*$B6*'Hypotheses'!C$18*(1+'Hypotheses'!$C$13)^1 | P6: ='Hypotheses'!$C$4*$B6*'Hypotheses'!D$18*(1+'Hypotheses'!$C$13)^1 | Q6: ='Hypotheses'!$C$4*$B6*'Hypotheses'!E$18*(1+'Hypotheses'!$C$13)^1 | R6: ='Hypotheses'!$C$4*$B6*'Hypotheses'!F$18*(1+'Hypotheses'!$C$13)^1 | S6: ='Hypotheses'!$C$4*$B6*'Hypotheses'!G$18*(1+'Hypotheses'!$C$13)^1 | T6: ='Hypotheses'!$C$4*$B6*'Hypotheses'!H$18*(1+'Hypotheses'!$C$13)^1 | U6: ='Hypotheses'!$C$4*$B6*'Hypotheses'!I$18*(1+'Hypotheses'!$C$13)^1 | V6: ='Hypotheses'!$C$4*$B6*'Hypotheses'!J$18*(1+'Hypotheses'!$C$13)^1 | ... Z6: ='Hypotheses'!$C$4*$B6*'Hypotheses'!N$18*(1+'Hypotheses'!$C$13)^1 | AA6: ='Hypotheses'!$C$4*$B6*'Hypotheses'!C$18*(1+'Hypotheses'!$C$13)^2 | AB6: ='Hypotheses'!$C$4*$B6*'Hypotheses'!D$18*(1+'Hypotheses'!$C$13)^2 | AC6: ='Hypotheses'!$C$4*$B6*'Hypotheses'!E$18*(1+'Hypotheses'!$C$13)^2 | AD6: ='Hypotheses'!$C$4*$B6*'Hypotheses'!F$18*(1+'Hypotheses'!$C$13)^2 | AE6: ='Hypotheses'!$C$4*$B6*'Hypotheses'!G$18*(1+'Hypotheses'!$C$13)^2 | AF6: ='Hypotheses'!$C$4*$B6*'Hypotheses'!H$18*(1+'Hypotheses'!$C$13)^2 | AG6: ='Hypotheses'!$C$4*$B6*'Hypotheses'!I$18*(1+'Hypotheses'!$C$13)^2 | AH6: ='Hypotheses'!$C$4*$B6*'Hypotheses'!J$18*(1+'Hypotheses'!$C$13)^2 | ... AL6: ='Hypotheses'!$C$4*$B6*'Hypotheses'!N$18*(1+'Hypotheses'!$C$13)^2
A7: Drinks | B7: 0.12 | C7: ='Hypotheses'!$C$4*$B7*'Hypotheses'!C$18*(1+'Hypotheses'!$C$13)^0 | D7: ='Hypotheses'!$C$4*$B7*'Hypotheses'!D$18*(1+'Hypotheses'!$C$13)^0 | E7: ='Hypotheses'!$C$4*$B7*'Hypotheses'!E$18*(1+'Hypotheses'!$C$13)^0 | F7: ='Hypotheses'!$C$4*$B7*'Hypotheses'!F$18*(1+'Hypotheses'!$C$13)^0 | G7: ='Hypotheses'!$C$4*$B7*'Hypotheses'!G$18*(1+'Hypotheses'!$C$13)^0 | H7: ='Hypotheses'!$C$4*$B7*'Hypotheses'!H$18*(1+'Hypotheses'!$C$13)^0 | I7: ='Hypotheses'!$C$4*$B7*'Hypotheses'!I$18*(1+'Hypotheses'!$C$13)^0 | J7: ='Hypotheses'!$C$4*$B7*'Hypotheses'!J$18*(1+'Hypotheses'!$C$13)^0 | ... N7: ='Hypotheses'!$C$4*$B7*'Hypotheses'!N$18*(1+'Hypotheses'!$C$13)^0 | O7: ='Hypotheses'!$C$4*$B7*'Hypotheses'!C$18*(1+'Hypotheses'!$C$13)^1 | P7: ='Hypotheses'!$C$4*$B7*'Hypotheses'!D$18*(1+'Hypotheses'!$C$13)^1 | Q7: ='Hypotheses'!$C$4*$B7*'Hypotheses'!E$18*(1+'Hypotheses'!$C$13)^1 | R7: ='Hypotheses'!$C$4*$B7*'Hypotheses'!F$18*(1+'Hypotheses'!$C$13)^1 | S7: ='Hypotheses'!$C$4*$B7*'Hypotheses'!G$18*(1+'Hypotheses'!$C$13)^1 | T7: ='Hypotheses'!$C$4*$B7*'Hypotheses'!H$18*(1+'Hypotheses'!$C$13)^1 | U7: ='Hypotheses'!$C$4*$B7*'Hypotheses'!I$18*(1+'Hypotheses'!$C$13)^1 | V7: ='Hypotheses'!$C$4*$B7*'Hypotheses'!J$18*(1+'Hypotheses'!$C$13)^1 | ... Z7: ='Hypotheses'!$C$4*$B7*'Hypotheses'!N$18*(1+'Hypotheses'!$C$13)^1 | AA7: ='Hypotheses'!$C$4*$B7*'Hypotheses'!C$18*(1+'Hypotheses'!$C$13)^2 | AB7: ='Hypotheses'!$C$4*$B7*'Hypotheses'!D$18*(1+'Hypotheses'!$C$13)^2 | AC7: ='Hypotheses'!$C$4*$B7*'Hypotheses'!E$18*(1+'Hypotheses'!$C$13)^2 | AD7: ='Hypotheses'!$C$4*$B7*'Hypotheses'!F$18*(1+'Hypotheses'!$C$13)^2 | AE7: ='Hypotheses'!$C$4*$B7*'Hypotheses'!G$18*(1+'Hypotheses'!$C$13)^2 | AF7: ='Hypotheses'!$C$4*$B7*'Hypotheses'!H$18*(1+'Hypotheses'!$C$13)^2 | AG7: ='Hypotheses'!$C$4*$B7*'Hypotheses'!I$18*(1+'Hypotheses'!$C$13)^2 | AH7: ='Hypotheses'!$C$4*$B7*'Hypotheses'!J$18*(1+'Hypotheses'!$C$13)^2 | ... AL7: ='Hypotheses'!$C$4*$B7*'Hypotheses'!N$18*(1+'Hypotheses'!$C$13)^2
A8: Takeaway and catering | B8: 0.06 | C8: ='Hypotheses'!$C$4*$B8*'Hypotheses'!C$18*(1+'Hypotheses'!$C$13)^0 | D8: ='Hypotheses'!$C$4*$B8*'Hypotheses'!D$18*(1+'Hypotheses'!$C$13)^0 | E8: ='Hypotheses'!$C$4*$B8*'Hypotheses'!E$18*(1+'Hypotheses'!$C$13)^0 | F8: ='Hypotheses'!$C$4*$B8*'Hypotheses'!F$18*(1+'Hypotheses'!$C$13)^0 | G8: ='Hypotheses'!$C$4*$B8*'Hypotheses'!G$18*(1+'Hypotheses'!$C$13)^0 | H8: ='Hypotheses'!$C$4*$B8*'Hypotheses'!H$18*(1+'Hypotheses'!$C$13)^0 | I8: ='Hypotheses'!$C$4*$B8*'Hypotheses'!I$18*(1+'Hypotheses'!$C$13)^0 | J8: ='Hypotheses'!$C$4*$B8*'Hypotheses'!J$18*(1+'Hypotheses'!$C$13)^0 | ... N8: ='Hypotheses'!$C$4*$B8*'Hypotheses'!N$18*(1+'Hypotheses'!$C$13)^0 | O8: ='Hypotheses'!$C$4*$B8*'Hypotheses'!C$18*(1+'Hypotheses'!$C$13)^1 | P8: ='Hypotheses'!$C$4*$B8*'Hypotheses'!D$18*(1+'Hypotheses'!$C$13)^1 | Q8: ='Hypotheses'!$C$4*$B8*'Hypotheses'!E$18*(1+'Hypotheses'!$C$13)^1 | R8: ='Hypotheses'!$C$4*$B8*'Hypotheses'!F$18*(1+'Hypotheses'!$C$13)^1 | S8: ='Hypotheses'!$C$4*$B8*'Hypotheses'!G$18*(1+'Hypotheses'!$C$13)^1 | T8: ='Hypotheses'!$C$4*$B8*'Hypotheses'!H$18*(1+'Hypotheses'!$C$13)^1 | U8: ='Hypotheses'!$C$4*$B8*'Hypotheses'!I$18*(1+'Hypotheses'!$C$13)^1 | V8: ='Hypotheses'!$C$4*$B8*'Hypotheses'!J$18*(1+'Hypotheses'!$C$13)^1 | ... Z8: ='Hypotheses'!$C$4*$B8*'Hypotheses'!N$18*(1+'Hypotheses'!$C$13)^1 | AA8: ='Hypotheses'!$C$4*$B8*'Hypotheses'!C$18*(1+'Hypotheses'!$C$13)^2 | AB8: ='Hypotheses'!$C$4*$B8*'Hypotheses'!D$18*(1+'Hypotheses'!$C$13)^2 | AC8: ='Hypotheses'!$C$4*$B8*'Hypotheses'!E$18*(1+'Hypotheses'!$C$13)^2 | AD8: ='Hypotheses'!$C$4*$B8*'Hypotheses'!F$18*(1+'Hypotheses'!$C$13)^2 | AE8: ='Hypotheses'!$C$4*$B8*'Hypotheses'!G$18*(1+'Hypotheses'!$C$13)^2 | AF8: ='Hypotheses'!$C$4*$B8*'Hypotheses'!H$18*(1+'Hypotheses'!$C$13)^2 | AG8: ='Hypotheses'!$C$4*$B8*'Hypotheses'!I$18*(1+'Hypotheses'!$C$13)^2 | AH8: ='Hypotheses'!$C$4*$B8*'Hypotheses'!J$18*(1+'Hypotheses'!$C$13)^2 | ... AL8: ='Hypotheses'!$C$4*$B8*'Hypotheses'!N$18*(1+'Hypotheses'!$C$13)^2
A9: TOTAL CA HT | C9: =SUM(C5:C8) | D9: =SUM(D5:D8) | E9: =SUM(E5:E8) | F9: =SUM(F5:F8) | G9: =SUM(G5:G8) | H9: =SUM(H5:H8) | I9: =SUM(I5:I8) | J9: =SUM(J5:J8) | ... AL9: =SUM(AL5:AL8)
A10: Control sum revenue mix | B10: =SUM(B5:B8)
A11: TVA collectee sur les ventes | C11: =C9*'Hypotheses'!$C$5 | D11: =D9*'Hypotheses'!$C$5 | E11: =E9*'Hypotheses'!$C$5 | F11: =F9*'Hypotheses'!$C$5 | G11: =G9*'Hypotheses'!$C$5 | H11: =H9*'Hypotheses'!$C$5 | I11: =I9*'Hypotheses'!$C$5 | J11: =J9*'Hypotheses'!$C$5 | ... AL11: =AL9*'Hypotheses'!$C$5
A12: CA TTC encaissable | C12: =C9+C11 | D12: =D9+D11 | E12: =E9+E11 | F12: =F9+F11 | G12: =G9+G11 | H12: =H9+H11 | I12: =I9+I11 | J12: =J9+J11 | ... AL12: =AL9+AL11

Sheet Depenses detaillees
A1: Restaurant - Depenses detaillees
A2: Quantity x seasonality x unit price x inflation = monthly cost. Market rows use monthly price series.
H3: ANNEE 1 | T3: ANNEE 2 | AF3: ANNEE 3
A4: Categorie | B4: Poste | C4: Qte base/mois A1 | D4: Unite | E4: Prix unitaire A1 | F4: Underlying | G4: Source prix | H4: Jan A1 | I4: Feb A1 | J4: Mar A1 | K4: Apr A1 | L4: May A1 | M4: Jun A1 | N4: Jul A1 | O4: Aug A1 | P4: Sep A1 | Q4: Oct A1 | R4: Nov A1 | S4: Dec A1 | T4: Jan A2 | U4: Feb A2 | V4: Mar A2 | W4: Apr A2 | X4: May A2 | Y4: Jun A2 | Z4: Jul A2 | AA4: Aug A2 | AB4: Sep A2 | AC4: Oct A2 | AD4: Nov A2 | AE4: Dec A2 | AF4: Jan A3 | AG4: Feb A3 | AH4: Mar A3 | AI4: Apr A3 | AJ4: May A3 | AK4: Jun A3 | AL4: Jul A3 | AM4: Aug A3 | AN4: Sep A3 | AO4: Oct A3 | AP4: Nov A3 | AQ4: Dec A3
A5: Raw materials | B5: Food purchases - market price | C5: 1 | D5: monthly package | E5: =AVERAGE(H5:AQ5) | G5: INSEE BDM 010763739: Indice de prix de production de l'industrie française pour le marché français − CPF 10.8 − Autres produits alimentaires ; normalized to model unit price | H5: 10000 | I5: 9939.8798 | J5: 9979.9599 | K5: 9969.9399 | L5: 9989.98 | M5: 10000 | N5: 9959.9198 | O5: 9969.9399 | P5: 10040.08 | Q5: 10100.2 | R5: 10160.321 | S5: 10140.281 | T5: 10320.641 | U5: 10460.922 | V5: 10781.563 | W5: 11292.585 | X5: 11402.806 | Y5: 11543.086 | Z5: 11713.427 | AA5: 11873.747 | AB5: 11943.888 | AC5: 12294.589 | AD5: 12474.95 | AE5: 12735.471 | AF5: 13156.313 | AG5: 13356.713 | AH5: 13617.235 | AI5: 13837.675 | AJ5: 13847.695 | AK5: 13847.695 | AL5: 13677.355 | AM5: 13747.495 | AN5: 13657.315 | AO5: 13707.415 | AP5: 13747.495 | AQ5: 13777.555
A6: Raw materials | B6: Cost (Food purchases) | C6: 1 | D6: monthly package | E6: =E5 | G6: Cost = quantity x seasonality x monthly market price | H6: =$C6*'Hypotheses'!C$17*H5 | I6: =$C6*'Hypotheses'!D$17*I5 | J6: =$C6*'Hypotheses'!E$17*J5 | K6: =$C6*'Hypotheses'!F$17*K5 | L6: =$C6*'Hypotheses'!G$17*L5 | M6: =$C6*'Hypotheses'!H$17*M5 | N6: =$C6*'Hypotheses'!I$17*N5 | O6: =$C6*'Hypotheses'!J$17*O5 | ... S6: =$C6*'Hypotheses'!N$17*S5 | T6: =$C6*'Hypotheses'!C$17*T5 | U6: =$C6*'Hypotheses'!D$17*U5 | V6: =$C6*'Hypotheses'!E$17*V5 | W6: =$C6*'Hypotheses'!F$17*W5 | X6: =$C6*'Hypotheses'!G$17*X5 | Y6: =$C6*'Hypotheses'!H$17*Y5 | Z6: =$C6*'Hypotheses'!I$17*Z5 | AA6: =$C6*'Hypotheses'!J$17*AA5 | ... AE6: =$C6*'Hypotheses'!N$17*AE5 | AF6: =$C6*'Hypotheses'!C$17*AF5 | AG6: =$C6*'Hypotheses'!D$17*AG5 | AH6: =$C6*'Hypotheses'!E$17*AH5 | AI6: =$C6*'Hypotheses'!F$17*AI5 | AJ6: =$C6*'Hypotheses'!G$17*AJ5 | AK6: =$C6*'Hypotheses'!H$17*AK5 | AL6: =$C6*'Hypotheses'!I$17*AL5 | AM6: =$C6*'Hypotheses'!J$17*AM5 | ... AQ6: =$C6*'Hypotheses'!N$17*AQ5
A7: Raw materials | B7: Butter, cream and dairy fats - market price | C7: 320 | D7: kg/L | E7: =AVERAGE(H7:AQ7) | F7: Fats | G7: INSEE BDM 010763706: Indice de prix de production de l'industrie française pour le marché français − CPF 10.51 − Produits laitiers et fromages pour grossistes et restaurateurs ; normalized to model unit price | H7: 4.2 | I7: 4.2522 | J7: 4.3174 | K7: 4.3435 | L7: 4.3652 | M7: 4.3522 | N7: 4.3957 | O7: 4.387 | P7: 4.387 | Q7: 4.3391 | R7: 4.4739 | S7: 4.3565 | T7: 4.7435 | U7: 4.7565 | V7: 4.7783 | W7: 4.913 | X7: 4.9652 | Y7: 5.0478 | Z7: 5.3783 | AA7: 5.4087 | AB7: 5.4478 | AC7: 5.6391 | AD7: 5.5783 | AE7: 5.5217 | AF7: 5.7696 | AG7: 5.887 | AH7: 6.0174 | AI7: 6.0478 | AJ7: 6.1 | AK7: 6.0304 | AL7: 6.0696 | AM7: 5.9435 | AN7: 5.9609 | AO7: 5.9522 | AP7: 5.8783 | AQ7: 5.9043
A8: Raw materials | B8: Cost (Butter, cream and dairy fats) | C8: 320 | D8: kg/L | E8: =E7 | F8: Fats | G8: Cost = quantity x seasonality x monthly market price | H8: =$C8*'Hypotheses'!C$17*H7 | I8: =$C8*'Hypotheses'!D$17*I7 | J8: =$C8*'Hypotheses'!E$17*J7 | K8: =$C8*'Hypotheses'!F$17*K7 | L8: =$C8*'Hypotheses'!G$17*L7 | M8: =$C8*'Hypotheses'!H$17*M7 | N8: =$C8*'Hypotheses'!I$17*N7 | O8: =$C8*'Hypotheses'!J$17*O7 | ... S8: =$C8*'Hypotheses'!N$17*S7 | T8: =$C8*'Hypotheses'!C$17*T7 | U8: =$C8*'Hypotheses'!D$17*U7 | V8: =$C8*'Hypotheses'!E$17*V7 | W8: =$C8*'Hypotheses'!F$17*W7 | X8: =$C8*'Hypotheses'!G$17*X7 | Y8: =$C8*'Hypotheses'!H$17*Y7 | Z8: =$C8*'Hypotheses'!I$17*Z7 | AA8: =$C8*'Hypotheses'!J$17*AA7 | ... AE8: =$C8*'Hypotheses'!N$17*AE7 | AF8: =$C8*'Hypotheses'!C$17*AF7 | AG8: =$C8*'Hypotheses'!D$17*AG7 | AH8: =$C8*'Hypotheses'!E$17*AH7 | AI8: =$C8*'Hypotheses'!F$17*AI7 | AJ8: =$C8*'Hypotheses'!G$17*AJ7 | AK8: =$C8*'Hypotheses'!H$17*AK7 | AL8: =$C8*'Hypotheses'!I$17*AL7 | AM8: =$C8*'Hypotheses'!J$17*AM7 | ... AQ8: =$C8*'Hypotheses'!N$17*AQ7
A9: Raw materials | B9: Bread and flour-based inputs - market price | C9: 1 | D9: monthly package | E9: =AVERAGE(H9:AQ9) | F9: Wheat | G9: INSEE BDM 010002046: Cours des matières premières importées - Blé de force rouge d'hiver, contrat à terme à la 1ère échéance, CME (Chicago Mercantile Exchange) - Prix en cents US par boisseau; normalized to model unit price | H9: 2500 | I9: 2530.527 | J9: 2391.1472 | K9: 2502.0084 | L9: 2642.9949 | M9: 2492.7699 | N9: 2544.9871 | O9: 2857.4871 | P9: 2832.1819 | Q9: 3030.2057 | R9: 3312.1787 | S9: 3292.8985 | T9: 3170.3888 | U9: 3349.5341 | V9: 4417.1754 | W9: 4516.7898 | X9: 4899.9839 | Y9: 4368.9749 | Z9: 3503.7757 | AA9: 3494.1356 | AB9: 3749.5983 | AC9: 3864.8779 | AD9: 3768.8785 | AE9: 3479.2738 | AF9: 3390.5045 | AG9: 3535.5077 | AH9: 3331.8605 | AI9: 3417.0148 | AJ9: 3402.5546 | AK9: 3292.8985 | AL9: 3384.8811 | AM9: 3020.1639 | AN9: 2890.8258 | AO9: 2677.5386 | AP9: 2532.5353 | AQ9: 2573.5058
A10: Raw materials | B10: Cost (Bread and flour-based inputs) | C10: 1 | D10: monthly package | E10: =E9 | F10: Wheat | G10: Cost = quantity x seasonality x monthly market price | H10: =$C10*'Hypotheses'!C$17*H9 | I10: =$C10*'Hypotheses'!D$17*I9 | J10: =$C10*'Hypotheses'!E$17*J9 | K10: =$C10*'Hypotheses'!F$17*K9 | L10: =$C10*'Hypotheses'!G$17*L9 | M10: =$C10*'Hypotheses'!H$17*M9 | N10: =$C10*'Hypotheses'!I$17*N9 | O10: =$C10*'Hypotheses'!J$17*O9 | ... S10: =$C10*'Hypotheses'!N$17*S9 | T10: =$C10*'Hypotheses'!C$17*T9 | U10: =$C10*'Hypotheses'!D$17*U9 | V10: =$C10*'Hypotheses'!E$17*V9 | W10: =$C10*'Hypotheses'!F$17*W9 | X10: =$C10*'Hypotheses'!G$17*X9 | Y10: =$C10*'Hypotheses'!H$17*Y9 | Z10: =$C10*'Hypotheses'!I$17*Z9 | AA10: =$C10*'Hypotheses'!J$17*AA9 | ... AE10: =$C10*'Hypotheses'!N$17*AE9 | AF10: =$C10*'Hypotheses'!C$17*AF9 | AG10: =$C10*'Hypotheses'!D$17*AG9 | AH10: =$C10*'Hypotheses'!E$17*AH9 | AI10: =$C10*'Hypotheses'!F$17*AI9 | AJ10: =$C10*'Hypotheses'!G$17*AJ9 | AK10: =$C10*'Hypotheses'!H$17*AK9 | AL10: =$C10*'Hypotheses'!I$17*AL9 | AM10: =$C10*'Hypotheses'!J$17*AM9 | ... AQ10: =$C10*'Hypotheses'!N$17*AQ9
A11: SOUS-TOTAL Raw materials | H11: =SUM(H6,H8,H10) | I11: =SUM(I6,I8,I10) | J11: =SUM(J6,J8,J10) | K11: =SUM(K6,K8,K10) | L11: =SUM(L6,L8,L10) | M11: =SUM(M6,M8,M10) | N11: =SUM(N6,N8,N10) | O11: =SUM(O6,O8,O10) | ... AQ11: =SUM(AQ6,AQ8,AQ10)
A12: Energy | B12: Cooking gas - market price | C12: 5200 | D12: kWh | E12: =AVERAGE(H12:AQ12) | F12: Gas | G12: INSEE BDM 010767333: Gaz naturel TTF, contrats à terme à la première échéance aux Pays-Bas - ICE Futures Europe - Prix en euros par mégawattheure; normalized to model unit price | H12: 0.105 | I12: 0.0896 | J12: 0.0906 | K12: 0.105 | L12: 0.1287 | M12: 0.1503 | N12: 0.1858 | O12: 0.2301 | P12: 0.3407 | Q12: 0.4699 | R12: 0.4251 | S12: 0.5909 | T12: 0.4385 | U12: 0.4215 | V12: 0.6758 | W12: 0.524 | X12: 0.4843 | Y12: 0.5574 | Z12: 0.8853 | AA12: 1.2147 | AB12: 1.0474 | AC12: 0.6974 | AD12: 0.6151 | AE12: 0.5981 | AF12: 0.3289 | AG12: 0.2707 | AH12: 0.2265 | AI12: 0.2167 | AJ12: 0.1632 | AK12: 0.1678 | AL12: 0.1518 | AM12: 0.1801 | AN12: 0.1899 | AO12: 0.2424 | AP12: 0.2352 | AQ12: 0.1853
A13: Energy | B13: Cost (Cooking gas) | C13: 5200 | D13: kWh | E13: =E12 | F13: Gas | G13: Cost = quantity x seasonality x monthly market price | H13: =$C13*'Hypotheses'!C$17*H12 | I13: =$C13*'Hypotheses'!D$17*I12 | J13: =$C13*'Hypotheses'!E$17*J12 | K13: =$C13*'Hypotheses'!F$17*K12 | L13: =$C13*'Hypotheses'!G$17*L12 | M13: =$C13*'Hypotheses'!H$17*M12 | N13: =$C13*'Hypotheses'!I$17*N12 | O13: =$C13*'Hypotheses'!J$17*O12 | ... S13: =$C13*'Hypotheses'!N$17*S12 | T13: =$C13*'Hypotheses'!C$17*T12 | U13: =$C13*'Hypotheses'!D$17*U12 | V13: =$C13*'Hypotheses'!E$17*V12 | W13: =$C13*'Hypotheses'!F$17*W12 | X13: =$C13*'Hypotheses'!G$17*X12 | Y13: =$C13*'Hypotheses'!H$17*Y12 | Z13: =$C13*'Hypotheses'!I$17*Z12 | AA13: =$C13*'Hypotheses'!J$17*AA12 | ... AE13: =$C13*'Hypotheses'!N$17*AE12 | AF13: =$C13*'Hypotheses'!C$17*AF12 | AG13: =$C13*'Hypotheses'!D$17*AG12 | AH13: =$C13*'Hypotheses'!E$17*AH12 | AI13: =$C13*'Hypotheses'!F$17*AI12 | AJ13: =$C13*'Hypotheses'!G$17*AJ12 | AK13: =$C13*'Hypotheses'!H$17*AK12 | AL13: =$C13*'Hypotheses'!I$17*AL12 | AM13: =$C13*'Hypotheses'!J$17*AM12 | ... AQ13: =$C13*'Hypotheses'!N$17*AQ12
A14: Energy | B14: Electricity for kitchen and refrigeration - market price | C14: 7600 | D14: kWh | E14: =AVERAGE(H14:AQ14) | F14: Electricity | G14: INSEE BDM 010777317: Indice mensuel des prix d'achat des moyens de production agricole (IPAMPA) - Electricité; normalized to model unit price | H14: 0.17 | I14: 0.1725 | J14: 0.1725 | K14: 0.1725 | L14: 0.1727 | M14: 0.1727 | N14: 0.1727 | O14: 0.1737 | P14: 0.1737 | Q14: 0.1742 | R14: 0.1754 | S14: 0.175 | T14: 0.1766 | U14: 0.1809 | V14: 0.1829 | W14: 0.1845 | X14: 0.1838 | Y14: 0.1858 | Z14: 0.187 | AA14: 0.1872 | AB14: 0.1922 | AC14: 0.1895 | AD14: 0.1927 | AE14: 0.1878 | AF14: 0.1821 | AG14: 0.1993 | AH14: 0.2031 | AI14: 0.2051 | AJ14: 0.2046 | AK14: 0.2045 | AL14: 0.2045 | AM14: 0.2208 | AN14: 0.2231 | AO14: 0.2245 | AP14: 0.2236 | AQ14: 0.2235
A15: Energy | B15: Cost (Electricity for kitchen and refrigeration) | C15: 7600 | D15: kWh | E15: =E14 | F15: Electricity | G15: Cost = quantity x seasonality x monthly market price | H15: =$C15*'Hypotheses'!C$17*H14 | I15: =$C15*'Hypotheses'!D$17*I14 | J15: =$C15*'Hypotheses'!E$17*J14 | K15: =$C15*'Hypotheses'!F$17*K14 | L15: =$C15*'Hypotheses'!G$17*L14 | M15: =$C15*'Hypotheses'!H$17*M14 | N15: =$C15*'Hypotheses'!I$17*N14 | O15: =$C15*'Hypotheses'!J$17*O14 | ... S15: =$C15*'Hypotheses'!N$17*S14 | T15: =$C15*'Hypotheses'!C$17*T14 | U15: =$C15*'Hypotheses'!D$17*U14 | V15: =$C15*'Hypotheses'!E$17*V14 | W15: =$C15*'Hypotheses'!F$17*W14 | X15: =$C15*'Hypotheses'!G$17*X14 | Y15: =$C15*'Hypotheses'!H$17*Y14 | Z15: =$C15*'Hypotheses'!I$17*Z14 | AA15: =$C15*'Hypotheses'!J$17*AA14 | ... AE15: =$C15*'Hypotheses'!N$17*AE14 | AF15: =$C15*'Hypotheses'!C$17*AF14 | AG15: =$C15*'Hypotheses'!D$17*AG14 | AH15: =$C15*'Hypotheses'!E$17*AH14 | AI15: =$C15*'Hypotheses'!F$17*AI14 | AJ15: =$C15*'Hypotheses'!G$17*AJ14 | AK15: =$C15*'Hypotheses'!H$17*AK14 | AL15: =$C15*'Hypotheses'!I$17*AL14 | AM15: =$C15*'Hypotheses'!J$17*AM14 | ... AQ15: =$C15*'Hypotheses'!N$17*AQ14
A16: SOUS-TOTAL Energy | H16: =SUM(H13,H15) | I16: =SUM(I13,I15) | J16: =SUM(J13,J15) | K16: =SUM(K13,K15) | L16: =SUM(L13,L15) | M16: =SUM(M13,M15) | N16: =SUM(N13,N15) | O16: =SUM(O13,O15) | ... AQ16: =SUM(AQ13,AQ15)
A17: Personnel | B17: Kitchen and service payroll - market price | C17: 1 | D17: monthly package | E17: =AVERAGE(H17:AQ17) | G17: INSEE BDM 010762009: Indice du coût du travail - Coût horaire - Hébergement, restauration (NAF rév. 2 section I) - Base 100 en 2020 ; normalized to model unit price | H17: 16000 | I17: 16000 | J17: 16000 | K17: 16000 | L17: 16000 | M17: 16000 | N17: 16000 | O17: 16000 | P17: 16000 | Q17: 16000 | R17: 16000 | S17: 16000 | T17: 16000 | U17: 16000 | V17: 16000 | W17: 16000 | X17: 16000 | Y17: 16000 | Z17: 16000 | AA17: 16000 | AB17: 16000 | AC17: 16000 | AD17: 16000 | AE17: 16000 | AF17: 16000 | AG17: 16000 | AH17: 16000 | AI17: 16000 | AJ17: 16000 | AK17: 16000 | AL17: 16000 | AM17: 16000 | AN17: 16000 | AO17: 16000 | AP17: 16000 | AQ17: 16000
A18: Personnel | B18: Cost (Kitchen and service payroll) | C18: 1 | D18: monthly package | E18: =E17 | G18: Cost = quantity x seasonality x monthly market price | H18: =$C18*H17 | I18: =$C18*I17 | J18: =$C18*J17 | K18: =$C18*K17 | L18: =$C18*L17 | M18: =$C18*M17 | N18: =$C18*N17 | O18: =$C18*O17 | ... AQ18: =$C18*AQ17
A19: SOUS-TOTAL Personnel | H19: =SUM(H18) | I19: =SUM(I18) | J19: =SUM(J18) | K19: =SUM(K18) | L19: =SUM(L18) | M19: =SUM(M18) | N19: =SUM(N18) | O19: =SUM(O18) | ... AQ19: =SUM(AQ18)
A20: Fixed costs | B20: Rent - market price | C20: 1 | D20: monthly package | E20: =AVERAGE(H20:AQ20) | G20: INSEE BDM 001532540: Indice des loyers commerciaux (ILC) - Base 100 au 1er trimestre 2008; normalized to model unit price | H20: 5200 | I20: 5200 | J20: 5200 | K20: 5200 | L20: 5200 | M20: 5200 | N20: 5200 | O20: 5200 | P20: 5200 | Q20: 5200 | R20: 5200 | S20: 5200 | T20: 5200 | U20: 5200 | V20: 5200 | W20: 5200 | X20: 5200 | Y20: 5200 | Z20: 5200 | AA20: 5200 | AB20: 5200 | AC20: 5200 | AD20: 5200 | AE20: 5200 | AF20: 5200 | AG20: 5200 | AH20: 5200 | AI20: 5200 | AJ20: 5200 | AK20: 5200 | AL20: 5200 | AM20: 5200 | AN20: 5200 | AO20: 5200 | AP20: 5200 | AQ20: 5200
A21: Fixed costs | B21: Cost (Rent) | C21: 1 | D21: monthly package | E21: =E20 | G21: Cost = quantity x seasonality x monthly market price | H21: =$C21*H20 | I21: =$C21*I20 | J21: =$C21*J20 | K21: =$C21*K20 | L21: =$C21*L20 | M21: =$C21*M20 | N21: =$C21*N20 | O21: =$C21*O20 | ... AQ21: =$C21*AQ20
A22: Fixed costs | B22: Insurance, accounting, software - market price | C22: 1 | D22: monthly package | E22: =AVERAGE(H22:AQ22) | G22: INSEE BDM 010766756: Indices des prix de production des services français aux entreprises françaises (BtoB) − CPF 82.11 − Services administratifs combinés ; normalized to model unit price | H22: 2400 | I22: 2400 | J22: 2400 | K22: 2400 | L22: 2400 | M22: 2400 | N22: 2400 | O22: 2400 | P22: 2400 | Q22: 2400 | R22: 2400 | S22: 2400 | T22: 2400 | U22: 2400 | V22: 2400 | W22: 2400 | X22: 2400 | Y22: 2400 | Z22: 2400 | AA22: 2400 | AB22: 2400 | AC22: 2400 | AD22: 2400 | AE22: 2400 | AF22: 2400 | AG22: 2400 | AH22: 2400 | AI22: 2400 | AJ22: 2400 | AK22: 2400 | AL22: 2400 | AM22: 2400 | AN22: 2400 | AO22: 2400 | AP22: 2400 | AQ22: 2400
A23: Fixed costs | B23: Cost (Insurance, accounting, software) | C23: 1 | D23: monthly package | E23: =E22 | G23: Cost = quantity x seasonality x monthly market price | H23: =$C23*H22 | I23: =$C23*I22 | J23: =$C23*J22 | K23: =$C23*K22 | L23: =$C23*L22 | M23: =$C23*M22 | N23: =$C23*N22 | O23: =$C23*O22 | ... AQ23: =$C23*AQ22
A24: SOUS-TOTAL Fixed costs | H24: =SUM(H21,H23) | I24: =SUM(I21,I23) | J24: =SUM(J21,J23) | K24: =SUM(K21,K23) | L24: =SUM(L21,L23) | M24: =SUM(M21,M23) | N24: =SUM(N21,N23) | O24: =SUM(O21,O23) | ... AQ24: =SUM(AQ21,AQ23)
A26: TOTAL GENERAL DEPENSES | H26: =SUM(H11,H16,H19,H24) | I26: =SUM(I11,I16,I19,I24) | J26: =SUM(J11,J16,J19,J24) | K26: =SUM(K11,K16,K19,K24) | L26: =SUM(L11,L16,L19,L24) | M26: =SUM(M11,M16,M19,M24) | N26: =SUM(N11,N16,N19,N24) | O26: =SUM(O11,O16,O19,O24) | ... AQ26: =SUM(AQ11,AQ16,AQ19,AQ24)
A27: Total depenses A1 / CA A1 | C27: =SUM(H26:S26)/'Hypotheses'!$C$4

Sheet Plan de tresorerie
A1: Restaurant - Plan de tresorerie mensuel
A2: Opening cash + collections - disbursements = ending cash.
C3: ANNEE 1 | O3: ANNEE 2 | AA3: ANNEE 3
A4: Mois | C4: Jan A1 | D4: Feb A1 | E4: Mar A1 | F4: Apr A1 | G4: May A1 | H4: Jun A1 | I4: Jul A1 | J4: Aug A1 | K4: Sep A1 | L4: Oct A1 | M4: Nov A1 | N4: Dec A1 | O4: Jan A2 | P4: Feb A2 | Q4: Mar A2 | R4: Apr A2 | S4: May A2 | T4: Jun A2 | U4: Jul A2 | V4: Aug A2 | W4: Sep A2 | X4: Oct A2 | Y4: Nov A2 | Z4: Dec A2 | AA4: Jan A3 | AB4: Feb A3 | AC4: Mar A3 | AD4: Apr A3 | AE4: May A3 | AF4: Jun A3 | AG4: Jul A3 | AH4: Aug A3 | AI4: Sep A3 | AJ4: Oct A3 | AK4: Nov A3 | AL4: Dec A3
A5: Tresorerie en debut de mois | C5: ='Hypotheses'!$C$7 | D5: =C18 | E5: =D18 | F5: =E18 | G5: =F18 | H5: =G18 | I5: =H18 | J5: =I18 | K5: =J18 | ... AL5: =AK18
A6: ENCAISSEMENTS
A7: Encaissements clients TTC | C7: ='Revenus'!C12*'Hypotheses'!$C$10+0+0 | D7: ='Revenus'!D12*'Hypotheses'!$C$10+'Revenus'!C12*'Hypotheses'!$C$11+0 | E7: ='Revenus'!E12*'Hypotheses'!$C$10+'Revenus'!D12*'Hypotheses'!$C$11+'Revenus'!C12*'Hypotheses'!$C$12 | F7: ='Revenus'!F12*'Hypotheses'!$C$10+'Revenus'!E12*'Hypotheses'!$C$11+'Revenus'!D12*'Hypotheses'!$C$12 | G7: ='Revenus'!G12*'Hypotheses'!$C$10+'Revenus'!F12*'Hypotheses'!$C$11+'Revenus'!E12*'Hypotheses'!$C$12 | H7: ='Revenus'!H12*'Hypotheses'!$C$10+'Revenus'!G12*'Hypotheses'!$C$11+'Revenus'!F12*'Hypotheses'!$C$12 | I7: ='Revenus'!I12*'Hypotheses'!$C$10+'Revenus'!H12*'Hypotheses'!$C$11+'Revenus'!G12*'Hypotheses'!$C$12 | J7: ='Revenus'!J12*'Hypotheses'!$C$10+'Revenus'!I12*'Hypotheses'!$C$11+'Revenus'!H12*'Hypotheses'!$C$12 | K7: ='Revenus'!K12*'Hypotheses'!$C$10+'Revenus'!J12*'Hypotheses'!$C$11+'Revenus'!I12*'Hypotheses'!$C$12 | L7: ='Revenus'!L12*'Hypotheses'!$C$10+'Revenus'!K12*'Hypotheses'!$C$11+'Revenus'!J12*'Hypotheses'!$C$12 | ... AL7: ='Revenus'!AL12*'Hypotheses'!$C$10+'Revenus'!AK12*'Hypotheses'!$C$11+'Revenus'!AJ12*'Hypotheses'!$C$12
A8: TOTAL ENCAISSEMENTS | C8: =C7 | D8: =D7 | E8: =E7 | F8: =F7 | G8: =G7 | H8: =H7 | I8: =I7 | J8: =J7 | ... AL8: =AL7
A9: DECAISSEMENTS
A10: Achats variables et commodity-linked | C10: =SUM('Depenses detaillees'!H11,'Depenses detaillees'!H16) | D10: =SUM('Depenses detaillees'!I11,'Depenses detaillees'!I16) | E10: =SUM('Depenses detaillees'!J11,'Depenses detaillees'!J16) | F10: =SUM('Depenses detaillees'!K11,'Depenses detaillees'!K16) | G10: =SUM('Depenses detaillees'!L11,'Depenses detaillees'!L16) | H10: =SUM('Depenses detaillees'!M11,'Depenses detaillees'!M16) | I10: =SUM('Depenses detaillees'!N11,'Depenses detaillees'!N16) | J10: =SUM('Depenses detaillees'!O11,'Depenses detaillees'!O16) | ... AL10: =SUM('Depenses detaillees'!AQ11,'Depenses detaillees'!AQ16)
A11: Personnel | C11: =SUM('Depenses detaillees'!H19) | D11: =SUM('Depenses detaillees'!I19) | E11: =SUM('Depenses detaillees'!J19) | F11: =SUM('Depenses detaillees'!K19) | G11: =SUM('Depenses detaillees'!L19) | H11: =SUM('Depenses detaillees'!M19) | I11: =SUM('Depenses detaillees'!N19) | J11: =SUM('Depenses detaillees'!O19) | ... AL11: =SUM('Depenses detaillees'!AQ19)
A12: Charges fixes et maintenance | C12: =SUM('Depenses detaillees'!H24) | D12: =SUM('Depenses detaillees'!I24) | E12: =SUM('Depenses detaillees'!J24) | F12: =SUM('Depenses detaillees'!K24) | G12: =SUM('Depenses detaillees'!L24) | H12: =SUM('Depenses detaillees'!M24) | I12: =SUM('Depenses detaillees'!N24) | J12: =SUM('Depenses detaillees'!O24) | ... AL12: =SUM('Depenses detaillees'!AQ24)
A13: Cotisations sociales dirigeant | C13: 0 | D13: 0 | E13: ='Hypotheses'!$C$8*(1+'Hypotheses'!$C$14)^0 | F13: 0 | G13: 0 | H13: ='Hypotheses'!$C$8*(1+'Hypotheses'!$C$14)^0 | I13: 0 | J13: 0 | K13: ='Hypotheses'!$C$8*(1+'Hypotheses'!$C$14)^0 | L13: 0 | M13: 0 | N13: ='Hypotheses'!$C$8*(1+'Hypotheses'!$C$14)^0 | O13: 0 | P13: 0 | Q13: ='Hypotheses'!$C$8*(1+'Hypotheses'!$C$14)^1 | R13: 0 | S13: 0 | T13: ='Hypotheses'!$C$8*(1+'Hypotheses'!$C$14)^1 | U13: 0 | V13: 0 | W13: ='Hypotheses'!$C$8*(1+'Hypotheses'!$C$14)^1 | X13: 0 | Y13: 0 | Z13: ='Hypotheses'!$C$8*(1+'Hypotheses'!$C$14)^1 | AA13: 0 | AB13: 0 | AC13: ='Hypotheses'!$C$8*(1+'Hypotheses'!$C$14)^2 | AD13: 0 | AE13: 0 | AF13: ='Hypotheses'!$C$8*(1+'Hypotheses'!$C$14)^2 | AG13: 0 | AH13: 0 | AI13: ='Hypotheses'!$C$8*(1+'Hypotheses'!$C$14)^2 | AJ13: 0 | AK13: 0 | AL13: ='Hypotheses'!$C$8*(1+'Hypotheses'!$C$14)^2
A14: TVA nette versee | C14: 0 | D14: 0 | E14: =MAX(0,SUM(C22:E22)) | F14: 0 | G14: 0 | H14: =MAX(0,SUM(F22:H22)) | I14: 0 | J14: 0 | K14: =MAX(0,SUM(I22:K22)) | L14: 0 | M14: 0 | N14: =MAX(0,SUM(L22:N22)) | O14: 0 | P14: 0 | Q14: =MAX(0,SUM(O22:Q22)) | R14: 0 | S14: 0 | T14: =MAX(0,SUM(R22:T22)) | U14: 0 | V14: 0 | W14: =MAX(0,SUM(U22:W22)) | X14: 0 | Y14: 0 | Z14: =MAX(0,SUM(X22:Z22)) | AA14: 0 | AB14: 0 | AC14: =MAX(0,SUM(AA22:AC22)) | AD14: 0 | AE14: 0 | AF14: =MAX(0,SUM(AD22:AF22)) | AG14: 0 | AH14: 0 | AI14: =MAX(0,SUM(AG22:AI22)) | AJ14: 0 | AK14: 0 | AL14: =MAX(0,SUM(AJ22:AL22))
A15: Remboursement emprunt materiel | C15: ='Hypotheses'!$C$9 | D15: ='Hypotheses'!$C$9 | E15: ='Hypotheses'!$C$9 | F15: ='Hypotheses'!$C$9 | G15: ='Hypotheses'!$C$9 | H15: ='Hypotheses'!$C$9 | I15: ='Hypotheses'!$C$9 | J15: ='Hypotheses'!$C$9 | ... AL15: ='Hypotheses'!$C$9
A16: TOTAL DECAISSEMENTS | C16: =SUM(C10:C15) | D16: =SUM(D10:D15) | E16: =SUM(E10:E15) | F16: =SUM(F10:F15) | G16: =SUM(G10:G15) | H16: =SUM(H10:H15) | I16: =SUM(I10:I15) | J16: =SUM(J10:J15) | ... AL16: =SUM(AL10:AL15)
A17: Variation de tresorerie du mois | C17: =C8-C16 | D17: =D8-D16 | E17: =E8-E16 | F17: =F8-F16 | G17: =G8-G16 | H17: =H8-H16 | I17: =I8-I16 | J17: =J8-J16 | ... AL17: =AL8-AL16
A18: TRESORERIE EN FIN DE MOIS | C18: =C5+C17 | D18: =D5+D17 | E18: =E5+E17 | F18: =F5+F17 | G18: =G5+G17 | H18: =H5+H17 | I18: =I5+I17 | J18: =J5+J17 | ... AL18: =AL5+AL17
A20: Memo - TVA collectee du mois | C20: ='Revenus'!C11 | D20: ='Revenus'!D11 | E20: ='Revenus'!E11 | F20: ='Revenus'!F11 | G20: ='Revenus'!G11 | H20: ='Revenus'!H11 | I20: ='Revenus'!I11 | J20: ='Revenus'!J11 | ... AL20: ='Revenus'!AL11
A21: Memo - TVA deductible du mois | C21: =(C10+C12)*'Hypotheses'!$C$6 | D21: =(D10+D12)*'Hypotheses'!$C$6 | E21: =(E10+E12)*'Hypotheses'!$C$6 | F21: =(F10+F12)*'Hypotheses'!$C$6 | G21: =(G10+G12)*'Hypotheses'!$C$6 | H21: =(H10+H12)*'Hypotheses'!$C$6 | I21: =(I10+I12)*'Hypotheses'!$C$6 | J21: =(J10+J12)*'Hypotheses'!$C$6 | ... AL21: =(AL10+AL12)*'Hypotheses'!$C$6
A22: Memo - TVA nette du mois | C22: =C20-C21 | D22: =D20-D21 | E22: =E20-E21 | F22: =F20-F21 | G22: =G20-G21 | H22: =H20-H21 | I22: =I20-I21 | J22: =J20-J21 | ... AL22: =AL20-AL21
A24: Minimum cash over period | C24: =MIN(C18:AL18)

Sheet Market data
A1: Market data used by model
A2: External series are normalized to each model unit price to preserve realistic movement without unit mismatch.
A4: Cost line | B4: Underlying | C4: Market code | D4: Source | E4: Model unit | F4: Model unit price | G4: Month | H4: Value
A5: Insurance, accounting, software | C5: ADMIN_SERVICES | D5: INSEE BDM 010766756: Indices des prix de production des services français aux entreprises françaises (BtoB) − CPF 82.11 − Services administratifs combinés | E5: monthly package | F5: 2400 | G5: 2021-01 | H5: 2400
A6: Insurance, accounting, software | C6: ADMIN_SERVICES | D6: INSEE BDM 010766756: Indices des prix de production des services français aux entreprises françaises (BtoB) − CPF 82.11 − Services administratifs combinés | E6: monthly package | F6: 2400 | G6: 2021-02 | H6: 2400
A7: Insurance, accounting, software | C7: ADMIN_SERVICES | D7: INSEE BDM 010766756: Indices des prix de production des services français aux entreprises françaises (BtoB) − CPF 82.11 − Services administratifs combinés | E7: monthly package | F7: 2400 | G7: 2021-03 | H7: 2400
A8: Insurance, accounting, software | C8: ADMIN_SERVICES | D8: INSEE BDM 010766756: Indices des prix de production des services français aux entreprises françaises (BtoB) − CPF 82.11 − Services administratifs combinés | E8: monthly package | F8: 2400 | G8: 2021-04 | H8: 2400
A9: Insurance, accounting, software | C9: ADMIN_SERVICES | D9: INSEE BDM 010766756: Indices des prix de production des services français aux entreprises françaises (BtoB) − CPF 82.11 − Services administratifs combinés | E9: monthly package | F9: 2400 | G9: 2021-05 | H9: 2400
A10: Insurance, accounting, software | C10: ADMIN_SERVICES | D10: INSEE BDM 010766756: Indices des prix de production des services français aux entreprises françaises (BtoB) − CPF 82.11 − Services administratifs combinés | E10: monthly package | F10: 2400 | G10: 2021-06 | H10: 2400
A11: Insurance, accounting, software | C11: ADMIN_SERVICES | D11: INSEE BDM 010766756: Indices des prix de production des services français aux entreprises françaises (BtoB) − CPF 82.11 − Services administratifs combinés | E11: monthly package | F11: 2400 | G11: 2021-07 | H11: 2400
A12: Insurance, accounting, software | C12: ADMIN_SERVICES | D12: INSEE BDM 010766756: Indices des prix de production des services français aux entreprises françaises (BtoB) − CPF 82.11 − Services administratifs combinés | E12: monthly package | F12: 2400 | G12: 2021-08 | H12: 2400
A13: Insurance, accounting, software | C13: ADMIN_SERVICES | D13: INSEE BDM 010766756: Indices des prix de production des services français aux entreprises françaises (BtoB) − CPF 82.11 − Services administratifs combinés | E13: monthly package | F13: 2400 | G13: 2021-09 | H13: 2400
A14: Insurance, accounting, software | C14: ADMIN_SERVICES | D14: INSEE BDM 010766756: Indices des prix de production des services français aux entreprises françaises (BtoB) − CPF 82.11 − Services administratifs combinés | E14: monthly package | F14: 2400 | G14: 2021-10 | H14: 2400
A15: Insurance, accounting, software | C15: ADMIN_SERVICES | D15: INSEE BDM 010766756: Indices des prix de production des services français aux entreprises françaises (BtoB) − CPF 82.11 − Services administratifs combinés | E15: monthly package | F15: 2400 | G15: 2021-11 | H15: 2400
A16: Insurance, accounting, software | C16: ADMIN_SERVICES | D16: INSEE BDM 010766756: Indices des prix de production des services français aux entreprises françaises (BtoB) − CPF 82.11 − Services administratifs combinés | E16: monthly package | F16: 2400 | G16: 2021-12 | H16: 2400
... A40: Insurance, accounting, software | C40: ADMIN_SERVICES | D40: INSEE BDM 010766756: Indices des prix de production des services français aux entreprises françaises (BtoB) − CPF 82.11 − Services administratifs combinés | E40: monthly package | F40: 2400 | G40: 2023-12 | H40: 2400
A41: Butter, cream and dairy fats | B41: Fats | C41: DAIRY_FATS | D41: INSEE BDM 010763706: Indice de prix de production de l'industrie française pour le marché français − CPF 10.51 − Produits laitiers et fromages pour grossistes et restaurateurs | E41: kg/L | F41: 4.2 | G41: 2021-01 | H41: 4.2
A42: Butter, cream and dairy fats | B42: Fats | C42: DAIRY_FATS | D42: INSEE BDM 010763706: Indice de prix de production de l'industrie française pour le marché français − CPF 10.51 − Produits laitiers et fromages pour grossistes et restaurateurs | E42: kg/L | F42: 4.2 | G42: 2021-02 | H42: 4.2522
A43: Butter, cream and dairy fats | B43: Fats | C43: DAIRY_FATS | D43: INSEE BDM 010763706: Indice de prix de production de l'industrie française pour le marché français − CPF 10.51 − Produits laitiers et fromages pour grossistes et restaurateurs | E43: kg/L | F43: 4.2 | G43: 2021-03 | H43: 4.3174
A44: Butter, cream and dairy fats | B44: Fats | C44: DAIRY_FATS | D44: INSEE BDM 010763706: Indice de prix de production de l'industrie française pour le marché français − CPF 10.51 − Produits laitiers et fromages pour grossistes et restaurateurs | E44: kg/L | F44: 4.2 | G44: 2021-04 | H44: 4.3435
A45: Butter, cream and dairy fats | B45: Fats | C45: DAIRY_FATS | D45: INSEE BDM 010763706: Indice de prix de production de l'industrie française pour le marché français − CPF 10.51 − Produits laitiers et fromages pour grossistes et restaurateurs | E45: kg/L | F45: 4.2 | G45: 2021-05 | H45: 4.3652
A46: Butter, cream and dairy fats | B46: Fats | C46: DAIRY_FATS | D46: INSEE BDM 010763706: Indice de prix de production de l'industrie française pour le marché français − CPF 10.51 − Produits laitiers et fromages pour grossistes et restaurateurs | E46: kg/L | F46: 4.2 | G46: 2021-06 | H46: 4.3522
A47: Butter, cream and dairy fats | B47: Fats | C47: DAIRY_FATS | D47: INSEE BDM 010763706: Indice de prix de production de l'industrie française pour le marché français − CPF 10.51 − Produits laitiers et fromages pour grossistes et restaurateurs | E47: kg/L | F47: 4.2 | G47: 2021-07 | H47: 4.3957
A48: Butter, cream and dairy fats | B48: Fats | C48: DAIRY_FATS | D48: INSEE BDM 010763706: Indice de prix de production de l'industrie française pour le marché français − CPF 10.51 − Produits laitiers et fromages pour grossistes et restaurateurs | E48: kg/L | F48: 4.2 | G48: 2021-08 | H48: 4.387
A49: Butter, cream and dairy fats | B49: Fats | C49: DAIRY_FATS | D49: INSEE BDM 010763706: Indice de prix de production de l'industrie française pour le marché français − CPF 10.51 − Produits laitiers et fromages pour grossistes et restaurateurs | E49: kg/L | F49: 4.2 | G49: 2021-09 | H49: 4.387
A50: Butter, cream and dairy fats | B50: Fats | C50: DAIRY_FATS | D50: INSEE BDM 010763706: Indice de prix de production de l'industrie française pour le marché français − CPF 10.51 − Produits laitiers et fromages pour grossistes et restaurateurs | E50: kg/L | F50: 4.2 | G50: 2021-10 | H50: 4.3391
A51: Butter, cream and dairy fats | B51: Fats | C51: DAIRY_FATS | D51: INSEE BDM 010763706: Indice de prix de production de l'industrie française pour le marché français − CPF 10.51 − Produits laitiers et fromages pour grossistes et restaurateurs | E51: kg/L | F51: 4.2 | G51: 2021-11 | H51: 4.4739
A52: Butter, cream and dairy fats | B52: Fats | C52: DAIRY_FATS | D52: INSEE BDM 010763706: Indice de prix de production de l'industrie française pour le marché français − CPF 10.51 − Produits laitiers et fromages pour grossistes et restaurateurs | E52: kg/L | F52: 4.2 | G52: 2021-12 | H52: 4.3565
... A112: Electricity for kitchen and refrigeration | B112: Electricity | C112: ELECTRICITY | D112: INSEE BDM 010777317: Indice mensuel des prix d'achat des moyens de production agricole (IPAMPA) - Electricité | E112: kWh | F112: 0.17 | G112: 2023-12 | H112: 0.2235
A113: Food purchases | C113: FOOD_PRODUCTS | D113: INSEE BDM 010763739: Indice de prix de production de l'industrie française pour le marché français − CPF 10.8 − Autres produits alimentaires | E113: monthly package | F113: 10000 | G113: 2021-01 | H113: 10000
A114: Food purchases | C114: FOOD_PRODUCTS | D114: INSEE BDM 010763739: Indice de prix de production de l'industrie française pour le marché français − CPF 10.8 − Autres produits alimentaires | E114: monthly package | F114: 10000 | G114: 2021-02 | H114: 9939.8798
A115: Food purchases | C115: FOOD_PRODUCTS | D115: INSEE BDM 010763739: Indice de prix de production de l'industrie française pour le marché français − CPF 10.8 − Autres produits alimentaires | E115: monthly package | F115: 10000 | G115: 2021-03 | H115: 9979.9599
A116: Food purchases | C116: FOOD_PRODUCTS | D116: INSEE BDM 010763739: Indice de prix de production de l'industrie française pour le marché français − CPF 10.8 − Autres produits alimentaires | E116: monthly package | F116: 10000 | G116: 2021-04 | H116: 9969.9399
A117: Food purchases | C117: FOOD_PRODUCTS | D117: INSEE BDM 010763739: Indice de prix de production de l'industrie française pour le marché français − CPF 10.8 − Autres produits alimentaires | E117: monthly package | F117: 10000 | G117: 2021-05 | H117: 9989.98
A118: Food purchases | C118: FOOD_PRODUCTS | D118: INSEE BDM 010763739: Indice de prix de production de l'industrie française pour le marché français − CPF 10.8 − Autres produits alimentaires | E118: monthly package | F118: 10000 | G118: 2021-06 | H118: 10000
A119: Food purchases | C119: FOOD_PRODUCTS | D119: INSEE BDM 010763739: Indice de prix de production de l'industrie française pour le marché français − CPF 10.8 − Autres produits alimentaires | E119: monthly package | F119: 10000 | G119: 2021-07 | H119: 9959.9198
A120: Food purchases | C120: FOOD_PRODUCTS | D120: INSEE BDM 010763739: Indice de prix de production de l'industrie française pour le marché français − CPF 10.8 − Autres produits alimentaires | E120: monthly package | F120: 10000 | G120: 2021-08 | H120: 9969.9399
A121: Food purchases | C121: FOOD_PRODUCTS | D121: INSEE BDM 010763739: Indice de prix de production de l'industrie française pour le marché français − CPF 10.8 − Autres produits alimentaires | E121: monthly package | F121: 10000 | G121: 2021-09 | H121: 10040.08
A122: Food purchases | C122: FOOD_PRODUCTS | D122: INSEE BDM 010763739: Indice de prix de production de l'industrie française pour le marché français − CPF 10.8 − Autres produits alimentaires | E122: monthly package | F122: 10000 | G122: 2021-10 | H122: 10100.2
A123: Food purchases | C123: FOOD_PRODUCTS | D123: INSEE BDM 010763739: Indice de prix de production de l'industrie française pour le marché français − CPF 10.8 − Autres produits alimentaires | E123: monthly package | F123: 10000 | G123: 2021-11 | H123: 10160.321
...

Sheet Benchmarks & sources
A1: Restaurant - Benchmarks & sources
A2: Ratios and API sources used to construct the synthetic cash-plan model.
A4: Item | B4: Value retained | C4: Source | D4: Comment
A5: Annual revenue A1 | B5: 520000 | C5: Generated profile | D5: Editable in Hypotheses
A6: Archetype | B6: restaurant | C6: Local inference | D6: Selected from business description keywords
A7: Commodity API mode | B7: online | C7: Generator flag | D7: Offline mode uses deterministic synthetic series
A8: Commodity monthly history | B8: INSEE BDM, ENTSO-E, World Bank Pink Sheet or Alpha Vantage when enabled | C8: https://bdm.insee.fr/series/sdmx/dataflow | D8: Online mode uses curated INSEE IDBANK series first, then venue/API-specific market data and synthetic fallback only when unavailable.
A9: French statistical series | B9: INSEE BDM API | C9: https://www.insee.fr/fr/information/2862759 | D9: Official INSEE SDMX web service for time-series data. Exact series IDs can be configured later.
A10: Business ratios | B10: Generated benchmark assumptions | C10: local archetype generator | D10: Ratios are v1 synthetic assumptions, designed to be replaced by INSEE/sector benchmark series.
