Workbook

Sheet Hypotheses
A1: Menuiserie Bois - Hypotheses
A2: Metier: Industrial SME profile inferred from the business description. | Archetype: woodworking | CA cible A1: 1,500,000 EUR | Blue cells are editable
A4: Chiffre d'affaires annuel HT - Annee 1 (EUR) | C4: 1500000
A5: Taux de TVA moyen sur les ventes | C5: 0.2
A6: Taux de TVA moyen sur les achats | C6: 0.2
A7: Tresorerie disponible au 1er janvier A1 (EUR) | C7: 82500
A8: Cotisations sociales dirigeant - par trimestre A1 (EUR) | C8: 27000
A9: Remboursement emprunt materiel - mensualite fixe (EUR) | C9: 15000
A10: Part du CA encaissee le mois meme | C10: 1
A11: Part du CA encaissee a M-1 | C11: 0
A12: Part du CA encaissee a M-2 | C12: 0 | D12: Control should equal 100% | E12: =SUM(C10:C12)
A13: Taux de croissance du CA - par an | C13: 0.03
A14: Taux d'inflation des prix d'achat - par an | C14: 0.035
A16: Month pattern repeated every year | C16: Jan | D16: Feb | E16: Mar | F16: Apr | G16: May | H16: Jun | I16: Jul | J16: Aug | K16: Sep | L16: Oct | M16: Nov | N16: Dec
A17: Seasonality index (1 = average month) | C17: 1.02 | D17: 0.96 | E17: 0.98 | F17: 1 | G17: 1.02 | H17: 1.03 | I17: 1.04 | J17: 0.88 | K17: 1.03 | L17: 1.05 | M17: 1.02 | N17: 1.07
A18: Month weight in year (normalized) | C18: =C17/SUM($C$17:$N$17) | D18: =D17/SUM($C$17:$N$17) | E18: =E17/SUM($C$17:$N$17) | F18: =F17/SUM($C$17:$N$17) | G18: =G17/SUM($C$17:$N$17) | H18: =H17/SUM($C$17:$N$17) | I18: =I17/SUM($C$17:$N$17) | J18: =J17/SUM($C$17:$N$17) | ... N18: =N17/SUM($C$17:$N$17)
A21: v1 note: ratios and quantities are synthetic benchmark assumptions unless a source/API is explicitly listed.
A22: Commodity-linked rows preserve realistic monthly variation. External series are normalized to the model unit price.
A23: INSEE support is intentionally configurable by URL/series because exact indicators depend on the sector and use case.
A25: Legend
A26: Blue | B26: Editable assumption
A27: Gray | B27: Formula calculated automatically
A28: Light blue | B28: Link to another sheet
A29: Yellow | B29: Source/API note

Sheet Revenus
A1: Menuiserie Bois - Revenus mensuels
A2: Revenue streams x annual mix x seasonality x annual growth.
C3: ANNEE 1 | O3: ANNEE 2 | AA3: ANNEE 3
A4: Source de revenus | B4: % du CA annuel | C4: Jan A1 | D4: Feb A1 | E4: Mar A1 | F4: Apr A1 | G4: May A1 | H4: Jun A1 | I4: Jul A1 | J4: Aug A1 | K4: Sep A1 | L4: Oct A1 | M4: Nov A1 | N4: Dec A1 | O4: Jan A2 | P4: Feb A2 | Q4: Mar A2 | R4: Apr A2 | S4: May A2 | T4: Jun A2 | U4: Jul A2 | V4: Aug A2 | W4: Sep A2 | X4: Oct A2 | Y4: Nov A2 | Z4: Dec A2 | AA4: Jan A3 | AB4: Feb A3 | AC4: Mar A3 | AD4: Apr A3 | AE4: May A3 | AF4: Jun A3 | AG4: Jul A3 | AH4: Aug A3 | AI4: Sep A3 | AJ4: Oct A3 | AK4: Nov A3 | AL4: Dec A3
A5: Production contracts | B5: 0.62 | C5: ='Hypotheses'!$C$4*$B5*'Hypotheses'!C$18*(1+'Hypotheses'!$C$13)^0 | D5: ='Hypotheses'!$C$4*$B5*'Hypotheses'!D$18*(1+'Hypotheses'!$C$13)^0 | E5: ='Hypotheses'!$C$4*$B5*'Hypotheses'!E$18*(1+'Hypotheses'!$C$13)^0 | F5: ='Hypotheses'!$C$4*$B5*'Hypotheses'!F$18*(1+'Hypotheses'!$C$13)^0 | G5: ='Hypotheses'!$C$4*$B5*'Hypotheses'!G$18*(1+'Hypotheses'!$C$13)^0 | H5: ='Hypotheses'!$C$4*$B5*'Hypotheses'!H$18*(1+'Hypotheses'!$C$13)^0 | I5: ='Hypotheses'!$C$4*$B5*'Hypotheses'!I$18*(1+'Hypotheses'!$C$13)^0 | J5: ='Hypotheses'!$C$4*$B5*'Hypotheses'!J$18*(1+'Hypotheses'!$C$13)^0 | ... N5: ='Hypotheses'!$C$4*$B5*'Hypotheses'!N$18*(1+'Hypotheses'!$C$13)^0 | O5: ='Hypotheses'!$C$4*$B5*'Hypotheses'!C$18*(1+'Hypotheses'!$C$13)^1 | P5: ='Hypotheses'!$C$4*$B5*'Hypotheses'!D$18*(1+'Hypotheses'!$C$13)^1 | Q5: ='Hypotheses'!$C$4*$B5*'Hypotheses'!E$18*(1+'Hypotheses'!$C$13)^1 | R5: ='Hypotheses'!$C$4*$B5*'Hypotheses'!F$18*(1+'Hypotheses'!$C$13)^1 | S5: ='Hypotheses'!$C$4*$B5*'Hypotheses'!G$18*(1+'Hypotheses'!$C$13)^1 | T5: ='Hypotheses'!$C$4*$B5*'Hypotheses'!H$18*(1+'Hypotheses'!$C$13)^1 | U5: ='Hypotheses'!$C$4*$B5*'Hypotheses'!I$18*(1+'Hypotheses'!$C$13)^1 | V5: ='Hypotheses'!$C$4*$B5*'Hypotheses'!J$18*(1+'Hypotheses'!$C$13)^1 | ... Z5: ='Hypotheses'!$C$4*$B5*'Hypotheses'!N$18*(1+'Hypotheses'!$C$13)^1 | AA5: ='Hypotheses'!$C$4*$B5*'Hypotheses'!C$18*(1+'Hypotheses'!$C$13)^2 | AB5: ='Hypotheses'!$C$4*$B5*'Hypotheses'!D$18*(1+'Hypotheses'!$C$13)^2 | AC5: ='Hypotheses'!$C$4*$B5*'Hypotheses'!E$18*(1+'Hypotheses'!$C$13)^2 | AD5: ='Hypotheses'!$C$4*$B5*'Hypotheses'!F$18*(1+'Hypotheses'!$C$13)^2 | AE5: ='Hypotheses'!$C$4*$B5*'Hypotheses'!G$18*(1+'Hypotheses'!$C$13)^2 | AF5: ='Hypotheses'!$C$4*$B5*'Hypotheses'!H$18*(1+'Hypotheses'!$C$13)^2 | AG5: ='Hypotheses'!$C$4*$B5*'Hypotheses'!I$18*(1+'Hypotheses'!$C$13)^2 | AH5: ='Hypotheses'!$C$4*$B5*'Hypotheses'!J$18*(1+'Hypotheses'!$C$13)^2 | ... AL5: ='Hypotheses'!$C$4*$B5*'Hypotheses'!N$18*(1+'Hypotheses'!$C$13)^2
A6: Small series and custom jobs | B6: 0.24 | C6: ='Hypotheses'!$C$4*$B6*'Hypotheses'!C$18*(1+'Hypotheses'!$C$13)^0 | D6: ='Hypotheses'!$C$4*$B6*'Hypotheses'!D$18*(1+'Hypotheses'!$C$13)^0 | E6: ='Hypotheses'!$C$4*$B6*'Hypotheses'!E$18*(1+'Hypotheses'!$C$13)^0 | F6: ='Hypotheses'!$C$4*$B6*'Hypotheses'!F$18*(1+'Hypotheses'!$C$13)^0 | G6: ='Hypotheses'!$C$4*$B6*'Hypotheses'!G$18*(1+'Hypotheses'!$C$13)^0 | H6: ='Hypotheses'!$C$4*$B6*'Hypotheses'!H$18*(1+'Hypotheses'!$C$13)^0 | I6: ='Hypotheses'!$C$4*$B6*'Hypotheses'!I$18*(1+'Hypotheses'!$C$13)^0 | J6: ='Hypotheses'!$C$4*$B6*'Hypotheses'!J$18*(1+'Hypotheses'!$C$13)^0 | ... N6: ='Hypotheses'!$C$4*$B6*'Hypotheses'!N$18*(1+'Hypotheses'!$C$13)^0 | O6: ='Hypotheses'!$C$4*$B6*'Hypotheses'!C$18*(1+'Hypotheses'!$C$13)^1 | P6: ='Hypotheses'!$C$4*$B6*'Hypotheses'!D$18*(1+'Hypotheses'!$C$13)^1 | Q6: ='Hypotheses'!$C$4*$B6*'Hypotheses'!E$18*(1+'Hypotheses'!$C$13)^1 | R6: ='Hypotheses'!$C$4*$B6*'Hypotheses'!F$18*(1+'Hypotheses'!$C$13)^1 | S6: ='Hypotheses'!$C$4*$B6*'Hypotheses'!G$18*(1+'Hypotheses'!$C$13)^1 | T6: ='Hypotheses'!$C$4*$B6*'Hypotheses'!H$18*(1+'Hypotheses'!$C$13)^1 | U6: ='Hypotheses'!$C$4*$B6*'Hypotheses'!I$18*(1+'Hypotheses'!$C$13)^1 | V6: ='Hypotheses'!$C$4*$B6*'Hypotheses'!J$18*(1+'Hypotheses'!$C$13)^1 | ... Z6: ='Hypotheses'!$C$4*$B6*'Hypotheses'!N$18*(1+'Hypotheses'!$C$13)^1 | AA6: ='Hypotheses'!$C$4*$B6*'Hypotheses'!C$18*(1+'Hypotheses'!$C$13)^2 | AB6: ='Hypotheses'!$C$4*$B6*'Hypotheses'!D$18*(1+'Hypotheses'!$C$13)^2 | AC6: ='Hypotheses'!$C$4*$B6*'Hypotheses'!E$18*(1+'Hypotheses'!$C$13)^2 | AD6: ='Hypotheses'!$C$4*$B6*'Hypotheses'!F$18*(1+'Hypotheses'!$C$13)^2 | AE6: ='Hypotheses'!$C$4*$B6*'Hypotheses'!G$18*(1+'Hypotheses'!$C$13)^2 | AF6: ='Hypotheses'!$C$4*$B6*'Hypotheses'!H$18*(1+'Hypotheses'!$C$13)^2 | AG6: ='Hypotheses'!$C$4*$B6*'Hypotheses'!I$18*(1+'Hypotheses'!$C$13)^2 | AH6: ='Hypotheses'!$C$4*$B6*'Hypotheses'!J$18*(1+'Hypotheses'!$C$13)^2 | ... AL6: ='Hypotheses'!$C$4*$B6*'Hypotheses'!N$18*(1+'Hypotheses'!$C$13)^2
A7: Maintenance, tooling and services | B7: 0.14 | C7: ='Hypotheses'!$C$4*$B7*'Hypotheses'!C$18*(1+'Hypotheses'!$C$13)^0 | D7: ='Hypotheses'!$C$4*$B7*'Hypotheses'!D$18*(1+'Hypotheses'!$C$13)^0 | E7: ='Hypotheses'!$C$4*$B7*'Hypotheses'!E$18*(1+'Hypotheses'!$C$13)^0 | F7: ='Hypotheses'!$C$4*$B7*'Hypotheses'!F$18*(1+'Hypotheses'!$C$13)^0 | G7: ='Hypotheses'!$C$4*$B7*'Hypotheses'!G$18*(1+'Hypotheses'!$C$13)^0 | H7: ='Hypotheses'!$C$4*$B7*'Hypotheses'!H$18*(1+'Hypotheses'!$C$13)^0 | I7: ='Hypotheses'!$C$4*$B7*'Hypotheses'!I$18*(1+'Hypotheses'!$C$13)^0 | J7: ='Hypotheses'!$C$4*$B7*'Hypotheses'!J$18*(1+'Hypotheses'!$C$13)^0 | ... N7: ='Hypotheses'!$C$4*$B7*'Hypotheses'!N$18*(1+'Hypotheses'!$C$13)^0 | O7: ='Hypotheses'!$C$4*$B7*'Hypotheses'!C$18*(1+'Hypotheses'!$C$13)^1 | P7: ='Hypotheses'!$C$4*$B7*'Hypotheses'!D$18*(1+'Hypotheses'!$C$13)^1 | Q7: ='Hypotheses'!$C$4*$B7*'Hypotheses'!E$18*(1+'Hypotheses'!$C$13)^1 | R7: ='Hypotheses'!$C$4*$B7*'Hypotheses'!F$18*(1+'Hypotheses'!$C$13)^1 | S7: ='Hypotheses'!$C$4*$B7*'Hypotheses'!G$18*(1+'Hypotheses'!$C$13)^1 | T7: ='Hypotheses'!$C$4*$B7*'Hypotheses'!H$18*(1+'Hypotheses'!$C$13)^1 | U7: ='Hypotheses'!$C$4*$B7*'Hypotheses'!I$18*(1+'Hypotheses'!$C$13)^1 | V7: ='Hypotheses'!$C$4*$B7*'Hypotheses'!J$18*(1+'Hypotheses'!$C$13)^1 | ... Z7: ='Hypotheses'!$C$4*$B7*'Hypotheses'!N$18*(1+'Hypotheses'!$C$13)^1 | AA7: ='Hypotheses'!$C$4*$B7*'Hypotheses'!C$18*(1+'Hypotheses'!$C$13)^2 | AB7: ='Hypotheses'!$C$4*$B7*'Hypotheses'!D$18*(1+'Hypotheses'!$C$13)^2 | AC7: ='Hypotheses'!$C$4*$B7*'Hypotheses'!E$18*(1+'Hypotheses'!$C$13)^2 | AD7: ='Hypotheses'!$C$4*$B7*'Hypotheses'!F$18*(1+'Hypotheses'!$C$13)^2 | AE7: ='Hypotheses'!$C$4*$B7*'Hypotheses'!G$18*(1+'Hypotheses'!$C$13)^2 | AF7: ='Hypotheses'!$C$4*$B7*'Hypotheses'!H$18*(1+'Hypotheses'!$C$13)^2 | AG7: ='Hypotheses'!$C$4*$B7*'Hypotheses'!I$18*(1+'Hypotheses'!$C$13)^2 | AH7: ='Hypotheses'!$C$4*$B7*'Hypotheses'!J$18*(1+'Hypotheses'!$C$13)^2 | ... AL7: ='Hypotheses'!$C$4*$B7*'Hypotheses'!N$18*(1+'Hypotheses'!$C$13)^2
A8: TOTAL CA HT | C8: =SUM(C5:C7) | D8: =SUM(D5:D7) | E8: =SUM(E5:E7) | F8: =SUM(F5:F7) | G8: =SUM(G5:G7) | H8: =SUM(H5:H7) | I8: =SUM(I5:I7) | J8: =SUM(J5:J7) | ... AL8: =SUM(AL5:AL7)
A9: Control sum revenue mix | B9: =SUM(B5:B7)
A10: TVA collectee sur les ventes | C10: =C8*'Hypotheses'!$C$5 | D10: =D8*'Hypotheses'!$C$5 | E10: =E8*'Hypotheses'!$C$5 | F10: =F8*'Hypotheses'!$C$5 | G10: =G8*'Hypotheses'!$C$5 | H10: =H8*'Hypotheses'!$C$5 | I10: =I8*'Hypotheses'!$C$5 | J10: =J8*'Hypotheses'!$C$5 | ... AL10: =AL8*'Hypotheses'!$C$5
A11: CA TTC encaissable | C11: =C8+C10 | D11: =D8+D10 | E11: =E8+E10 | F11: =F8+F10 | G11: =G8+G10 | H11: =H8+H10 | I11: =I8+I10 | J11: =J8+J10 | ... AL11: =AL8+AL10

Sheet Depenses detaillees
A1: Menuiserie Bois - Depenses detaillees
A2: Quantity x seasonality x unit price x inflation = monthly cost. Market rows use monthly price series.
H3: ANNEE 1 | T3: ANNEE 2 | AF3: ANNEE 3
A4: Categorie | B4: Poste | C4: Qte base/mois A1 | D4: Unite | E4: Prix unitaire A1 | F4: Underlying | G4: Source prix | H4: Jan A1 | I4: Feb A1 | J4: Mar A1 | K4: Apr A1 | L4: May A1 | M4: Jun A1 | N4: Jul A1 | O4: Aug A1 | P4: Sep A1 | Q4: Oct A1 | R4: Nov A1 | S4: Dec A1 | T4: Jan A2 | U4: Feb A2 | V4: Mar A2 | W4: Apr A2 | X4: May A2 | Y4: Jun A2 | Z4: Jul A2 | AA4: Aug A2 | AB4: Sep A2 | AC4: Oct A2 | AD4: Nov A2 | AE4: Dec A2 | AF4: Jan A3 | AG4: Feb A3 | AH4: Mar A3 | AI4: Apr A3 | AJ4: May A3 | AK4: Jun A3 | AL4: Jul A3 | AM4: Aug A3 | AN4: Sep A3 | AO4: Oct A3 | AP4: Nov A3 | AQ4: Dec A3
A5: Raw materials | B5: Timber, boards and panels - market price | C5: 73.4754 | D5: m3 | E5: =AVERAGE(H5:AQ5) | F5: Wood | G5: INSEE BDM 010762320: Cours des matières premières importées - Bois de charpente - Contrats à terme à la 1ère échéance portant sur 27500 pied-planches livrés à Chicago - Chicago Mercantile Exchange - Prix en dollars US pour 1000 pied-planches (424 pied-planches = 1 mètre cube); normalized to model unit price
A6: Raw materials | B6: Cost (Timber, boards and panels) | C6: 73.4754 | D6: m3 | E6: =E5 | F6: Wood | G6: Cost = quantity x seasonality x monthly market price | H6: =$C6*'Hypotheses'!C$17*H5 | I6: =$C6*'Hypotheses'!D$17*I5 | J6: =$C6*'Hypotheses'!E$17*J5 | K6: =$C6*'Hypotheses'!F$17*K5 | L6: =$C6*'Hypotheses'!G$17*L5 | M6: =$C6*'Hypotheses'!H$17*M5 | N6: =$C6*'Hypotheses'!I$17*N5 | O6: =$C6*'Hypotheses'!J$17*O5 | ... S6: =$C6*'Hypotheses'!N$17*S5 | T6: =$C6*'Hypotheses'!C$17*T5 | U6: =$C6*'Hypotheses'!D$17*U5 | V6: =$C6*'Hypotheses'!E$17*V5 | W6: =$C6*'Hypotheses'!F$17*W5 | X6: =$C6*'Hypotheses'!G$17*X5 | Y6: =$C6*'Hypotheses'!H$17*Y5 | Z6: =$C6*'Hypotheses'!I$17*Z5 | AA6: =$C6*'Hypotheses'!J$17*AA5 | ... AE6: =$C6*'Hypotheses'!N$17*AE5 | AF6: =$C6*'Hypotheses'!C$17*AF5 | AG6: =$C6*'Hypotheses'!D$17*AG5 | AH6: =$C6*'Hypotheses'!E$17*AH5 | AI6: =$C6*'Hypotheses'!F$17*AI5 | AJ6: =$C6*'Hypotheses'!G$17*AJ5 | AK6: =$C6*'Hypotheses'!H$17*AK5 | AL6: =$C6*'Hypotheses'!I$17*AL5 | AM6: =$C6*'Hypotheses'!J$17*AM5 | ... AQ6: =$C6*'Hypotheses'!N$17*AQ5
A7: Raw materials | B7: Glue, varnish and oil-linked finishing chemicals - market price | C7: 797.9051 | D7: kg | E7: =AVERAGE(H7:AQ7) | F7: Oil | G7: INSEE BDM 010002078: Cours des matières premières importées - Pétrole brut Brent (Londres) - Prix au comptant en euros par baril ; normalized to model unit price | H7: 5.4 | I7: 6.18 | J7: 6.6 | K7: 6.492 | L7: 6.768 | M7: 7.296 | N7: 7.62 | O7: 7.224 | P7: 7.596 | Q7: 8.64 | R7: 8.52 | S7: 7.896 | T7: 9.18 | U7: 10.248 | V7: 12.768 | W7: 11.604 | X7: 12.828 | Y7: 13.86 | Z7: 13.188 | AA7: 11.928 | AB7: 10.872 | AC7: 11.4 | AD7: 10.764 | AE7: 9.18 | AF7: 9.192 | AG7: 9.276 | AH7: 8.796 | AI7: 9.264 | AJ7: 8.352 | AK7: 8.28 | AL7: 8.688 | AM7: 9.468 | AN7: 10.5 | AO7: 10.296 | AP7: 9.216 | AQ7: 8.544
A8: Raw materials | B8: Cost (Glue, varnish and oil-linked finishing chemicals) | C8: 797.9051 | D8: kg | E8: =E7 | F8: Oil | G8: Cost = quantity x seasonality x monthly market price | H8: =$C8*'Hypotheses'!C$17*H7 | I8: =$C8*'Hypotheses'!D$17*I7 | J8: =$C8*'Hypotheses'!E$17*J7 | K8: =$C8*'Hypotheses'!F$17*K7 | L8: =$C8*'Hypotheses'!G$17*L7 | M8: =$C8*'Hypotheses'!H$17*M7 | N8: =$C8*'Hypotheses'!I$17*N7 | O8: =$C8*'Hypotheses'!J$17*O7 | ... S8: =$C8*'Hypotheses'!N$17*S7 | T8: =$C8*'Hypotheses'!C$17*T7 | U8: =$C8*'Hypotheses'!D$17*U7 | V8: =$C8*'Hypotheses'!E$17*V7 | W8: =$C8*'Hypotheses'!F$17*W7 | X8: =$C8*'Hypotheses'!G$17*X7 | Y8: =$C8*'Hypotheses'!H$17*Y7 | Z8: =$C8*'Hypotheses'!I$17*Z7 | AA8: =$C8*'Hypotheses'!J$17*AA7 | ... AE8: =$C8*'Hypotheses'!N$17*AE7 | AF8: =$C8*'Hypotheses'!C$17*AF7 | AG8: =$C8*'Hypotheses'!D$17*AG7 | AH8: =$C8*'Hypotheses'!E$17*AH7 | AI8: =$C8*'Hypotheses'!F$17*AI7 | AJ8: =$C8*'Hypotheses'!G$17*AJ7 | AK8: =$C8*'Hypotheses'!H$17*AK7 | AL8: =$C8*'Hypotheses'!I$17*AL7 | AM8: =$C8*'Hypotheses'!J$17*AM7 | ... AQ8: =$C8*'Hypotheses'!N$17*AQ7
A9: Raw materials | B9: Steel screws, brackets and structural hardware - market price | C9: 2593.7982 | D9: kg | E9: =AVERAGE(H9:AQ9) | F9: Steel | G9: INSEE BDM 010002059: Cours des matières premières importées - Minerai de fer, Type 62 % Fe - Importations chinoises, port de Tianjin - Prix au comptant - CAF - Prix en dollars US par tonne; normalized to model unit price | H9: 0.95 | I9: 0.9175 | J9: 0.9422 | K9: 1.0071 | L9: 1.1634 | M9: 1.2009 | N9: 1.1993 | O9: 0.9085 | P9: 0.6974 | Q9: 0.6884 | R9: 0.5389 | S9: 0.6554 | T9: 0.7422 | U9: 0.7999 | V9: 0.852 | W9: 0.8469 | X9: 0.7349 | Y9: 0.7321 | Z9: 0.6083 | AA9: 0.6094 | AB9: 0.559 | AC9: 0.5187 | AD9: 0.5226 | AE9: 0.6262 | AF9: 0.6845 | AG9: 0.7147 | AH9: 0.7192 | AI9: 0.6576 | AJ9: 0.5893 | AK9: 0.6352 | AL9: 0.6408 | AM9: 0.6173 | AN9: 0.6778 | AO9: 0.6666 | AP9: 0.7343 | AQ9: 0.768
A10: Raw materials | B10: Cost (Steel screws, brackets and structural hardware) | C10: 2593.7982 | D10: kg | E10: =E9 | F10: Steel | G10: Cost = quantity x seasonality x monthly market price | H10: =$C10*'Hypotheses'!C$17*H9 | I10: =$C10*'Hypotheses'!D$17*I9 | J10: =$C10*'Hypotheses'!E$17*J9 | K10: =$C10*'Hypotheses'!F$17*K9 | L10: =$C10*'Hypotheses'!G$17*L9 | M10: =$C10*'Hypotheses'!H$17*M9 | N10: =$C10*'Hypotheses'!I$17*N9 | O10: =$C10*'Hypotheses'!J$17*O9 | ... S10: =$C10*'Hypotheses'!N$17*S9 | T10: =$C10*'Hypotheses'!C$17*T9 | U10: =$C10*'Hypotheses'!D$17*U9 | V10: =$C10*'Hypotheses'!E$17*V9 | W10: =$C10*'Hypotheses'!F$17*W9 | X10: =$C10*'Hypotheses'!G$17*X9 | Y10: =$C10*'Hypotheses'!H$17*Y9 | Z10: =$C10*'Hypotheses'!I$17*Z9 | AA10: =$C10*'Hypotheses'!J$17*AA9 | ... AE10: =$C10*'Hypotheses'!N$17*AE9 | AF10: =$C10*'Hypotheses'!C$17*AF9 | AG10: =$C10*'Hypotheses'!D$17*AG9 | AH10: =$C10*'Hypotheses'!E$17*AH9 | AI10: =$C10*'Hypotheses'!F$17*AI9 | AJ10: =$C10*'Hypotheses'!G$17*AJ9 | AK10: =$C10*'Hypotheses'!H$17*AK9 | AL10: =$C10*'Hypotheses'!I$17*AL9 | AM10: =$C10*'Hypotheses'!J$17*AM9 | ... AQ10: =$C10*'Hypotheses'!N$17*AQ9
A11: Raw materials | B11: Zinc-plated hinges, fasteners and handles - market price | C11: 520.1112 | D11: kg | E11: =AVERAGE(H11:AQ11) | F11: Zinc | G11: INSEE BDM 010002072: Cours des matières premières importées - Zinc, Pureté 99,995% - prix d’acquisition au comptant, LME (London Metal Exchange) - Prix en dollars US par tonne; normalized to model unit price | H11: 2.8 | I11: 2.8367 | J11: 2.8869 | K11: 2.9237 | L11: 3.0716 | M11: 3.0507 | N11: 3.0433 | O11: 3.0908 | P11: 3.1447 | Q11: 3.4836 | R11: 3.429 | S11: 3.5229 | T11: 3.7316 | U11: 3.7673 | V11: 4.1083 | W11: 4.5188 | X11: 3.8862 | Y11: 3.7668 | Z11: 3.2015 | AA11: 3.693 | AB11: 3.2419 | AC11: 3.0591 | AD11: 3.0218 | AE11: 3.2334 | AF11: 3.3998 | AG11: 3.2494 | AH11: 3.0556 | AI11: 2.8658 | AJ11: 2.5609 | AK11: 2.4479 | AL11: 2.4771 | AM11: 2.4817 | AN11: 2.5722 | AO11: 2.5318 | AP11: 2.6294 | AQ11: 2.5862
A12: Raw materials | B12: Cost (Zinc-plated hinges, fasteners and handles) | C12: 520.1112 | D12: kg | E12: =E11 | F12: Zinc | G12: Cost = quantity x seasonality x monthly market price | H12: =$C12*'Hypotheses'!C$17*H11 | I12: =$C12*'Hypotheses'!D$17*I11 | J12: =$C12*'Hypotheses'!E$17*J11 | K12: =$C12*'Hypotheses'!F$17*K11 | L12: =$C12*'Hypotheses'!G$17*L11 | M12: =$C12*'Hypotheses'!H$17*M11 | N12: =$C12*'Hypotheses'!I$17*N11 | O12: =$C12*'Hypotheses'!J$17*O11 | ... S12: =$C12*'Hypotheses'!N$17*S11 | T12: =$C12*'Hypotheses'!C$17*T11 | U12: =$C12*'Hypotheses'!D$17*U11 | V12: =$C12*'Hypotheses'!E$17*V11 | W12: =$C12*'Hypotheses'!F$17*W11 | X12: =$C12*'Hypotheses'!G$17*X11 | Y12: =$C12*'Hypotheses'!H$17*Y11 | Z12: =$C12*'Hypotheses'!I$17*Z11 | AA12: =$C12*'Hypotheses'!J$17*AA11 | ... AE12: =$C12*'Hypotheses'!N$17*AE11 | AF12: =$C12*'Hypotheses'!C$17*AF11 | AG12: =$C12*'Hypotheses'!D$17*AG11 | AH12: =$C12*'Hypotheses'!E$17*AH11 | AI12: =$C12*'Hypotheses'!F$17*AI11 | AJ12: =$C12*'Hypotheses'!G$17*AJ11 | AK12: =$C12*'Hypotheses'!H$17*AK11 | AL12: =$C12*'Hypotheses'!I$17*AL11 | AM12: =$C12*'Hypotheses'!J$17*AM11 | ... AQ12: =$C12*'Hypotheses'!N$17*AQ11
A13: Raw materials | B13: Aluminium rails and light fittings - market price | C13: 595.5344 | D13: kg | E13: =AVERAGE(H13:AQ13) | F13: Aluminium | G13: INSEE BDM 010002041: Cours des matières premières importées - Aluminium, pureté 99,7 % - Prix d’acquisition au comptant, LME (London Metal Exchange) - Prix en dollars US par tonne; normalized to model unit price | H13: 2.6 | I13: 2.6984 | J13: 2.8437 | K13: 3.0152 | L13: 3.1579 | M13: 3.1648 | N13: 3.2335 | O13: 3.3873 | P13: 3.684 | Q13: 3.8336 | R13: 3.4264 | S13: 3.4961 | T13: 3.8955 | U13: 4.2296 | V13: 4.589 | W13: 4.2243 | X13: 3.6662 | Y13: 3.3245 | Z13: 3.1149 | AA13: 3.1537 | AB13: 2.8923 | AC13: 2.9097 | AD13: 3.0291 | AE13: 3.1064 | AF13: 3.2285 | AG13: 3.1352 | AH13: 2.9704 | AI13: 3.0365 | AJ13: 2.9413 | AK13: 2.8291 | AL13: 2.7918 | AM13: 2.7682 | AN13: 2.8246 | AO13: 2.8439 | AP13: 2.8567 | AQ13: 2.8205
A14: Raw materials | B14: Cost (Aluminium rails and light fittings) | C14: 595.5344 | D14: kg | E14: =E13 | F14: Aluminium | G14: Cost = quantity x seasonality x monthly market price | H14: =$C14*'Hypotheses'!C$17*H13 | I14: =$C14*'Hypotheses'!D$17*I13 | J14: =$C14*'Hypotheses'!E$17*J13 | K14: =$C14*'Hypotheses'!F$17*K13 | L14: =$C14*'Hypotheses'!G$17*L13 | M14: =$C14*'Hypotheses'!H$17*M13 | N14: =$C14*'Hypotheses'!I$17*N13 | O14: =$C14*'Hypotheses'!J$17*O13 | ... S14: =$C14*'Hypotheses'!N$17*S13 | T14: =$C14*'Hypotheses'!C$17*T13 | U14: =$C14*'Hypotheses'!D$17*U13 | V14: =$C14*'Hypotheses'!E$17*V13 | W14: =$C14*'Hypotheses'!F$17*W13 | X14: =$C14*'Hypotheses'!G$17*X13 | Y14: =$C14*'Hypotheses'!H$17*Y13 | Z14: =$C14*'Hypotheses'!I$17*Z13 | AA14: =$C14*'Hypotheses'!J$17*AA13 | ... AE14: =$C14*'Hypotheses'!N$17*AE13 | AF14: =$C14*'Hypotheses'!C$17*AF13 | AG14: =$C14*'Hypotheses'!D$17*AG13 | AH14: =$C14*'Hypotheses'!E$17*AH13 | AI14: =$C14*'Hypotheses'!F$17*AI13 | AJ14: =$C14*'Hypotheses'!G$17*AJ13 | AK14: =$C14*'Hypotheses'!H$17*AK13 | AL14: =$C14*'Hypotheses'!I$17*AL13 | AM14: =$C14*'Hypotheses'!J$17*AM13 | ... AQ14: =$C14*'Hypotheses'!N$17*AQ13
A15: SOUS-TOTAL Raw materials | H15: =SUM(H6,H8,H10,H12,H14) | I15: =SUM(I6,I8,I10,I12,I14) | J15: =SUM(J6,J8,J10,J12,J14) | K15: =SUM(K6,K8,K10,K12,K14) | L15: =SUM(L6,L8,L10,L12,L14) | M15: =SUM(M6,M8,M10,M12,M14) | N15: =SUM(N6,N8,N10,N12,N14) | O15: =SUM(O6,O8,O10,O12,O14) | ... AQ15: =SUM(AQ6,AQ8,AQ10,AQ12,AQ14)
A16: Energy | B16: Electricity for CNC, saws and dust extraction - market price | C16: 19214.321 | D16: kWh | E16: =AVERAGE(H16:AQ16) | F16: Electricity | G16: INSEE BDM 010777317: Indice mensuel des prix d'achat des moyens de production agricole (IPAMPA) - Electricité; normalized to model unit price | H16: 0.16 | I16: 0.1624 | J16: 0.1624 | K16: 0.1624 | L16: 0.1625 | M16: 0.1625 | N16: 0.1625 | O16: 0.1635 | P16: 0.1635 | Q16: 0.164 | R16: 0.1651 | S16: 0.1647 | T16: 0.1662 | U16: 0.1703 | V16: 0.1722 | W16: 0.1736 | X16: 0.173 | Y16: 0.1749 | Z16: 0.176 | AA16: 0.1761 | AB16: 0.1809 | AC16: 0.1784 | AD16: 0.1814 | AE16: 0.1768 | AF16: 0.1714 | AG16: 0.1875 | AH16: 0.1912 | AI16: 0.1931 | AJ16: 0.1926 | AK16: 0.1924 | AL16: 0.1924 | AM16: 0.2078 | AN16: 0.21 | AO16: 0.2113 | AP16: 0.2105 | AQ16: 0.2103
A17: Energy | B17: Cost (Electricity for CNC, saws and dust extraction) | C17: 19214.321 | D17: kWh | E17: =E16 | F17: Electricity | G17: Cost = quantity x seasonality x monthly market price | H17: =$C17*'Hypotheses'!C$17*H16 | I17: =$C17*'Hypotheses'!D$17*I16 | J17: =$C17*'Hypotheses'!E$17*J16 | K17: =$C17*'Hypotheses'!F$17*K16 | L17: =$C17*'Hypotheses'!G$17*L16 | M17: =$C17*'Hypotheses'!H$17*M16 | N17: =$C17*'Hypotheses'!I$17*N16 | O17: =$C17*'Hypotheses'!J$17*O16 | ... S17: =$C17*'Hypotheses'!N$17*S16 | T17: =$C17*'Hypotheses'!C$17*T16 | U17: =$C17*'Hypotheses'!D$17*U16 | V17: =$C17*'Hypotheses'!E$17*V16 | W17: =$C17*'Hypotheses'!F$17*W16 | X17: =$C17*'Hypotheses'!G$17*X16 | Y17: =$C17*'Hypotheses'!H$17*Y16 | Z17: =$C17*'Hypotheses'!I$17*Z16 | AA17: =$C17*'Hypotheses'!J$17*AA16 | ... AE17: =$C17*'Hypotheses'!N$17*AE16 | AF17: =$C17*'Hypotheses'!C$17*AF16 | AG17: =$C17*'Hypotheses'!D$17*AG16 | AH17: =$C17*'Hypotheses'!E$17*AH16 | AI17: =$C17*'Hypotheses'!F$17*AI16 | AJ17: =$C17*'Hypotheses'!G$17*AJ16 | AK17: =$C17*'Hypotheses'!H$17*AK16 | AL17: =$C17*'Hypotheses'!I$17*AL16 | AM17: =$C17*'Hypotheses'!J$17*AM16 | ... AQ17: =$C17*'Hypotheses'!N$17*AQ16
A18: SOUS-TOTAL Energy | H18: =SUM(H17) | I18: =SUM(I17) | J18: =SUM(J17) | K18: =SUM(K17) | L18: =SUM(L17) | M18: =SUM(M17) | N18: =SUM(N17) | O18: =SUM(O17) | ... AQ18: =SUM(AQ17)
A19: Fuel and mobility | B19: Delivery fuel - market price | C19: 1881.2612 | D19: L | E19: =AVERAGE(H19:AQ19) | F19: Oil | G19: INSEE BDM 010002076: Cours des matières premières importées - Gazole à faible teneur en soufre - Prix en euros par tonne - CAF - 1% de soufre; normalized to model unit price | H19: 1.62 | I19: 1.8426 | J19: 1.9319 | K19: 1.9055 | L19: 2.0115 | M19: 2.161 | N19: 2.2288 | O19: 2.1654 | P19: 2.351 | Q19: 2.7408 | R19: 2.6638 | S19: 2.5164 | T19: 2.9022 | U19: 3.2268 | V19: 4.5798 | W19: 4.4676 | X19: 4.7148 | Y19: 5.3966 | Z19: 4.8169 | AA19: 4.622 | AB19: 4.5261 | AC19: 5.0421 | AD19: 4.268 | AE19: 3.6834 | AF19: 3.7749 | AG19: 3.3671 | AH19: 3.2519 | AI19: 3.0007 | AJ19: 2.7496 | AK19: 2.8727 | AL19: 3.0931 | AM19: 3.6693 | AN19: 4.0102 | AO19: 3.7586 | AP19: 3.3966 | AQ19: 3.1353
A20: Fuel and mobility | B20: Cost (Delivery fuel) | C20: 1881.2612 | D20: L | E20: =E19 | F20: Oil | G20: Cost = quantity x seasonality x monthly market price | H20: =$C20*'Hypotheses'!C$17*H19 | I20: =$C20*'Hypotheses'!D$17*I19 | J20: =$C20*'Hypotheses'!E$17*J19 | K20: =$C20*'Hypotheses'!F$17*K19 | L20: =$C20*'Hypotheses'!G$17*L19 | M20: =$C20*'Hypotheses'!H$17*M19 | N20: =$C20*'Hypotheses'!I$17*N19 | O20: =$C20*'Hypotheses'!J$17*O19 | ... S20: =$C20*'Hypotheses'!N$17*S19 | T20: =$C20*'Hypotheses'!C$17*T19 | U20: =$C20*'Hypotheses'!D$17*U19 | V20: =$C20*'Hypotheses'!E$17*V19 | W20: =$C20*'Hypotheses'!F$17*W19 | X20: =$C20*'Hypotheses'!G$17*X19 | Y20: =$C20*'Hypotheses'!H$17*Y19 | Z20: =$C20*'Hypotheses'!I$17*Z19 | AA20: =$C20*'Hypotheses'!J$17*AA19 | ... AE20: =$C20*'Hypotheses'!N$17*AE19 | AF20: =$C20*'Hypotheses'!C$17*AF19 | AG20: =$C20*'Hypotheses'!D$17*AG19 | AH20: =$C20*'Hypotheses'!E$17*AH19 | AI20: =$C20*'Hypotheses'!F$17*AI19 | AJ20: =$C20*'Hypotheses'!G$17*AJ19 | AK20: =$C20*'Hypotheses'!H$17*AK19 | AL20: =$C20*'Hypotheses'!I$17*AL19 | AM20: =$C20*'Hypotheses'!J$17*AM19 | ... AQ20: =$C20*'Hypotheses'!N$17*AQ19
A21: SOUS-TOTAL Fuel and mobility | H21: =SUM(H20) | I21: =SUM(I20) | J21: =SUM(J20) | K21: =SUM(K20) | L21: =SUM(L20) | M21: =SUM(M20) | N21: =SUM(N20) | O21: =SUM(O20) | ... AQ21: =SUM(AQ20)
A22: Personnel | B22: Workshop payroll and charges - market price | C22: 1.0083 | D22: monthly package | E22: =AVERAGE(H22:AQ22) | G22: INSEE BDM 010762004: Indice du coût du travail - Coût horaire - Industrie manufacturière (NAF rév. 2 section C) - Base 100 en 2020 ; normalized to model unit price | H22: 38750 | I22: 38750 | J22: 38750 | K22: 38750 | L22: 38750 | M22: 38750 | N22: 38750 | O22: 38750 | P22: 38750 | Q22: 38750 | R22: 38750 | S22: 38750 | T22: 38750 | U22: 38750 | V22: 38750 | W22: 38750 | X22: 38750 | Y22: 38750 | Z22: 38750 | AA22: 38750 | AB22: 38750 | AC22: 38750 | AD22: 38750 | AE22: 38750 | AF22: 38750 | AG22: 38750 | AH22: 38750 | AI22: 38750 | AJ22: 38750 | AK22: 38750 | AL22: 38750 | AM22: 38750 | AN22: 38750 | AO22: 38750 | AP22: 38750 | AQ22: 38750
A23: Personnel | B23: Cost (Workshop payroll and charges) | C23: 1.0083 | D23: monthly package | E23: =E22 | G23: Cost = quantity x seasonality x monthly market price | H23: =$C23*H22 | I23: =$C23*I22 | J23: =$C23*J22 | K23: =$C23*K22 | L23: =$C23*L22 | M23: =$C23*M22 | N23: =$C23*N22 | O23: =$C23*O22 | ... AQ23: =$C23*AQ22
A24: SOUS-TOTAL Personnel | H24: =SUM(H23) | I24: =SUM(I23) | J24: =SUM(J23) | K24: =SUM(K23) | L24: =SUM(L23) | M24: =SUM(M23) | N24: =SUM(N23) | O24: =SUM(O23) | ... AQ24: =SUM(AQ23)
A25: Fixed costs | B25: Workshop rent - market price | C25: 0.9647 | D25: monthly package | E25: =AVERAGE(H25:AQ25) | G25: INSEE BDM 001532540: Indice des loyers commerciaux (ILC) - Base 100 au 1er trimestre 2008; normalized to model unit price | H25: 9375 | I25: 9375 | J25: 9375 | K25: 9375 | L25: 9375 | M25: 9375 | N25: 9375 | O25: 9375 | P25: 9375 | Q25: 9375 | R25: 9375 | S25: 9375 | T25: 9375 | U25: 9375 | V25: 9375 | W25: 9375 | X25: 9375 | Y25: 9375 | Z25: 9375 | AA25: 9375 | AB25: 9375 | AC25: 9375 | AD25: 9375 | AE25: 9375 | AF25: 9375 | AG25: 9375 | AH25: 9375 | AI25: 9375 | AJ25: 9375 | AK25: 9375 | AL25: 9375 | AM25: 9375 | AN25: 9375 | AO25: 9375 | AP25: 9375 | AQ25: 9375
A26: Fixed costs | B26: Cost (Workshop rent) | C26: 0.9647 | D26: monthly package | E26: =E25 | G26: Cost = quantity x seasonality x monthly market price | H26: =$C26*H25 | I26: =$C26*I25 | J26: =$C26*J25 | K26: =$C26*K25 | L26: =$C26*L25 | M26: =$C26*M25 | N26: =$C26*N25 | O26: =$C26*O25 | ... AQ26: =$C26*AQ25
A27: Fixed costs | B27: Machine maintenance, blades and tooling - market price | C27: 1.0257 | D27: monthly package | E27: =AVERAGE(H27:AQ27) | G27: INSEE BDM 010777481: Indice mensuel des prix d'achat des moyens de production agricole (IPAMPA) - Entretien et réparation; normalized to model unit price | H27: 6250 | I27: 6256.1335 | J27: 6280.6673 | K27: 6262.2669 | L27: 6274.5339 | M27: 6292.9342 | N27: 6317.4681 | O27: 6317.4681 | P27: 6329.735 | Q27: 6354.2689 | R27: 6372.6693 | S27: 6391.0697 | T27: 6458.5378 | U27: 6483.0716 | V27: 6519.8724 | W27: 6562.8067 | X27: 6605.7409 | Y27: 6667.0756 | Z27: 6722.2767 | AA27: 6765.211 | AB27: 6795.8783 | AC27: 6820.4122 | AD27: 6844.946 | AE27: 6869.4799 | AF27: 7004.4161 | AG27: 7071.8842 | AH27: 7108.685 | AI27: 7145.4858 | AJ27: 7163.8862 | AK27: 7176.1531 | AL27: 7194.5535 | AM27: 7212.9539 | AN27: 7249.7547 | AO27: 7286.5554 | AP27: 7304.9558 | AQ27: 7323.3562
A28: Fixed costs | B28: Cost (Machine maintenance, blades and tooling) | C28: 1.0257 | D28: monthly package | E28: =E27 | G28: Cost = quantity x seasonality x monthly market price | H28: =$C28*H27 | I28: =$C28*I27 | J28: =$C28*J27 | K28: =$C28*K27 | L28: =$C28*L27 | M28: =$C28*M27 | N28: =$C28*N27 | O28: =$C28*O27 | ... AQ28: =$C28*AQ27
A29: Fixed costs | B29: Insurance, admin, accounting - market price | C29: 0.9715 | D29: monthly package | E29: =AVERAGE(H29:AQ29) | G29: INSEE BDM 010766756: Indices des prix de production des services français aux entreprises françaises (BtoB) − CPF 82.11 − Services administratifs combinés ; normalized to model unit price | H29: 5625 | I29: 5625 | J29: 5625 | K29: 5625 | L29: 5625 | M29: 5625 | N29: 5625 | O29: 5625 | P29: 5625 | Q29: 5625 | R29: 5625 | S29: 5625 | T29: 5625 | U29: 5625 | V29: 5625 | W29: 5625 | X29: 5625 | Y29: 5625 | Z29: 5625 | AA29: 5625 | AB29: 5625 | AC29: 5625 | AD29: 5625 | AE29: 5625 | AF29: 5625 | AG29: 5625 | AH29: 5625 | AI29: 5625 | AJ29: 5625 | AK29: 5625 | AL29: 5625 | AM29: 5625 | AN29: 5625 | AO29: 5625 | AP29: 5625 | AQ29: 5625
A30: Fixed costs | B30: Cost (Insurance, admin, accounting) | C30: 0.9715 | D30: monthly package | E30: =E29 | G30: Cost = quantity x seasonality x monthly market price | H30: =$C30*H29 | I30: =$C30*I29 | J30: =$C30*J29 | K30: =$C30*K29 | L30: =$C30*L29 | M30: =$C30*M29 | N30: =$C30*N29 | O30: =$C30*O29 | ... AQ30: =$C30*AQ29
A31: SOUS-TOTAL Fixed costs | H31: =SUM(H26,H28,H30) | I31: =SUM(I26,I28,I30) | J31: =SUM(J26,J28,J30) | K31: =SUM(K26,K28,K30) | L31: =SUM(L26,L28,L30) | M31: =SUM(M26,M28,M30) | N31: =SUM(N26,N28,N30) | O31: =SUM(O26,O28,O30) | ... AQ31: =SUM(AQ26,AQ28,AQ30)
A33: TOTAL GENERAL DEPENSES | H33: =SUM(H15,H18,H21,H24,H31) | I33: =SUM(I15,I18,I21,I24,I31) | J33: =SUM(J15,J18,J21,J24,J31) | K33: =SUM(K15,K18,K21,K24,K31) | L33: =SUM(L15,L18,L21,L24,L31) | M33: =SUM(M15,M18,M21,M24,M31) | N33: =SUM(N15,N18,N21,N24,N31) | O33: =SUM(O15,O18,O21,O24,O31) | ... AQ33: =SUM(AQ15,AQ18,AQ21,AQ24,AQ31)
A34: Total depenses A1 / CA A1 | C34: =SUM(H33:S33)/'Hypotheses'!$C$4

Sheet Plan de tresorerie
A1: Menuiserie Bois - Plan de tresorerie mensuel
A2: Opening cash + collections - disbursements = ending cash.
C3: ANNEE 1 | O3: ANNEE 2 | AA3: ANNEE 3
A4: Mois | C4: Jan A1 | D4: Feb A1 | E4: Mar A1 | F4: Apr A1 | G4: May A1 | H4: Jun A1 | I4: Jul A1 | J4: Aug A1 | K4: Sep A1 | L4: Oct A1 | M4: Nov A1 | N4: Dec A1 | O4: Jan A2 | P4: Feb A2 | Q4: Mar A2 | R4: Apr A2 | S4: May A2 | T4: Jun A2 | U4: Jul A2 | V4: Aug A2 | W4: Sep A2 | X4: Oct A2 | Y4: Nov A2 | Z4: Dec A2 | AA4: Jan A3 | AB4: Feb A3 | AC4: Mar A3 | AD4: Apr A3 | AE4: May A3 | AF4: Jun A3 | AG4: Jul A3 | AH4: Aug A3 | AI4: Sep A3 | AJ4: Oct A3 | AK4: Nov A3 | AL4: Dec A3
A5: Tresorerie en debut de mois | C5: ='Hypotheses'!$C$7 | D5: =C18 | E5: =D18 | F5: =E18 | G5: =F18 | H5: =G18 | I5: =H18 | J5: =I18 | K5: =J18 | ... AL5: =AK18
A6: ENCAISSEMENTS
A7: Encaissements clients TTC | C7: ='Revenus'!C11*'Hypotheses'!$C$10+0+0 | D7: ='Revenus'!D11*'Hypotheses'!$C$10+'Revenus'!C11*'Hypotheses'!$C$11+0 | E7: ='Revenus'!E11*'Hypotheses'!$C$10+'Revenus'!D11*'Hypotheses'!$C$11+'Revenus'!C11*'Hypotheses'!$C$12 | F7: ='Revenus'!F11*'Hypotheses'!$C$10+'Revenus'!E11*'Hypotheses'!$C$11+'Revenus'!D11*'Hypotheses'!$C$12 | G7: ='Revenus'!G11*'Hypotheses'!$C$10+'Revenus'!F11*'Hypotheses'!$C$11+'Revenus'!E11*'Hypotheses'!$C$12 | H7: ='Revenus'!H11*'Hypotheses'!$C$10+'Revenus'!G11*'Hypotheses'!$C$11+'Revenus'!F11*'Hypotheses'!$C$12 | I7: ='Revenus'!I11*'Hypotheses'!$C$10+'Revenus'!H11*'Hypotheses'!$C$11+'Revenus'!G11*'Hypotheses'!$C$12 | J7: ='Revenus'!J11*'Hypotheses'!$C$10+'Revenus'!I11*'Hypotheses'!$C$11+'Revenus'!H11*'Hypotheses'!$C$12 | K7: ='Revenus'!K11*'Hypotheses'!$C$10+'Revenus'!J11*'Hypotheses'!$C$11+'Revenus'!I11*'Hypotheses'!$C$12 | L7: ='Revenus'!L11*'Hypotheses'!$C$10+'Revenus'!K11*'Hypotheses'!$C$11+'Revenus'!J11*'Hypotheses'!$C$12 | ... AL7: ='Revenus'!AL11*'Hypotheses'!$C$10+'Revenus'!AK11*'Hypotheses'!$C$11+'Revenus'!AJ11*'Hypotheses'!$C$12
A8: TOTAL ENCAISSEMENTS | C8: =C7 | D8: =D7 | E8: =E7 | F8: =F7 | G8: =G7 | H8: =H7 | I8: =I7 | J8: =J7 | ... AL8: =AL7
A9: DECAISSEMENTS
A10: Achats variables et commodity-linked | C10: =SUM('Depenses detaillees'!H15,'Depenses detaillees'!H18,'Depenses detaillees'!H21) | D10: =SUM('Depenses detaillees'!I15,'Depenses detaillees'!I18,'Depenses detaillees'!I21) | E10: =SUM('Depenses detaillees'!J15,'Depenses detaillees'!J18,'Depenses detaillees'!J21) | F10: =SUM('Depenses detaillees'!K15,'Depenses detaillees'!K18,'Depenses detaillees'!K21) | G10: =SUM('Depenses detaillees'!L15,'Depenses detaillees'!L18,'Depenses detaillees'!L21) | H10: =SUM('Depenses detaillees'!M15,'Depenses detaillees'!M18,'Depenses detaillees'!M21) | I10: =SUM('Depenses detaillees'!N15,'Depenses detaillees'!N18,'Depenses detaillees'!N21) | J10: =SUM('Depenses detaillees'!O15,'Depenses detaillees'!O18,'Depenses detaillees'!O21) | ... AL10: =SUM('Depenses detaillees'!AQ15,'Depenses detaillees'!AQ18,'Depenses detaillees'!AQ21)
A11: Personnel | C11: =SUM('Depenses detaillees'!H24) | D11: =SUM('Depenses detaillees'!I24) | E11: =SUM('Depenses detaillees'!J24) | F11: =SUM('Depenses detaillees'!K24) | G11: =SUM('Depenses detaillees'!L24) | H11: =SUM('Depenses detaillees'!M24) | I11: =SUM('Depenses detaillees'!N24) | J11: =SUM('Depenses detaillees'!O24) | ... AL11: =SUM('Depenses detaillees'!AQ24)
A12: Charges fixes et maintenance | C12: =SUM('Depenses detaillees'!H31) | D12: =SUM('Depenses detaillees'!I31) | E12: =SUM('Depenses detaillees'!J31) | F12: =SUM('Depenses detaillees'!K31) | G12: =SUM('Depenses detaillees'!L31) | H12: =SUM('Depenses detaillees'!M31) | I12: =SUM('Depenses detaillees'!N31) | J12: =SUM('Depenses detaillees'!O31) | ... AL12: =SUM('Depenses detaillees'!AQ31)
A13: Cotisations sociales dirigeant | C13: 0 | D13: 0 | E13: ='Hypotheses'!$C$8*(1+'Hypotheses'!$C$14)^0 | F13: 0 | G13: 0 | H13: ='Hypotheses'!$C$8*(1+'Hypotheses'!$C$14)^0 | I13: 0 | J13: 0 | K13: ='Hypotheses'!$C$8*(1+'Hypotheses'!$C$14)^0 | L13: 0 | M13: 0 | N13: ='Hypotheses'!$C$8*(1+'Hypotheses'!$C$14)^0 | O13: 0 | P13: 0 | Q13: ='Hypotheses'!$C$8*(1+'Hypotheses'!$C$14)^1 | R13: 0 | S13: 0 | T13: ='Hypotheses'!$C$8*(1+'Hypotheses'!$C$14)^1 | U13: 0 | V13: 0 | W13: ='Hypotheses'!$C$8*(1+'Hypotheses'!$C$14)^1 | X13: 0 | Y13: 0 | Z13: ='Hypotheses'!$C$8*(1+'Hypotheses'!$C$14)^1 | AA13: 0 | AB13: 0 | AC13: ='Hypotheses'!$C$8*(1+'Hypotheses'!$C$14)^2 | AD13: 0 | AE13: 0 | AF13: ='Hypotheses'!$C$8*(1+'Hypotheses'!$C$14)^2 | AG13: 0 | AH13: 0 | AI13: ='Hypotheses'!$C$8*(1+'Hypotheses'!$C$14)^2 | AJ13: 0 | AK13: 0 | AL13: ='Hypotheses'!$C$8*(1+'Hypotheses'!$C$14)^2
A14: TVA nette versee | C14: 0 | D14: 0 | E14: =MAX(0,SUM(C22:E22)) | F14: 0 | G14: 0 | H14: =MAX(0,SUM(F22:H22)) | I14: 0 | J14: 0 | K14: =MAX(0,SUM(I22:K22)) | L14: 0 | M14: 0 | N14: =MAX(0,SUM(L22:N22)) | O14: 0 | P14: 0 | Q14: =MAX(0,SUM(O22:Q22)) | R14: 0 | S14: 0 | T14: =MAX(0,SUM(R22:T22)) | U14: 0 | V14: 0 | W14: =MAX(0,SUM(U22:W22)) | X14: 0 | Y14: 0 | Z14: =MAX(0,SUM(X22:Z22)) | AA14: 0 | AB14: 0 | AC14: =MAX(0,SUM(AA22:AC22)) | AD14: 0 | AE14: 0 | AF14: =MAX(0,SUM(AD22:AF22)) | AG14: 0 | AH14: 0 | AI14: =MAX(0,SUM(AG22:AI22)) | AJ14: 0 | AK14: 0 | AL14: =MAX(0,SUM(AJ22:AL22))
A15: Remboursement emprunt materiel | C15: ='Hypotheses'!$C$9 | D15: ='Hypotheses'!$C$9 | E15: ='Hypotheses'!$C$9 | F15: ='Hypotheses'!$C$9 | G15: ='Hypotheses'!$C$9 | H15: ='Hypotheses'!$C$9 | I15: ='Hypotheses'!$C$9 | J15: ='Hypotheses'!$C$9 | ... AL15: ='Hypotheses'!$C$9
A16: TOTAL DECAISSEMENTS | C16: =SUM(C10:C15) | D16: =SUM(D10:D15) | E16: =SUM(E10:E15) | F16: =SUM(F10:F15) | G16: =SUM(G10:G15) | H16: =SUM(H10:H15) | I16: =SUM(I10:I15) | J16: =SUM(J10:J15) | ... AL16: =SUM(AL10:AL15)
A17: Variation de tresorerie du mois | C17: =C8-C16 | D17: =D8-D16 | E17: =E8-E16 | F17: =F8-F16 | G17: =G8-G16 | H17: =H8-H16 | I17: =I8-I16 | J17: =J8-J16 | ... AL17: =AL8-AL16
A18: TRESORERIE EN FIN DE MOIS | C18: =C5+C17 | D18: =D5+D17 | E18: =E5+E17 | F18: =F5+F17 | G18: =G5+G17 | H18: =H5+H17 | I18: =I5+I17 | J18: =J5+J17 | ... AL18: =AL5+AL17
A20: Memo - TVA collectee du mois | C20: ='Revenus'!C10 | D20: ='Revenus'!D10 | E20: ='Revenus'!E10 | F20: ='Revenus'!F10 | G20: ='Revenus'!G10 | H20: ='Revenus'!H10 | I20: ='Revenus'!I10 | J20: ='Revenus'!J10 | ... AL20: ='Revenus'!AL10
A21: Memo - TVA deductible du mois | C21: =(C10+C12)*'Hypotheses'!$C$6 | D21: =(D10+D12)*'Hypotheses'!$C$6 | E21: =(E10+E12)*'Hypotheses'!$C$6 | F21: =(F10+F12)*'Hypotheses'!$C$6 | G21: =(G10+G12)*'Hypotheses'!$C$6 | H21: =(H10+H12)*'Hypotheses'!$C$6 | I21: =(I10+I12)*'Hypotheses'!$C$6 | J21: =(J10+J12)*'Hypotheses'!$C$6 | ... AL21: =(AL10+AL12)*'Hypotheses'!$C$6
A22: Memo - TVA nette du mois | C22: =C20-C21 | D22: =D20-D21 | E22: =E20-E21 | F22: =F20-F21 | G22: =G20-G21 | H22: =H20-H21 | I22: =I20-I21 | J22: =J20-J21 | ... AL22: =AL20-AL21
A24: Minimum cash over period | C24: =MIN(C18:AL18)

Sheet Market data
A1: Market data used by model
A2: External series are normalized to each model unit price to preserve realistic movement without unit mismatch.
A4: Cost line | B4: Underlying | C4: Market code | D4: Source | E4: Model unit | F4: Model unit price | G4: Month | H4: Value
A5: Insurance, admin, accounting | C5: ADMIN_SERVICES | D5: INSEE BDM 010766756: Indices des prix de production des services français aux entreprises françaises (BtoB) − CPF 82.11 − Services administratifs combinés | E5: monthly package | F5: 5625 | G5: 2021-01 | H5: 5625
A6: Insurance, admin, accounting | C6: ADMIN_SERVICES | D6: INSEE BDM 010766756: Indices des prix de production des services français aux entreprises françaises (BtoB) − CPF 82.11 − Services administratifs combinés | E6: monthly package | F6: 5625 | G6: 2021-02 | H6: 5625
A7: Insurance, admin, accounting | C7: ADMIN_SERVICES | D7: INSEE BDM 010766756: Indices des prix de production des services français aux entreprises françaises (BtoB) − CPF 82.11 − Services administratifs combinés | E7: monthly package | F7: 5625 | G7: 2021-03 | H7: 5625
A8: Insurance, admin, accounting | C8: ADMIN_SERVICES | D8: INSEE BDM 010766756: Indices des prix de production des services français aux entreprises françaises (BtoB) − CPF 82.11 − Services administratifs combinés | E8: monthly package | F8: 5625 | G8: 2021-04 | H8: 5625
A9: Insurance, admin, accounting | C9: ADMIN_SERVICES | D9: INSEE BDM 010766756: Indices des prix de production des services français aux entreprises françaises (BtoB) − CPF 82.11 − Services administratifs combinés | E9: monthly package | F9: 5625 | G9: 2021-05 | H9: 5625
A10: Insurance, admin, accounting | C10: ADMIN_SERVICES | D10: INSEE BDM 010766756: Indices des prix de production des services français aux entreprises françaises (BtoB) − CPF 82.11 − Services administratifs combinés | E10: monthly package | F10: 5625 | G10: 2021-06 | H10: 5625
A11: Insurance, admin, accounting | C11: ADMIN_SERVICES | D11: INSEE BDM 010766756: Indices des prix de production des services français aux entreprises françaises (BtoB) − CPF 82.11 − Services administratifs combinés | E11: monthly package | F11: 5625 | G11: 2021-07 | H11: 5625
A12: Insurance, admin, accounting | C12: ADMIN_SERVICES | D12: INSEE BDM 010766756: Indices des prix de production des services français aux entreprises françaises (BtoB) − CPF 82.11 − Services administratifs combinés | E12: monthly package | F12: 5625 | G12: 2021-08 | H12: 5625
A13: Insurance, admin, accounting | C13: ADMIN_SERVICES | D13: INSEE BDM 010766756: Indices des prix de production des services français aux entreprises françaises (BtoB) − CPF 82.11 − Services administratifs combinés | E13: monthly package | F13: 5625 | G13: 2021-09 | H13: 5625
A14: Insurance, admin, accounting | C14: ADMIN_SERVICES | D14: INSEE BDM 010766756: Indices des prix de production des services français aux entreprises françaises (BtoB) − CPF 82.11 − Services administratifs combinés | E14: monthly package | F14: 5625 | G14: 2021-10 | H14: 5625
A15: Insurance, admin, accounting | C15: ADMIN_SERVICES | D15: INSEE BDM 010766756: Indices des prix de production des services français aux entreprises françaises (BtoB) − CPF 82.11 − Services administratifs combinés | E15: monthly package | F15: 5625 | G15: 2021-11 | H15: 5625
A16: Insurance, admin, accounting | C16: ADMIN_SERVICES | D16: INSEE BDM 010766756: Indices des prix de production des services français aux entreprises françaises (BtoB) − CPF 82.11 − Services administratifs combinés | E16: monthly package | F16: 5625 | G16: 2021-12 | H16: 5625
... A40: Insurance, admin, accounting | C40: ADMIN_SERVICES | D40: INSEE BDM 010766756: Indices des prix de production des services français aux entreprises françaises (BtoB) − CPF 82.11 − Services administratifs combinés | E40: monthly package | F40: 5625 | G40: 2023-12 | H40: 5625
A41: Aluminium rails and light fittings | B41: Aluminium | C41: ALUMINUM | D41: INSEE BDM 010002041: Cours des matières premières importées - Aluminium, pureté 99,7 % - Prix d’acquisition au comptant, LME (London Metal Exchange) - Prix en dollars US par tonne | E41: kg | F41: 2.6 | G41: 2021-01 | H41: 2.6
A42: Aluminium rails and light fittings | B42: Aluminium | C42: ALUMINUM | D42: INSEE BDM 010002041: Cours des matières premières importées - Aluminium, pureté 99,7 % - Prix d’acquisition au comptant, LME (London Metal Exchange) - Prix en dollars US par tonne | E42: kg | F42: 2.6 | G42: 2021-02 | H42: 2.6984
A43: Aluminium rails and light fittings | B43: Aluminium | C43: ALUMINUM | D43: INSEE BDM 010002041: Cours des matières premières importées - Aluminium, pureté 99,7 % - Prix d’acquisition au comptant, LME (London Metal Exchange) - Prix en dollars US par tonne | E43: kg | F43: 2.6 | G43: 2021-03 | H43: 2.8437
A44: Aluminium rails and light fittings | B44: Aluminium | C44: ALUMINUM | D44: INSEE BDM 010002041: Cours des matières premières importées - Aluminium, pureté 99,7 % - Prix d’acquisition au comptant, LME (London Metal Exchange) - Prix en dollars US par tonne | E44: kg | F44: 2.6 | G44: 2021-04 | H44: 3.0152
A45: Aluminium rails and light fittings | B45: Aluminium | C45: ALUMINUM | D45: INSEE BDM 010002041: Cours des matières premières importées - Aluminium, pureté 99,7 % - Prix d’acquisition au comptant, LME (London Metal Exchange) - Prix en dollars US par tonne | E45: kg | F45: 2.6 | G45: 2021-05 | H45: 3.1579
A46: Aluminium rails and light fittings | B46: Aluminium | C46: ALUMINUM | D46: INSEE BDM 010002041: Cours des matières premières importées - Aluminium, pureté 99,7 % - Prix d’acquisition au comptant, LME (London Metal Exchange) - Prix en dollars US par tonne | E46: kg | F46: 2.6 | G46: 2021-06 | H46: 3.1648
A47: Aluminium rails and light fittings | B47: Aluminium | C47: ALUMINUM | D47: INSEE BDM 010002041: Cours des matières premières importées - Aluminium, pureté 99,7 % - Prix d’acquisition au comptant, LME (London Metal Exchange) - Prix en dollars US par tonne | E47: kg | F47: 2.6 | G47: 2021-07 | H47: 3.2335
A48: Aluminium rails and light fittings | B48: Aluminium | C48: ALUMINUM | D48: INSEE BDM 010002041: Cours des matières premières importées - Aluminium, pureté 99,7 % - Prix d’acquisition au comptant, LME (London Metal Exchange) - Prix en dollars US par tonne | E48: kg | F48: 2.6 | G48: 2021-08 | H48: 3.3873
A49: Aluminium rails and light fittings | B49: Aluminium | C49: ALUMINUM | D49: INSEE BDM 010002041: Cours des matières premières importées - Aluminium, pureté 99,7 % - Prix d’acquisition au comptant, LME (London Metal Exchange) - Prix en dollars US par tonne | E49: kg | F49: 2.6 | G49: 2021-09 | H49: 3.684
A50: Aluminium rails and light fittings | B50: Aluminium | C50: ALUMINUM | D50: INSEE BDM 010002041: Cours des matières premières importées - Aluminium, pureté 99,7 % - Prix d’acquisition au comptant, LME (London Metal Exchange) - Prix en dollars US par tonne | E50: kg | F50: 2.6 | G50: 2021-10 | H50: 3.8336
A51: Aluminium rails and light fittings | B51: Aluminium | C51: ALUMINUM | D51: INSEE BDM 010002041: Cours des matières premières importées - Aluminium, pureté 99,7 % - Prix d’acquisition au comptant, LME (London Metal Exchange) - Prix en dollars US par tonne | E51: kg | F51: 2.6 | G51: 2021-11 | H51: 3.4264
A52: Aluminium rails and light fittings | B52: Aluminium | C52: ALUMINUM | D52: INSEE BDM 010002041: Cours des matières premières importées - Aluminium, pureté 99,7 % - Prix d’acquisition au comptant, LME (London Metal Exchange) - Prix en dollars US par tonne | E52: kg | F52: 2.6 | G52: 2021-12 | H52: 3.4961
... A220: Steel screws, brackets and structural hardware | B220: Steel | C220: IRON_ORE | D220: INSEE BDM 010002059: Cours des matières premières importées - Minerai de fer, Type 62 % Fe - Importations chinoises, port de Tianjin - Prix au comptant - CAF - Prix en dollars US par tonne | E220: kg | F220: 0.95 | G220: 2023-12 | H220: 0.768
A221: Workshop payroll and charges | C221: LABOR_INDUSTRY | D221: INSEE BDM 010762004: Indice du coût du travail - Coût horaire - Industrie manufacturière (NAF rév. 2 section C) - Base 100 en 2020 | E221: monthly package | F221: 38750 | G221: 2021-01 | H221: 38750
A222: Workshop payroll and charges | C222: LABOR_INDUSTRY | D222: INSEE BDM 010762004: Indice du coût du travail - Coût horaire - Industrie manufacturière (NAF rév. 2 section C) - Base 100 en 2020 | E222: monthly package | F222: 38750 | G222: 2021-02 | H222: 38750
A223: Workshop payroll and charges | C223: LABOR_INDUSTRY | D223: INSEE BDM 010762004: Indice du coût du travail - Coût horaire - Industrie manufacturière (NAF rév. 2 section C) - Base 100 en 2020 | E223: monthly package | F223: 38750 | G223: 2021-03 | H223: 38750
A224: Workshop payroll and charges | C224: LABOR_INDUSTRY | D224: INSEE BDM 010762004: Indice du coût du travail - Coût horaire - Industrie manufacturière (NAF rév. 2 section C) - Base 100 en 2020 | E224: monthly package | F224: 38750 | G224: 2021-04 | H224: 38750
A225: Workshop payroll and charges | C225: LABOR_INDUSTRY | D225: INSEE BDM 010762004: Indice du coût du travail - Coût horaire - Industrie manufacturière (NAF rév. 2 section C) - Base 100 en 2020 | E225: monthly package | F225: 38750 | G225: 2021-05 | H225: 38750
A226: Workshop payroll and charges | C226: LABOR_INDUSTRY | D226: INSEE BDM 010762004: Indice du coût du travail - Coût horaire - Industrie manufacturière (NAF rév. 2 section C) - Base 100 en 2020 | E226: monthly package | F226: 38750 | G226: 2021-06 | H226: 38750
A227: Workshop payroll and charges | C227: LABOR_INDUSTRY | D227: INSEE BDM 010762004: Indice du coût du travail - Coût horaire - Industrie manufacturière (NAF rév. 2 section C) - Base 100 en 2020 | E227: monthly package | F227: 38750 | G227: 2021-07 | H227: 38750
A228: Workshop payroll and charges | C228: LABOR_INDUSTRY | D228: INSEE BDM 010762004: Indice du coût du travail - Coût horaire - Industrie manufacturière (NAF rév. 2 section C) - Base 100 en 2020 | E228: monthly package | F228: 38750 | G228: 2021-08 | H228: 38750
A229: Workshop payroll and charges | C229: LABOR_INDUSTRY | D229: INSEE BDM 010762004: Indice du coût du travail - Coût horaire - Industrie manufacturière (NAF rév. 2 section C) - Base 100 en 2020 | E229: monthly package | F229: 38750 | G229: 2021-09 | H229: 38750
A230: Workshop payroll and charges | C230: LABOR_INDUSTRY | D230: INSEE BDM 010762004: Indice du coût du travail - Coût horaire - Industrie manufacturière (NAF rév. 2 section C) - Base 100 en 2020 | E230: monthly package | F230: 38750 | G230: 2021-10 | H230: 38750
A231: Workshop payroll and charges | C231: LABOR_INDUSTRY | D231: INSEE BDM 010762004: Indice du coût du travail - Coût horaire - Industrie manufacturière (NAF rév. 2 section C) - Base 100 en 2020 | E231: monthly package | F231: 38750 | G231: 2021-11 | H231: 38750
...

Sheet Benchmarks & sources
A1: Menuiserie Bois - Benchmarks & sources
A2: Ratios and API sources used to construct the synthetic cash-plan model.
A4: Item | B4: Value retained | C4: Source | D4: Comment
A5: Annual revenue A1 | B5: 1500000 | C5: Generated profile | D5: Editable in Hypotheses
A6: Archetype | B6: woodworking | C6: Local inference | D6: Selected from business description keywords
A7: Commodity API mode | B7: online | C7: Generator flag | D7: Offline mode uses deterministic synthetic series
A8: Commodity monthly history | B8: INSEE BDM, ENTSO-E, World Bank Pink Sheet or Alpha Vantage when enabled | C8: https://bdm.insee.fr/series/sdmx/dataflow | D8: Online mode uses curated INSEE IDBANK series first, then venue/API-specific market data and synthetic fallback only when unavailable.
A9: French statistical series | B9: INSEE BDM API | C9: https://www.insee.fr/fr/information/2862759 | D9: Official INSEE SDMX web service for time-series data. Exact series IDs can be configured later.
A10: Business ratios | B10: Generated benchmark assumptions | C10: local archetype generator | D10: Ratios are v1 synthetic assumptions, designed to be replaced by INSEE/sector benchmark series.
A11: Industrial cost preset | B11: Woodworking / furniture workshop | C11: cashplan/industrial_costs.py | D11: Industrial SME making wood products, furniture, packaging or carpentry.
A12: Industrial ratio method | B12: Revenue-share driver model | C12: local generator | D12: Each cost line starts from an annual revenue share, unit price and realistic monthly quantity.
A13: Industrial metals coverage | B13: Aluminium, copper, iron ore, lead, nickel, tin, zinc | C13: https://www.worldbank.org/en/research/commodity-markets | D13: World Bank Pink Sheet is the primary no-key monthly source for detailed base metals.
A14: Base metal index components | B14: Aluminium, copper, lead, nickel, tin, zinc | C14: World Bank Commodity Markets Chapter 4 | D14: World Bank documentation describes the base metal index as covering these metals.
